2022-09-14 08:23:43,678 [autoreload | INFO] Watching for file changes with StatReloader
2022-09-14 08:24:26,530 [autoreload | INFO] /Users/zharkynaskatkyzy/PycharmProjects/Zmall/server/apps/advert/models.py changed, reloading.
2022-09-14 08:24:27,161 [autoreload | INFO] Watching for file changes with StatReloader
2022-09-14 08:24:52,244 [autoreload | INFO] /Users/zharkynaskatkyzy/PycharmProjects/Zmall/server/config/settings/base.py changed, reloading.
2022-09-14 08:24:52,717 [autoreload | INFO] Watching for file changes with StatReloader
2022-09-14 08:25:32,793 [log | ERROR] Internal Server Error: /api/v1/advert_report/
Traceback (most recent call last):
  File "/Library/Frameworks/Python.framework/Versions/3.10/lib/python3.10/site-packages/django/db/backends/utils.py", line 89, in _execute
    return self.cursor.execute(sql, params)
psycopg2.errors.NotNullViolation: null value in column "report" of relation "advert_advertreport" violates not-null constraint
DETAIL:  Failing row contains (2, 'sth', null, 1).


The above exception was the direct cause of the following exception:

Traceback (most recent call last):
  File "/Library/Frameworks/Python.framework/Versions/3.10/lib/python3.10/site-packages/django/core/handlers/exception.py", line 55, in inner
    response = get_response(request)
  File "/Library/Frameworks/Python.framework/Versions/3.10/lib/python3.10/site-packages/django/core/handlers/base.py", line 197, in _get_response
    response = wrapped_callback(request, *callback_args, **callback_kwargs)
  File "/Library/Frameworks/Python.framework/Versions/3.10/lib/python3.10/site-packages/django/views/decorators/csrf.py", line 54, in wrapped_view
    return view_func(*args, **kwargs)
  File "/Library/Frameworks/Python.framework/Versions/3.10/lib/python3.10/site-packages/django/views/generic/base.py", line 103, in view
    return self.dispatch(request, *args, **kwargs)
  File "/Library/Frameworks/Python.framework/Versions/3.10/lib/python3.10/site-packages/rest_framework/views.py", line 509, in dispatch
    response = self.handle_exception(exc)
  File "/Library/Frameworks/Python.framework/Versions/3.10/lib/python3.10/site-packages/rest_framework/views.py", line 469, in handle_exception
    self.raise_uncaught_exception(exc)
  File "/Library/Frameworks/Python.framework/Versions/3.10/lib/python3.10/site-packages/rest_framework/views.py", line 480, in raise_uncaught_exception
    raise exc
  File "/Library/Frameworks/Python.framework/Versions/3.10/lib/python3.10/site-packages/rest_framework/views.py", line 506, in dispatch
    response = handler(request, *args, **kwargs)
  File "/Library/Frameworks/Python.framework/Versions/3.10/lib/python3.10/site-packages/rest_framework/generics.py", line 190, in post
    return self.create(request, *args, **kwargs)
  File "/Library/Frameworks/Python.framework/Versions/3.10/lib/python3.10/site-packages/rest_framework/mixins.py", line 19, in create
    self.perform_create(serializer)
  File "/Library/Frameworks/Python.framework/Versions/3.10/lib/python3.10/site-packages/rest_framework/mixins.py", line 24, in perform_create
    serializer.save()
  File "/Library/Frameworks/Python.framework/Versions/3.10/lib/python3.10/site-packages/rest_framework/serializers.py", line 212, in save
    self.instance = self.create(validated_data)
  File "/Library/Frameworks/Python.framework/Versions/3.10/lib/python3.10/site-packages/rest_framework/serializers.py", line 962, in create
    instance = ModelClass._default_manager.create(**validated_data)
  File "/Library/Frameworks/Python.framework/Versions/3.10/lib/python3.10/site-packages/django/db/models/manager.py", line 85, in manager_method
    return getattr(self.get_queryset(), name)(*args, **kwargs)
  File "/Library/Frameworks/Python.framework/Versions/3.10/lib/python3.10/site-packages/django/db/models/query.py", line 671, in create
    obj.save(force_insert=True, using=self.db)
  File "/Library/Frameworks/Python.framework/Versions/3.10/lib/python3.10/site-packages/django/db/models/base.py", line 831, in save
    self.save_base(
  File "/Library/Frameworks/Python.framework/Versions/3.10/lib/python3.10/site-packages/django/db/models/base.py", line 882, in save_base
    updated = self._save_table(
  File "/Library/Frameworks/Python.framework/Versions/3.10/lib/python3.10/site-packages/django/db/models/base.py", line 1025, in _save_table
    results = self._do_insert(
  File "/Library/Frameworks/Python.framework/Versions/3.10/lib/python3.10/site-packages/django/db/models/base.py", line 1066, in _do_insert
    return manager._insert(
  File "/Library/Frameworks/Python.framework/Versions/3.10/lib/python3.10/site-packages/django/db/models/manager.py", line 85, in manager_method
    return getattr(self.get_queryset(), name)(*args, **kwargs)
  File "/Library/Frameworks/Python.framework/Versions/3.10/lib/python3.10/site-packages/django/db/models/query.py", line 1790, in _insert
    return query.get_compiler(using=using).execute_sql(returning_fields)
  File "/Library/Frameworks/Python.framework/Versions/3.10/lib/python3.10/site-packages/django/db/models/sql/compiler.py", line 1657, in execute_sql
    cursor.execute(sql, params)
  File "/Library/Frameworks/Python.framework/Versions/3.10/lib/python3.10/site-packages/django/db/backends/utils.py", line 103, in execute
    return super().execute(sql, params)
  File "/Library/Frameworks/Python.framework/Versions/3.10/lib/python3.10/site-packages/django/db/backends/utils.py", line 67, in execute
    return self._execute_with_wrappers(
  File "/Library/Frameworks/Python.framework/Versions/3.10/lib/python3.10/site-packages/django/db/backends/utils.py", line 80, in _execute_with_wrappers
    return executor(sql, params, many, context)
  File "/Library/Frameworks/Python.framework/Versions/3.10/lib/python3.10/site-packages/django/db/backends/utils.py", line 84, in _execute
    with self.db.wrap_database_errors:
  File "/Library/Frameworks/Python.framework/Versions/3.10/lib/python3.10/site-packages/django/db/utils.py", line 91, in __exit__
    raise dj_exc_value.with_traceback(traceback) from exc_value
  File "/Library/Frameworks/Python.framework/Versions/3.10/lib/python3.10/site-packages/django/db/backends/utils.py", line 89, in _execute
    return self.cursor.execute(sql, params)
django.db.utils.IntegrityError: null value in column "report" of relation "advert_advertreport" violates not-null constraint
DETAIL:  Failing row contains (2, 'sth', null, 1).

2022-09-14 08:28:03,210 [autoreload | INFO] /Users/zharkynaskatkyzy/PycharmProjects/Zmall/server/apps/advert/admin.py changed, reloading.
2022-09-14 08:28:03,985 [autoreload | INFO] Watching for file changes with StatReloader
2022-09-14 08:28:56,230 [autoreload | INFO] /Users/zharkynaskatkyzy/PycharmProjects/Zmall/server/apps/advert/admin.py changed, reloading.
2022-09-14 08:28:56,781 [autoreload | INFO] Watching for file changes with StatReloader
2022-09-14 08:31:25,083 [autoreload | INFO] /Users/zharkynaskatkyzy/PycharmProjects/Zmall/server/apps/advert/admin.py changed, reloading.
2022-09-14 08:31:25,609 [autoreload | INFO] Watching for file changes with StatReloader
2022-09-14 08:32:47,274 [autoreload | INFO] /Users/zharkynaskatkyzy/PycharmProjects/Zmall/server/apps/advert/admin.py changed, reloading.
2022-09-14 08:32:47,859 [autoreload | INFO] Watching for file changes with StatReloader
2022-09-14 08:32:50,502 [log | WARNING] Not Found: /
2022-09-14 08:32:55,943 [log | WARNING] Not Found: /
2022-09-14 08:32:56,665 [base | WARNING] view's ContactView raised exception during schema generation; use `getattr(self, 'swagger_fake_view', False)` to detect and short-circuit this
Traceback (most recent call last):
  File "/Library/Frameworks/Python.framework/Versions/3.10/lib/python3.10/site-packages/drf_yasg/inspectors/base.py", line 42, in call_view_method
    return view_method()
  File "/Library/Frameworks/Python.framework/Versions/3.10/lib/python3.10/site-packages/rest_framework/generics.py", line 108, in get_serializer
    serializer_class = self.get_serializer_class()
  File "/Library/Frameworks/Python.framework/Versions/3.10/lib/python3.10/site-packages/rest_framework/generics.py", line 122, in get_serializer_class
    assert self.serializer_class is not None, (
AssertionError: 'ContactView' should either include a `serializer_class` attribute, or override the `get_serializer_class()` method.
2022-09-14 08:32:56,666 [base | WARNING] view's ContactView raised exception during schema generation; use `getattr(self, 'swagger_fake_view', False)` to detect and short-circuit this
Traceback (most recent call last):
  File "/Library/Frameworks/Python.framework/Versions/3.10/lib/python3.10/site-packages/drf_yasg/inspectors/base.py", line 42, in call_view_method
    return view_method()
  File "/Library/Frameworks/Python.framework/Versions/3.10/lib/python3.10/site-packages/rest_framework/generics.py", line 108, in get_serializer
    serializer_class = self.get_serializer_class()
  File "/Library/Frameworks/Python.framework/Versions/3.10/lib/python3.10/site-packages/rest_framework/generics.py", line 122, in get_serializer_class
    assert self.serializer_class is not None, (
AssertionError: 'ContactView' should either include a `serializer_class` attribute, or override the `get_serializer_class()` method.
2022-09-14 08:32:56,676 [base | WARNING] view's VerifyEmail raised exception during schema generation; use `getattr(self, 'swagger_fake_view', False)` to detect and short-circuit this
Traceback (most recent call last):
  File "/Library/Frameworks/Python.framework/Versions/3.10/lib/python3.10/site-packages/drf_yasg/inspectors/base.py", line 42, in call_view_method
    return view_method()
  File "/Library/Frameworks/Python.framework/Versions/3.10/lib/python3.10/site-packages/rest_framework/generics.py", line 108, in get_serializer
    serializer_class = self.get_serializer_class()
  File "/Library/Frameworks/Python.framework/Versions/3.10/lib/python3.10/site-packages/rest_framework/generics.py", line 122, in get_serializer_class
    assert self.serializer_class is not None, (
AssertionError: 'VerifyEmail' should either include a `serializer_class` attribute, or override the `get_serializer_class()` method.
2022-09-14 08:33:51,220 [autoreload | INFO] /Users/zharkynaskatkyzy/PycharmProjects/Zmall/server/apps/advert/admin.py changed, reloading.
2022-09-14 08:33:51,784 [autoreload | INFO] Watching for file changes with StatReloader
2022-09-14 08:34:38,974 [autoreload | INFO] /Users/zharkynaskatkyzy/PycharmProjects/Zmall/server/apps/advert/admin.py changed, reloading.
2022-09-14 08:34:39,733 [autoreload | INFO] Watching for file changes with StatReloader
2022-09-14 08:35:25,461 [autoreload | INFO] /Users/zharkynaskatkyzy/PycharmProjects/Zmall/server/apps/advert/admin.py changed, reloading.
2022-09-14 08:35:26,030 [autoreload | INFO] Watching for file changes with StatReloader
2022-09-14 08:36:06,909 [autoreload | INFO] /Users/zharkynaskatkyzy/PycharmProjects/Zmall/server/apps/advert/admin.py changed, reloading.
2022-09-14 08:36:07,460 [autoreload | INFO] Watching for file changes with StatReloader
2022-09-14 08:37:07,887 [autoreload | INFO] /Users/zharkynaskatkyzy/PycharmProjects/Zmall/server/apps/advert/models.py changed, reloading.
2022-09-14 08:37:08,477 [autoreload | INFO] Watching for file changes with StatReloader
2022-09-14 08:38:26,721 [autoreload | INFO] /Users/zharkynaskatkyzy/PycharmProjects/Zmall/server/apps/advert/admin.py changed, reloading.
2022-09-14 08:38:27,355 [autoreload | INFO] Watching for file changes with StatReloader
2022-09-14 08:38:32,635 [autoreload | INFO] /Users/zharkynaskatkyzy/PycharmProjects/Zmall/server/apps/advert/admin.py changed, reloading.
2022-09-14 08:38:33,072 [autoreload | INFO] Watching for file changes with StatReloader
2022-09-14 08:38:57,993 [autoreload | INFO] /Users/zharkynaskatkyzy/PycharmProjects/Zmall/server/apps/advert/serializers/advert_serializers.py changed, reloading.
2022-09-14 08:38:58,468 [autoreload | INFO] Watching for file changes with StatReloader
2022-09-14 08:39:10,970 [autoreload | INFO] /Users/zharkynaskatkyzy/PycharmProjects/Zmall/server/apps/advert/serializers/advert_serializers.py changed, reloading.
2022-09-14 08:39:11,496 [autoreload | INFO] Watching for file changes with StatReloader
2022-09-14 08:45:46,394 [autoreload | INFO] /Users/zharkynaskatkyzy/PycharmProjects/Zmall/server/apps/advert/views/advert_views.py changed, reloading.
2022-09-14 08:45:47,902 [autoreload | INFO] Watching for file changes with StatReloader
2022-09-14 08:50:37,147 [autoreload | INFO] /Users/zharkynaskatkyzy/PycharmProjects/Zmall/server/apps/advert/views/advert_views.py changed, reloading.
2022-09-14 08:50:37,921 [autoreload | INFO] Watching for file changes with StatReloader
2022-09-14 08:50:59,338 [log | WARNING] Not Found: /api/v1/user_advert
2022-09-14 08:51:10,734 [log | ERROR] Internal Server Error: /api/v1/user_advert/1
Traceback (most recent call last):
  File "/Library/Frameworks/Python.framework/Versions/3.10/lib/python3.10/site-packages/django/core/handlers/exception.py", line 55, in inner
    response = get_response(request)
  File "/Library/Frameworks/Python.framework/Versions/3.10/lib/python3.10/site-packages/django/core/handlers/base.py", line 197, in _get_response
    response = wrapped_callback(request, *callback_args, **callback_kwargs)
  File "/Library/Frameworks/Python.framework/Versions/3.10/lib/python3.10/site-packages/django/views/decorators/csrf.py", line 54, in wrapped_view
    return view_func(*args, **kwargs)
  File "/Library/Frameworks/Python.framework/Versions/3.10/lib/python3.10/site-packages/django/views/generic/base.py", line 103, in view
    return self.dispatch(request, *args, **kwargs)
  File "/Library/Frameworks/Python.framework/Versions/3.10/lib/python3.10/site-packages/rest_framework/views.py", line 509, in dispatch
    response = self.handle_exception(exc)
  File "/Library/Frameworks/Python.framework/Versions/3.10/lib/python3.10/site-packages/rest_framework/views.py", line 469, in handle_exception
    self.raise_uncaught_exception(exc)
  File "/Library/Frameworks/Python.framework/Versions/3.10/lib/python3.10/site-packages/rest_framework/views.py", line 480, in raise_uncaught_exception
    raise exc
  File "/Library/Frameworks/Python.framework/Versions/3.10/lib/python3.10/site-packages/rest_framework/views.py", line 506, in dispatch
    response = handler(request, *args, **kwargs)
  File "/Library/Frameworks/Python.framework/Versions/3.10/lib/python3.10/site-packages/rest_framework/generics.py", line 199, in get
    return self.list(request, *args, **kwargs)
  File "/Library/Frameworks/Python.framework/Versions/3.10/lib/python3.10/site-packages/rest_framework/mixins.py", line 38, in list
    queryset = self.filter_queryset(self.get_queryset())
  File "/Users/zharkynaskatkyzy/PycharmProjects/Zmall/server/apps/advert/views/advert_views.py", line 127, in get_queryset
    return Response(serializer.data, status=status.HTTP_200_OK)
  File "/Library/Frameworks/Python.framework/Versions/3.10/lib/python3.10/site-packages/rest_framework/serializers.py", line 555, in data
    ret = super().data
  File "/Library/Frameworks/Python.framework/Versions/3.10/lib/python3.10/site-packages/rest_framework/serializers.py", line 249, in data
    raise AssertionError(msg)
AssertionError: When a serializer is passed a `data` keyword argument you must call `.is_valid()` before attempting to access the serialized `.data` representation.
You should either call `.is_valid()` first, or access `.initial_data` instead.
2022-09-14 08:51:49,289 [autoreload | INFO] /Users/zharkynaskatkyzy/PycharmProjects/Zmall/server/apps/advert/views/advert_views.py changed, reloading.
2022-09-14 08:51:49,916 [autoreload | INFO] Watching for file changes with StatReloader
2022-09-14 08:51:52,506 [log | WARNING] Bad Request: /api/v1/user_advert/1
2022-09-14 08:52:24,493 [autoreload | INFO] /Users/zharkynaskatkyzy/PycharmProjects/Zmall/server/apps/advert/views/advert_views.py changed, reloading.
2022-09-14 08:52:25,023 [autoreload | INFO] Watching for file changes with StatReloader
2022-09-14 08:52:27,321 [log | WARNING] Bad Request: /api/v1/user_advert/1
2022-09-14 08:53:01,702 [autoreload | INFO] /Users/zharkynaskatkyzy/PycharmProjects/Zmall/server/apps/advert/views/advert_views.py changed, reloading.
2022-09-14 08:53:02,283 [autoreload | INFO] Watching for file changes with StatReloader
2022-09-14 08:53:04,604 [log | ERROR] Internal Server Error: /api/v1/user_advert/1
Traceback (most recent call last):
  File "/Library/Frameworks/Python.framework/Versions/3.10/lib/python3.10/site-packages/django/core/handlers/exception.py", line 55, in inner
    response = get_response(request)
  File "/Library/Frameworks/Python.framework/Versions/3.10/lib/python3.10/site-packages/django/core/handlers/base.py", line 197, in _get_response
    response = wrapped_callback(request, *callback_args, **callback_kwargs)
  File "/Library/Frameworks/Python.framework/Versions/3.10/lib/python3.10/site-packages/django/views/decorators/csrf.py", line 54, in wrapped_view
    return view_func(*args, **kwargs)
  File "/Library/Frameworks/Python.framework/Versions/3.10/lib/python3.10/site-packages/django/views/generic/base.py", line 103, in view
    return self.dispatch(request, *args, **kwargs)
  File "/Library/Frameworks/Python.framework/Versions/3.10/lib/python3.10/site-packages/rest_framework/views.py", line 509, in dispatch
    response = self.handle_exception(exc)
  File "/Library/Frameworks/Python.framework/Versions/3.10/lib/python3.10/site-packages/rest_framework/views.py", line 469, in handle_exception
    self.raise_uncaught_exception(exc)
  File "/Library/Frameworks/Python.framework/Versions/3.10/lib/python3.10/site-packages/rest_framework/views.py", line 480, in raise_uncaught_exception
    raise exc
  File "/Library/Frameworks/Python.framework/Versions/3.10/lib/python3.10/site-packages/rest_framework/views.py", line 506, in dispatch
    response = handler(request, *args, **kwargs)
  File "/Library/Frameworks/Python.framework/Versions/3.10/lib/python3.10/site-packages/rest_framework/generics.py", line 199, in get
    return self.list(request, *args, **kwargs)
  File "/Library/Frameworks/Python.framework/Versions/3.10/lib/python3.10/site-packages/rest_framework/mixins.py", line 46, in list
    return Response(serializer.data)
  File "/Library/Frameworks/Python.framework/Versions/3.10/lib/python3.10/site-packages/rest_framework/serializers.py", line 768, in data
    ret = super().data
  File "/Library/Frameworks/Python.framework/Versions/3.10/lib/python3.10/site-packages/rest_framework/serializers.py", line 253, in data
    self._data = self.to_representation(self.instance)
  File "/Library/Frameworks/Python.framework/Versions/3.10/lib/python3.10/site-packages/rest_framework/serializers.py", line 686, in to_representation
    return [
  File "/Library/Frameworks/Python.framework/Versions/3.10/lib/python3.10/site-packages/django/template/response.py", line 127, in __iter__
    raise ContentNotRenderedError(
django.template.response.ContentNotRenderedError: The response content must be rendered before it can be iterated over.
2022-09-14 08:53:25,430 [autoreload | INFO] /Users/zharkynaskatkyzy/PycharmProjects/Zmall/server/apps/advert/views/advert_views.py changed, reloading.
2022-09-14 08:53:25,916 [autoreload | INFO] Watching for file changes with StatReloader
2022-09-14 08:53:27,734 [log | ERROR] Internal Server Error: /api/v1/user_advert/1
Traceback (most recent call last):
  File "/Library/Frameworks/Python.framework/Versions/3.10/lib/python3.10/site-packages/django/core/handlers/exception.py", line 55, in inner
    response = get_response(request)
  File "/Library/Frameworks/Python.framework/Versions/3.10/lib/python3.10/site-packages/django/core/handlers/base.py", line 197, in _get_response
    response = wrapped_callback(request, *callback_args, **callback_kwargs)
  File "/Library/Frameworks/Python.framework/Versions/3.10/lib/python3.10/site-packages/django/views/decorators/csrf.py", line 54, in wrapped_view
    return view_func(*args, **kwargs)
  File "/Library/Frameworks/Python.framework/Versions/3.10/lib/python3.10/site-packages/django/views/generic/base.py", line 103, in view
    return self.dispatch(request, *args, **kwargs)
  File "/Library/Frameworks/Python.framework/Versions/3.10/lib/python3.10/site-packages/rest_framework/views.py", line 509, in dispatch
    response = self.handle_exception(exc)
  File "/Library/Frameworks/Python.framework/Versions/3.10/lib/python3.10/site-packages/rest_framework/views.py", line 469, in handle_exception
    self.raise_uncaught_exception(exc)
  File "/Library/Frameworks/Python.framework/Versions/3.10/lib/python3.10/site-packages/rest_framework/views.py", line 480, in raise_uncaught_exception
    raise exc
  File "/Library/Frameworks/Python.framework/Versions/3.10/lib/python3.10/site-packages/rest_framework/views.py", line 506, in dispatch
    response = handler(request, *args, **kwargs)
  File "/Library/Frameworks/Python.framework/Versions/3.10/lib/python3.10/site-packages/rest_framework/generics.py", line 199, in get
    return self.list(request, *args, **kwargs)
  File "/Library/Frameworks/Python.framework/Versions/3.10/lib/python3.10/site-packages/rest_framework/mixins.py", line 46, in list
    return Response(serializer.data)
  File "/Library/Frameworks/Python.framework/Versions/3.10/lib/python3.10/site-packages/rest_framework/serializers.py", line 768, in data
    ret = super().data
  File "/Library/Frameworks/Python.framework/Versions/3.10/lib/python3.10/site-packages/rest_framework/serializers.py", line 253, in data
    self._data = self.to_representation(self.instance)
  File "/Library/Frameworks/Python.framework/Versions/3.10/lib/python3.10/site-packages/rest_framework/serializers.py", line 686, in to_representation
    return [
  File "/Library/Frameworks/Python.framework/Versions/3.10/lib/python3.10/site-packages/django/template/response.py", line 127, in __iter__
    raise ContentNotRenderedError(
django.template.response.ContentNotRenderedError: The response content must be rendered before it can be iterated over.
2022-09-14 08:53:28,510 [log | ERROR] Internal Server Error: /api/v1/user_advert/1
Traceback (most recent call last):
  File "/Library/Frameworks/Python.framework/Versions/3.10/lib/python3.10/site-packages/django/core/handlers/exception.py", line 55, in inner
    response = get_response(request)
  File "/Library/Frameworks/Python.framework/Versions/3.10/lib/python3.10/site-packages/django/core/handlers/base.py", line 197, in _get_response
    response = wrapped_callback(request, *callback_args, **callback_kwargs)
  File "/Library/Frameworks/Python.framework/Versions/3.10/lib/python3.10/site-packages/django/views/decorators/csrf.py", line 54, in wrapped_view
    return view_func(*args, **kwargs)
  File "/Library/Frameworks/Python.framework/Versions/3.10/lib/python3.10/site-packages/django/views/generic/base.py", line 103, in view
    return self.dispatch(request, *args, **kwargs)
  File "/Library/Frameworks/Python.framework/Versions/3.10/lib/python3.10/site-packages/rest_framework/views.py", line 509, in dispatch
    response = self.handle_exception(exc)
  File "/Library/Frameworks/Python.framework/Versions/3.10/lib/python3.10/site-packages/rest_framework/views.py", line 469, in handle_exception
    self.raise_uncaught_exception(exc)
  File "/Library/Frameworks/Python.framework/Versions/3.10/lib/python3.10/site-packages/rest_framework/views.py", line 480, in raise_uncaught_exception
    raise exc
  File "/Library/Frameworks/Python.framework/Versions/3.10/lib/python3.10/site-packages/rest_framework/views.py", line 506, in dispatch
    response = handler(request, *args, **kwargs)
  File "/Library/Frameworks/Python.framework/Versions/3.10/lib/python3.10/site-packages/rest_framework/generics.py", line 199, in get
    return self.list(request, *args, **kwargs)
  File "/Library/Frameworks/Python.framework/Versions/3.10/lib/python3.10/site-packages/rest_framework/mixins.py", line 46, in list
    return Response(serializer.data)
  File "/Library/Frameworks/Python.framework/Versions/3.10/lib/python3.10/site-packages/rest_framework/serializers.py", line 768, in data
    ret = super().data
  File "/Library/Frameworks/Python.framework/Versions/3.10/lib/python3.10/site-packages/rest_framework/serializers.py", line 253, in data
    self._data = self.to_representation(self.instance)
  File "/Library/Frameworks/Python.framework/Versions/3.10/lib/python3.10/site-packages/rest_framework/serializers.py", line 686, in to_representation
    return [
  File "/Library/Frameworks/Python.framework/Versions/3.10/lib/python3.10/site-packages/django/template/response.py", line 127, in __iter__
    raise ContentNotRenderedError(
django.template.response.ContentNotRenderedError: The response content must be rendered before it can be iterated over.
2022-09-14 08:55:15,229 [autoreload | INFO] /Users/zharkynaskatkyzy/PycharmProjects/Zmall/server/apps/advert/views/advert_views.py changed, reloading.
2022-09-14 08:55:15,908 [autoreload | INFO] Watching for file changes with StatReloader
2022-09-14 08:55:42,331 [autoreload | INFO] /Users/zharkynaskatkyzy/PycharmProjects/Zmall/server/apps/advert/views/advert_views.py changed, reloading.
2022-09-14 08:55:42,833 [autoreload | INFO] Watching for file changes with StatReloader
2022-09-14 08:56:06,988 [connectionpool | DEBUG] Starting new HTTP connection (1): resume.doska.kg:80
2022-09-14 08:56:07,007 [connectionpool | DEBUG] http://resume.doska.kg:80 "GET /vacancy/ HTTP/1.1" 200 None
2022-09-14 08:57:03,357 [autoreload | INFO] /Users/zharkynaskatkyzy/PycharmProjects/Zmall/server/apps/advert/views/advert_views.py changed, reloading.
2022-09-14 08:57:03,927 [autoreload | INFO] Watching for file changes with StatReloader
2022-09-14 08:58:52,257 [autoreload | INFO] /Users/zharkynaskatkyzy/PycharmProjects/Zmall/server/apps/advert/views/advert_views.py changed, reloading.
2022-09-14 08:58:53,789 [autoreload | INFO] Watching for file changes with StatReloader
2022-09-14 09:00:06,529 [autoreload | INFO] /Users/zharkynaskatkyzy/PycharmProjects/Zmall/server/apps/advert/views/advert_views.py changed, reloading.
2022-09-14 09:00:07,386 [autoreload | INFO] Watching for file changes with StatReloader
2022-09-14 09:00:39,807 [log | WARNING] Not Found: /api/v1/user_advert/
2022-09-14 09:01:01,219 [autoreload | INFO] /Users/zharkynaskatkyzy/PycharmProjects/Zmall/server/apps/advert/views/advert_views.py changed, reloading.
2022-09-14 09:01:01,811 [autoreload | INFO] Watching for file changes with StatReloader
2022-09-14 09:01:14,581 [autoreload | INFO] /Users/zharkynaskatkyzy/PycharmProjects/Zmall/server/apps/advert/views/advert_views.py changed, reloading.
2022-09-14 09:01:15,123 [autoreload | INFO] Watching for file changes with StatReloader
2022-09-14 09:02:03,112 [autoreload | INFO] /Users/zharkynaskatkyzy/PycharmProjects/Zmall/server/apps/advert/views/advert_views.py changed, reloading.
2022-09-14 09:02:03,569 [autoreload | INFO] Watching for file changes with StatReloader
2022-09-14 09:02:12,702 [log | WARNING] Method Not Allowed: /api/v1/advert_report/
2022-09-14 09:02:35,214 [autoreload | INFO] /Users/zharkynaskatkyzy/PycharmProjects/Zmall/server/apps/advert/views/advert_views.py changed, reloading.
2022-09-14 09:02:35,750 [autoreload | INFO] Watching for file changes with StatReloader
2022-09-14 09:02:53,697 [autoreload | INFO] /Users/zharkynaskatkyzy/PycharmProjects/Zmall/server/apps/advert/views/advert_views.py changed, reloading.
2022-09-14 09:02:54,557 [autoreload | INFO] Watching for file changes with StatReloader
2022-09-14 09:05:00,315 [autoreload | INFO] /Users/zharkynaskatkyzy/PycharmProjects/Zmall/server/apps/advert/views/advert_views.py changed, reloading.
2022-09-14 09:05:01,297 [autoreload | INFO] Watching for file changes with StatReloader
2022-09-14 09:05:22,157 [autoreload | INFO] /Users/zharkynaskatkyzy/PycharmProjects/Zmall/server/apps/advert/views/advert_views.py changed, reloading.
2022-09-14 09:05:22,871 [autoreload | INFO] Watching for file changes with StatReloader
2022-09-14 09:07:16,701 [autoreload | INFO] /Users/zharkynaskatkyzy/PycharmProjects/Zmall/server/apps/advert/views/advert_views.py changed, reloading.
2022-09-14 09:07:17,303 [autoreload | INFO] Watching for file changes with StatReloader
2022-09-14 09:07:22,301 [log | WARNING] Method Not Allowed: /api/v1/advert_report/
2022-09-14 09:07:28,591 [log | WARNING] Not Found: /api/v1/user_advert/
2022-09-14 09:07:46,757 [autoreload | INFO] /Users/zharkynaskatkyzy/PycharmProjects/Zmall/server/apps/advert/urls.py changed, reloading.
2022-09-14 09:07:47,272 [autoreload | INFO] Watching for file changes with StatReloader
2022-09-14 09:07:49,614 [log | ERROR] Internal Server Error: /api/v1/user_advert/
Traceback (most recent call last):
  File "/Library/Frameworks/Python.framework/Versions/3.10/lib/python3.10/site-packages/django/db/models/fields/__init__.py", line 2018, in get_prep_value
    return int(value)
  File "/Library/Frameworks/Python.framework/Versions/3.10/lib/python3.10/site-packages/django/contrib/auth/models.py", line 437, in __int__
    raise TypeError(
TypeError: Cannot cast AnonymousUser to int. Are you trying to use it in place of User?

The above exception was the direct cause of the following exception:

Traceback (most recent call last):
  File "/Library/Frameworks/Python.framework/Versions/3.10/lib/python3.10/site-packages/django/core/handlers/exception.py", line 55, in inner
    response = get_response(request)
  File "/Library/Frameworks/Python.framework/Versions/3.10/lib/python3.10/site-packages/django/core/handlers/base.py", line 197, in _get_response
    response = wrapped_callback(request, *callback_args, **callback_kwargs)
  File "/Library/Frameworks/Python.framework/Versions/3.10/lib/python3.10/site-packages/django/views/decorators/csrf.py", line 54, in wrapped_view
    return view_func(*args, **kwargs)
  File "/Library/Frameworks/Python.framework/Versions/3.10/lib/python3.10/site-packages/django/views/generic/base.py", line 103, in view
    return self.dispatch(request, *args, **kwargs)
  File "/Library/Frameworks/Python.framework/Versions/3.10/lib/python3.10/site-packages/rest_framework/views.py", line 509, in dispatch
    response = self.handle_exception(exc)
  File "/Library/Frameworks/Python.framework/Versions/3.10/lib/python3.10/site-packages/rest_framework/views.py", line 469, in handle_exception
    self.raise_uncaught_exception(exc)
  File "/Library/Frameworks/Python.framework/Versions/3.10/lib/python3.10/site-packages/rest_framework/views.py", line 480, in raise_uncaught_exception
    raise exc
  File "/Library/Frameworks/Python.framework/Versions/3.10/lib/python3.10/site-packages/rest_framework/views.py", line 506, in dispatch
    response = handler(request, *args, **kwargs)
  File "/Library/Frameworks/Python.framework/Versions/3.10/lib/python3.10/site-packages/rest_framework/generics.py", line 199, in get
    return self.list(request, *args, **kwargs)
  File "/Library/Frameworks/Python.framework/Versions/3.10/lib/python3.10/site-packages/rest_framework/mixins.py", line 38, in list
    queryset = self.filter_queryset(self.get_queryset())
  File "/Users/zharkynaskatkyzy/PycharmProjects/Zmall/server/apps/advert/views/advert_views.py", line 123, in get_queryset
    return Advert.objects.filter(owner=user)
  File "/Library/Frameworks/Python.framework/Versions/3.10/lib/python3.10/site-packages/django/db/models/manager.py", line 85, in manager_method
    return getattr(self.get_queryset(), name)(*args, **kwargs)
  File "/Library/Frameworks/Python.framework/Versions/3.10/lib/python3.10/site-packages/django/db/models/query.py", line 1420, in filter
    return self._filter_or_exclude(False, args, kwargs)
  File "/Library/Frameworks/Python.framework/Versions/3.10/lib/python3.10/site-packages/django/db/models/query.py", line 1438, in _filter_or_exclude
    clone._filter_or_exclude_inplace(negate, args, kwargs)
  File "/Library/Frameworks/Python.framework/Versions/3.10/lib/python3.10/site-packages/django/db/models/query.py", line 1445, in _filter_or_exclude_inplace
    self._query.add_q(Q(*args, **kwargs))
  File "/Library/Frameworks/Python.framework/Versions/3.10/lib/python3.10/site-packages/django/db/models/sql/query.py", line 1532, in add_q
    clause, _ = self._add_q(q_object, self.used_aliases)
  File "/Library/Frameworks/Python.framework/Versions/3.10/lib/python3.10/site-packages/django/db/models/sql/query.py", line 1562, in _add_q
    child_clause, needed_inner = self.build_filter(
  File "/Library/Frameworks/Python.framework/Versions/3.10/lib/python3.10/site-packages/django/db/models/sql/query.py", line 1478, in build_filter
    condition = self.build_lookup(lookups, col, value)
  File "/Library/Frameworks/Python.framework/Versions/3.10/lib/python3.10/site-packages/django/db/models/sql/query.py", line 1303, in build_lookup
    lookup = lookup_class(lhs, rhs)
  File "/Library/Frameworks/Python.framework/Versions/3.10/lib/python3.10/site-packages/django/db/models/lookups.py", line 27, in __init__
    self.rhs = self.get_prep_lookup()
  File "/Library/Frameworks/Python.framework/Versions/3.10/lib/python3.10/site-packages/django/db/models/fields/related_lookups.py", line 166, in get_prep_lookup
    self.rhs = target_field.get_prep_value(self.rhs)
  File "/Library/Frameworks/Python.framework/Versions/3.10/lib/python3.10/site-packages/django/db/models/fields/__init__.py", line 2020, in get_prep_value
    raise e.__class__(
TypeError: Field 'id' expected a number but got <django.contrib.auth.models.AnonymousUser object at 0x104c78ee0>.
2022-09-14 09:08:04,208 [autoreload | INFO] /Users/zharkynaskatkyzy/PycharmProjects/Zmall/server/apps/advert/views/advert_views.py changed, reloading.
2022-09-14 09:08:04,785 [autoreload | INFO] Watching for file changes with StatReloader
2022-09-14 09:12:18,311 [base | WARNING] view's ContactView raised exception during schema generation; use `getattr(self, 'swagger_fake_view', False)` to detect and short-circuit this
Traceback (most recent call last):
  File "/Library/Frameworks/Python.framework/Versions/3.10/lib/python3.10/site-packages/drf_yasg/inspectors/base.py", line 42, in call_view_method
    return view_method()
  File "/Library/Frameworks/Python.framework/Versions/3.10/lib/python3.10/site-packages/rest_framework/generics.py", line 108, in get_serializer
    serializer_class = self.get_serializer_class()
  File "/Library/Frameworks/Python.framework/Versions/3.10/lib/python3.10/site-packages/rest_framework/generics.py", line 122, in get_serializer_class
    assert self.serializer_class is not None, (
AssertionError: 'ContactView' should either include a `serializer_class` attribute, or override the `get_serializer_class()` method.
2022-09-14 09:12:18,313 [base | WARNING] view's ContactView raised exception during schema generation; use `getattr(self, 'swagger_fake_view', False)` to detect and short-circuit this
Traceback (most recent call last):
  File "/Library/Frameworks/Python.framework/Versions/3.10/lib/python3.10/site-packages/drf_yasg/inspectors/base.py", line 42, in call_view_method
    return view_method()
  File "/Library/Frameworks/Python.framework/Versions/3.10/lib/python3.10/site-packages/rest_framework/generics.py", line 108, in get_serializer
    serializer_class = self.get_serializer_class()
  File "/Library/Frameworks/Python.framework/Versions/3.10/lib/python3.10/site-packages/rest_framework/generics.py", line 122, in get_serializer_class
    assert self.serializer_class is not None, (
AssertionError: 'ContactView' should either include a `serializer_class` attribute, or override the `get_serializer_class()` method.
2022-09-14 09:12:18,328 [base | WARNING] view's VerifyEmail raised exception during schema generation; use `getattr(self, 'swagger_fake_view', False)` to detect and short-circuit this
Traceback (most recent call last):
  File "/Library/Frameworks/Python.framework/Versions/3.10/lib/python3.10/site-packages/drf_yasg/inspectors/base.py", line 42, in call_view_method
    return view_method()
  File "/Library/Frameworks/Python.framework/Versions/3.10/lib/python3.10/site-packages/rest_framework/generics.py", line 108, in get_serializer
    serializer_class = self.get_serializer_class()
  File "/Library/Frameworks/Python.framework/Versions/3.10/lib/python3.10/site-packages/rest_framework/generics.py", line 122, in get_serializer_class
    assert self.serializer_class is not None, (
AssertionError: 'VerifyEmail' should either include a `serializer_class` attribute, or override the `get_serializer_class()` method.
2022-09-14 09:13:00,796 [log | WARNING] Unauthorized: /api/v1/user/login/
2022-09-14 09:13:20,017 [log | WARNING] Method Not Allowed: /api/v1/user/login/
2022-09-14 09:15:15,301 [log | WARNING] Not Found: /
2022-09-14 09:15:18,698 [log | WARNING] Not Found: /
2022-09-14 09:15:28,094 [base | WARNING] view's ContactView raised exception during schema generation; use `getattr(self, 'swagger_fake_view', False)` to detect and short-circuit this
Traceback (most recent call last):
  File "/Library/Frameworks/Python.framework/Versions/3.10/lib/python3.10/site-packages/drf_yasg/inspectors/base.py", line 42, in call_view_method
    return view_method()
  File "/Library/Frameworks/Python.framework/Versions/3.10/lib/python3.10/site-packages/rest_framework/generics.py", line 108, in get_serializer
    serializer_class = self.get_serializer_class()
  File "/Library/Frameworks/Python.framework/Versions/3.10/lib/python3.10/site-packages/rest_framework/generics.py", line 122, in get_serializer_class
    assert self.serializer_class is not None, (
AssertionError: 'ContactView' should either include a `serializer_class` attribute, or override the `get_serializer_class()` method.
2022-09-14 09:15:28,095 [base | WARNING] view's ContactView raised exception during schema generation; use `getattr(self, 'swagger_fake_view', False)` to detect and short-circuit this
Traceback (most recent call last):
  File "/Library/Frameworks/Python.framework/Versions/3.10/lib/python3.10/site-packages/drf_yasg/inspectors/base.py", line 42, in call_view_method
    return view_method()
  File "/Library/Frameworks/Python.framework/Versions/3.10/lib/python3.10/site-packages/rest_framework/generics.py", line 108, in get_serializer
    serializer_class = self.get_serializer_class()
  File "/Library/Frameworks/Python.framework/Versions/3.10/lib/python3.10/site-packages/rest_framework/generics.py", line 122, in get_serializer_class
    assert self.serializer_class is not None, (
AssertionError: 'ContactView' should either include a `serializer_class` attribute, or override the `get_serializer_class()` method.
2022-09-14 09:15:28,109 [base | WARNING] view's VerifyEmail raised exception during schema generation; use `getattr(self, 'swagger_fake_view', False)` to detect and short-circuit this
Traceback (most recent call last):
  File "/Library/Frameworks/Python.framework/Versions/3.10/lib/python3.10/site-packages/drf_yasg/inspectors/base.py", line 42, in call_view_method
    return view_method()
  File "/Library/Frameworks/Python.framework/Versions/3.10/lib/python3.10/site-packages/rest_framework/generics.py", line 108, in get_serializer
    serializer_class = self.get_serializer_class()
  File "/Library/Frameworks/Python.framework/Versions/3.10/lib/python3.10/site-packages/rest_framework/generics.py", line 122, in get_serializer_class
    assert self.serializer_class is not None, (
AssertionError: 'VerifyEmail' should either include a `serializer_class` attribute, or override the `get_serializer_class()` method.
2022-09-14 09:15:31,915 [log | WARNING] Not Found: /accounts/login/
2022-09-14 09:15:50,365 [log | WARNING] Method Not Allowed: /api/v1/user/login/
2022-09-14 09:16:12,664 [log | WARNING] Method Not Allowed: /api/v1/user/login/
2022-09-14 09:17:10,212 [autoreload | INFO] /Users/zharkynaskatkyzy/PycharmProjects/Zmall/server/apps/advert/views/advert_views.py changed, reloading.
2022-09-14 09:17:11,626 [autoreload | INFO] Watching for file changes with StatReloader
2022-09-14 09:17:12,825 [log | WARNING] Not Found: /
2022-09-14 09:21:47,354 [log | WARNING] Not Found: /
2022-09-14 09:28:59,717 [autoreload | INFO] /Users/zharkynaskatkyzy/PycharmProjects/Zmall/server/apps/advert/views/advert_views.py changed, reloading.
2022-09-14 09:29:00,442 [autoreload | INFO] Watching for file changes with StatReloader
2022-09-14 09:29:03,669 [log | WARNING] Not Found: /
2022-09-14 09:29:05,915 [log | WARNING] Not Found: /
2022-09-14 09:29:35,340 [autoreload | INFO] /Users/zharkynaskatkyzy/PycharmProjects/Zmall/server/apps/advert/views/advert_views.py changed, reloading.
2022-09-14 09:29:35,896 [autoreload | INFO] Watching for file changes with StatReloader
2022-09-14 09:31:51,538 [autoreload | INFO] /Users/zharkynaskatkyzy/PycharmProjects/Zmall/server/apps/advert/views/advert_views.py changed, reloading.
2022-09-14 09:31:52,344 [autoreload | INFO] Watching for file changes with StatReloader
2022-09-14 09:32:25,951 [autoreload | INFO] /Users/zharkynaskatkyzy/PycharmProjects/Zmall/server/apps/advert/views/advert_views.py changed, reloading.
2022-09-14 09:32:26,504 [autoreload | INFO] Watching for file changes with StatReloader
2022-09-14 09:32:43,415 [autoreload | INFO] /Users/zharkynaskatkyzy/PycharmProjects/Zmall/server/apps/advert/views/advert_views.py changed, reloading.
2022-09-14 09:32:43,906 [autoreload | INFO] Watching for file changes with StatReloader
2022-09-14 09:33:16,281 [autoreload | INFO] /Users/zharkynaskatkyzy/PycharmProjects/Zmall/server/apps/advert/views/advert_views.py changed, reloading.
2022-09-14 09:33:16,796 [autoreload | INFO] Watching for file changes with StatReloader
2022-09-14 09:34:08,017 [autoreload | INFO] /Users/zharkynaskatkyzy/PycharmProjects/Zmall/server/apps/advert/views/advert_views.py changed, reloading.
2022-09-14 09:34:08,496 [autoreload | INFO] Watching for file changes with StatReloader
2022-09-14 09:34:14,879 [log | WARNING] Unauthorized: /api/v1/user_advert/
2022-09-14 09:34:23,698 [base | WARNING] view's ContactView raised exception during schema generation; use `getattr(self, 'swagger_fake_view', False)` to detect and short-circuit this
Traceback (most recent call last):
  File "/Library/Frameworks/Python.framework/Versions/3.10/lib/python3.10/site-packages/drf_yasg/inspectors/base.py", line 42, in call_view_method
    return view_method()
  File "/Library/Frameworks/Python.framework/Versions/3.10/lib/python3.10/site-packages/rest_framework/generics.py", line 108, in get_serializer
    serializer_class = self.get_serializer_class()
  File "/Library/Frameworks/Python.framework/Versions/3.10/lib/python3.10/site-packages/rest_framework/generics.py", line 122, in get_serializer_class
    assert self.serializer_class is not None, (
AssertionError: 'ContactView' should either include a `serializer_class` attribute, or override the `get_serializer_class()` method.
2022-09-14 09:34:23,699 [base | WARNING] view's ContactView raised exception during schema generation; use `getattr(self, 'swagger_fake_view', False)` to detect and short-circuit this
Traceback (most recent call last):
  File "/Library/Frameworks/Python.framework/Versions/3.10/lib/python3.10/site-packages/drf_yasg/inspectors/base.py", line 42, in call_view_method
    return view_method()
  File "/Library/Frameworks/Python.framework/Versions/3.10/lib/python3.10/site-packages/rest_framework/generics.py", line 108, in get_serializer
    serializer_class = self.get_serializer_class()
  File "/Library/Frameworks/Python.framework/Versions/3.10/lib/python3.10/site-packages/rest_framework/generics.py", line 122, in get_serializer_class
    assert self.serializer_class is not None, (
AssertionError: 'ContactView' should either include a `serializer_class` attribute, or override the `get_serializer_class()` method.
2022-09-14 09:34:23,711 [base | WARNING] view's VerifyEmail raised exception during schema generation; use `getattr(self, 'swagger_fake_view', False)` to detect and short-circuit this
Traceback (most recent call last):
  File "/Library/Frameworks/Python.framework/Versions/3.10/lib/python3.10/site-packages/drf_yasg/inspectors/base.py", line 42, in call_view_method
    return view_method()
  File "/Library/Frameworks/Python.framework/Versions/3.10/lib/python3.10/site-packages/rest_framework/generics.py", line 108, in get_serializer
    serializer_class = self.get_serializer_class()
  File "/Library/Frameworks/Python.framework/Versions/3.10/lib/python3.10/site-packages/rest_framework/generics.py", line 122, in get_serializer_class
    assert self.serializer_class is not None, (
AssertionError: 'VerifyEmail' should either include a `serializer_class` attribute, or override the `get_serializer_class()` method.
2022-09-14 09:35:21,830 [log | WARNING] Method Not Allowed: /api/v1/user/login/
2022-09-14 09:38:06,918 [autoreload | INFO] /Users/zharkynaskatkyzy/PycharmProjects/Zmall/server/config/settings/base.py changed, reloading.
2022-09-14 09:38:07,712 [autoreload | INFO] Watching for file changes with StatReloader
