2022-09-14 11:58:37,593 [log | ERROR] Internal Server Error: /api/v1/advert/1/ @ /Library/Frameworks/Python.framework/Versions/3.10/lib/python3.10/site-packages/django/utils/log.py : 241 : log_response
Traceback (most recent call last):
  File "/Library/Frameworks/Python.framework/Versions/3.10/lib/python3.10/site-packages/django/db/backends/utils.py", line 89, in _execute
    return self.cursor.execute(sql, params)
psycopg2.errors.UndefinedColumn: column advert_advert.promote_id does not exist
LINE 1: ...rt"."sub_category_id", "advert_advert"."city_id", "advert_ad...
                                                             ^


The above exception was the direct cause of the following exception:

Traceback (most recent call last):
  File "/Library/Frameworks/Python.framework/Versions/3.10/lib/python3.10/site-packages/django/core/handlers/exception.py", line 55, in inner
    response = get_response(request)
  File "/Users/zharkynaskatkyzy/PycharmProjects/Zmall/server/config/middleware.py", line 65, in __call__
    set_advert_count(int(path.name), str(user), client_ip)
  File "/Users/zharkynaskatkyzy/PycharmProjects/Zmall/server/apps/advert/services.py", line 37, in set_advert_count
    ad = Advert.objects.get(id=id)
  File "/Library/Frameworks/Python.framework/Versions/3.10/lib/python3.10/site-packages/django/db/models/manager.py", line 85, in manager_method
    return getattr(self.get_queryset(), name)(*args, **kwargs)
  File "/Library/Frameworks/Python.framework/Versions/3.10/lib/python3.10/site-packages/django/db/models/query.py", line 646, in get
    num = len(clone)
  File "/Library/Frameworks/Python.framework/Versions/3.10/lib/python3.10/site-packages/django/db/models/query.py", line 376, in __len__
    self._fetch_all()
  File "/Library/Frameworks/Python.framework/Versions/3.10/lib/python3.10/site-packages/django/db/models/query.py", line 1866, in _fetch_all
    self._result_cache = list(self._iterable_class(self))
  File "/Library/Frameworks/Python.framework/Versions/3.10/lib/python3.10/site-packages/django/db/models/query.py", line 87, in __iter__
    results = compiler.execute_sql(
  File "/Library/Frameworks/Python.framework/Versions/3.10/lib/python3.10/site-packages/django/db/models/sql/compiler.py", line 1395, in execute_sql
    cursor.execute(sql, params)
  File "/Library/Frameworks/Python.framework/Versions/3.10/lib/python3.10/site-packages/django/db/backends/utils.py", line 103, in execute
    return super().execute(sql, params)
  File "/Library/Frameworks/Python.framework/Versions/3.10/lib/python3.10/site-packages/django/db/backends/utils.py", line 67, in execute
    return self._execute_with_wrappers(
  File "/Library/Frameworks/Python.framework/Versions/3.10/lib/python3.10/site-packages/django/db/backends/utils.py", line 80, in _execute_with_wrappers
    return executor(sql, params, many, context)
  File "/Library/Frameworks/Python.framework/Versions/3.10/lib/python3.10/site-packages/django/db/backends/utils.py", line 84, in _execute
    with self.db.wrap_database_errors:
  File "/Library/Frameworks/Python.framework/Versions/3.10/lib/python3.10/site-packages/django/db/utils.py", line 91, in __exit__
    raise dj_exc_value.with_traceback(traceback) from exc_value
  File "/Library/Frameworks/Python.framework/Versions/3.10/lib/python3.10/site-packages/django/db/backends/utils.py", line 89, in _execute
    return self.cursor.execute(sql, params)
django.db.utils.ProgrammingError: column advert_advert.promote_id does not exist
LINE 1: ...rt"."sub_category_id", "advert_advert"."city_id", "advert_ad...
                                                             ^

2022-09-14 11:58:56,053 [log | ERROR] Internal Server Error: /api/v1/advert/ @ /Library/Frameworks/Python.framework/Versions/3.10/lib/python3.10/site-packages/django/utils/log.py : 241 : log_response
Traceback (most recent call last):
  File "/Library/Frameworks/Python.framework/Versions/3.10/lib/python3.10/site-packages/django/db/backends/utils.py", line 89, in _execute
    return self.cursor.execute(sql, params)
psycopg2.errors.UndefinedColumn: column advert_advert.promote_id does not exist
LINE 1: ...rt"."sub_category_id", "advert_advert"."city_id", "advert_ad...
                                                             ^


The above exception was the direct cause of the following exception:

Traceback (most recent call last):
  File "/Library/Frameworks/Python.framework/Versions/3.10/lib/python3.10/site-packages/django/core/handlers/exception.py", line 55, in inner
    response = get_response(request)
  File "/Library/Frameworks/Python.framework/Versions/3.10/lib/python3.10/site-packages/django/core/handlers/base.py", line 197, in _get_response
    response = wrapped_callback(request, *callback_args, **callback_kwargs)
  File "/Library/Frameworks/Python.framework/Versions/3.10/lib/python3.10/site-packages/django/views/decorators/csrf.py", line 54, in wrapped_view
    return view_func(*args, **kwargs)
  File "/Library/Frameworks/Python.framework/Versions/3.10/lib/python3.10/site-packages/rest_framework/viewsets.py", line 125, in view
    return self.dispatch(request, *args, **kwargs)
  File "/Library/Frameworks/Python.framework/Versions/3.10/lib/python3.10/site-packages/rest_framework/views.py", line 509, in dispatch
    response = self.handle_exception(exc)
  File "/Library/Frameworks/Python.framework/Versions/3.10/lib/python3.10/site-packages/rest_framework/views.py", line 469, in handle_exception
    self.raise_uncaught_exception(exc)
  File "/Library/Frameworks/Python.framework/Versions/3.10/lib/python3.10/site-packages/rest_framework/views.py", line 480, in raise_uncaught_exception
    raise exc
  File "/Library/Frameworks/Python.framework/Versions/3.10/lib/python3.10/site-packages/rest_framework/views.py", line 506, in dispatch
    response = handler(request, *args, **kwargs)
  File "/Library/Frameworks/Python.framework/Versions/3.10/lib/python3.10/site-packages/rest_framework/mixins.py", line 40, in list
    page = self.paginate_queryset(queryset)
  File "/Library/Frameworks/Python.framework/Versions/3.10/lib/python3.10/site-packages/rest_framework/generics.py", line 171, in paginate_queryset
    return self.paginator.paginate_queryset(queryset, self.request, view=self)
  File "/Library/Frameworks/Python.framework/Versions/3.10/lib/python3.10/site-packages/rest_framework/pagination.py", line 395, in paginate_queryset
    return list(queryset[self.offset:self.offset + self.limit])
  File "/Library/Frameworks/Python.framework/Versions/3.10/lib/python3.10/site-packages/django/db/models/query.py", line 376, in __len__
    self._fetch_all()
  File "/Library/Frameworks/Python.framework/Versions/3.10/lib/python3.10/site-packages/django/db/models/query.py", line 1866, in _fetch_all
    self._result_cache = list(self._iterable_class(self))
  File "/Library/Frameworks/Python.framework/Versions/3.10/lib/python3.10/site-packages/django/db/models/query.py", line 87, in __iter__
    results = compiler.execute_sql(
  File "/Library/Frameworks/Python.framework/Versions/3.10/lib/python3.10/site-packages/django/db/models/sql/compiler.py", line 1395, in execute_sql
    cursor.execute(sql, params)
  File "/Library/Frameworks/Python.framework/Versions/3.10/lib/python3.10/site-packages/django/db/backends/utils.py", line 103, in execute
    return super().execute(sql, params)
  File "/Library/Frameworks/Python.framework/Versions/3.10/lib/python3.10/site-packages/django/db/backends/utils.py", line 67, in execute
    return self._execute_with_wrappers(
  File "/Library/Frameworks/Python.framework/Versions/3.10/lib/python3.10/site-packages/django/db/backends/utils.py", line 80, in _execute_with_wrappers
    return executor(sql, params, many, context)
  File "/Library/Frameworks/Python.framework/Versions/3.10/lib/python3.10/site-packages/django/db/backends/utils.py", line 84, in _execute
    with self.db.wrap_database_errors:
  File "/Library/Frameworks/Python.framework/Versions/3.10/lib/python3.10/site-packages/django/db/utils.py", line 91, in __exit__
    raise dj_exc_value.with_traceback(traceback) from exc_value
  File "/Library/Frameworks/Python.framework/Versions/3.10/lib/python3.10/site-packages/django/db/backends/utils.py", line 89, in _execute
    return self.cursor.execute(sql, params)
django.db.utils.ProgrammingError: column advert_advert.promote_id does not exist
LINE 1: ...rt"."sub_category_id", "advert_advert"."city_id", "advert_ad...
                                                             ^

2022-09-14 12:00:16,387 [log | ERROR] Internal Server Error: /admin/advert/advert/ @ /Library/Frameworks/Python.framework/Versions/3.10/lib/python3.10/site-packages/django/utils/log.py : 241 : log_response
Traceback (most recent call last):
  File "/Library/Frameworks/Python.framework/Versions/3.10/lib/python3.10/site-packages/django/db/backends/utils.py", line 89, in _execute
    return self.cursor.execute(sql, params)
psycopg2.errors.UndefinedColumn: column advert_advert.promote_id does not exist
LINE 1: ...rt"."sub_category_id", "advert_advert"."city_id", "advert_ad...
                                                             ^


The above exception was the direct cause of the following exception:

Traceback (most recent call last):
  File "/Library/Frameworks/Python.framework/Versions/3.10/lib/python3.10/site-packages/django/core/handlers/exception.py", line 55, in inner
    response = get_response(request)
  File "/Library/Frameworks/Python.framework/Versions/3.10/lib/python3.10/site-packages/django/core/handlers/base.py", line 197, in _get_response
    response = wrapped_callback(request, *callback_args, **callback_kwargs)
  File "/Library/Frameworks/Python.framework/Versions/3.10/lib/python3.10/site-packages/django/contrib/admin/options.py", line 686, in wrapper
    return self.admin_site.admin_view(view)(*args, **kwargs)
  File "/Library/Frameworks/Python.framework/Versions/3.10/lib/python3.10/site-packages/django/utils/decorators.py", line 133, in _wrapped_view
    response = view_func(request, *args, **kwargs)
  File "/Library/Frameworks/Python.framework/Versions/3.10/lib/python3.10/site-packages/django/views/decorators/cache.py", line 62, in _wrapped_view_func
    response = view_func(request, *args, **kwargs)
  File "/Library/Frameworks/Python.framework/Versions/3.10/lib/python3.10/site-packages/django/contrib/admin/sites.py", line 242, in inner
    return view(request, *args, **kwargs)
  File "/Library/Frameworks/Python.framework/Versions/3.10/lib/python3.10/site-packages/django/utils/decorators.py", line 46, in _wrapper
    return bound_method(*args, **kwargs)
  File "/Library/Frameworks/Python.framework/Versions/3.10/lib/python3.10/site-packages/django/utils/decorators.py", line 133, in _wrapped_view
    response = view_func(request, *args, **kwargs)
  File "/Library/Frameworks/Python.framework/Versions/3.10/lib/python3.10/site-packages/django/contrib/admin/options.py", line 2068, in changelist_view
    "selection_note": _("0 of %(cnt)s selected") % {"cnt": len(cl.result_list)},
  File "/Library/Frameworks/Python.framework/Versions/3.10/lib/python3.10/site-packages/django/db/models/query.py", line 376, in __len__
    self._fetch_all()
  File "/Library/Frameworks/Python.framework/Versions/3.10/lib/python3.10/site-packages/django/db/models/query.py", line 1866, in _fetch_all
    self._result_cache = list(self._iterable_class(self))
  File "/Library/Frameworks/Python.framework/Versions/3.10/lib/python3.10/site-packages/django/db/models/query.py", line 87, in __iter__
    results = compiler.execute_sql(
  File "/Library/Frameworks/Python.framework/Versions/3.10/lib/python3.10/site-packages/django/db/models/sql/compiler.py", line 1395, in execute_sql
    cursor.execute(sql, params)
  File "/Library/Frameworks/Python.framework/Versions/3.10/lib/python3.10/site-packages/django/db/backends/utils.py", line 103, in execute
    return super().execute(sql, params)
  File "/Library/Frameworks/Python.framework/Versions/3.10/lib/python3.10/site-packages/django/db/backends/utils.py", line 67, in execute
    return self._execute_with_wrappers(
  File "/Library/Frameworks/Python.framework/Versions/3.10/lib/python3.10/site-packages/django/db/backends/utils.py", line 80, in _execute_with_wrappers
    return executor(sql, params, many, context)
  File "/Library/Frameworks/Python.framework/Versions/3.10/lib/python3.10/site-packages/django/db/backends/utils.py", line 84, in _execute
    with self.db.wrap_database_errors:
  File "/Library/Frameworks/Python.framework/Versions/3.10/lib/python3.10/site-packages/django/db/utils.py", line 91, in __exit__
    raise dj_exc_value.with_traceback(traceback) from exc_value
  File "/Library/Frameworks/Python.framework/Versions/3.10/lib/python3.10/site-packages/django/db/backends/utils.py", line 89, in _execute
    return self.cursor.execute(sql, params)
django.db.utils.ProgrammingError: column advert_advert.promote_id does not exist
LINE 1: ...rt"."sub_category_id", "advert_advert"."city_id", "advert_ad...
                                                             ^

2022-09-14 12:00:16,777 [log | ERROR] Internal Server Error: /admin/advert/advert/ @ /Library/Frameworks/Python.framework/Versions/3.10/lib/python3.10/site-packages/django/utils/log.py : 241 : log_response
Traceback (most recent call last):
  File "/Library/Frameworks/Python.framework/Versions/3.10/lib/python3.10/site-packages/django/db/backends/utils.py", line 89, in _execute
    return self.cursor.execute(sql, params)
psycopg2.errors.UndefinedColumn: column advert_advert.promote_id does not exist
LINE 1: ...rt"."sub_category_id", "advert_advert"."city_id", "advert_ad...
                                                             ^


The above exception was the direct cause of the following exception:

Traceback (most recent call last):
  File "/Library/Frameworks/Python.framework/Versions/3.10/lib/python3.10/site-packages/django/core/handlers/exception.py", line 55, in inner
    response = get_response(request)
  File "/Library/Frameworks/Python.framework/Versions/3.10/lib/python3.10/site-packages/django/core/handlers/base.py", line 197, in _get_response
    response = wrapped_callback(request, *callback_args, **callback_kwargs)
  File "/Library/Frameworks/Python.framework/Versions/3.10/lib/python3.10/site-packages/django/contrib/admin/options.py", line 686, in wrapper
    return self.admin_site.admin_view(view)(*args, **kwargs)
  File "/Library/Frameworks/Python.framework/Versions/3.10/lib/python3.10/site-packages/django/utils/decorators.py", line 133, in _wrapped_view
    response = view_func(request, *args, **kwargs)
  File "/Library/Frameworks/Python.framework/Versions/3.10/lib/python3.10/site-packages/django/views/decorators/cache.py", line 62, in _wrapped_view_func
    response = view_func(request, *args, **kwargs)
  File "/Library/Frameworks/Python.framework/Versions/3.10/lib/python3.10/site-packages/django/contrib/admin/sites.py", line 242, in inner
    return view(request, *args, **kwargs)
  File "/Library/Frameworks/Python.framework/Versions/3.10/lib/python3.10/site-packages/django/utils/decorators.py", line 46, in _wrapper
    return bound_method(*args, **kwargs)
  File "/Library/Frameworks/Python.framework/Versions/3.10/lib/python3.10/site-packages/django/utils/decorators.py", line 133, in _wrapped_view
    response = view_func(request, *args, **kwargs)
  File "/Library/Frameworks/Python.framework/Versions/3.10/lib/python3.10/site-packages/django/contrib/admin/options.py", line 2068, in changelist_view
    "selection_note": _("0 of %(cnt)s selected") % {"cnt": len(cl.result_list)},
  File "/Library/Frameworks/Python.framework/Versions/3.10/lib/python3.10/site-packages/django/db/models/query.py", line 376, in __len__
    self._fetch_all()
  File "/Library/Frameworks/Python.framework/Versions/3.10/lib/python3.10/site-packages/django/db/models/query.py", line 1866, in _fetch_all
    self._result_cache = list(self._iterable_class(self))
  File "/Library/Frameworks/Python.framework/Versions/3.10/lib/python3.10/site-packages/django/db/models/query.py", line 87, in __iter__
    results = compiler.execute_sql(
  File "/Library/Frameworks/Python.framework/Versions/3.10/lib/python3.10/site-packages/django/db/models/sql/compiler.py", line 1395, in execute_sql
    cursor.execute(sql, params)
  File "/Library/Frameworks/Python.framework/Versions/3.10/lib/python3.10/site-packages/django/db/backends/utils.py", line 103, in execute
    return super().execute(sql, params)
  File "/Library/Frameworks/Python.framework/Versions/3.10/lib/python3.10/site-packages/django/db/backends/utils.py", line 67, in execute
    return self._execute_with_wrappers(
  File "/Library/Frameworks/Python.framework/Versions/3.10/lib/python3.10/site-packages/django/db/backends/utils.py", line 80, in _execute_with_wrappers
    return executor(sql, params, many, context)
  File "/Library/Frameworks/Python.framework/Versions/3.10/lib/python3.10/site-packages/django/db/backends/utils.py", line 84, in _execute
    with self.db.wrap_database_errors:
  File "/Library/Frameworks/Python.framework/Versions/3.10/lib/python3.10/site-packages/django/db/utils.py", line 91, in __exit__
    raise dj_exc_value.with_traceback(traceback) from exc_value
  File "/Library/Frameworks/Python.framework/Versions/3.10/lib/python3.10/site-packages/django/db/backends/utils.py", line 89, in _execute
    return self.cursor.execute(sql, params)
django.db.utils.ProgrammingError: column advert_advert.promote_id does not exist
LINE 1: ...rt"."sub_category_id", "advert_advert"."city_id", "advert_ad...
                                                             ^

2022-09-14 12:04:01,609 [log | ERROR] Internal Server Error: /api/v1/advert/1 @ /Library/Frameworks/Python.framework/Versions/3.10/lib/python3.10/site-packages/django/utils/log.py : 241 : log_response
Traceback (most recent call last):
  File "/Library/Frameworks/Python.framework/Versions/3.10/lib/python3.10/site-packages/django/core/handlers/exception.py", line 55, in inner
    response = get_response(request)
  File "/Library/Frameworks/Python.framework/Versions/3.10/lib/python3.10/site-packages/django/utils/deprecation.py", line 135, in __call__
    response = self.process_request(request)
  File "/Library/Frameworks/Python.framework/Versions/3.10/lib/python3.10/site-packages/django/middleware/common.py", line 54, in process_request
    path = self.get_full_path_with_slash(request)
  File "/Library/Frameworks/Python.framework/Versions/3.10/lib/python3.10/site-packages/django/middleware/common.py", line 88, in get_full_path_with_slash
    raise RuntimeError(
RuntimeError: You called this URL via PUT, but the URL doesn't end in a slash and you have APPEND_SLASH set. Django can't redirect to the slash URL while maintaining PUT data. Change your form to point to 127.0.0.1:8000/api/v1/advert/1/?promote=2 (note the trailing slash), or set APPEND_SLASH=False in your Django settings.
2022-09-14 12:04:21,547 [log | ERROR] Internal Server Error: /api/v1/advert/1 @ /Library/Frameworks/Python.framework/Versions/3.10/lib/python3.10/site-packages/django/utils/log.py : 241 : log_response
Traceback (most recent call last):
  File "/Library/Frameworks/Python.framework/Versions/3.10/lib/python3.10/site-packages/django/core/handlers/exception.py", line 55, in inner
    response = get_response(request)
  File "/Library/Frameworks/Python.framework/Versions/3.10/lib/python3.10/site-packages/django/utils/deprecation.py", line 135, in __call__
    response = self.process_request(request)
  File "/Library/Frameworks/Python.framework/Versions/3.10/lib/python3.10/site-packages/django/middleware/common.py", line 54, in process_request
    path = self.get_full_path_with_slash(request)
  File "/Library/Frameworks/Python.framework/Versions/3.10/lib/python3.10/site-packages/django/middleware/common.py", line 88, in get_full_path_with_slash
    raise RuntimeError(
RuntimeError: You called this URL via PUT, but the URL doesn't end in a slash and you have APPEND_SLASH set. Django can't redirect to the slash URL while maintaining PUT data. Change your form to point to 127.0.0.1:8000/api/v1/advert/1/?promote=2/ (note the trailing slash), or set APPEND_SLASH=False in your Django settings.
2022-09-14 12:04:30,029 [log | ERROR] Internal Server Error: /api/v1/advert/1/ @ /Library/Frameworks/Python.framework/Versions/3.10/lib/python3.10/site-packages/django/utils/log.py : 241 : log_response
Traceback (most recent call last):
  File "/Library/Frameworks/Python.framework/Versions/3.10/lib/python3.10/site-packages/django/core/handlers/exception.py", line 55, in inner
    response = get_response(request)
  File "/Users/zharkynaskatkyzy/PycharmProjects/Zmall/server/config/middleware.py", line 65, in __call__
    set_advert_count(int(path.name), str(user), client_ip)
  File "/Users/zharkynaskatkyzy/PycharmProjects/Zmall/server/apps/advert/services.py", line 63, in set_advert_count
    view.set(id, json.dumps(advert_views))
  File "/Library/Frameworks/Python.framework/Versions/3.10/lib/python3.10/json/__init__.py", line 231, in dumps
    return _default_encoder.encode(obj)
  File "/Library/Frameworks/Python.framework/Versions/3.10/lib/python3.10/json/encoder.py", line 199, in encode
    chunks = self.iterencode(o, _one_shot=True)
  File "/Library/Frameworks/Python.framework/Versions/3.10/lib/python3.10/json/encoder.py", line 257, in iterencode
    return _iterencode(o, 0)
  File "/Library/Frameworks/Python.framework/Versions/3.10/lib/python3.10/json/encoder.py", line 179, in default
    raise TypeError(f'Object of type {o.__class__.__name__} '
TypeError: Object of type datetime is not JSON serializable
2022-09-14 12:04:38,345 [log | ERROR] Internal Server Error: /api/v1/advert/1/ @ /Library/Frameworks/Python.framework/Versions/3.10/lib/python3.10/site-packages/django/utils/log.py : 241 : log_response
Traceback (most recent call last):
  File "/Library/Frameworks/Python.framework/Versions/3.10/lib/python3.10/site-packages/django/core/handlers/exception.py", line 55, in inner
    response = get_response(request)
  File "/Users/zharkynaskatkyzy/PycharmProjects/Zmall/server/config/middleware.py", line 65, in __call__
    set_advert_count(int(path.name), str(user), client_ip)
  File "/Users/zharkynaskatkyzy/PycharmProjects/Zmall/server/apps/advert/services.py", line 63, in set_advert_count
    view.set(id, json.dumps(advert_views))
  File "/Library/Frameworks/Python.framework/Versions/3.10/lib/python3.10/json/__init__.py", line 231, in dumps
    return _default_encoder.encode(obj)
  File "/Library/Frameworks/Python.framework/Versions/3.10/lib/python3.10/json/encoder.py", line 199, in encode
    chunks = self.iterencode(o, _one_shot=True)
  File "/Library/Frameworks/Python.framework/Versions/3.10/lib/python3.10/json/encoder.py", line 257, in iterencode
    return _iterencode(o, 0)
  File "/Library/Frameworks/Python.framework/Versions/3.10/lib/python3.10/json/encoder.py", line 179, in default
    raise TypeError(f'Object of type {o.__class__.__name__} '
TypeError: Object of type datetime is not JSON serializable
2022-09-14 12:04:39,538 [log | ERROR] Internal Server Error: /api/v1/advert/1/ @ /Library/Frameworks/Python.framework/Versions/3.10/lib/python3.10/site-packages/django/utils/log.py : 241 : log_response
Traceback (most recent call last):
  File "/Library/Frameworks/Python.framework/Versions/3.10/lib/python3.10/site-packages/django/core/handlers/exception.py", line 55, in inner
    response = get_response(request)
  File "/Users/zharkynaskatkyzy/PycharmProjects/Zmall/server/config/middleware.py", line 65, in __call__
    set_advert_count(int(path.name), str(user), client_ip)
  File "/Users/zharkynaskatkyzy/PycharmProjects/Zmall/server/apps/advert/services.py", line 63, in set_advert_count
    view.set(id, json.dumps(advert_views))
  File "/Library/Frameworks/Python.framework/Versions/3.10/lib/python3.10/json/__init__.py", line 231, in dumps
    return _default_encoder.encode(obj)
  File "/Library/Frameworks/Python.framework/Versions/3.10/lib/python3.10/json/encoder.py", line 199, in encode
    chunks = self.iterencode(o, _one_shot=True)
  File "/Library/Frameworks/Python.framework/Versions/3.10/lib/python3.10/json/encoder.py", line 257, in iterencode
    return _iterencode(o, 0)
  File "/Library/Frameworks/Python.framework/Versions/3.10/lib/python3.10/json/encoder.py", line 179, in default
    raise TypeError(f'Object of type {o.__class__.__name__} '
TypeError: Object of type datetime is not JSON serializable
2022-09-14 12:04:55,647 [log | ERROR] Internal Server Error: /api/v1/advert/1/ @ /Library/Frameworks/Python.framework/Versions/3.10/lib/python3.10/site-packages/django/utils/log.py : 241 : log_response
Traceback (most recent call last):
  File "/Library/Frameworks/Python.framework/Versions/3.10/lib/python3.10/site-packages/django/core/handlers/exception.py", line 55, in inner
    response = get_response(request)
  File "/Users/zharkynaskatkyzy/PycharmProjects/Zmall/server/config/middleware.py", line 65, in __call__
    set_advert_count(int(path.name), str(user), client_ip)
  File "/Users/zharkynaskatkyzy/PycharmProjects/Zmall/server/apps/advert/services.py", line 63, in set_advert_count
    view.set(id, json.dumps(advert_views))
  File "/Library/Frameworks/Python.framework/Versions/3.10/lib/python3.10/json/__init__.py", line 231, in dumps
    return _default_encoder.encode(obj)
  File "/Library/Frameworks/Python.framework/Versions/3.10/lib/python3.10/json/encoder.py", line 199, in encode
    chunks = self.iterencode(o, _one_shot=True)
  File "/Library/Frameworks/Python.framework/Versions/3.10/lib/python3.10/json/encoder.py", line 257, in iterencode
    return _iterencode(o, 0)
  File "/Library/Frameworks/Python.framework/Versions/3.10/lib/python3.10/json/encoder.py", line 179, in default
    raise TypeError(f'Object of type {o.__class__.__name__} '
TypeError: Object of type datetime is not JSON serializable
2022-09-14 12:04:57,015 [log | ERROR] Internal Server Error: /api/v1/advert/1/ @ /Library/Frameworks/Python.framework/Versions/3.10/lib/python3.10/site-packages/django/utils/log.py : 241 : log_response
Traceback (most recent call last):
  File "/Library/Frameworks/Python.framework/Versions/3.10/lib/python3.10/site-packages/django/core/handlers/exception.py", line 55, in inner
    response = get_response(request)
  File "/Users/zharkynaskatkyzy/PycharmProjects/Zmall/server/config/middleware.py", line 65, in __call__
    set_advert_count(int(path.name), str(user), client_ip)
  File "/Users/zharkynaskatkyzy/PycharmProjects/Zmall/server/apps/advert/services.py", line 63, in set_advert_count
    view.set(id, json.dumps(advert_views))
  File "/Library/Frameworks/Python.framework/Versions/3.10/lib/python3.10/json/__init__.py", line 231, in dumps
    return _default_encoder.encode(obj)
  File "/Library/Frameworks/Python.framework/Versions/3.10/lib/python3.10/json/encoder.py", line 199, in encode
    chunks = self.iterencode(o, _one_shot=True)
  File "/Library/Frameworks/Python.framework/Versions/3.10/lib/python3.10/json/encoder.py", line 257, in iterencode
    return _iterencode(o, 0)
  File "/Library/Frameworks/Python.framework/Versions/3.10/lib/python3.10/json/encoder.py", line 179, in default
    raise TypeError(f'Object of type {o.__class__.__name__} '
TypeError: Object of type datetime is not JSON serializable
2022-09-14 12:04:58,304 [log | ERROR] Internal Server Error: /api/v1/advert/1/ @ /Library/Frameworks/Python.framework/Versions/3.10/lib/python3.10/site-packages/django/utils/log.py : 241 : log_response
Traceback (most recent call last):
  File "/Library/Frameworks/Python.framework/Versions/3.10/lib/python3.10/site-packages/django/core/handlers/exception.py", line 55, in inner
    response = get_response(request)
  File "/Users/zharkynaskatkyzy/PycharmProjects/Zmall/server/config/middleware.py", line 65, in __call__
    set_advert_count(int(path.name), str(user), client_ip)
  File "/Users/zharkynaskatkyzy/PycharmProjects/Zmall/server/apps/advert/services.py", line 63, in set_advert_count
    view.set(id, json.dumps(advert_views))
  File "/Library/Frameworks/Python.framework/Versions/3.10/lib/python3.10/json/__init__.py", line 231, in dumps
    return _default_encoder.encode(obj)
  File "/Library/Frameworks/Python.framework/Versions/3.10/lib/python3.10/json/encoder.py", line 199, in encode
    chunks = self.iterencode(o, _one_shot=True)
  File "/Library/Frameworks/Python.framework/Versions/3.10/lib/python3.10/json/encoder.py", line 257, in iterencode
    return _iterencode(o, 0)
  File "/Library/Frameworks/Python.framework/Versions/3.10/lib/python3.10/json/encoder.py", line 179, in default
    raise TypeError(f'Object of type {o.__class__.__name__} '
TypeError: Object of type datetime is not JSON serializable
2022-09-14 15:32:51,511 [log | ERROR] Internal Server Error: /admin/advert/advert/ @ /Library/Frameworks/Python.framework/Versions/3.10/lib/python3.10/site-packages/django/utils/log.py : 241 : log_response
Traceback (most recent call last):
  File "/Library/Frameworks/Python.framework/Versions/3.10/lib/python3.10/site-packages/django/core/handlers/exception.py", line 55, in inner
    response = get_response(request)
  File "/Library/Frameworks/Python.framework/Versions/3.10/lib/python3.10/site-packages/django/core/handlers/base.py", line 197, in _get_response
    response = wrapped_callback(request, *callback_args, **callback_kwargs)
  File "/Library/Frameworks/Python.framework/Versions/3.10/lib/python3.10/site-packages/django/contrib/admin/options.py", line 686, in wrapper
    return self.admin_site.admin_view(view)(*args, **kwargs)
  File "/Library/Frameworks/Python.framework/Versions/3.10/lib/python3.10/site-packages/django/utils/decorators.py", line 133, in _wrapped_view
    response = view_func(request, *args, **kwargs)
  File "/Library/Frameworks/Python.framework/Versions/3.10/lib/python3.10/site-packages/django/views/decorators/cache.py", line 62, in _wrapped_view_func
    response = view_func(request, *args, **kwargs)
  File "/Library/Frameworks/Python.framework/Versions/3.10/lib/python3.10/site-packages/django/contrib/admin/sites.py", line 242, in inner
    return view(request, *args, **kwargs)
  File "/Library/Frameworks/Python.framework/Versions/3.10/lib/python3.10/site-packages/django/utils/decorators.py", line 46, in _wrapper
    return bound_method(*args, **kwargs)
  File "/Library/Frameworks/Python.framework/Versions/3.10/lib/python3.10/site-packages/django/utils/decorators.py", line 133, in _wrapped_view
    response = view_func(request, *args, **kwargs)
  File "/Library/Frameworks/Python.framework/Versions/3.10/lib/python3.10/site-packages/django/contrib/admin/options.py", line 2066, in changelist_view
    **self.admin_site.each_context(request),
  File "/Library/Frameworks/Python.framework/Versions/3.10/lib/python3.10/site-packages/django/contrib/admin/sites.py", line 337, in each_context
    "available_apps": self.get_app_list(request),
  File "/Library/Frameworks/Python.framework/Versions/3.10/lib/python3.10/site-packages/django/contrib/admin/sites.py", line 536, in get_app_list
    app_dict = self._build_app_dict(request, app_label)
  File "/Library/Frameworks/Python.framework/Versions/3.10/lib/python3.10/site-packages/django/contrib/admin/sites.py", line 482, in _build_app_dict
    perms = model_admin.get_model_perms(request)
  File "/Library/Frameworks/Python.framework/Versions/3.10/lib/python3.10/site-packages/django/contrib/admin/options.py", line 749, in get_model_perms
    "add": self.has_add_permission(request),
  File "/Users/zharkynaskatkyzy/PycharmProjects/Zmall/server/apps/advert/admin.py", line 85, in has_add_permission
    if has_add and Promote.objects.count < 3:
TypeError: '<' not supported between instances of 'method' and 'int'
2022-09-14 15:32:53,730 [log | ERROR] Internal Server Error: /admin/advert/advert/ @ /Library/Frameworks/Python.framework/Versions/3.10/lib/python3.10/site-packages/django/utils/log.py : 241 : log_response
Traceback (most recent call last):
  File "/Library/Frameworks/Python.framework/Versions/3.10/lib/python3.10/site-packages/django/core/handlers/exception.py", line 55, in inner
    response = get_response(request)
  File "/Library/Frameworks/Python.framework/Versions/3.10/lib/python3.10/site-packages/django/core/handlers/base.py", line 197, in _get_response
    response = wrapped_callback(request, *callback_args, **callback_kwargs)
  File "/Library/Frameworks/Python.framework/Versions/3.10/lib/python3.10/site-packages/django/contrib/admin/options.py", line 686, in wrapper
    return self.admin_site.admin_view(view)(*args, **kwargs)
  File "/Library/Frameworks/Python.framework/Versions/3.10/lib/python3.10/site-packages/django/utils/decorators.py", line 133, in _wrapped_view
    response = view_func(request, *args, **kwargs)
  File "/Library/Frameworks/Python.framework/Versions/3.10/lib/python3.10/site-packages/django/views/decorators/cache.py", line 62, in _wrapped_view_func
    response = view_func(request, *args, **kwargs)
  File "/Library/Frameworks/Python.framework/Versions/3.10/lib/python3.10/site-packages/django/contrib/admin/sites.py", line 242, in inner
    return view(request, *args, **kwargs)
  File "/Library/Frameworks/Python.framework/Versions/3.10/lib/python3.10/site-packages/django/utils/decorators.py", line 46, in _wrapper
    return bound_method(*args, **kwargs)
  File "/Library/Frameworks/Python.framework/Versions/3.10/lib/python3.10/site-packages/django/utils/decorators.py", line 133, in _wrapped_view
    response = view_func(request, *args, **kwargs)
  File "/Library/Frameworks/Python.framework/Versions/3.10/lib/python3.10/site-packages/django/contrib/admin/options.py", line 2066, in changelist_view
    **self.admin_site.each_context(request),
  File "/Library/Frameworks/Python.framework/Versions/3.10/lib/python3.10/site-packages/django/contrib/admin/sites.py", line 337, in each_context
    "available_apps": self.get_app_list(request),
  File "/Library/Frameworks/Python.framework/Versions/3.10/lib/python3.10/site-packages/django/contrib/admin/sites.py", line 536, in get_app_list
    app_dict = self._build_app_dict(request, app_label)
  File "/Library/Frameworks/Python.framework/Versions/3.10/lib/python3.10/site-packages/django/contrib/admin/sites.py", line 482, in _build_app_dict
    perms = model_admin.get_model_perms(request)
  File "/Library/Frameworks/Python.framework/Versions/3.10/lib/python3.10/site-packages/django/contrib/admin/options.py", line 749, in get_model_perms
    "add": self.has_add_permission(request),
  File "/Users/zharkynaskatkyzy/PycharmProjects/Zmall/server/apps/advert/admin.py", line 85, in has_add_permission
    if has_add and Promote.objects.count < 3:
TypeError: '<' not supported between instances of 'method' and 'int'
2022-09-14 15:32:54,070 [log | ERROR] Internal Server Error: /admin/ @ /Library/Frameworks/Python.framework/Versions/3.10/lib/python3.10/site-packages/django/utils/log.py : 241 : log_response
Traceback (most recent call last):
  File "/Library/Frameworks/Python.framework/Versions/3.10/lib/python3.10/site-packages/django/core/handlers/exception.py", line 55, in inner
    response = get_response(request)
  File "/Library/Frameworks/Python.framework/Versions/3.10/lib/python3.10/site-packages/django/core/handlers/base.py", line 197, in _get_response
    response = wrapped_callback(request, *callback_args, **callback_kwargs)
  File "/Library/Frameworks/Python.framework/Versions/3.10/lib/python3.10/site-packages/django/contrib/admin/sites.py", line 261, in wrapper
    return self.admin_view(view, cacheable)(*args, **kwargs)
  File "/Library/Frameworks/Python.framework/Versions/3.10/lib/python3.10/site-packages/django/utils/decorators.py", line 133, in _wrapped_view
    response = view_func(request, *args, **kwargs)
  File "/Library/Frameworks/Python.framework/Versions/3.10/lib/python3.10/site-packages/django/views/decorators/cache.py", line 62, in _wrapped_view_func
    response = view_func(request, *args, **kwargs)
  File "/Library/Frameworks/Python.framework/Versions/3.10/lib/python3.10/site-packages/django/contrib/admin/sites.py", line 242, in inner
    return view(request, *args, **kwargs)
  File "/Library/Frameworks/Python.framework/Versions/3.10/lib/python3.10/site-packages/django/contrib/admin/sites.py", line 552, in index
    app_list = self.get_app_list(request)
  File "/Library/Frameworks/Python.framework/Versions/3.10/lib/python3.10/site-packages/django/contrib/admin/sites.py", line 536, in get_app_list
    app_dict = self._build_app_dict(request, app_label)
  File "/Library/Frameworks/Python.framework/Versions/3.10/lib/python3.10/site-packages/django/contrib/admin/sites.py", line 482, in _build_app_dict
    perms = model_admin.get_model_perms(request)
  File "/Library/Frameworks/Python.framework/Versions/3.10/lib/python3.10/site-packages/django/contrib/admin/options.py", line 749, in get_model_perms
    "add": self.has_add_permission(request),
  File "/Users/zharkynaskatkyzy/PycharmProjects/Zmall/server/apps/advert/admin.py", line 85, in has_add_permission
    if has_add and Promote.objects.count < 3:
TypeError: '<' not supported between instances of 'method' and 'int'
2022-09-14 16:33:29,890 [log | ERROR] Internal Server Error: /admin/advert/feedbackmessage/ @ /Library/Frameworks/Python.framework/Versions/3.10/lib/python3.10/site-packages/django/utils/log.py : 241 : log_response
Traceback (most recent call last):
  File "/Library/Frameworks/Python.framework/Versions/3.10/lib/python3.10/site-packages/django/db/models/options.py", line 668, in get_field
    return self.fields_map[field_name]
KeyError: '__str__'

During handling of the above exception, another exception occurred:

Traceback (most recent call last):
  File "/Library/Frameworks/Python.framework/Versions/3.10/lib/python3.10/site-packages/django/contrib/admin/utils.py", line 271, in lookup_field
    f = _get_non_gfk_field(opts, name)
  File "/Library/Frameworks/Python.framework/Versions/3.10/lib/python3.10/site-packages/django/contrib/admin/utils.py", line 302, in _get_non_gfk_field
    field = opts.get_field(name)
  File "/Library/Frameworks/Python.framework/Versions/3.10/lib/python3.10/site-packages/django/db/models/options.py", line 670, in get_field
    raise FieldDoesNotExist(
django.core.exceptions.FieldDoesNotExist: FeedbackMessage has no field named '__str__'

During handling of the above exception, another exception occurred:

Traceback (most recent call last):
  File "/Library/Frameworks/Python.framework/Versions/3.10/lib/python3.10/site-packages/django/core/handlers/exception.py", line 55, in inner
    response = get_response(request)
  File "/Library/Frameworks/Python.framework/Versions/3.10/lib/python3.10/site-packages/django/core/handlers/base.py", line 220, in _get_response
    response = response.render()
  File "/Library/Frameworks/Python.framework/Versions/3.10/lib/python3.10/site-packages/django/template/response.py", line 114, in render
    self.content = self.rendered_content
  File "/Library/Frameworks/Python.framework/Versions/3.10/lib/python3.10/site-packages/django/template/response.py", line 92, in rendered_content
    return template.render(context, self._request)
  File "/Library/Frameworks/Python.framework/Versions/3.10/lib/python3.10/site-packages/django/template/backends/django.py", line 62, in render
    return self.template.render(context)
  File "/Library/Frameworks/Python.framework/Versions/3.10/lib/python3.10/site-packages/django/template/base.py", line 175, in render
    return self._render(context)
  File "/Library/Frameworks/Python.framework/Versions/3.10/lib/python3.10/site-packages/django/template/base.py", line 167, in _render
    return self.nodelist.render(context)
  File "/Library/Frameworks/Python.framework/Versions/3.10/lib/python3.10/site-packages/django/template/base.py", line 1005, in render
    return SafeString("".join([node.render_annotated(context) for node in self]))
  File "/Library/Frameworks/Python.framework/Versions/3.10/lib/python3.10/site-packages/django/template/base.py", line 1005, in <listcomp>
    return SafeString("".join([node.render_annotated(context) for node in self]))
  File "/Library/Frameworks/Python.framework/Versions/3.10/lib/python3.10/site-packages/django/template/base.py", line 966, in render_annotated
    return self.render(context)
  File "/Library/Frameworks/Python.framework/Versions/3.10/lib/python3.10/site-packages/django/template/loader_tags.py", line 157, in render
    return compiled_parent._render(context)
  File "/Library/Frameworks/Python.framework/Versions/3.10/lib/python3.10/site-packages/django/template/base.py", line 167, in _render
    return self.nodelist.render(context)
  File "/Library/Frameworks/Python.framework/Versions/3.10/lib/python3.10/site-packages/django/template/base.py", line 1005, in render
    return SafeString("".join([node.render_annotated(context) for node in self]))
  File "/Library/Frameworks/Python.framework/Versions/3.10/lib/python3.10/site-packages/django/template/base.py", line 1005, in <listcomp>
    return SafeString("".join([node.render_annotated(context) for node in self]))
  File "/Library/Frameworks/Python.framework/Versions/3.10/lib/python3.10/site-packages/django/template/base.py", line 966, in render_annotated
    return self.render(context)
  File "/Library/Frameworks/Python.framework/Versions/3.10/lib/python3.10/site-packages/django/template/loader_tags.py", line 157, in render
    return compiled_parent._render(context)
  File "/Library/Frameworks/Python.framework/Versions/3.10/lib/python3.10/site-packages/django/template/base.py", line 167, in _render
    return self.nodelist.render(context)
  File "/Library/Frameworks/Python.framework/Versions/3.10/lib/python3.10/site-packages/django/template/base.py", line 1005, in render
    return SafeString("".join([node.render_annotated(context) for node in self]))
  File "/Library/Frameworks/Python.framework/Versions/3.10/lib/python3.10/site-packages/django/template/base.py", line 1005, in <listcomp>
    return SafeString("".join([node.render_annotated(context) for node in self]))
  File "/Library/Frameworks/Python.framework/Versions/3.10/lib/python3.10/site-packages/django/template/base.py", line 966, in render_annotated
    return self.render(context)
  File "/Library/Frameworks/Python.framework/Versions/3.10/lib/python3.10/site-packages/django/template/loader_tags.py", line 63, in render
    result = block.nodelist.render(context)
  File "/Library/Frameworks/Python.framework/Versions/3.10/lib/python3.10/site-packages/django/template/base.py", line 1005, in render
    return SafeString("".join([node.render_annotated(context) for node in self]))
  File "/Library/Frameworks/Python.framework/Versions/3.10/lib/python3.10/site-packages/django/template/base.py", line 1005, in <listcomp>
    return SafeString("".join([node.render_annotated(context) for node in self]))
  File "/Library/Frameworks/Python.framework/Versions/3.10/lib/python3.10/site-packages/django/template/base.py", line 966, in render_annotated
    return self.render(context)
  File "/Library/Frameworks/Python.framework/Versions/3.10/lib/python3.10/site-packages/django/template/loader_tags.py", line 63, in render
    result = block.nodelist.render(context)
  File "/Library/Frameworks/Python.framework/Versions/3.10/lib/python3.10/site-packages/django/template/base.py", line 1005, in render
    return SafeString("".join([node.render_annotated(context) for node in self]))
  File "/Library/Frameworks/Python.framework/Versions/3.10/lib/python3.10/site-packages/django/template/base.py", line 1005, in <listcomp>
    return SafeString("".join([node.render_annotated(context) for node in self]))
  File "/Library/Frameworks/Python.framework/Versions/3.10/lib/python3.10/site-packages/django/template/base.py", line 966, in render_annotated
    return self.render(context)
  File "/Library/Frameworks/Python.framework/Versions/3.10/lib/python3.10/site-packages/django/template/loader_tags.py", line 63, in render
    result = block.nodelist.render(context)
  File "/Library/Frameworks/Python.framework/Versions/3.10/lib/python3.10/site-packages/django/template/base.py", line 1005, in render
    return SafeString("".join([node.render_annotated(context) for node in self]))
  File "/Library/Frameworks/Python.framework/Versions/3.10/lib/python3.10/site-packages/django/template/base.py", line 1005, in <listcomp>
    return SafeString("".join([node.render_annotated(context) for node in self]))
  File "/Library/Frameworks/Python.framework/Versions/3.10/lib/python3.10/site-packages/django/template/base.py", line 966, in render_annotated
    return self.render(context)
  File "/Library/Frameworks/Python.framework/Versions/3.10/lib/python3.10/site-packages/django/contrib/admin/templatetags/base.py", line 45, in render
    return super().render(context)
  File "/Library/Frameworks/Python.framework/Versions/3.10/lib/python3.10/site-packages/django/template/library.py", line 258, in render
    _dict = self.func(*resolved_args, **resolved_kwargs)
  File "/Library/Frameworks/Python.framework/Versions/3.10/lib/python3.10/site-packages/django/contrib/admin/templatetags/admin_list.py", line 336, in result_list
    "results": list(results(cl)),
  File "/Library/Frameworks/Python.framework/Versions/3.10/lib/python3.10/site-packages/django/contrib/admin/templatetags/admin_list.py", line 312, in results
    yield ResultList(None, items_for_result(cl, res, None))
  File "/Library/Frameworks/Python.framework/Versions/3.10/lib/python3.10/site-packages/django/contrib/admin/templatetags/admin_list.py", line 303, in __init__
    super().__init__(*items)
  File "/Library/Frameworks/Python.framework/Versions/3.10/lib/python3.10/site-packages/django/contrib/admin/templatetags/admin_list.py", line 213, in items_for_result
    f, attr, value = lookup_field(field_name, result, cl.model_admin)
  File "/Library/Frameworks/Python.framework/Versions/3.10/lib/python3.10/site-packages/django/contrib/admin/utils.py", line 284, in lookup_field
    value = attr()
  File "/Users/zharkynaskatkyzy/PycharmProjects/Zmall/server/apps/advert/models.py", line 226, in __str__
    return self.name
AttributeError: 'FeedbackMessage' object has no attribute 'name'
