2022-09-07 10:44:42,960 [log | ERROR] Internal Server Error: / @ /Users/c0mrade/Documents/Zmall/server/env/lib/python3.10/site-packages/django/utils/log.py : 241 : log_response
Traceback (most recent call last):
  File "/Users/c0mrade/Documents/Zmall/server/env/lib/python3.10/site-packages/django/core/handlers/exception.py", line 55, in inner
    response = get_response(request)
  File "/Users/c0mrade/Documents/Zmall/server/env/lib/python3.10/site-packages/django/utils/deprecation.py", line 138, in __call__
    response = self.process_response(request, response)
  File "/Users/c0mrade/Documents/Zmall/server/env/lib/python3.10/site-packages/django/middleware/common.py", line 114, in process_response
    response.headers["Content-Length"] = str(len(response.content))
  File "/Users/c0mrade/Documents/Zmall/server/env/lib/python3.10/site-packages/django/template/response.py", line 135, in content
    raise ContentNotRenderedError(
django.template.response.ContentNotRenderedError: The response content must be rendered before it can be accessed.
2022-09-07 10:44:43,311 [log | ERROR] Internal Server Error: /favicon.ico @ /Users/c0mrade/Documents/Zmall/server/env/lib/python3.10/site-packages/django/utils/log.py : 241 : log_response
Traceback (most recent call last):
  File "/Users/c0mrade/Documents/Zmall/server/env/lib/python3.10/site-packages/django/core/handlers/exception.py", line 55, in inner
    response = get_response(request)
  File "/Users/c0mrade/Documents/Zmall/server/env/lib/python3.10/site-packages/django/utils/deprecation.py", line 138, in __call__
    response = self.process_response(request, response)
  File "/Users/c0mrade/Documents/Zmall/server/env/lib/python3.10/site-packages/django/middleware/common.py", line 114, in process_response
    response.headers["Content-Length"] = str(len(response.content))
  File "/Users/c0mrade/Documents/Zmall/server/env/lib/python3.10/site-packages/django/template/response.py", line 135, in content
    raise ContentNotRenderedError(
django.template.response.ContentNotRenderedError: The response content must be rendered before it can be accessed.
2022-09-07 10:45:19,523 [log | ERROR] Internal Server Error: / @ /Users/c0mrade/Documents/Zmall/server/env/lib/python3.10/site-packages/django/utils/log.py : 241 : log_response
Traceback (most recent call last):
  File "/Users/c0mrade/Documents/Zmall/server/env/lib/python3.10/site-packages/django/core/handlers/exception.py", line 55, in inner
    response = get_response(request)
  File "/Users/c0mrade/Documents/Zmall/server/config/middleware.py", line 32, in __call__
    raise ValueError("rate limit")
ValueError: rate limit
2022-09-07 10:45:19,566 [log | ERROR] Internal Server Error: /favicon.ico @ /Users/c0mrade/Documents/Zmall/server/env/lib/python3.10/site-packages/django/utils/log.py : 241 : log_response
Traceback (most recent call last):
  File "/Users/c0mrade/Documents/Zmall/server/env/lib/python3.10/site-packages/django/core/handlers/exception.py", line 55, in inner
    response = get_response(request)
  File "/Users/c0mrade/Documents/Zmall/server/config/middleware.py", line 32, in __call__
    raise ValueError("rate limit")
ValueError: rate limit
2022-09-07 10:45:20,272 [log | ERROR] Internal Server Error: / @ /Users/c0mrade/Documents/Zmall/server/env/lib/python3.10/site-packages/django/utils/log.py : 241 : log_response
Traceback (most recent call last):
  File "/Users/c0mrade/Documents/Zmall/server/env/lib/python3.10/site-packages/django/core/handlers/exception.py", line 55, in inner
    response = get_response(request)
  File "/Users/c0mrade/Documents/Zmall/server/config/middleware.py", line 32, in __call__
    raise ValueError("rate limit")
ValueError: rate limit
2022-09-07 10:45:20,447 [log | ERROR] Internal Server Error: / @ /Users/c0mrade/Documents/Zmall/server/env/lib/python3.10/site-packages/django/utils/log.py : 241 : log_response
Traceback (most recent call last):
  File "/Users/c0mrade/Documents/Zmall/server/env/lib/python3.10/site-packages/django/core/handlers/exception.py", line 55, in inner
    response = get_response(request)
  File "/Users/c0mrade/Documents/Zmall/server/config/middleware.py", line 32, in __call__
    raise ValueError("rate limit")
ValueError: rate limit
2022-09-07 10:45:20,580 [log | ERROR] Internal Server Error: / @ /Users/c0mrade/Documents/Zmall/server/env/lib/python3.10/site-packages/django/utils/log.py : 241 : log_response
Traceback (most recent call last):
  File "/Users/c0mrade/Documents/Zmall/server/env/lib/python3.10/site-packages/django/core/handlers/exception.py", line 55, in inner
    response = get_response(request)
  File "/Users/c0mrade/Documents/Zmall/server/config/middleware.py", line 32, in __call__
    raise ValueError("rate limit")
ValueError: rate limit
2022-09-07 10:45:20,632 [log | ERROR] Internal Server Error: /favicon.ico @ /Users/c0mrade/Documents/Zmall/server/env/lib/python3.10/site-packages/django/utils/log.py : 241 : log_response
Traceback (most recent call last):
  File "/Users/c0mrade/Documents/Zmall/server/env/lib/python3.10/site-packages/django/core/handlers/exception.py", line 55, in inner
    response = get_response(request)
  File "/Users/c0mrade/Documents/Zmall/server/config/middleware.py", line 32, in __call__
    raise ValueError("rate limit")
ValueError: rate limit
2022-09-07 10:50:09,736 [log | ERROR] Internal Server Error: / @ /Users/c0mrade/Documents/Zmall/server/env/lib/python3.10/site-packages/django/utils/log.py : 241 : log_response
Traceback (most recent call last):
  File "/Users/c0mrade/Documents/Zmall/server/env/lib/python3.10/site-packages/django/core/handlers/exception.py", line 55, in inner
    response = get_response(request)
  File "/Users/c0mrade/Documents/Zmall/server/config/middleware.py", line 33, in __call__
    if redis.get(client_ip) > 10:
TypeError: '>' not supported between instances of 'bytes' and 'int'
2022-09-07 10:50:09,823 [log | ERROR] Internal Server Error: /favicon.ico @ /Users/c0mrade/Documents/Zmall/server/env/lib/python3.10/site-packages/django/utils/log.py : 241 : log_response
Traceback (most recent call last):
  File "/Users/c0mrade/Documents/Zmall/server/env/lib/python3.10/site-packages/django/core/handlers/exception.py", line 55, in inner
    response = get_response(request)
  File "/Users/c0mrade/Documents/Zmall/server/config/middleware.py", line 33, in __call__
    if redis.get(client_ip) > 10:
TypeError: '>' not supported between instances of 'bytes' and 'int'
2022-09-07 10:50:55,914 [log | ERROR] Internal Server Error: / @ /Users/c0mrade/Documents/Zmall/server/env/lib/python3.10/site-packages/django/utils/log.py : 241 : log_response
Traceback (most recent call last):
  File "/Users/c0mrade/Documents/Zmall/server/env/lib/python3.10/site-packages/django/core/handlers/exception.py", line 55, in inner
    response = get_response(request)
  File "/Users/c0mrade/Documents/Zmall/server/config/middleware.py", line 34, in __call__
    raise ValueError("rate limit")
ValueError: rate limit
2022-09-07 10:50:56,272 [log | ERROR] Internal Server Error: / @ /Users/c0mrade/Documents/Zmall/server/env/lib/python3.10/site-packages/django/utils/log.py : 241 : log_response
Traceback (most recent call last):
  File "/Users/c0mrade/Documents/Zmall/server/env/lib/python3.10/site-packages/django/core/handlers/exception.py", line 55, in inner
    response = get_response(request)
  File "/Users/c0mrade/Documents/Zmall/server/config/middleware.py", line 34, in __call__
    raise ValueError("rate limit")
ValueError: rate limit
2022-09-07 11:34:16,859 [log | ERROR] Internal Server Error: / @ /Users/c0mrade/Documents/Zmall/server/env/lib/python3.10/site-packages/django/utils/log.py : 241 : log_response
Traceback (most recent call last):
  File "/Users/c0mrade/Documents/Zmall/server/env/lib/python3.10/site-packages/django/core/handlers/exception.py", line 55, in inner
    response = get_response(request)
  File "/Users/c0mrade/Documents/Zmall/server/config/middleware.py", line 34, in __call__
    request_count, request_date = str(redis.get(client_ip)).split(',')
ValueError: not enough values to unpack (expected 2, got 1)
2022-09-07 11:34:17,206 [log | ERROR] Internal Server Error: /favicon.ico @ /Users/c0mrade/Documents/Zmall/server/env/lib/python3.10/site-packages/django/utils/log.py : 241 : log_response
Traceback (most recent call last):
  File "/Users/c0mrade/Documents/Zmall/server/env/lib/python3.10/site-packages/django/core/handlers/exception.py", line 55, in inner
    response = get_response(request)
  File "/Users/c0mrade/Documents/Zmall/server/config/middleware.py", line 34, in __call__
    request_count, request_date = str(redis.get(client_ip)).split(',')
ValueError: not enough values to unpack (expected 2, got 1)
2022-09-07 11:34:37,640 [log | ERROR] Internal Server Error: / @ /Users/c0mrade/Documents/Zmall/server/env/lib/python3.10/site-packages/django/utils/log.py : 241 : log_response
Traceback (most recent call last):
  File "/Users/c0mrade/Documents/Zmall/server/env/lib/python3.10/site-packages/django/core/handlers/exception.py", line 55, in inner
    response = get_response(request)
  File "/Users/c0mrade/Documents/Zmall/server/config/middleware.py", line 35, in __call__
    if int(request_count) > 10 and request_date == today:
ValueError: invalid literal for int() with base 10: "b'15'"
2022-09-07 11:34:37,691 [log | ERROR] Internal Server Error: /favicon.ico @ /Users/c0mrade/Documents/Zmall/server/env/lib/python3.10/site-packages/django/utils/log.py : 241 : log_response
Traceback (most recent call last):
  File "/Users/c0mrade/Documents/Zmall/server/env/lib/python3.10/site-packages/django/core/handlers/exception.py", line 55, in inner
    response = get_response(request)
  File "/Users/c0mrade/Documents/Zmall/server/config/middleware.py", line 35, in __call__
    if int(request_count) > 10 and request_date == today:
ValueError: invalid literal for int() with base 10: "b'16'"
2022-09-07 11:36:31,555 [log | ERROR] Internal Server Error: / @ /Users/c0mrade/Documents/Zmall/server/env/lib/python3.10/site-packages/django/utils/log.py : 241 : log_response
Traceback (most recent call last):
  File "/Users/c0mrade/Documents/Zmall/server/env/lib/python3.10/site-packages/django/core/handlers/exception.py", line 55, in inner
    response = get_response(request)
  File "/Users/c0mrade/Documents/Zmall/server/config/middleware.py", line 35, in __call__
    print(int(request_count, base=10), request_date)
ValueError: invalid literal for int() with base 10: "b'19'"
2022-09-07 11:36:31,642 [log | ERROR] Internal Server Error: /favicon.ico @ /Users/c0mrade/Documents/Zmall/server/env/lib/python3.10/site-packages/django/utils/log.py : 241 : log_response
Traceback (most recent call last):
  File "/Users/c0mrade/Documents/Zmall/server/env/lib/python3.10/site-packages/django/core/handlers/exception.py", line 55, in inner
    response = get_response(request)
  File "/Users/c0mrade/Documents/Zmall/server/config/middleware.py", line 35, in __call__
    print(int(request_count, base=10), request_date)
ValueError: invalid literal for int() with base 10: "b'20'"
2022-09-07 11:37:36,499 [log | ERROR] Internal Server Error: / @ /Users/c0mrade/Documents/Zmall/server/env/lib/python3.10/site-packages/django/utils/log.py : 241 : log_response
Traceback (most recent call last):
  File "/Users/c0mrade/Documents/Zmall/server/env/lib/python3.10/site-packages/django/core/handlers/exception.py", line 55, in inner
    response = get_response(request)
  File "/Users/c0mrade/Documents/Zmall/server/config/middleware.py", line 35, in __call__
    print(int(str(request_count)), request_date)
ValueError: invalid literal for int() with base 10: "b'21'"
2022-09-07 11:37:36,576 [log | ERROR] Internal Server Error: /favicon.ico @ /Users/c0mrade/Documents/Zmall/server/env/lib/python3.10/site-packages/django/utils/log.py : 241 : log_response
Traceback (most recent call last):
  File "/Users/c0mrade/Documents/Zmall/server/env/lib/python3.10/site-packages/django/core/handlers/exception.py", line 55, in inner
    response = get_response(request)
  File "/Users/c0mrade/Documents/Zmall/server/config/middleware.py", line 35, in __call__
    print(int(str(request_count)), request_date)
ValueError: invalid literal for int() with base 10: "b'22'"
2022-09-07 17:29:29,939 [log | ERROR] Internal Server Error: / @ /Users/c0mrade/Documents/Zmall/server/env/lib/python3.10/site-packages/django/utils/log.py : 241 : log_response
Traceback (most recent call last):
  File "/Users/c0mrade/Documents/Zmall/server/env/lib/python3.10/site-packages/django/core/handlers/exception.py", line 55, in inner
    response = get_response(request)
  File "/Users/c0mrade/Documents/Zmall/server/config/middleware.py", line 35, in __call__
    print(int(request_count), request_date)
ValueError: invalid literal for int() with base 10: "b'36'"
2022-09-07 17:29:29,988 [log | ERROR] Internal Server Error: /favicon.ico @ /Users/c0mrade/Documents/Zmall/server/env/lib/python3.10/site-packages/django/utils/log.py : 241 : log_response
Traceback (most recent call last):
  File "/Users/c0mrade/Documents/Zmall/server/env/lib/python3.10/site-packages/django/core/handlers/exception.py", line 55, in inner
    response = get_response(request)
  File "/Users/c0mrade/Documents/Zmall/server/config/middleware.py", line 35, in __call__
    print(int(request_count), request_date)
ValueError: invalid literal for int() with base 10: "b'37'"
2022-09-07 17:30:16,565 [log | ERROR] Internal Server Error: / @ /Users/c0mrade/Documents/Zmall/server/env/lib/python3.10/site-packages/django/utils/log.py : 241 : log_response
Traceback (most recent call last):
  File "/Users/c0mrade/Documents/Zmall/server/env/lib/python3.10/site-packages/django/core/handlers/exception.py", line 55, in inner
    response = get_response(request)
  File "/Users/c0mrade/Documents/Zmall/server/config/middleware.py", line 35, in __call__
    print(int(request_count, 2), request_date)
ValueError: invalid literal for int() with base 2: "b'38'"
2022-09-07 17:30:16,638 [log | ERROR] Internal Server Error: /favicon.ico @ /Users/c0mrade/Documents/Zmall/server/env/lib/python3.10/site-packages/django/utils/log.py : 241 : log_response
Traceback (most recent call last):
  File "/Users/c0mrade/Documents/Zmall/server/env/lib/python3.10/site-packages/django/core/handlers/exception.py", line 55, in inner
    response = get_response(request)
  File "/Users/c0mrade/Documents/Zmall/server/config/middleware.py", line 35, in __call__
    print(int(request_count, 2), request_date)
ValueError: invalid literal for int() with base 2: "b'39'"
2022-09-07 17:32:17,742 [log | ERROR] Internal Server Error: / @ /Users/c0mrade/Documents/Zmall/server/env/lib/python3.10/site-packages/django/utils/log.py : 241 : log_response
Traceback (most recent call last):
  File "/Users/c0mrade/Documents/Zmall/server/env/lib/python3.10/site-packages/django/core/handlers/exception.py", line 55, in inner
    response = get_response(request)
  File "/Users/c0mrade/Documents/Zmall/server/config/middleware.py", line 33, in __call__
    redis.incr(client_ip)
  File "/Users/c0mrade/Documents/Zmall/server/env/lib/python3.10/site-packages/redis/commands/core.py", line 1831, in incrby
    return self.execute_command("INCRBY", name, amount)
  File "/Users/c0mrade/Documents/Zmall/server/env/lib/python3.10/site-packages/redis/client.py", line 1238, in execute_command
    return conn.retry.call_with_retry(
  File "/Users/c0mrade/Documents/Zmall/server/env/lib/python3.10/site-packages/redis/retry.py", line 46, in call_with_retry
    return do()
  File "/Users/c0mrade/Documents/Zmall/server/env/lib/python3.10/site-packages/redis/client.py", line 1239, in <lambda>
    lambda: self._send_command_parse_response(
  File "/Users/c0mrade/Documents/Zmall/server/env/lib/python3.10/site-packages/redis/client.py", line 1215, in _send_command_parse_response
    return self.parse_response(conn, command_name, **options)
  File "/Users/c0mrade/Documents/Zmall/server/env/lib/python3.10/site-packages/redis/client.py", line 1254, in parse_response
    response = connection.read_response()
  File "/Users/c0mrade/Documents/Zmall/server/env/lib/python3.10/site-packages/redis/connection.py", line 839, in read_response
    raise response
redis.exceptions.ResponseError: value is not an integer or out of range
2022-09-07 17:32:17,831 [log | ERROR] Internal Server Error: /favicon.ico @ /Users/c0mrade/Documents/Zmall/server/env/lib/python3.10/site-packages/django/utils/log.py : 241 : log_response
Traceback (most recent call last):
  File "/Users/c0mrade/Documents/Zmall/server/env/lib/python3.10/site-packages/django/core/handlers/exception.py", line 55, in inner
    response = get_response(request)
  File "/Users/c0mrade/Documents/Zmall/server/config/middleware.py", line 33, in __call__
    redis.incr(client_ip)
  File "/Users/c0mrade/Documents/Zmall/server/env/lib/python3.10/site-packages/redis/commands/core.py", line 1831, in incrby
    return self.execute_command("INCRBY", name, amount)
  File "/Users/c0mrade/Documents/Zmall/server/env/lib/python3.10/site-packages/redis/client.py", line 1238, in execute_command
    return conn.retry.call_with_retry(
  File "/Users/c0mrade/Documents/Zmall/server/env/lib/python3.10/site-packages/redis/retry.py", line 46, in call_with_retry
    return do()
  File "/Users/c0mrade/Documents/Zmall/server/env/lib/python3.10/site-packages/redis/client.py", line 1239, in <lambda>
    lambda: self._send_command_parse_response(
  File "/Users/c0mrade/Documents/Zmall/server/env/lib/python3.10/site-packages/redis/client.py", line 1215, in _send_command_parse_response
    return self.parse_response(conn, command_name, **options)
  File "/Users/c0mrade/Documents/Zmall/server/env/lib/python3.10/site-packages/redis/client.py", line 1254, in parse_response
    response = connection.read_response()
  File "/Users/c0mrade/Documents/Zmall/server/env/lib/python3.10/site-packages/redis/connection.py", line 839, in read_response
    raise response
redis.exceptions.ResponseError: value is not an integer or out of range
2022-09-07 17:32:31,171 [log | ERROR] Internal Server Error: / @ /Users/c0mrade/Documents/Zmall/server/env/lib/python3.10/site-packages/django/utils/log.py : 241 : log_response
Traceback (most recent call last):
  File "/Users/c0mrade/Documents/Zmall/server/env/lib/python3.10/site-packages/django/core/handlers/exception.py", line 55, in inner
    response = get_response(request)
  File "/Users/c0mrade/Documents/Zmall/server/config/middleware.py", line 33, in __call__
    redis.incr(client_ip)
  File "/Users/c0mrade/Documents/Zmall/server/env/lib/python3.10/site-packages/redis/commands/core.py", line 1831, in incrby
    return self.execute_command("INCRBY", name, amount)
  File "/Users/c0mrade/Documents/Zmall/server/env/lib/python3.10/site-packages/redis/client.py", line 1238, in execute_command
    return conn.retry.call_with_retry(
  File "/Users/c0mrade/Documents/Zmall/server/env/lib/python3.10/site-packages/redis/retry.py", line 46, in call_with_retry
    return do()
  File "/Users/c0mrade/Documents/Zmall/server/env/lib/python3.10/site-packages/redis/client.py", line 1239, in <lambda>
    lambda: self._send_command_parse_response(
  File "/Users/c0mrade/Documents/Zmall/server/env/lib/python3.10/site-packages/redis/client.py", line 1215, in _send_command_parse_response
    return self.parse_response(conn, command_name, **options)
  File "/Users/c0mrade/Documents/Zmall/server/env/lib/python3.10/site-packages/redis/client.py", line 1254, in parse_response
    response = connection.read_response()
  File "/Users/c0mrade/Documents/Zmall/server/env/lib/python3.10/site-packages/redis/connection.py", line 839, in read_response
    raise response
redis.exceptions.ResponseError: value is not an integer or out of range
2022-09-07 17:32:31,232 [log | ERROR] Internal Server Error: /favicon.ico @ /Users/c0mrade/Documents/Zmall/server/env/lib/python3.10/site-packages/django/utils/log.py : 241 : log_response
Traceback (most recent call last):
  File "/Users/c0mrade/Documents/Zmall/server/env/lib/python3.10/site-packages/django/core/handlers/exception.py", line 55, in inner
    response = get_response(request)
  File "/Users/c0mrade/Documents/Zmall/server/config/middleware.py", line 33, in __call__
    redis.incr(client_ip)
  File "/Users/c0mrade/Documents/Zmall/server/env/lib/python3.10/site-packages/redis/commands/core.py", line 1831, in incrby
    return self.execute_command("INCRBY", name, amount)
  File "/Users/c0mrade/Documents/Zmall/server/env/lib/python3.10/site-packages/redis/client.py", line 1238, in execute_command
    return conn.retry.call_with_retry(
  File "/Users/c0mrade/Documents/Zmall/server/env/lib/python3.10/site-packages/redis/retry.py", line 46, in call_with_retry
    return do()
  File "/Users/c0mrade/Documents/Zmall/server/env/lib/python3.10/site-packages/redis/client.py", line 1239, in <lambda>
    lambda: self._send_command_parse_response(
  File "/Users/c0mrade/Documents/Zmall/server/env/lib/python3.10/site-packages/redis/client.py", line 1215, in _send_command_parse_response
    return self.parse_response(conn, command_name, **options)
  File "/Users/c0mrade/Documents/Zmall/server/env/lib/python3.10/site-packages/redis/client.py", line 1254, in parse_response
    response = connection.read_response()
  File "/Users/c0mrade/Documents/Zmall/server/env/lib/python3.10/site-packages/redis/connection.py", line 839, in read_response
    raise response
redis.exceptions.ResponseError: value is not an integer or out of range
2022-09-07 17:32:51,557 [log | ERROR] Internal Server Error: / @ /Users/c0mrade/Documents/Zmall/server/env/lib/python3.10/site-packages/django/utils/log.py : 241 : log_response
Traceback (most recent call last):
  File "/Users/c0mrade/Documents/Zmall/server/env/lib/python3.10/site-packages/django/core/handlers/exception.py", line 55, in inner
    response = get_response(request)
  File "/Users/c0mrade/Documents/Zmall/server/config/middleware.py", line 33, in __call__
    redis.incr(client_ip)
  File "/Users/c0mrade/Documents/Zmall/server/env/lib/python3.10/site-packages/redis/commands/core.py", line 1831, in incrby
    return self.execute_command("INCRBY", name, amount)
  File "/Users/c0mrade/Documents/Zmall/server/env/lib/python3.10/site-packages/redis/client.py", line 1238, in execute_command
    return conn.retry.call_with_retry(
  File "/Users/c0mrade/Documents/Zmall/server/env/lib/python3.10/site-packages/redis/retry.py", line 46, in call_with_retry
    return do()
  File "/Users/c0mrade/Documents/Zmall/server/env/lib/python3.10/site-packages/redis/client.py", line 1239, in <lambda>
    lambda: self._send_command_parse_response(
  File "/Users/c0mrade/Documents/Zmall/server/env/lib/python3.10/site-packages/redis/client.py", line 1215, in _send_command_parse_response
    return self.parse_response(conn, command_name, **options)
  File "/Users/c0mrade/Documents/Zmall/server/env/lib/python3.10/site-packages/redis/client.py", line 1254, in parse_response
    response = connection.read_response()
  File "/Users/c0mrade/Documents/Zmall/server/env/lib/python3.10/site-packages/redis/connection.py", line 839, in read_response
    raise response
redis.exceptions.ResponseError: value is not an integer or out of range
2022-09-07 17:32:51,630 [log | ERROR] Internal Server Error: /favicon.ico @ /Users/c0mrade/Documents/Zmall/server/env/lib/python3.10/site-packages/django/utils/log.py : 241 : log_response
Traceback (most recent call last):
  File "/Users/c0mrade/Documents/Zmall/server/env/lib/python3.10/site-packages/django/core/handlers/exception.py", line 55, in inner
    response = get_response(request)
  File "/Users/c0mrade/Documents/Zmall/server/config/middleware.py", line 33, in __call__
    redis.incr(client_ip)
  File "/Users/c0mrade/Documents/Zmall/server/env/lib/python3.10/site-packages/redis/commands/core.py", line 1831, in incrby
    return self.execute_command("INCRBY", name, amount)
  File "/Users/c0mrade/Documents/Zmall/server/env/lib/python3.10/site-packages/redis/client.py", line 1238, in execute_command
    return conn.retry.call_with_retry(
  File "/Users/c0mrade/Documents/Zmall/server/env/lib/python3.10/site-packages/redis/retry.py", line 46, in call_with_retry
    return do()
  File "/Users/c0mrade/Documents/Zmall/server/env/lib/python3.10/site-packages/redis/client.py", line 1239, in <lambda>
    lambda: self._send_command_parse_response(
  File "/Users/c0mrade/Documents/Zmall/server/env/lib/python3.10/site-packages/redis/client.py", line 1215, in _send_command_parse_response
    return self.parse_response(conn, command_name, **options)
  File "/Users/c0mrade/Documents/Zmall/server/env/lib/python3.10/site-packages/redis/client.py", line 1254, in parse_response
    response = connection.read_response()
  File "/Users/c0mrade/Documents/Zmall/server/env/lib/python3.10/site-packages/redis/connection.py", line 839, in read_response
    raise response
redis.exceptions.ResponseError: value is not an integer or out of range
2022-09-07 17:33:04,948 [log | ERROR] Internal Server Error: / @ /Users/c0mrade/Documents/Zmall/server/env/lib/python3.10/site-packages/django/utils/log.py : 241 : log_response
Traceback (most recent call last):
  File "/Users/c0mrade/Documents/Zmall/server/env/lib/python3.10/site-packages/django/core/handlers/exception.py", line 55, in inner
    response = get_response(request)
  File "/Users/c0mrade/Documents/Zmall/server/config/middleware.py", line 33, in __call__
    redis.incr(client_ip)
  File "/Users/c0mrade/Documents/Zmall/server/env/lib/python3.10/site-packages/redis/commands/core.py", line 1831, in incrby
    return self.execute_command("INCRBY", name, amount)
  File "/Users/c0mrade/Documents/Zmall/server/env/lib/python3.10/site-packages/redis/client.py", line 1238, in execute_command
    return conn.retry.call_with_retry(
  File "/Users/c0mrade/Documents/Zmall/server/env/lib/python3.10/site-packages/redis/retry.py", line 46, in call_with_retry
    return do()
  File "/Users/c0mrade/Documents/Zmall/server/env/lib/python3.10/site-packages/redis/client.py", line 1239, in <lambda>
    lambda: self._send_command_parse_response(
  File "/Users/c0mrade/Documents/Zmall/server/env/lib/python3.10/site-packages/redis/client.py", line 1215, in _send_command_parse_response
    return self.parse_response(conn, command_name, **options)
  File "/Users/c0mrade/Documents/Zmall/server/env/lib/python3.10/site-packages/redis/client.py", line 1254, in parse_response
    response = connection.read_response()
  File "/Users/c0mrade/Documents/Zmall/server/env/lib/python3.10/site-packages/redis/connection.py", line 839, in read_response
    raise response
redis.exceptions.ResponseError: value is not an integer or out of range
2022-09-07 17:33:05,022 [log | ERROR] Internal Server Error: /favicon.ico @ /Users/c0mrade/Documents/Zmall/server/env/lib/python3.10/site-packages/django/utils/log.py : 241 : log_response
Traceback (most recent call last):
  File "/Users/c0mrade/Documents/Zmall/server/env/lib/python3.10/site-packages/django/core/handlers/exception.py", line 55, in inner
    response = get_response(request)
  File "/Users/c0mrade/Documents/Zmall/server/config/middleware.py", line 33, in __call__
    redis.incr(client_ip)
  File "/Users/c0mrade/Documents/Zmall/server/env/lib/python3.10/site-packages/redis/commands/core.py", line 1831, in incrby
    return self.execute_command("INCRBY", name, amount)
  File "/Users/c0mrade/Documents/Zmall/server/env/lib/python3.10/site-packages/redis/client.py", line 1238, in execute_command
    return conn.retry.call_with_retry(
  File "/Users/c0mrade/Documents/Zmall/server/env/lib/python3.10/site-packages/redis/retry.py", line 46, in call_with_retry
    return do()
  File "/Users/c0mrade/Documents/Zmall/server/env/lib/python3.10/site-packages/redis/client.py", line 1239, in <lambda>
    lambda: self._send_command_parse_response(
  File "/Users/c0mrade/Documents/Zmall/server/env/lib/python3.10/site-packages/redis/client.py", line 1215, in _send_command_parse_response
    return self.parse_response(conn, command_name, **options)
  File "/Users/c0mrade/Documents/Zmall/server/env/lib/python3.10/site-packages/redis/client.py", line 1254, in parse_response
    response = connection.read_response()
  File "/Users/c0mrade/Documents/Zmall/server/env/lib/python3.10/site-packages/redis/connection.py", line 839, in read_response
    raise response
redis.exceptions.ResponseError: value is not an integer or out of range
2022-09-07 17:35:07,200 [log | ERROR] Internal Server Error: / @ /Users/c0mrade/Documents/Zmall/server/env/lib/python3.10/site-packages/django/utils/log.py : 241 : log_response
Traceback (most recent call last):
  File "/Users/c0mrade/Documents/Zmall/server/env/lib/python3.10/site-packages/django/core/handlers/exception.py", line 55, in inner
    response = get_response(request)
  File "/Users/c0mrade/Documents/Zmall/server/config/middleware.py", line 34, in __call__
    redis.mset({client_ip: f"{int(request_count) + 1},{today}"})
ValueError: invalid literal for int() with base 10: "b'0"
2022-09-07 17:35:07,267 [log | ERROR] Internal Server Error: /favicon.ico @ /Users/c0mrade/Documents/Zmall/server/env/lib/python3.10/site-packages/django/utils/log.py : 241 : log_response
Traceback (most recent call last):
  File "/Users/c0mrade/Documents/Zmall/server/env/lib/python3.10/site-packages/django/core/handlers/exception.py", line 55, in inner
    response = get_response(request)
  File "/Users/c0mrade/Documents/Zmall/server/config/middleware.py", line 34, in __call__
    redis.mset({client_ip: f"{int(request_count) + 1},{today}"})
ValueError: invalid literal for int() with base 10: "b'0"
2022-09-07 17:35:19,907 [log | ERROR] Internal Server Error: / @ /Users/c0mrade/Documents/Zmall/server/env/lib/python3.10/site-packages/django/utils/log.py : 241 : log_response
Traceback (most recent call last):
  File "/Users/c0mrade/Documents/Zmall/server/env/lib/python3.10/site-packages/django/core/handlers/exception.py", line 55, in inner
    response = get_response(request)
  File "/Users/c0mrade/Documents/Zmall/server/config/middleware.py", line 34, in __call__
    redis.mset({client_ip: f"{int(request_count[2:-1]) + 1},{today}"})
ValueError: invalid literal for int() with base 10: ''
2022-09-07 17:35:19,953 [log | ERROR] Internal Server Error: /favicon.ico @ /Users/c0mrade/Documents/Zmall/server/env/lib/python3.10/site-packages/django/utils/log.py : 241 : log_response
Traceback (most recent call last):
  File "/Users/c0mrade/Documents/Zmall/server/env/lib/python3.10/site-packages/django/core/handlers/exception.py", line 55, in inner
    response = get_response(request)
  File "/Users/c0mrade/Documents/Zmall/server/config/middleware.py", line 34, in __call__
    redis.mset({client_ip: f"{int(request_count[2:-1]) + 1},{today}"})
ValueError: invalid literal for int() with base 10: ''
2022-09-07 17:35:28,543 [log | ERROR] Internal Server Error: / @ /Users/c0mrade/Documents/Zmall/server/env/lib/python3.10/site-packages/django/utils/log.py : 241 : log_response
Traceback (most recent call last):
  File "/Users/c0mrade/Documents/Zmall/server/env/lib/python3.10/site-packages/django/core/handlers/exception.py", line 55, in inner
    response = get_response(request)
  File "/Users/c0mrade/Documents/Zmall/server/config/middleware.py", line 34, in __call__
    redis.mset({client_ip: f"{int(request_count[1:-1]) + 1},{today}"})
ValueError: invalid literal for int() with base 10: "'"
2022-09-07 17:35:28,608 [log | ERROR] Internal Server Error: /favicon.ico @ /Users/c0mrade/Documents/Zmall/server/env/lib/python3.10/site-packages/django/utils/log.py : 241 : log_response
Traceback (most recent call last):
  File "/Users/c0mrade/Documents/Zmall/server/env/lib/python3.10/site-packages/django/core/handlers/exception.py", line 55, in inner
    response = get_response(request)
  File "/Users/c0mrade/Documents/Zmall/server/config/middleware.py", line 34, in __call__
    redis.mset({client_ip: f"{int(request_count[1:-1]) + 1},{today}"})
ValueError: invalid literal for int() with base 10: "'"
2022-09-07 17:35:29,106 [log | ERROR] Internal Server Error: / @ /Users/c0mrade/Documents/Zmall/server/env/lib/python3.10/site-packages/django/utils/log.py : 241 : log_response
Traceback (most recent call last):
  File "/Users/c0mrade/Documents/Zmall/server/env/lib/python3.10/site-packages/django/core/handlers/exception.py", line 55, in inner
    response = get_response(request)
  File "/Users/c0mrade/Documents/Zmall/server/config/middleware.py", line 34, in __call__
    redis.mset({client_ip: f"{int(request_count[1:-1]) + 1},{today}"})
ValueError: invalid literal for int() with base 10: "'"
2022-09-07 17:35:29,173 [log | ERROR] Internal Server Error: /favicon.ico @ /Users/c0mrade/Documents/Zmall/server/env/lib/python3.10/site-packages/django/utils/log.py : 241 : log_response
Traceback (most recent call last):
  File "/Users/c0mrade/Documents/Zmall/server/env/lib/python3.10/site-packages/django/core/handlers/exception.py", line 55, in inner
    response = get_response(request)
  File "/Users/c0mrade/Documents/Zmall/server/config/middleware.py", line 34, in __call__
    redis.mset({client_ip: f"{int(request_count[1:-1]) + 1},{today}"})
ValueError: invalid literal for int() with base 10: "'"
2022-09-07 17:36:04,808 [log | ERROR] Internal Server Error: / @ /Users/c0mrade/Documents/Zmall/server/env/lib/python3.10/site-packages/django/utils/log.py : 241 : log_response
Traceback (most recent call last):
  File "/Users/c0mrade/Documents/Zmall/server/env/lib/python3.10/site-packages/django/core/handlers/exception.py", line 55, in inner
    response = get_response(request)
  File "/Users/c0mrade/Documents/Zmall/server/config/middleware.py", line 35, in __call__
    redis.mset({client_ip: f"{int(str(request_count[1:-1])) + 1},{today}"})
ValueError: invalid literal for int() with base 10: "'"
2022-09-07 17:36:06,183 [log | ERROR] Internal Server Error: / @ /Users/c0mrade/Documents/Zmall/server/env/lib/python3.10/site-packages/django/utils/log.py : 241 : log_response
Traceback (most recent call last):
  File "/Users/c0mrade/Documents/Zmall/server/env/lib/python3.10/site-packages/django/core/handlers/exception.py", line 55, in inner
    response = get_response(request)
  File "/Users/c0mrade/Documents/Zmall/server/config/middleware.py", line 35, in __call__
    redis.mset({client_ip: f"{int(str(request_count[1:-1])) + 1},{today}"})
ValueError: invalid literal for int() with base 10: "'"
2022-09-07 17:36:06,264 [log | ERROR] Internal Server Error: /favicon.ico @ /Users/c0mrade/Documents/Zmall/server/env/lib/python3.10/site-packages/django/utils/log.py : 241 : log_response
Traceback (most recent call last):
  File "/Users/c0mrade/Documents/Zmall/server/env/lib/python3.10/site-packages/django/core/handlers/exception.py", line 55, in inner
    response = get_response(request)
  File "/Users/c0mrade/Documents/Zmall/server/config/middleware.py", line 35, in __call__
    redis.mset({client_ip: f"{int(str(request_count[1:-1])) + 1},{today}"})
ValueError: invalid literal for int() with base 10: "'"
2022-09-07 17:36:13,932 [log | ERROR] Internal Server Error: / @ /Users/c0mrade/Documents/Zmall/server/env/lib/python3.10/site-packages/django/utils/log.py : 241 : log_response
Traceback (most recent call last):
  File "/Users/c0mrade/Documents/Zmall/server/env/lib/python3.10/site-packages/django/core/handlers/exception.py", line 55, in inner
    response = get_response(request)
  File "/Users/c0mrade/Documents/Zmall/server/config/middleware.py", line 35, in __call__
    # redis.mset({client_ip: f"{int(str(request_count[1:-1])) + 1},{today}"})
ValueError: invalid literal for int() with base 10: "'"
2022-09-07 17:41:00,037 [log | ERROR] Internal Server Error: / @ /Users/c0mrade/Documents/Zmall/server/env/lib/python3.10/site-packages/django/utils/log.py : 241 : log_response
Traceback (most recent call last):
  File "/Users/c0mrade/Documents/Zmall/server/env/lib/python3.10/site-packages/django/core/handlers/exception.py", line 55, in inner
    response = get_response(request)
  File "/Users/c0mrade/Documents/Zmall/server/config/middleware.py", line 38, in __call__
    redis.mset({client_ip: f"{int(request_count[2:]) + 1},{request_date}"})
TypeError: 'int' object is not subscriptable
2022-09-07 17:41:33,812 [log | ERROR] Internal Server Error: / @ /Users/c0mrade/Documents/Zmall/server/env/lib/python3.10/site-packages/django/utils/log.py : 241 : log_response
Traceback (most recent call last):
  File "/Users/c0mrade/Documents/Zmall/server/env/lib/python3.10/site-packages/django/core/handlers/exception.py", line 55, in inner
    response = get_response(request)
  File "/Users/c0mrade/Documents/Zmall/server/config/middleware.py", line 40, in __call__
    raise ValueError("rate limit")
ValueError: rate limit
2022-09-07 17:46:53,810 [log | ERROR] Internal Server Error: / @ /Users/c0mrade/Documents/Zmall/server/env/lib/python3.10/site-packages/django/utils/log.py : 241 : log_response
Traceback (most recent call last):
  File "/Users/c0mrade/Documents/Zmall/server/env/lib/python3.10/site-packages/django/core/handlers/exception.py", line 55, in inner
    response = get_response(request)
  File "/Users/c0mrade/Documents/Zmall/server/config/middleware.py", line 39, in __call__
    redis.set({client_ip: f"{int(request_count[2:]) + 1},{request_date}"})
TypeError: BasicKeyCommands.set() missing 1 required positional argument: 'value'
2022-09-07 17:46:53,866 [log | ERROR] Internal Server Error: /favicon.ico @ /Users/c0mrade/Documents/Zmall/server/env/lib/python3.10/site-packages/django/utils/log.py : 241 : log_response
Traceback (most recent call last):
  File "/Users/c0mrade/Documents/Zmall/server/env/lib/python3.10/site-packages/django/core/handlers/exception.py", line 55, in inner
    response = get_response(request)
  File "/Users/c0mrade/Documents/Zmall/server/config/middleware.py", line 39, in __call__
    redis.set({client_ip: f"{int(request_count[2:]) + 1},{request_date}"})
TypeError: BasicKeyCommands.set() missing 1 required positional argument: 'value'
2022-09-07 17:53:20,373 [log | ERROR] Internal Server Error: / @ /Users/c0mrade/Documents/Zmall/server/env/lib/python3.10/site-packages/django/utils/log.py : 241 : log_response
Traceback (most recent call last):
  File "/Users/c0mrade/Documents/Zmall/server/env/lib/python3.10/site-packages/django/core/handlers/exception.py", line 55, in inner
    response = get_response(request)
  File "/Users/c0mrade/Documents/Zmall/server/config/middleware.py", line 39, in __call__
    if client_date < today:
TypeError: '<' not supported between instances of 'bytes' and 'str'
2022-09-07 17:53:20,450 [log | ERROR] Internal Server Error: /favicon.ico @ /Users/c0mrade/Documents/Zmall/server/env/lib/python3.10/site-packages/django/utils/log.py : 241 : log_response
Traceback (most recent call last):
  File "/Users/c0mrade/Documents/Zmall/server/env/lib/python3.10/site-packages/django/core/handlers/exception.py", line 55, in inner
    response = get_response(request)
  File "/Users/c0mrade/Documents/Zmall/server/config/middleware.py", line 39, in __call__
    if client_date < today:
TypeError: '<' not supported between instances of 'bytes' and 'str'
2022-09-07 17:54:01,938 [log | ERROR] Internal Server Error: / @ /Users/c0mrade/Documents/Zmall/server/env/lib/python3.10/site-packages/django/utils/log.py : 241 : log_response
Traceback (most recent call last):
  File "/Users/c0mrade/Documents/Zmall/server/env/lib/python3.10/site-packages/django/core/handlers/exception.py", line 55, in inner
    response = get_response(request)
  File "/Users/c0mrade/Documents/Zmall/server/config/middleware.py", line 46, in __call__
    if int(client_count) > 10 and client_date == today:
ValueError: invalid literal for int() with base 10: "4'"
2022-09-07 17:54:08,385 [log | ERROR] Internal Server Error: / @ /Users/c0mrade/Documents/Zmall/server/env/lib/python3.10/site-packages/django/utils/log.py : 241 : log_response
Traceback (most recent call last):
  File "/Users/c0mrade/Documents/Zmall/server/env/lib/python3.10/site-packages/django/core/handlers/exception.py", line 55, in inner
    response = get_response(request)
  File "/Users/c0mrade/Documents/Zmall/server/config/middleware.py", line 46, in __call__
    if int(client_count) > 10 and client_date == today:
ValueError: invalid literal for int() with base 10: ''
2022-09-07 17:54:48,444 [log | ERROR] Internal Server Error: / @ /Users/c0mrade/Documents/Zmall/server/env/lib/python3.10/site-packages/django/utils/log.py : 241 : log_response
Traceback (most recent call last):
  File "/Users/c0mrade/Documents/Zmall/server/env/lib/python3.10/site-packages/django/core/handlers/exception.py", line 55, in inner
    response = get_response(request)
  File "/Users/c0mrade/Documents/Zmall/server/config/middleware.py", line 44, in __call__
    raise ValueError("rate limit")
ValueError: rate limit
2022-09-07 17:54:49,316 [log | ERROR] Internal Server Error: / @ /Users/c0mrade/Documents/Zmall/server/env/lib/python3.10/site-packages/django/utils/log.py : 241 : log_response
Traceback (most recent call last):
  File "/Users/c0mrade/Documents/Zmall/server/env/lib/python3.10/site-packages/django/core/handlers/exception.py", line 55, in inner
    response = get_response(request)
  File "/Users/c0mrade/Documents/Zmall/server/config/middleware.py", line 44, in __call__
    raise ValueError("rate limit")
ValueError: rate limit
2022-09-07 17:54:49,474 [log | ERROR] Internal Server Error: / @ /Users/c0mrade/Documents/Zmall/server/env/lib/python3.10/site-packages/django/utils/log.py : 241 : log_response
Traceback (most recent call last):
  File "/Users/c0mrade/Documents/Zmall/server/env/lib/python3.10/site-packages/django/core/handlers/exception.py", line 55, in inner
    response = get_response(request)
  File "/Users/c0mrade/Documents/Zmall/server/config/middleware.py", line 44, in __call__
    raise ValueError("rate limit")
ValueError: rate limit
2022-09-07 17:54:49,634 [log | ERROR] Internal Server Error: / @ /Users/c0mrade/Documents/Zmall/server/env/lib/python3.10/site-packages/django/utils/log.py : 241 : log_response
Traceback (most recent call last):
  File "/Users/c0mrade/Documents/Zmall/server/env/lib/python3.10/site-packages/django/core/handlers/exception.py", line 55, in inner
    response = get_response(request)
  File "/Users/c0mrade/Documents/Zmall/server/config/middleware.py", line 44, in __call__
    raise ValueError("rate limit")
ValueError: rate limit
2022-09-07 18:09:11,556 [log | ERROR] Internal Server Error: /swagger/ @ /Users/c0mrade/Documents/Zmall/server/env/lib/python3.10/site-packages/django/utils/log.py : 241 : log_response
Traceback (most recent call last):
  File "/Users/c0mrade/Documents/Zmall/server/env/lib/python3.10/site-packages/django/core/handlers/exception.py", line 55, in inner
    response = get_response(request)
  File "/Users/c0mrade/Documents/Zmall/server/env/lib/python3.10/site-packages/django/core/handlers/base.py", line 197, in _get_response
    response = wrapped_callback(request, *callback_args, **callback_kwargs)
  File "/Users/c0mrade/Documents/Zmall/server/env/lib/python3.10/site-packages/django/views/decorators/csrf.py", line 54, in wrapped_view
    return view_func(*args, **kwargs)
  File "/Users/c0mrade/Documents/Zmall/server/env/lib/python3.10/site-packages/django/views/generic/base.py", line 103, in view
    return self.dispatch(request, *args, **kwargs)
  File "/Users/c0mrade/Documents/Zmall/server/env/lib/python3.10/site-packages/rest_framework/views.py", line 509, in dispatch
    response = self.handle_exception(exc)
  File "/Users/c0mrade/Documents/Zmall/server/env/lib/python3.10/site-packages/rest_framework/views.py", line 469, in handle_exception
    self.raise_uncaught_exception(exc)
  File "/Users/c0mrade/Documents/Zmall/server/env/lib/python3.10/site-packages/rest_framework/views.py", line 480, in raise_uncaught_exception
    raise exc
  File "/Users/c0mrade/Documents/Zmall/server/env/lib/python3.10/site-packages/rest_framework/views.py", line 506, in dispatch
    response = handler(request, *args, **kwargs)
  File "/Users/c0mrade/Documents/Zmall/server/env/lib/python3.10/site-packages/drf_yasg/views.py", line 94, in get
    schema = generator.get_schema(request, self.public)
  File "/Users/c0mrade/Documents/Zmall/server/env/lib/python3.10/site-packages/drf_yasg/generators.py", line 248, in get_schema
    paths, prefix = self.get_paths(endpoints, components, request, public)
  File "/Users/c0mrade/Documents/Zmall/server/env/lib/python3.10/site-packages/drf_yasg/generators.py", line 406, in get_paths
    operation = self.get_operation(view, path, prefix, method, components, request)
  File "/Users/c0mrade/Documents/Zmall/server/env/lib/python3.10/site-packages/drf_yasg/generators.py", line 448, in get_operation
    operation = view_inspector.get_operation(operation_keys)
  File "/Users/c0mrade/Documents/Zmall/server/env/lib/python3.10/site-packages/drf_yasg/inspectors/view.py", line 45, in get_operation
    responses = self.get_responses()
  File "/Users/c0mrade/Documents/Zmall/server/env/lib/python3.10/site-packages/drf_yasg/inspectors/view.py", line 180, in get_responses
    response_serializers = self.get_response_serializers()
  File "/Users/c0mrade/Documents/Zmall/server/env/lib/python3.10/site-packages/drf_yasg/inspectors/view.py", line 235, in get_response_serializers
    responses = self.get_default_responses()
  File "/Users/c0mrade/Documents/Zmall/server/env/lib/python3.10/site-packages/drf_yasg/inspectors/view.py", line 211, in get_default_responses
    default_schema = self.serializer_to_schema(default_schema) or ''
  File "/Users/c0mrade/Documents/Zmall/server/env/lib/python3.10/site-packages/drf_yasg/inspectors/base.py", line 438, in serializer_to_schema
    return self.probe_inspectors(
  File "/Users/c0mrade/Documents/Zmall/server/env/lib/python3.10/site-packages/drf_yasg/inspectors/base.py", line 110, in probe_inspectors
    result = method(obj, **kwargs)
  File "/Users/c0mrade/Documents/Zmall/server/env/lib/python3.10/site-packages/drf_yasg/inspectors/field.py", line 33, in get_schema
    return self.probe_field_inspectors(serializer, openapi.Schema, self.use_definitions)
  File "/Users/c0mrade/Documents/Zmall/server/env/lib/python3.10/site-packages/drf_yasg/inspectors/base.py", line 228, in probe_field_inspectors
    return self.probe_inspectors(
  File "/Users/c0mrade/Documents/Zmall/server/env/lib/python3.10/site-packages/drf_yasg/inspectors/base.py", line 110, in probe_inspectors
    result = method(obj, **kwargs)
  File "/Users/c0mrade/Documents/Zmall/server/env/lib/python3.10/site-packages/drf_yasg/inspectors/field.py", line 132, in field_to_swagger_object
    raise SwaggerGenerationError(
drf_yasg.errors.SwaggerGenerationError: Schema for <class 'advert.serializers.advert_serializers.AdvertImageSerializer'> would override distinct serializer <class 'custom_admin.serializers.AdvertImageSerializer'> because they implicitly share the same ref_name; explicitly set the ref_name attribute on both serializers' Meta classes
2022-09-07 18:09:12,557 [log | ERROR] Internal Server Error: /swagger/ @ /Users/c0mrade/Documents/Zmall/server/env/lib/python3.10/site-packages/django/utils/log.py : 241 : log_response
Traceback (most recent call last):
  File "/Users/c0mrade/Documents/Zmall/server/env/lib/python3.10/site-packages/django/core/handlers/exception.py", line 55, in inner
    response = get_response(request)
  File "/Users/c0mrade/Documents/Zmall/server/env/lib/python3.10/site-packages/django/core/handlers/base.py", line 197, in _get_response
    response = wrapped_callback(request, *callback_args, **callback_kwargs)
  File "/Users/c0mrade/Documents/Zmall/server/env/lib/python3.10/site-packages/django/views/decorators/csrf.py", line 54, in wrapped_view
    return view_func(*args, **kwargs)
  File "/Users/c0mrade/Documents/Zmall/server/env/lib/python3.10/site-packages/django/views/generic/base.py", line 103, in view
    return self.dispatch(request, *args, **kwargs)
  File "/Users/c0mrade/Documents/Zmall/server/env/lib/python3.10/site-packages/rest_framework/views.py", line 509, in dispatch
    response = self.handle_exception(exc)
  File "/Users/c0mrade/Documents/Zmall/server/env/lib/python3.10/site-packages/rest_framework/views.py", line 469, in handle_exception
    self.raise_uncaught_exception(exc)
  File "/Users/c0mrade/Documents/Zmall/server/env/lib/python3.10/site-packages/rest_framework/views.py", line 480, in raise_uncaught_exception
    raise exc
  File "/Users/c0mrade/Documents/Zmall/server/env/lib/python3.10/site-packages/rest_framework/views.py", line 506, in dispatch
    response = handler(request, *args, **kwargs)
  File "/Users/c0mrade/Documents/Zmall/server/env/lib/python3.10/site-packages/drf_yasg/views.py", line 94, in get
    schema = generator.get_schema(request, self.public)
  File "/Users/c0mrade/Documents/Zmall/server/env/lib/python3.10/site-packages/drf_yasg/generators.py", line 248, in get_schema
    paths, prefix = self.get_paths(endpoints, components, request, public)
  File "/Users/c0mrade/Documents/Zmall/server/env/lib/python3.10/site-packages/drf_yasg/generators.py", line 406, in get_paths
    operation = self.get_operation(view, path, prefix, method, components, request)
  File "/Users/c0mrade/Documents/Zmall/server/env/lib/python3.10/site-packages/drf_yasg/generators.py", line 448, in get_operation
    operation = view_inspector.get_operation(operation_keys)
  File "/Users/c0mrade/Documents/Zmall/server/env/lib/python3.10/site-packages/drf_yasg/inspectors/view.py", line 45, in get_operation
    responses = self.get_responses()
  File "/Users/c0mrade/Documents/Zmall/server/env/lib/python3.10/site-packages/drf_yasg/inspectors/view.py", line 180, in get_responses
    response_serializers = self.get_response_serializers()
  File "/Users/c0mrade/Documents/Zmall/server/env/lib/python3.10/site-packages/drf_yasg/inspectors/view.py", line 235, in get_response_serializers
    responses = self.get_default_responses()
  File "/Users/c0mrade/Documents/Zmall/server/env/lib/python3.10/site-packages/drf_yasg/inspectors/view.py", line 211, in get_default_responses
    default_schema = self.serializer_to_schema(default_schema) or ''
  File "/Users/c0mrade/Documents/Zmall/server/env/lib/python3.10/site-packages/drf_yasg/inspectors/base.py", line 438, in serializer_to_schema
    return self.probe_inspectors(
  File "/Users/c0mrade/Documents/Zmall/server/env/lib/python3.10/site-packages/drf_yasg/inspectors/base.py", line 110, in probe_inspectors
    result = method(obj, **kwargs)
  File "/Users/c0mrade/Documents/Zmall/server/env/lib/python3.10/site-packages/drf_yasg/inspectors/field.py", line 33, in get_schema
    return self.probe_field_inspectors(serializer, openapi.Schema, self.use_definitions)
  File "/Users/c0mrade/Documents/Zmall/server/env/lib/python3.10/site-packages/drf_yasg/inspectors/base.py", line 228, in probe_field_inspectors
    return self.probe_inspectors(
  File "/Users/c0mrade/Documents/Zmall/server/env/lib/python3.10/site-packages/drf_yasg/inspectors/base.py", line 110, in probe_inspectors
    result = method(obj, **kwargs)
  File "/Users/c0mrade/Documents/Zmall/server/env/lib/python3.10/site-packages/drf_yasg/inspectors/field.py", line 132, in field_to_swagger_object
    raise SwaggerGenerationError(
drf_yasg.errors.SwaggerGenerationError: Schema for <class 'advert.serializers.advert_serializers.AdvertImageSerializer'> would override distinct serializer <class 'custom_admin.serializers.AdvertImageSerializer'> because they implicitly share the same ref_name; explicitly set the ref_name attribute on both serializers' Meta classes
2022-09-07 18:09:51,882 [log | ERROR] Internal Server Error: /swagger/ @ /Users/c0mrade/Documents/Zmall/server/env/lib/python3.10/site-packages/django/utils/log.py : 241 : log_response
Traceback (most recent call last):
  File "/Users/c0mrade/Documents/Zmall/server/env/lib/python3.10/site-packages/django/core/handlers/exception.py", line 55, in inner
    response = get_response(request)
  File "/Users/c0mrade/Documents/Zmall/server/env/lib/python3.10/site-packages/django/core/handlers/base.py", line 197, in _get_response
    response = wrapped_callback(request, *callback_args, **callback_kwargs)
  File "/Users/c0mrade/Documents/Zmall/server/env/lib/python3.10/site-packages/django/views/decorators/csrf.py", line 54, in wrapped_view
    return view_func(*args, **kwargs)
  File "/Users/c0mrade/Documents/Zmall/server/env/lib/python3.10/site-packages/django/views/generic/base.py", line 103, in view
    return self.dispatch(request, *args, **kwargs)
  File "/Users/c0mrade/Documents/Zmall/server/env/lib/python3.10/site-packages/rest_framework/views.py", line 509, in dispatch
    response = self.handle_exception(exc)
  File "/Users/c0mrade/Documents/Zmall/server/env/lib/python3.10/site-packages/rest_framework/views.py", line 469, in handle_exception
    self.raise_uncaught_exception(exc)
  File "/Users/c0mrade/Documents/Zmall/server/env/lib/python3.10/site-packages/rest_framework/views.py", line 480, in raise_uncaught_exception
    raise exc
  File "/Users/c0mrade/Documents/Zmall/server/env/lib/python3.10/site-packages/rest_framework/views.py", line 506, in dispatch
    response = handler(request, *args, **kwargs)
  File "/Users/c0mrade/Documents/Zmall/server/env/lib/python3.10/site-packages/drf_yasg/views.py", line 94, in get
    schema = generator.get_schema(request, self.public)
  File "/Users/c0mrade/Documents/Zmall/server/env/lib/python3.10/site-packages/drf_yasg/generators.py", line 248, in get_schema
    paths, prefix = self.get_paths(endpoints, components, request, public)
  File "/Users/c0mrade/Documents/Zmall/server/env/lib/python3.10/site-packages/drf_yasg/generators.py", line 406, in get_paths
    operation = self.get_operation(view, path, prefix, method, components, request)
  File "/Users/c0mrade/Documents/Zmall/server/env/lib/python3.10/site-packages/drf_yasg/generators.py", line 448, in get_operation
    operation = view_inspector.get_operation(operation_keys)
  File "/Users/c0mrade/Documents/Zmall/server/env/lib/python3.10/site-packages/drf_yasg/inspectors/view.py", line 45, in get_operation
    responses = self.get_responses()
  File "/Users/c0mrade/Documents/Zmall/server/env/lib/python3.10/site-packages/drf_yasg/inspectors/view.py", line 180, in get_responses
    response_serializers = self.get_response_serializers()
  File "/Users/c0mrade/Documents/Zmall/server/env/lib/python3.10/site-packages/drf_yasg/inspectors/view.py", line 235, in get_response_serializers
    responses = self.get_default_responses()
  File "/Users/c0mrade/Documents/Zmall/server/env/lib/python3.10/site-packages/drf_yasg/inspectors/view.py", line 211, in get_default_responses
    default_schema = self.serializer_to_schema(default_schema) or ''
  File "/Users/c0mrade/Documents/Zmall/server/env/lib/python3.10/site-packages/drf_yasg/inspectors/base.py", line 438, in serializer_to_schema
    return self.probe_inspectors(
  File "/Users/c0mrade/Documents/Zmall/server/env/lib/python3.10/site-packages/drf_yasg/inspectors/base.py", line 110, in probe_inspectors
    result = method(obj, **kwargs)
  File "/Users/c0mrade/Documents/Zmall/server/env/lib/python3.10/site-packages/drf_yasg/inspectors/field.py", line 33, in get_schema
    return self.probe_field_inspectors(serializer, openapi.Schema, self.use_definitions)
  File "/Users/c0mrade/Documents/Zmall/server/env/lib/python3.10/site-packages/drf_yasg/inspectors/base.py", line 228, in probe_field_inspectors
    return self.probe_inspectors(
  File "/Users/c0mrade/Documents/Zmall/server/env/lib/python3.10/site-packages/drf_yasg/inspectors/base.py", line 110, in probe_inspectors
    result = method(obj, **kwargs)
  File "/Users/c0mrade/Documents/Zmall/server/env/lib/python3.10/site-packages/drf_yasg/inspectors/field.py", line 132, in field_to_swagger_object
    raise SwaggerGenerationError(
drf_yasg.errors.SwaggerGenerationError: Schema for <class 'advert.serializers.category_serializers.CategorySerializer'> would override distinct serializer <class 'custom_admin.serializers.CategorySerializer'> because they implicitly share the same ref_name; explicitly set the ref_name attribute on both serializers' Meta classes
