2022-09-07 18:21:18,443 [log | ERROR] Internal Server Error: /api/v1/user/login/ @ /Users/c0mrade/Documents/Zmall/server/env/lib/python3.10/site-packages/django/utils/log.py : 241 : log_response
Traceback (most recent call last):
  File "/Users/c0mrade/Documents/Zmall/server/env/lib/python3.10/site-packages/django/core/handlers/exception.py", line 55, in inner
    response = get_response(request)
  File "/Users/c0mrade/Documents/Zmall/server/env/lib/python3.10/site-packages/django/core/handlers/base.py", line 197, in _get_response
    response = wrapped_callback(request, *callback_args, **callback_kwargs)
  File "/Users/c0mrade/Documents/Zmall/server/env/lib/python3.10/site-packages/django/views/decorators/csrf.py", line 54, in wrapped_view
    return view_func(*args, **kwargs)
  File "/Users/c0mrade/Documents/Zmall/server/env/lib/python3.10/site-packages/django/views/generic/base.py", line 103, in view
    return self.dispatch(request, *args, **kwargs)
  File "/Users/c0mrade/Documents/Zmall/server/env/lib/python3.10/site-packages/rest_framework/views.py", line 509, in dispatch
    response = self.handle_exception(exc)
  File "/Users/c0mrade/Documents/Zmall/server/env/lib/python3.10/site-packages/rest_framework/views.py", line 469, in handle_exception
    self.raise_uncaught_exception(exc)
  File "/Users/c0mrade/Documents/Zmall/server/env/lib/python3.10/site-packages/rest_framework/views.py", line 480, in raise_uncaught_exception
    raise exc
  File "/Users/c0mrade/Documents/Zmall/server/env/lib/python3.10/site-packages/rest_framework/views.py", line 506, in dispatch
    response = handler(request, *args, **kwargs)
  File "/Users/c0mrade/Documents/Zmall/server/env/lib/python3.10/site-packages/rest_framework_simplejwt/views.py", line 43, in post
    serializer.is_valid(raise_exception=True)
  File "/Users/c0mrade/Documents/Zmall/server/env/lib/python3.10/site-packages/rest_framework/serializers.py", line 227, in is_valid
    self._validated_data = self.run_validation(self.initial_data)
  File "/Users/c0mrade/Documents/Zmall/server/env/lib/python3.10/site-packages/rest_framework/serializers.py", line 429, in run_validation
    value = self.validate(value)
  File "/Users/c0mrade/Documents/Zmall/server/apps/user/api/serializers.py", line 43, in validate
    data = super(MyTokenObtainPairSerializer, self).validate()
TypeError: TokenObtainPairSerializer.validate() missing 1 required positional argument: 'attrs'
