2022-09-14 11:51:08,974 [autoreload | INFO] Watching for file changes with StatReloader
2022-09-14 11:51:40,638 [autoreload | INFO] /Users/zharkynaskatkyzy/PycharmProjects/Zmall/server/apps/advert/models.py changed, reloading.
2022-09-14 11:51:41,142 [autoreload | INFO] Watching for file changes with StatReloader
2022-09-14 11:52:11,798 [autoreload | INFO] /Users/zharkynaskatkyzy/PycharmProjects/Zmall/server/apps/advert/models.py changed, reloading.
2022-09-14 11:52:12,270 [autoreload | INFO] Watching for file changes with StatReloader
2022-09-14 11:54:11,570 [log | WARNING] Not Found: /
2022-09-14 11:54:13,214 [log | WARNING] Not Found: /
2022-09-14 11:54:15,018 [base | WARNING] view's ContactView raised exception during schema generation; use `getattr(self, 'swagger_fake_view', False)` to detect and short-circuit this
Traceback (most recent call last):
  File "/Library/Frameworks/Python.framework/Versions/3.10/lib/python3.10/site-packages/drf_yasg/inspectors/base.py", line 42, in call_view_method
    return view_method()
  File "/Library/Frameworks/Python.framework/Versions/3.10/lib/python3.10/site-packages/rest_framework/generics.py", line 108, in get_serializer
    serializer_class = self.get_serializer_class()
  File "/Library/Frameworks/Python.framework/Versions/3.10/lib/python3.10/site-packages/rest_framework/generics.py", line 122, in get_serializer_class
    assert self.serializer_class is not None, (
AssertionError: 'ContactView' should either include a `serializer_class` attribute, or override the `get_serializer_class()` method.
2022-09-14 11:54:15,019 [base | WARNING] view's ContactView raised exception during schema generation; use `getattr(self, 'swagger_fake_view', False)` to detect and short-circuit this
Traceback (most recent call last):
  File "/Library/Frameworks/Python.framework/Versions/3.10/lib/python3.10/site-packages/drf_yasg/inspectors/base.py", line 42, in call_view_method
    return view_method()
  File "/Library/Frameworks/Python.framework/Versions/3.10/lib/python3.10/site-packages/rest_framework/generics.py", line 108, in get_serializer
    serializer_class = self.get_serializer_class()
  File "/Library/Frameworks/Python.framework/Versions/3.10/lib/python3.10/site-packages/rest_framework/generics.py", line 122, in get_serializer_class
    assert self.serializer_class is not None, (
AssertionError: 'ContactView' should either include a `serializer_class` attribute, or override the `get_serializer_class()` method.
2022-09-14 11:54:15,033 [base | WARNING] view's VerifyEmail raised exception during schema generation; use `getattr(self, 'swagger_fake_view', False)` to detect and short-circuit this
Traceback (most recent call last):
  File "/Library/Frameworks/Python.framework/Versions/3.10/lib/python3.10/site-packages/drf_yasg/inspectors/base.py", line 42, in call_view_method
    return view_method()
  File "/Library/Frameworks/Python.framework/Versions/3.10/lib/python3.10/site-packages/rest_framework/generics.py", line 108, in get_serializer
    serializer_class = self.get_serializer_class()
  File "/Library/Frameworks/Python.framework/Versions/3.10/lib/python3.10/site-packages/rest_framework/generics.py", line 122, in get_serializer_class
    assert self.serializer_class is not None, (
AssertionError: 'VerifyEmail' should either include a `serializer_class` attribute, or override the `get_serializer_class()` method.
2022-09-14 11:57:15,619 [autoreload | INFO] /Users/zharkynaskatkyzy/PycharmProjects/Zmall/server/apps/advert/serializers/advert_serializers.py changed, reloading.
2022-09-14 11:57:16,247 [autoreload | INFO] Watching for file changes with StatReloader
2022-09-14 11:57:27,953 [autoreload | INFO] /Users/zharkynaskatkyzy/PycharmProjects/Zmall/server/apps/advert/serializers/advert_serializers.py changed, reloading.
2022-09-14 11:57:28,573 [autoreload | INFO] Watching for file changes with StatReloader
2022-09-14 11:57:30,126 [base | WARNING] view's ContactView raised exception during schema generation; use `getattr(self, 'swagger_fake_view', False)` to detect and short-circuit this
Traceback (most recent call last):
  File "/Library/Frameworks/Python.framework/Versions/3.10/lib/python3.10/site-packages/drf_yasg/inspectors/base.py", line 42, in call_view_method
    return view_method()
  File "/Library/Frameworks/Python.framework/Versions/3.10/lib/python3.10/site-packages/rest_framework/generics.py", line 108, in get_serializer
    serializer_class = self.get_serializer_class()
  File "/Library/Frameworks/Python.framework/Versions/3.10/lib/python3.10/site-packages/rest_framework/generics.py", line 122, in get_serializer_class
    assert self.serializer_class is not None, (
AssertionError: 'ContactView' should either include a `serializer_class` attribute, or override the `get_serializer_class()` method.
2022-09-14 11:57:30,127 [base | WARNING] view's ContactView raised exception during schema generation; use `getattr(self, 'swagger_fake_view', False)` to detect and short-circuit this
Traceback (most recent call last):
  File "/Library/Frameworks/Python.framework/Versions/3.10/lib/python3.10/site-packages/drf_yasg/inspectors/base.py", line 42, in call_view_method
    return view_method()
  File "/Library/Frameworks/Python.framework/Versions/3.10/lib/python3.10/site-packages/rest_framework/generics.py", line 108, in get_serializer
    serializer_class = self.get_serializer_class()
  File "/Library/Frameworks/Python.framework/Versions/3.10/lib/python3.10/site-packages/rest_framework/generics.py", line 122, in get_serializer_class
    assert self.serializer_class is not None, (
AssertionError: 'ContactView' should either include a `serializer_class` attribute, or override the `get_serializer_class()` method.
2022-09-14 11:57:30,139 [base | WARNING] view's VerifyEmail raised exception during schema generation; use `getattr(self, 'swagger_fake_view', False)` to detect and short-circuit this
Traceback (most recent call last):
  File "/Library/Frameworks/Python.framework/Versions/3.10/lib/python3.10/site-packages/drf_yasg/inspectors/base.py", line 42, in call_view_method
    return view_method()
  File "/Library/Frameworks/Python.framework/Versions/3.10/lib/python3.10/site-packages/rest_framework/generics.py", line 108, in get_serializer
    serializer_class = self.get_serializer_class()
  File "/Library/Frameworks/Python.framework/Versions/3.10/lib/python3.10/site-packages/rest_framework/generics.py", line 122, in get_serializer_class
    assert self.serializer_class is not None, (
AssertionError: 'VerifyEmail' should either include a `serializer_class` attribute, or override the `get_serializer_class()` method.
2022-09-14 11:58:21,056 [autoreload | INFO] /Users/zharkynaskatkyzy/PycharmProjects/Zmall/server/apps/advert/serializers/advert_serializers.py changed, reloading.
2022-09-14 11:58:21,541 [autoreload | INFO] Watching for file changes with StatReloader
2022-09-14 11:58:37,593 [log | ERROR] Internal Server Error: /api/v1/advert/1/
Traceback (most recent call last):
  File "/Library/Frameworks/Python.framework/Versions/3.10/lib/python3.10/site-packages/django/db/backends/utils.py", line 89, in _execute
    return self.cursor.execute(sql, params)
psycopg2.errors.UndefinedColumn: column advert_advert.promote_id does not exist
LINE 1: ...rt"."sub_category_id", "advert_advert"."city_id", "advert_ad...
                                                             ^


The above exception was the direct cause of the following exception:

Traceback (most recent call last):
  File "/Library/Frameworks/Python.framework/Versions/3.10/lib/python3.10/site-packages/django/core/handlers/exception.py", line 55, in inner
    response = get_response(request)
  File "/Users/zharkynaskatkyzy/PycharmProjects/Zmall/server/config/middleware.py", line 65, in __call__
    set_advert_count(int(path.name), str(user), client_ip)
  File "/Users/zharkynaskatkyzy/PycharmProjects/Zmall/server/apps/advert/services.py", line 37, in set_advert_count
    ad = Advert.objects.get(id=id)
  File "/Library/Frameworks/Python.framework/Versions/3.10/lib/python3.10/site-packages/django/db/models/manager.py", line 85, in manager_method
    return getattr(self.get_queryset(), name)(*args, **kwargs)
  File "/Library/Frameworks/Python.framework/Versions/3.10/lib/python3.10/site-packages/django/db/models/query.py", line 646, in get
    num = len(clone)
  File "/Library/Frameworks/Python.framework/Versions/3.10/lib/python3.10/site-packages/django/db/models/query.py", line 376, in __len__
    self._fetch_all()
  File "/Library/Frameworks/Python.framework/Versions/3.10/lib/python3.10/site-packages/django/db/models/query.py", line 1866, in _fetch_all
    self._result_cache = list(self._iterable_class(self))
  File "/Library/Frameworks/Python.framework/Versions/3.10/lib/python3.10/site-packages/django/db/models/query.py", line 87, in __iter__
    results = compiler.execute_sql(
  File "/Library/Frameworks/Python.framework/Versions/3.10/lib/python3.10/site-packages/django/db/models/sql/compiler.py", line 1395, in execute_sql
    cursor.execute(sql, params)
  File "/Library/Frameworks/Python.framework/Versions/3.10/lib/python3.10/site-packages/django/db/backends/utils.py", line 103, in execute
    return super().execute(sql, params)
  File "/Library/Frameworks/Python.framework/Versions/3.10/lib/python3.10/site-packages/django/db/backends/utils.py", line 67, in execute
    return self._execute_with_wrappers(
  File "/Library/Frameworks/Python.framework/Versions/3.10/lib/python3.10/site-packages/django/db/backends/utils.py", line 80, in _execute_with_wrappers
    return executor(sql, params, many, context)
  File "/Library/Frameworks/Python.framework/Versions/3.10/lib/python3.10/site-packages/django/db/backends/utils.py", line 84, in _execute
    with self.db.wrap_database_errors:
  File "/Library/Frameworks/Python.framework/Versions/3.10/lib/python3.10/site-packages/django/db/utils.py", line 91, in __exit__
    raise dj_exc_value.with_traceback(traceback) from exc_value
  File "/Library/Frameworks/Python.framework/Versions/3.10/lib/python3.10/site-packages/django/db/backends/utils.py", line 89, in _execute
    return self.cursor.execute(sql, params)
django.db.utils.ProgrammingError: column advert_advert.promote_id does not exist
LINE 1: ...rt"."sub_category_id", "advert_advert"."city_id", "advert_ad...
                                                             ^

2022-09-14 11:58:56,053 [log | ERROR] Internal Server Error: /api/v1/advert/
Traceback (most recent call last):
  File "/Library/Frameworks/Python.framework/Versions/3.10/lib/python3.10/site-packages/django/db/backends/utils.py", line 89, in _execute
    return self.cursor.execute(sql, params)
psycopg2.errors.UndefinedColumn: column advert_advert.promote_id does not exist
LINE 1: ...rt"."sub_category_id", "advert_advert"."city_id", "advert_ad...
                                                             ^


The above exception was the direct cause of the following exception:

Traceback (most recent call last):
  File "/Library/Frameworks/Python.framework/Versions/3.10/lib/python3.10/site-packages/django/core/handlers/exception.py", line 55, in inner
    response = get_response(request)
  File "/Library/Frameworks/Python.framework/Versions/3.10/lib/python3.10/site-packages/django/core/handlers/base.py", line 197, in _get_response
    response = wrapped_callback(request, *callback_args, **callback_kwargs)
  File "/Library/Frameworks/Python.framework/Versions/3.10/lib/python3.10/site-packages/django/views/decorators/csrf.py", line 54, in wrapped_view
    return view_func(*args, **kwargs)
  File "/Library/Frameworks/Python.framework/Versions/3.10/lib/python3.10/site-packages/rest_framework/viewsets.py", line 125, in view
    return self.dispatch(request, *args, **kwargs)
  File "/Library/Frameworks/Python.framework/Versions/3.10/lib/python3.10/site-packages/rest_framework/views.py", line 509, in dispatch
    response = self.handle_exception(exc)
  File "/Library/Frameworks/Python.framework/Versions/3.10/lib/python3.10/site-packages/rest_framework/views.py", line 469, in handle_exception
    self.raise_uncaught_exception(exc)
  File "/Library/Frameworks/Python.framework/Versions/3.10/lib/python3.10/site-packages/rest_framework/views.py", line 480, in raise_uncaught_exception
    raise exc
  File "/Library/Frameworks/Python.framework/Versions/3.10/lib/python3.10/site-packages/rest_framework/views.py", line 506, in dispatch
    response = handler(request, *args, **kwargs)
  File "/Library/Frameworks/Python.framework/Versions/3.10/lib/python3.10/site-packages/rest_framework/mixins.py", line 40, in list
    page = self.paginate_queryset(queryset)
  File "/Library/Frameworks/Python.framework/Versions/3.10/lib/python3.10/site-packages/rest_framework/generics.py", line 171, in paginate_queryset
    return self.paginator.paginate_queryset(queryset, self.request, view=self)
  File "/Library/Frameworks/Python.framework/Versions/3.10/lib/python3.10/site-packages/rest_framework/pagination.py", line 395, in paginate_queryset
    return list(queryset[self.offset:self.offset + self.limit])
  File "/Library/Frameworks/Python.framework/Versions/3.10/lib/python3.10/site-packages/django/db/models/query.py", line 376, in __len__
    self._fetch_all()
  File "/Library/Frameworks/Python.framework/Versions/3.10/lib/python3.10/site-packages/django/db/models/query.py", line 1866, in _fetch_all
    self._result_cache = list(self._iterable_class(self))
  File "/Library/Frameworks/Python.framework/Versions/3.10/lib/python3.10/site-packages/django/db/models/query.py", line 87, in __iter__
    results = compiler.execute_sql(
  File "/Library/Frameworks/Python.framework/Versions/3.10/lib/python3.10/site-packages/django/db/models/sql/compiler.py", line 1395, in execute_sql
    cursor.execute(sql, params)
  File "/Library/Frameworks/Python.framework/Versions/3.10/lib/python3.10/site-packages/django/db/backends/utils.py", line 103, in execute
    return super().execute(sql, params)
  File "/Library/Frameworks/Python.framework/Versions/3.10/lib/python3.10/site-packages/django/db/backends/utils.py", line 67, in execute
    return self._execute_with_wrappers(
  File "/Library/Frameworks/Python.framework/Versions/3.10/lib/python3.10/site-packages/django/db/backends/utils.py", line 80, in _execute_with_wrappers
    return executor(sql, params, many, context)
  File "/Library/Frameworks/Python.framework/Versions/3.10/lib/python3.10/site-packages/django/db/backends/utils.py", line 84, in _execute
    with self.db.wrap_database_errors:
  File "/Library/Frameworks/Python.framework/Versions/3.10/lib/python3.10/site-packages/django/db/utils.py", line 91, in __exit__
    raise dj_exc_value.with_traceback(traceback) from exc_value
  File "/Library/Frameworks/Python.framework/Versions/3.10/lib/python3.10/site-packages/django/db/backends/utils.py", line 89, in _execute
    return self.cursor.execute(sql, params)
django.db.utils.ProgrammingError: column advert_advert.promote_id does not exist
LINE 1: ...rt"."sub_category_id", "advert_advert"."city_id", "advert_ad...
                                                             ^

2022-09-14 12:00:13,014 [base | WARNING] view's ContactView raised exception during schema generation; use `getattr(self, 'swagger_fake_view', False)` to detect and short-circuit this
Traceback (most recent call last):
  File "/Library/Frameworks/Python.framework/Versions/3.10/lib/python3.10/site-packages/drf_yasg/inspectors/base.py", line 42, in call_view_method
    return view_method()
  File "/Library/Frameworks/Python.framework/Versions/3.10/lib/python3.10/site-packages/rest_framework/generics.py", line 108, in get_serializer
    serializer_class = self.get_serializer_class()
  File "/Library/Frameworks/Python.framework/Versions/3.10/lib/python3.10/site-packages/rest_framework/generics.py", line 122, in get_serializer_class
    assert self.serializer_class is not None, (
AssertionError: 'ContactView' should either include a `serializer_class` attribute, or override the `get_serializer_class()` method.
2022-09-14 12:00:13,016 [base | WARNING] view's ContactView raised exception during schema generation; use `getattr(self, 'swagger_fake_view', False)` to detect and short-circuit this
Traceback (most recent call last):
  File "/Library/Frameworks/Python.framework/Versions/3.10/lib/python3.10/site-packages/drf_yasg/inspectors/base.py", line 42, in call_view_method
    return view_method()
  File "/Library/Frameworks/Python.framework/Versions/3.10/lib/python3.10/site-packages/rest_framework/generics.py", line 108, in get_serializer
    serializer_class = self.get_serializer_class()
  File "/Library/Frameworks/Python.framework/Versions/3.10/lib/python3.10/site-packages/rest_framework/generics.py", line 122, in get_serializer_class
    assert self.serializer_class is not None, (
AssertionError: 'ContactView' should either include a `serializer_class` attribute, or override the `get_serializer_class()` method.
2022-09-14 12:00:13,060 [base | WARNING] view's VerifyEmail raised exception during schema generation; use `getattr(self, 'swagger_fake_view', False)` to detect and short-circuit this
Traceback (most recent call last):
  File "/Library/Frameworks/Python.framework/Versions/3.10/lib/python3.10/site-packages/drf_yasg/inspectors/base.py", line 42, in call_view_method
    return view_method()
  File "/Library/Frameworks/Python.framework/Versions/3.10/lib/python3.10/site-packages/rest_framework/generics.py", line 108, in get_serializer
    serializer_class = self.get_serializer_class()
  File "/Library/Frameworks/Python.framework/Versions/3.10/lib/python3.10/site-packages/rest_framework/generics.py", line 122, in get_serializer_class
    assert self.serializer_class is not None, (
AssertionError: 'VerifyEmail' should either include a `serializer_class` attribute, or override the `get_serializer_class()` method.
2022-09-14 12:00:16,387 [log | ERROR] Internal Server Error: /admin/advert/advert/
Traceback (most recent call last):
  File "/Library/Frameworks/Python.framework/Versions/3.10/lib/python3.10/site-packages/django/db/backends/utils.py", line 89, in _execute
    return self.cursor.execute(sql, params)
psycopg2.errors.UndefinedColumn: column advert_advert.promote_id does not exist
LINE 1: ...rt"."sub_category_id", "advert_advert"."city_id", "advert_ad...
                                                             ^


The above exception was the direct cause of the following exception:

Traceback (most recent call last):
  File "/Library/Frameworks/Python.framework/Versions/3.10/lib/python3.10/site-packages/django/core/handlers/exception.py", line 55, in inner
    response = get_response(request)
  File "/Library/Frameworks/Python.framework/Versions/3.10/lib/python3.10/site-packages/django/core/handlers/base.py", line 197, in _get_response
    response = wrapped_callback(request, *callback_args, **callback_kwargs)
  File "/Library/Frameworks/Python.framework/Versions/3.10/lib/python3.10/site-packages/django/contrib/admin/options.py", line 686, in wrapper
    return self.admin_site.admin_view(view)(*args, **kwargs)
  File "/Library/Frameworks/Python.framework/Versions/3.10/lib/python3.10/site-packages/django/utils/decorators.py", line 133, in _wrapped_view
    response = view_func(request, *args, **kwargs)
  File "/Library/Frameworks/Python.framework/Versions/3.10/lib/python3.10/site-packages/django/views/decorators/cache.py", line 62, in _wrapped_view_func
    response = view_func(request, *args, **kwargs)
  File "/Library/Frameworks/Python.framework/Versions/3.10/lib/python3.10/site-packages/django/contrib/admin/sites.py", line 242, in inner
    return view(request, *args, **kwargs)
  File "/Library/Frameworks/Python.framework/Versions/3.10/lib/python3.10/site-packages/django/utils/decorators.py", line 46, in _wrapper
    return bound_method(*args, **kwargs)
  File "/Library/Frameworks/Python.framework/Versions/3.10/lib/python3.10/site-packages/django/utils/decorators.py", line 133, in _wrapped_view
    response = view_func(request, *args, **kwargs)
  File "/Library/Frameworks/Python.framework/Versions/3.10/lib/python3.10/site-packages/django/contrib/admin/options.py", line 2068, in changelist_view
    "selection_note": _("0 of %(cnt)s selected") % {"cnt": len(cl.result_list)},
  File "/Library/Frameworks/Python.framework/Versions/3.10/lib/python3.10/site-packages/django/db/models/query.py", line 376, in __len__
    self._fetch_all()
  File "/Library/Frameworks/Python.framework/Versions/3.10/lib/python3.10/site-packages/django/db/models/query.py", line 1866, in _fetch_all
    self._result_cache = list(self._iterable_class(self))
  File "/Library/Frameworks/Python.framework/Versions/3.10/lib/python3.10/site-packages/django/db/models/query.py", line 87, in __iter__
    results = compiler.execute_sql(
  File "/Library/Frameworks/Python.framework/Versions/3.10/lib/python3.10/site-packages/django/db/models/sql/compiler.py", line 1395, in execute_sql
    cursor.execute(sql, params)
  File "/Library/Frameworks/Python.framework/Versions/3.10/lib/python3.10/site-packages/django/db/backends/utils.py", line 103, in execute
    return super().execute(sql, params)
  File "/Library/Frameworks/Python.framework/Versions/3.10/lib/python3.10/site-packages/django/db/backends/utils.py", line 67, in execute
    return self._execute_with_wrappers(
  File "/Library/Frameworks/Python.framework/Versions/3.10/lib/python3.10/site-packages/django/db/backends/utils.py", line 80, in _execute_with_wrappers
    return executor(sql, params, many, context)
  File "/Library/Frameworks/Python.framework/Versions/3.10/lib/python3.10/site-packages/django/db/backends/utils.py", line 84, in _execute
    with self.db.wrap_database_errors:
  File "/Library/Frameworks/Python.framework/Versions/3.10/lib/python3.10/site-packages/django/db/utils.py", line 91, in __exit__
    raise dj_exc_value.with_traceback(traceback) from exc_value
  File "/Library/Frameworks/Python.framework/Versions/3.10/lib/python3.10/site-packages/django/db/backends/utils.py", line 89, in _execute
    return self.cursor.execute(sql, params)
django.db.utils.ProgrammingError: column advert_advert.promote_id does not exist
LINE 1: ...rt"."sub_category_id", "advert_advert"."city_id", "advert_ad...
                                                             ^

2022-09-14 12:00:16,777 [log | ERROR] Internal Server Error: /admin/advert/advert/
Traceback (most recent call last):
  File "/Library/Frameworks/Python.framework/Versions/3.10/lib/python3.10/site-packages/django/db/backends/utils.py", line 89, in _execute
    return self.cursor.execute(sql, params)
psycopg2.errors.UndefinedColumn: column advert_advert.promote_id does not exist
LINE 1: ...rt"."sub_category_id", "advert_advert"."city_id", "advert_ad...
                                                             ^


The above exception was the direct cause of the following exception:

Traceback (most recent call last):
  File "/Library/Frameworks/Python.framework/Versions/3.10/lib/python3.10/site-packages/django/core/handlers/exception.py", line 55, in inner
    response = get_response(request)
  File "/Library/Frameworks/Python.framework/Versions/3.10/lib/python3.10/site-packages/django/core/handlers/base.py", line 197, in _get_response
    response = wrapped_callback(request, *callback_args, **callback_kwargs)
  File "/Library/Frameworks/Python.framework/Versions/3.10/lib/python3.10/site-packages/django/contrib/admin/options.py", line 686, in wrapper
    return self.admin_site.admin_view(view)(*args, **kwargs)
  File "/Library/Frameworks/Python.framework/Versions/3.10/lib/python3.10/site-packages/django/utils/decorators.py", line 133, in _wrapped_view
    response = view_func(request, *args, **kwargs)
  File "/Library/Frameworks/Python.framework/Versions/3.10/lib/python3.10/site-packages/django/views/decorators/cache.py", line 62, in _wrapped_view_func
    response = view_func(request, *args, **kwargs)
  File "/Library/Frameworks/Python.framework/Versions/3.10/lib/python3.10/site-packages/django/contrib/admin/sites.py", line 242, in inner
    return view(request, *args, **kwargs)
  File "/Library/Frameworks/Python.framework/Versions/3.10/lib/python3.10/site-packages/django/utils/decorators.py", line 46, in _wrapper
    return bound_method(*args, **kwargs)
  File "/Library/Frameworks/Python.framework/Versions/3.10/lib/python3.10/site-packages/django/utils/decorators.py", line 133, in _wrapped_view
    response = view_func(request, *args, **kwargs)
  File "/Library/Frameworks/Python.framework/Versions/3.10/lib/python3.10/site-packages/django/contrib/admin/options.py", line 2068, in changelist_view
    "selection_note": _("0 of %(cnt)s selected") % {"cnt": len(cl.result_list)},
  File "/Library/Frameworks/Python.framework/Versions/3.10/lib/python3.10/site-packages/django/db/models/query.py", line 376, in __len__
    self._fetch_all()
  File "/Library/Frameworks/Python.framework/Versions/3.10/lib/python3.10/site-packages/django/db/models/query.py", line 1866, in _fetch_all
    self._result_cache = list(self._iterable_class(self))
  File "/Library/Frameworks/Python.framework/Versions/3.10/lib/python3.10/site-packages/django/db/models/query.py", line 87, in __iter__
    results = compiler.execute_sql(
  File "/Library/Frameworks/Python.framework/Versions/3.10/lib/python3.10/site-packages/django/db/models/sql/compiler.py", line 1395, in execute_sql
    cursor.execute(sql, params)
  File "/Library/Frameworks/Python.framework/Versions/3.10/lib/python3.10/site-packages/django/db/backends/utils.py", line 103, in execute
    return super().execute(sql, params)
  File "/Library/Frameworks/Python.framework/Versions/3.10/lib/python3.10/site-packages/django/db/backends/utils.py", line 67, in execute
    return self._execute_with_wrappers(
  File "/Library/Frameworks/Python.framework/Versions/3.10/lib/python3.10/site-packages/django/db/backends/utils.py", line 80, in _execute_with_wrappers
    return executor(sql, params, many, context)
  File "/Library/Frameworks/Python.framework/Versions/3.10/lib/python3.10/site-packages/django/db/backends/utils.py", line 84, in _execute
    with self.db.wrap_database_errors:
  File "/Library/Frameworks/Python.framework/Versions/3.10/lib/python3.10/site-packages/django/db/utils.py", line 91, in __exit__
    raise dj_exc_value.with_traceback(traceback) from exc_value
  File "/Library/Frameworks/Python.framework/Versions/3.10/lib/python3.10/site-packages/django/db/backends/utils.py", line 89, in _execute
    return self.cursor.execute(sql, params)
django.db.utils.ProgrammingError: column advert_advert.promote_id does not exist
LINE 1: ...rt"."sub_category_id", "advert_advert"."city_id", "advert_ad...
                                                             ^

2022-09-14 12:04:01,609 [log | ERROR] Internal Server Error: /api/v1/advert/1
Traceback (most recent call last):
  File "/Library/Frameworks/Python.framework/Versions/3.10/lib/python3.10/site-packages/django/core/handlers/exception.py", line 55, in inner
    response = get_response(request)
  File "/Library/Frameworks/Python.framework/Versions/3.10/lib/python3.10/site-packages/django/utils/deprecation.py", line 135, in __call__
    response = self.process_request(request)
  File "/Library/Frameworks/Python.framework/Versions/3.10/lib/python3.10/site-packages/django/middleware/common.py", line 54, in process_request
    path = self.get_full_path_with_slash(request)
  File "/Library/Frameworks/Python.framework/Versions/3.10/lib/python3.10/site-packages/django/middleware/common.py", line 88, in get_full_path_with_slash
    raise RuntimeError(
RuntimeError: You called this URL via PUT, but the URL doesn't end in a slash and you have APPEND_SLASH set. Django can't redirect to the slash URL while maintaining PUT data. Change your form to point to 127.0.0.1:8000/api/v1/advert/1/?promote=2 (note the trailing slash), or set APPEND_SLASH=False in your Django settings.
2022-09-14 12:04:21,547 [log | ERROR] Internal Server Error: /api/v1/advert/1
Traceback (most recent call last):
  File "/Library/Frameworks/Python.framework/Versions/3.10/lib/python3.10/site-packages/django/core/handlers/exception.py", line 55, in inner
    response = get_response(request)
  File "/Library/Frameworks/Python.framework/Versions/3.10/lib/python3.10/site-packages/django/utils/deprecation.py", line 135, in __call__
    response = self.process_request(request)
  File "/Library/Frameworks/Python.framework/Versions/3.10/lib/python3.10/site-packages/django/middleware/common.py", line 54, in process_request
    path = self.get_full_path_with_slash(request)
  File "/Library/Frameworks/Python.framework/Versions/3.10/lib/python3.10/site-packages/django/middleware/common.py", line 88, in get_full_path_with_slash
    raise RuntimeError(
RuntimeError: You called this URL via PUT, but the URL doesn't end in a slash and you have APPEND_SLASH set. Django can't redirect to the slash URL while maintaining PUT data. Change your form to point to 127.0.0.1:8000/api/v1/advert/1/?promote=2/ (note the trailing slash), or set APPEND_SLASH=False in your Django settings.
2022-09-14 12:04:30,029 [log | ERROR] Internal Server Error: /api/v1/advert/1/
Traceback (most recent call last):
  File "/Library/Frameworks/Python.framework/Versions/3.10/lib/python3.10/site-packages/django/core/handlers/exception.py", line 55, in inner
    response = get_response(request)
  File "/Users/zharkynaskatkyzy/PycharmProjects/Zmall/server/config/middleware.py", line 65, in __call__
    set_advert_count(int(path.name), str(user), client_ip)
  File "/Users/zharkynaskatkyzy/PycharmProjects/Zmall/server/apps/advert/services.py", line 63, in set_advert_count
    view.set(id, json.dumps(advert_views))
  File "/Library/Frameworks/Python.framework/Versions/3.10/lib/python3.10/json/__init__.py", line 231, in dumps
    return _default_encoder.encode(obj)
  File "/Library/Frameworks/Python.framework/Versions/3.10/lib/python3.10/json/encoder.py", line 199, in encode
    chunks = self.iterencode(o, _one_shot=True)
  File "/Library/Frameworks/Python.framework/Versions/3.10/lib/python3.10/json/encoder.py", line 257, in iterencode
    return _iterencode(o, 0)
  File "/Library/Frameworks/Python.framework/Versions/3.10/lib/python3.10/json/encoder.py", line 179, in default
    raise TypeError(f'Object of type {o.__class__.__name__} '
TypeError: Object of type datetime is not JSON serializable
2022-09-14 12:04:38,345 [log | ERROR] Internal Server Error: /api/v1/advert/1/
Traceback (most recent call last):
  File "/Library/Frameworks/Python.framework/Versions/3.10/lib/python3.10/site-packages/django/core/handlers/exception.py", line 55, in inner
    response = get_response(request)
  File "/Users/zharkynaskatkyzy/PycharmProjects/Zmall/server/config/middleware.py", line 65, in __call__
    set_advert_count(int(path.name), str(user), client_ip)
  File "/Users/zharkynaskatkyzy/PycharmProjects/Zmall/server/apps/advert/services.py", line 63, in set_advert_count
    view.set(id, json.dumps(advert_views))
  File "/Library/Frameworks/Python.framework/Versions/3.10/lib/python3.10/json/__init__.py", line 231, in dumps
    return _default_encoder.encode(obj)
  File "/Library/Frameworks/Python.framework/Versions/3.10/lib/python3.10/json/encoder.py", line 199, in encode
    chunks = self.iterencode(o, _one_shot=True)
  File "/Library/Frameworks/Python.framework/Versions/3.10/lib/python3.10/json/encoder.py", line 257, in iterencode
    return _iterencode(o, 0)
  File "/Library/Frameworks/Python.framework/Versions/3.10/lib/python3.10/json/encoder.py", line 179, in default
    raise TypeError(f'Object of type {o.__class__.__name__} '
TypeError: Object of type datetime is not JSON serializable
2022-09-14 12:04:39,538 [log | ERROR] Internal Server Error: /api/v1/advert/1/
Traceback (most recent call last):
  File "/Library/Frameworks/Python.framework/Versions/3.10/lib/python3.10/site-packages/django/core/handlers/exception.py", line 55, in inner
    response = get_response(request)
  File "/Users/zharkynaskatkyzy/PycharmProjects/Zmall/server/config/middleware.py", line 65, in __call__
    set_advert_count(int(path.name), str(user), client_ip)
  File "/Users/zharkynaskatkyzy/PycharmProjects/Zmall/server/apps/advert/services.py", line 63, in set_advert_count
    view.set(id, json.dumps(advert_views))
  File "/Library/Frameworks/Python.framework/Versions/3.10/lib/python3.10/json/__init__.py", line 231, in dumps
    return _default_encoder.encode(obj)
  File "/Library/Frameworks/Python.framework/Versions/3.10/lib/python3.10/json/encoder.py", line 199, in encode
    chunks = self.iterencode(o, _one_shot=True)
  File "/Library/Frameworks/Python.framework/Versions/3.10/lib/python3.10/json/encoder.py", line 257, in iterencode
    return _iterencode(o, 0)
  File "/Library/Frameworks/Python.framework/Versions/3.10/lib/python3.10/json/encoder.py", line 179, in default
    raise TypeError(f'Object of type {o.__class__.__name__} '
TypeError: Object of type datetime is not JSON serializable
2022-09-14 12:04:55,647 [log | ERROR] Internal Server Error: /api/v1/advert/1/
Traceback (most recent call last):
  File "/Library/Frameworks/Python.framework/Versions/3.10/lib/python3.10/site-packages/django/core/handlers/exception.py", line 55, in inner
    response = get_response(request)
  File "/Users/zharkynaskatkyzy/PycharmProjects/Zmall/server/config/middleware.py", line 65, in __call__
    set_advert_count(int(path.name), str(user), client_ip)
  File "/Users/zharkynaskatkyzy/PycharmProjects/Zmall/server/apps/advert/services.py", line 63, in set_advert_count
    view.set(id, json.dumps(advert_views))
  File "/Library/Frameworks/Python.framework/Versions/3.10/lib/python3.10/json/__init__.py", line 231, in dumps
    return _default_encoder.encode(obj)
  File "/Library/Frameworks/Python.framework/Versions/3.10/lib/python3.10/json/encoder.py", line 199, in encode
    chunks = self.iterencode(o, _one_shot=True)
  File "/Library/Frameworks/Python.framework/Versions/3.10/lib/python3.10/json/encoder.py", line 257, in iterencode
    return _iterencode(o, 0)
  File "/Library/Frameworks/Python.framework/Versions/3.10/lib/python3.10/json/encoder.py", line 179, in default
    raise TypeError(f'Object of type {o.__class__.__name__} '
TypeError: Object of type datetime is not JSON serializable
2022-09-14 12:04:57,015 [log | ERROR] Internal Server Error: /api/v1/advert/1/
Traceback (most recent call last):
  File "/Library/Frameworks/Python.framework/Versions/3.10/lib/python3.10/site-packages/django/core/handlers/exception.py", line 55, in inner
    response = get_response(request)
  File "/Users/zharkynaskatkyzy/PycharmProjects/Zmall/server/config/middleware.py", line 65, in __call__
    set_advert_count(int(path.name), str(user), client_ip)
  File "/Users/zharkynaskatkyzy/PycharmProjects/Zmall/server/apps/advert/services.py", line 63, in set_advert_count
    view.set(id, json.dumps(advert_views))
  File "/Library/Frameworks/Python.framework/Versions/3.10/lib/python3.10/json/__init__.py", line 231, in dumps
    return _default_encoder.encode(obj)
  File "/Library/Frameworks/Python.framework/Versions/3.10/lib/python3.10/json/encoder.py", line 199, in encode
    chunks = self.iterencode(o, _one_shot=True)
  File "/Library/Frameworks/Python.framework/Versions/3.10/lib/python3.10/json/encoder.py", line 257, in iterencode
    return _iterencode(o, 0)
  File "/Library/Frameworks/Python.framework/Versions/3.10/lib/python3.10/json/encoder.py", line 179, in default
    raise TypeError(f'Object of type {o.__class__.__name__} '
TypeError: Object of type datetime is not JSON serializable
2022-09-14 12:04:58,304 [log | ERROR] Internal Server Error: /api/v1/advert/1/
Traceback (most recent call last):
  File "/Library/Frameworks/Python.framework/Versions/3.10/lib/python3.10/site-packages/django/core/handlers/exception.py", line 55, in inner
    response = get_response(request)
  File "/Users/zharkynaskatkyzy/PycharmProjects/Zmall/server/config/middleware.py", line 65, in __call__
    set_advert_count(int(path.name), str(user), client_ip)
  File "/Users/zharkynaskatkyzy/PycharmProjects/Zmall/server/apps/advert/services.py", line 63, in set_advert_count
    view.set(id, json.dumps(advert_views))
  File "/Library/Frameworks/Python.framework/Versions/3.10/lib/python3.10/json/__init__.py", line 231, in dumps
    return _default_encoder.encode(obj)
  File "/Library/Frameworks/Python.framework/Versions/3.10/lib/python3.10/json/encoder.py", line 199, in encode
    chunks = self.iterencode(o, _one_shot=True)
  File "/Library/Frameworks/Python.framework/Versions/3.10/lib/python3.10/json/encoder.py", line 257, in iterencode
    return _iterencode(o, 0)
  File "/Library/Frameworks/Python.framework/Versions/3.10/lib/python3.10/json/encoder.py", line 179, in default
    raise TypeError(f'Object of type {o.__class__.__name__} '
TypeError: Object of type datetime is not JSON serializable
2022-09-14 12:05:45,026 [log | WARNING] Unauthorized: /api/v1/advert/73/
2022-09-14 12:07:14,691 [autoreload | INFO] /Users/zharkynaskatkyzy/PycharmProjects/Zmall/server/config/settings/base.py changed, reloading.
2022-09-14 12:07:15,357 [autoreload | INFO] Watching for file changes with StatReloader
2022-09-14 15:24:10,639 [autoreload | INFO] Watching for file changes with StatReloader
2022-09-14 15:25:09,971 [autoreload | INFO] /Users/zharkynaskatkyzy/PycharmProjects/Zmall/server/config/settings/base.py changed, reloading.
2022-09-14 15:25:10,748 [autoreload | INFO] Watching for file changes with StatReloader
2022-09-14 15:32:40,603 [autoreload | INFO] /Users/zharkynaskatkyzy/PycharmProjects/Zmall/server/apps/advert/admin.py changed, reloading.
2022-09-14 15:32:41,547 [autoreload | INFO] Watching for file changes with StatReloader
2022-09-14 15:32:48,203 [log | WARNING] Not Found: /
2022-09-14 15:32:50,906 [log | WARNING] Not Found: /
2022-09-14 15:32:51,511 [log | ERROR] Internal Server Error: /admin/advert/advert/
Traceback (most recent call last):
  File "/Library/Frameworks/Python.framework/Versions/3.10/lib/python3.10/site-packages/django/core/handlers/exception.py", line 55, in inner
    response = get_response(request)
  File "/Library/Frameworks/Python.framework/Versions/3.10/lib/python3.10/site-packages/django/core/handlers/base.py", line 197, in _get_response
    response = wrapped_callback(request, *callback_args, **callback_kwargs)
  File "/Library/Frameworks/Python.framework/Versions/3.10/lib/python3.10/site-packages/django/contrib/admin/options.py", line 686, in wrapper
    return self.admin_site.admin_view(view)(*args, **kwargs)
  File "/Library/Frameworks/Python.framework/Versions/3.10/lib/python3.10/site-packages/django/utils/decorators.py", line 133, in _wrapped_view
    response = view_func(request, *args, **kwargs)
  File "/Library/Frameworks/Python.framework/Versions/3.10/lib/python3.10/site-packages/django/views/decorators/cache.py", line 62, in _wrapped_view_func
    response = view_func(request, *args, **kwargs)
  File "/Library/Frameworks/Python.framework/Versions/3.10/lib/python3.10/site-packages/django/contrib/admin/sites.py", line 242, in inner
    return view(request, *args, **kwargs)
  File "/Library/Frameworks/Python.framework/Versions/3.10/lib/python3.10/site-packages/django/utils/decorators.py", line 46, in _wrapper
    return bound_method(*args, **kwargs)
  File "/Library/Frameworks/Python.framework/Versions/3.10/lib/python3.10/site-packages/django/utils/decorators.py", line 133, in _wrapped_view
    response = view_func(request, *args, **kwargs)
  File "/Library/Frameworks/Python.framework/Versions/3.10/lib/python3.10/site-packages/django/contrib/admin/options.py", line 2066, in changelist_view
    **self.admin_site.each_context(request),
  File "/Library/Frameworks/Python.framework/Versions/3.10/lib/python3.10/site-packages/django/contrib/admin/sites.py", line 337, in each_context
    "available_apps": self.get_app_list(request),
  File "/Library/Frameworks/Python.framework/Versions/3.10/lib/python3.10/site-packages/django/contrib/admin/sites.py", line 536, in get_app_list
    app_dict = self._build_app_dict(request, app_label)
  File "/Library/Frameworks/Python.framework/Versions/3.10/lib/python3.10/site-packages/django/contrib/admin/sites.py", line 482, in _build_app_dict
    perms = model_admin.get_model_perms(request)
  File "/Library/Frameworks/Python.framework/Versions/3.10/lib/python3.10/site-packages/django/contrib/admin/options.py", line 749, in get_model_perms
    "add": self.has_add_permission(request),
  File "/Users/zharkynaskatkyzy/PycharmProjects/Zmall/server/apps/advert/admin.py", line 85, in has_add_permission
    if has_add and Promote.objects.count < 3:
TypeError: '<' not supported between instances of 'method' and 'int'
2022-09-14 15:32:53,730 [log | ERROR] Internal Server Error: /admin/advert/advert/
Traceback (most recent call last):
  File "/Library/Frameworks/Python.framework/Versions/3.10/lib/python3.10/site-packages/django/core/handlers/exception.py", line 55, in inner
    response = get_response(request)
  File "/Library/Frameworks/Python.framework/Versions/3.10/lib/python3.10/site-packages/django/core/handlers/base.py", line 197, in _get_response
    response = wrapped_callback(request, *callback_args, **callback_kwargs)
  File "/Library/Frameworks/Python.framework/Versions/3.10/lib/python3.10/site-packages/django/contrib/admin/options.py", line 686, in wrapper
    return self.admin_site.admin_view(view)(*args, **kwargs)
  File "/Library/Frameworks/Python.framework/Versions/3.10/lib/python3.10/site-packages/django/utils/decorators.py", line 133, in _wrapped_view
    response = view_func(request, *args, **kwargs)
  File "/Library/Frameworks/Python.framework/Versions/3.10/lib/python3.10/site-packages/django/views/decorators/cache.py", line 62, in _wrapped_view_func
    response = view_func(request, *args, **kwargs)
  File "/Library/Frameworks/Python.framework/Versions/3.10/lib/python3.10/site-packages/django/contrib/admin/sites.py", line 242, in inner
    return view(request, *args, **kwargs)
  File "/Library/Frameworks/Python.framework/Versions/3.10/lib/python3.10/site-packages/django/utils/decorators.py", line 46, in _wrapper
    return bound_method(*args, **kwargs)
  File "/Library/Frameworks/Python.framework/Versions/3.10/lib/python3.10/site-packages/django/utils/decorators.py", line 133, in _wrapped_view
    response = view_func(request, *args, **kwargs)
  File "/Library/Frameworks/Python.framework/Versions/3.10/lib/python3.10/site-packages/django/contrib/admin/options.py", line 2066, in changelist_view
    **self.admin_site.each_context(request),
  File "/Library/Frameworks/Python.framework/Versions/3.10/lib/python3.10/site-packages/django/contrib/admin/sites.py", line 337, in each_context
    "available_apps": self.get_app_list(request),
  File "/Library/Frameworks/Python.framework/Versions/3.10/lib/python3.10/site-packages/django/contrib/admin/sites.py", line 536, in get_app_list
    app_dict = self._build_app_dict(request, app_label)
  File "/Library/Frameworks/Python.framework/Versions/3.10/lib/python3.10/site-packages/django/contrib/admin/sites.py", line 482, in _build_app_dict
    perms = model_admin.get_model_perms(request)
  File "/Library/Frameworks/Python.framework/Versions/3.10/lib/python3.10/site-packages/django/contrib/admin/options.py", line 749, in get_model_perms
    "add": self.has_add_permission(request),
  File "/Users/zharkynaskatkyzy/PycharmProjects/Zmall/server/apps/advert/admin.py", line 85, in has_add_permission
    if has_add and Promote.objects.count < 3:
TypeError: '<' not supported between instances of 'method' and 'int'
2022-09-14 15:32:54,070 [log | ERROR] Internal Server Error: /admin/
Traceback (most recent call last):
  File "/Library/Frameworks/Python.framework/Versions/3.10/lib/python3.10/site-packages/django/core/handlers/exception.py", line 55, in inner
    response = get_response(request)
  File "/Library/Frameworks/Python.framework/Versions/3.10/lib/python3.10/site-packages/django/core/handlers/base.py", line 197, in _get_response
    response = wrapped_callback(request, *callback_args, **callback_kwargs)
  File "/Library/Frameworks/Python.framework/Versions/3.10/lib/python3.10/site-packages/django/contrib/admin/sites.py", line 261, in wrapper
    return self.admin_view(view, cacheable)(*args, **kwargs)
  File "/Library/Frameworks/Python.framework/Versions/3.10/lib/python3.10/site-packages/django/utils/decorators.py", line 133, in _wrapped_view
    response = view_func(request, *args, **kwargs)
  File "/Library/Frameworks/Python.framework/Versions/3.10/lib/python3.10/site-packages/django/views/decorators/cache.py", line 62, in _wrapped_view_func
    response = view_func(request, *args, **kwargs)
  File "/Library/Frameworks/Python.framework/Versions/3.10/lib/python3.10/site-packages/django/contrib/admin/sites.py", line 242, in inner
    return view(request, *args, **kwargs)
  File "/Library/Frameworks/Python.framework/Versions/3.10/lib/python3.10/site-packages/django/contrib/admin/sites.py", line 552, in index
    app_list = self.get_app_list(request)
  File "/Library/Frameworks/Python.framework/Versions/3.10/lib/python3.10/site-packages/django/contrib/admin/sites.py", line 536, in get_app_list
    app_dict = self._build_app_dict(request, app_label)
  File "/Library/Frameworks/Python.framework/Versions/3.10/lib/python3.10/site-packages/django/contrib/admin/sites.py", line 482, in _build_app_dict
    perms = model_admin.get_model_perms(request)
  File "/Library/Frameworks/Python.framework/Versions/3.10/lib/python3.10/site-packages/django/contrib/admin/options.py", line 749, in get_model_perms
    "add": self.has_add_permission(request),
  File "/Users/zharkynaskatkyzy/PycharmProjects/Zmall/server/apps/advert/admin.py", line 85, in has_add_permission
    if has_add and Promote.objects.count < 3:
TypeError: '<' not supported between instances of 'method' and 'int'
2022-09-14 15:33:11,147 [autoreload | INFO] /Users/zharkynaskatkyzy/PycharmProjects/Zmall/server/apps/advert/admin.py changed, reloading.
2022-09-14 15:33:11,650 [autoreload | INFO] Watching for file changes with StatReloader
2022-09-14 15:33:57,006 [autoreload | INFO] /Users/zharkynaskatkyzy/PycharmProjects/Zmall/server/apps/advert/admin.py changed, reloading.
2022-09-14 15:33:59,471 [autoreload | INFO] Watching for file changes with StatReloader
2022-09-14 15:34:05,062 [autoreload | INFO] /Users/zharkynaskatkyzy/PycharmProjects/Zmall/server/apps/advert/admin.py changed, reloading.
2022-09-14 15:34:05,515 [autoreload | INFO] Watching for file changes with StatReloader
2022-09-14 15:34:32,972 [autoreload | INFO] /Users/zharkynaskatkyzy/PycharmProjects/Zmall/server/apps/advert/admin.py changed, reloading.
2022-09-14 15:34:33,587 [autoreload | INFO] Watching for file changes with StatReloader
2022-09-14 15:35:53,388 [autoreload | INFO] /Users/zharkynaskatkyzy/PycharmProjects/Zmall/server/apps/advert/models.py changed, reloading.
2022-09-14 15:35:55,416 [autoreload | INFO] Watching for file changes with StatReloader
2022-09-14 15:36:41,742 [autoreload | INFO] /Users/zharkynaskatkyzy/PycharmProjects/Zmall/server/apps/advert/models.py changed, reloading.
2022-09-14 15:36:42,335 [autoreload | INFO] Watching for file changes with StatReloader
2022-09-14 15:43:41,570 [autoreload | INFO] /Users/zharkynaskatkyzy/PycharmProjects/Zmall/server/apps/advert/models.py changed, reloading.
2022-09-14 15:43:42,302 [autoreload | INFO] Watching for file changes with StatReloader
2022-09-14 15:44:15,916 [log | WARNING] Not Found: /media/icon.png
2022-09-14 15:44:15,947 [log | WARNING] Not Found: /media/icon.png
2022-09-14 15:44:23,167 [log | WARNING] Not Found: /media/icon.png
2022-09-14 15:44:31,214 [log | WARNING] Not Found: /
2022-09-14 15:47:11,641 [autoreload | INFO] /Users/zharkynaskatkyzy/PycharmProjects/Zmall/server/apps/advert/models.py changed, reloading.
2022-09-14 15:47:12,966 [autoreload | INFO] Watching for file changes with StatReloader
2022-09-14 15:47:35,863 [autoreload | INFO] /Users/zharkynaskatkyzy/PycharmProjects/Zmall/server/apps/advert/models.py changed, reloading.
2022-09-14 15:47:36,380 [autoreload | INFO] Watching for file changes with StatReloader
2022-09-14 15:48:25,849 [autoreload | INFO] /Users/zharkynaskatkyzy/PycharmProjects/Zmall/server/apps/advert/models.py changed, reloading.
2022-09-14 15:48:26,400 [autoreload | INFO] Watching for file changes with StatReloader
2022-09-14 15:49:18,746 [autoreload | INFO] /Users/zharkynaskatkyzy/PycharmProjects/Zmall/server/apps/advert/admin.py changed, reloading.
2022-09-14 15:49:19,377 [autoreload | INFO] Watching for file changes with StatReloader
2022-09-14 15:50:34,305 [autoreload | INFO] /Users/zharkynaskatkyzy/PycharmProjects/Zmall/server/apps/advert/admin.py changed, reloading.
2022-09-14 15:50:35,338 [autoreload | INFO] Watching for file changes with StatReloader
2022-09-14 15:51:20,191 [autoreload | INFO] Watching for file changes with StatReloader
2022-09-14 15:51:53,965 [autoreload | INFO] /Users/zharkynaskatkyzy/PycharmProjects/Zmall/server/apps/advert/admin.py changed, reloading.
2022-09-14 15:51:54,527 [autoreload | INFO] Watching for file changes with StatReloader
2022-09-14 15:53:00,274 [autoreload | INFO] /Users/zharkynaskatkyzy/PycharmProjects/Zmall/server/apps/advert/admin.py changed, reloading.
2022-09-14 15:53:00,826 [autoreload | INFO] Watching for file changes with StatReloader
2022-09-14 15:53:21,635 [log | WARNING] Not Found: /media/icon.png
2022-09-14 15:54:16,874 [autoreload | INFO] /Users/zharkynaskatkyzy/PycharmProjects/Zmall/server/apps/advert/admin.py changed, reloading.
2022-09-14 15:54:17,481 [autoreload | INFO] Watching for file changes with StatReloader
2022-09-14 15:54:19,382 [log | WARNING] Not Found: /media/icon.png
2022-09-14 15:54:21,945 [log | WARNING] Not Found: /media/icon.png
2022-09-14 15:54:21,977 [log | WARNING] Not Found: /media/icon.png
2022-09-14 15:54:39,684 [autoreload | INFO] /Users/zharkynaskatkyzy/PycharmProjects/Zmall/server/apps/advert/admin.py changed, reloading.
2022-09-14 15:54:40,441 [autoreload | INFO] Watching for file changes with StatReloader
2022-09-14 15:56:54,340 [log | WARNING] Not Found: /
2022-09-14 15:56:59,006 [log | WARNING] Not Found: /
2022-09-14 15:57:10,444 [log | WARNING] Not Found: /media/icon.png
2022-09-14 15:57:10,460 [log | WARNING] Not Found: /media/icon.png
2022-09-14 15:58:50,773 [autoreload | INFO] /Users/zharkynaskatkyzy/PycharmProjects/Zmall/server/apps/user/admin.py changed, reloading.
2022-09-14 15:58:51,525 [autoreload | INFO] Watching for file changes with StatReloader
2022-09-14 16:00:50,824 [autoreload | INFO] /Users/zharkynaskatkyzy/PycharmProjects/Zmall/server/apps/chat/admin.py changed, reloading.
2022-09-14 16:00:51,491 [autoreload | INFO] Watching for file changes with StatReloader
2022-09-14 16:01:04,235 [autoreload | INFO] Watching for file changes with StatReloader
2022-09-14 16:01:05,638 [log | WARNING] Not Found: /admin/chat/chat/
2022-09-14 16:01:09,386 [log | WARNING] Not Found: /admin/chat/chat/
2022-09-14 16:02:19,345 [autoreload | INFO] /Users/zharkynaskatkyzy/PycharmProjects/Zmall/server/apps/chat/models.py changed, reloading.
2022-09-14 16:02:19,904 [autoreload | INFO] Watching for file changes with StatReloader
2022-09-14 16:02:47,159 [autoreload | INFO] /Users/zharkynaskatkyzy/PycharmProjects/Zmall/server/apps/chat/models.py changed, reloading.
2022-09-14 16:02:47,686 [autoreload | INFO] Watching for file changes with StatReloader
2022-09-14 16:03:21,568 [autoreload | INFO] /Users/zharkynaskatkyzy/PycharmProjects/Zmall/server/apps/advert/admin.py changed, reloading.
2022-09-14 16:03:22,123 [autoreload | INFO] Watching for file changes with StatReloader
2022-09-14 16:04:21,679 [autoreload | INFO] /Users/zharkynaskatkyzy/PycharmProjects/Zmall/server/apps/advert/models.py changed, reloading.
2022-09-14 16:04:22,372 [autoreload | INFO] Watching for file changes with StatReloader
2022-09-14 16:05:09,343 [log | WARNING] Not Found: /
2022-09-14 16:05:10,256 [base | WARNING] view's ContactView raised exception during schema generation; use `getattr(self, 'swagger_fake_view', False)` to detect and short-circuit this
Traceback (most recent call last):
  File "/Library/Frameworks/Python.framework/Versions/3.10/lib/python3.10/site-packages/drf_yasg/inspectors/base.py", line 42, in call_view_method
    return view_method()
  File "/Library/Frameworks/Python.framework/Versions/3.10/lib/python3.10/site-packages/rest_framework/generics.py", line 108, in get_serializer
    serializer_class = self.get_serializer_class()
  File "/Library/Frameworks/Python.framework/Versions/3.10/lib/python3.10/site-packages/rest_framework/generics.py", line 122, in get_serializer_class
    assert self.serializer_class is not None, (
AssertionError: 'ContactView' should either include a `serializer_class` attribute, or override the `get_serializer_class()` method.
2022-09-14 16:05:10,257 [base | WARNING] view's ContactView raised exception during schema generation; use `getattr(self, 'swagger_fake_view', False)` to detect and short-circuit this
Traceback (most recent call last):
  File "/Library/Frameworks/Python.framework/Versions/3.10/lib/python3.10/site-packages/drf_yasg/inspectors/base.py", line 42, in call_view_method
    return view_method()
  File "/Library/Frameworks/Python.framework/Versions/3.10/lib/python3.10/site-packages/rest_framework/generics.py", line 108, in get_serializer
    serializer_class = self.get_serializer_class()
  File "/Library/Frameworks/Python.framework/Versions/3.10/lib/python3.10/site-packages/rest_framework/generics.py", line 122, in get_serializer_class
    assert self.serializer_class is not None, (
AssertionError: 'ContactView' should either include a `serializer_class` attribute, or override the `get_serializer_class()` method.
2022-09-14 16:05:10,271 [base | WARNING] view's VerifyEmail raised exception during schema generation; use `getattr(self, 'swagger_fake_view', False)` to detect and short-circuit this
Traceback (most recent call last):
  File "/Library/Frameworks/Python.framework/Versions/3.10/lib/python3.10/site-packages/drf_yasg/inspectors/base.py", line 42, in call_view_method
    return view_method()
  File "/Library/Frameworks/Python.framework/Versions/3.10/lib/python3.10/site-packages/rest_framework/generics.py", line 108, in get_serializer
    serializer_class = self.get_serializer_class()
  File "/Library/Frameworks/Python.framework/Versions/3.10/lib/python3.10/site-packages/rest_framework/generics.py", line 122, in get_serializer_class
    assert self.serializer_class is not None, (
AssertionError: 'VerifyEmail' should either include a `serializer_class` attribute, or override the `get_serializer_class()` method.
2022-09-14 16:05:40,362 [log | WARNING] Bad Request: /api/v1/advert_report/
2022-09-14 16:18:40,618 [autoreload | INFO] /Users/zharkynaskatkyzy/PycharmProjects/Zmall/server/apps/advert/admin.py changed, reloading.
2022-09-14 16:18:41,353 [autoreload | INFO] Watching for file changes with StatReloader
2022-09-14 16:19:24,277 [autoreload | INFO] /Users/zharkynaskatkyzy/PycharmProjects/Zmall/server/apps/advert/models.py changed, reloading.
2022-09-14 16:19:25,146 [autoreload | INFO] Watching for file changes with StatReloader
2022-09-14 16:20:39,237 [autoreload | INFO] /Users/zharkynaskatkyzy/PycharmProjects/Zmall/server/apps/advert/models.py changed, reloading.
2022-09-14 16:20:40,226 [autoreload | INFO] Watching for file changes with StatReloader
2022-09-14 16:21:08,871 [log | WARNING] Not Found: /
2022-09-14 16:21:51,787 [log | WARNING] Not Found: /
2022-09-14 16:22:26,594 [log | WARNING] Not Found: /
2022-09-14 16:22:30,518 [log | WARNING] Not Found: /
2022-09-14 16:22:51,591 [autoreload | INFO] Watching for file changes with StatReloader
2022-09-14 16:22:55,480 [log | WARNING] Not Found: /
2022-09-14 16:25:52,713 [autoreload | INFO] /Users/zharkynaskatkyzy/PycharmProjects/Zmall/server/apps/advert/admin.py changed, reloading.
2022-09-14 16:25:53,590 [autoreload | INFO] Watching for file changes with StatReloader
2022-09-14 16:26:18,694 [autoreload | INFO] /Users/zharkynaskatkyzy/PycharmProjects/Zmall/server/apps/advert/admin.py changed, reloading.
2022-09-14 16:26:19,208 [autoreload | INFO] Watching for file changes with StatReloader
2022-09-14 16:26:40,034 [autoreload | INFO] /Users/zharkynaskatkyzy/PycharmProjects/Zmall/server/apps/advert/admin.py changed, reloading.
2022-09-14 16:26:40,591 [autoreload | INFO] Watching for file changes with StatReloader
2022-09-14 16:28:20,961 [autoreload | INFO] /Users/zharkynaskatkyzy/PycharmProjects/Zmall/server/apps/advert/models.py changed, reloading.
2022-09-14 16:28:21,552 [autoreload | INFO] Watching for file changes with StatReloader
2022-09-14 16:28:38,702 [log | WARNING] Not Found: /admin/advert/feedback/
2022-09-14 16:29:08,189 [log | WARNING] Not Found: /admin/advert/feedback/
2022-09-14 16:29:09,224 [log | WARNING] Not Found: /admin/advert/feedback/
2022-09-14 16:29:17,170 [log | WARNING] Not Found: /admin/advert/feedback/
2022-09-14 16:29:18,118 [log | WARNING] Not Found: /admin/advert/favoriteadvert/
2022-09-14 16:30:04,922 [autoreload | INFO] /Users/zharkynaskatkyzy/PycharmProjects/Zmall/server/apps/advert/models.py changed, reloading.
2022-09-14 16:30:05,518 [autoreload | INFO] Watching for file changes with StatReloader
2022-09-14 16:30:33,811 [autoreload | INFO] /Users/zharkynaskatkyzy/PycharmProjects/Zmall/server/apps/advert/admin.py changed, reloading.
2022-09-14 16:30:34,323 [autoreload | INFO] Watching for file changes with StatReloader
2022-09-14 16:31:03,821 [autoreload | INFO] /Users/zharkynaskatkyzy/PycharmProjects/Zmall/server/apps/advert/models.py changed, reloading.
2022-09-14 16:31:05,027 [autoreload | INFO] Watching for file changes with StatReloader
2022-09-14 16:32:48,921 [autoreload | INFO] /Users/zharkynaskatkyzy/PycharmProjects/Zmall/server/apps/advert/models.py changed, reloading.
2022-09-14 16:32:49,951 [autoreload | INFO] Watching for file changes with StatReloader
2022-09-14 16:33:14,567 [autoreload | INFO] Watching for file changes with StatReloader
2022-09-14 16:33:21,940 [autoreload | INFO] Watching for file changes with StatReloader
2022-09-14 16:33:29,890 [log | ERROR] Internal Server Error: /admin/advert/feedbackmessage/
Traceback (most recent call last):
  File "/Library/Frameworks/Python.framework/Versions/3.10/lib/python3.10/site-packages/django/db/models/options.py", line 668, in get_field
    return self.fields_map[field_name]
KeyError: '__str__'

During handling of the above exception, another exception occurred:

Traceback (most recent call last):
  File "/Library/Frameworks/Python.framework/Versions/3.10/lib/python3.10/site-packages/django/contrib/admin/utils.py", line 271, in lookup_field
    f = _get_non_gfk_field(opts, name)
  File "/Library/Frameworks/Python.framework/Versions/3.10/lib/python3.10/site-packages/django/contrib/admin/utils.py", line 302, in _get_non_gfk_field
    field = opts.get_field(name)
  File "/Library/Frameworks/Python.framework/Versions/3.10/lib/python3.10/site-packages/django/db/models/options.py", line 670, in get_field
    raise FieldDoesNotExist(
django.core.exceptions.FieldDoesNotExist: FeedbackMessage has no field named '__str__'

During handling of the above exception, another exception occurred:

Traceback (most recent call last):
  File "/Library/Frameworks/Python.framework/Versions/3.10/lib/python3.10/site-packages/django/core/handlers/exception.py", line 55, in inner
    response = get_response(request)
  File "/Library/Frameworks/Python.framework/Versions/3.10/lib/python3.10/site-packages/django/core/handlers/base.py", line 220, in _get_response
    response = response.render()
  File "/Library/Frameworks/Python.framework/Versions/3.10/lib/python3.10/site-packages/django/template/response.py", line 114, in render
    self.content = self.rendered_content
  File "/Library/Frameworks/Python.framework/Versions/3.10/lib/python3.10/site-packages/django/template/response.py", line 92, in rendered_content
    return template.render(context, self._request)
  File "/Library/Frameworks/Python.framework/Versions/3.10/lib/python3.10/site-packages/django/template/backends/django.py", line 62, in render
    return self.template.render(context)
  File "/Library/Frameworks/Python.framework/Versions/3.10/lib/python3.10/site-packages/django/template/base.py", line 175, in render
    return self._render(context)
  File "/Library/Frameworks/Python.framework/Versions/3.10/lib/python3.10/site-packages/django/template/base.py", line 167, in _render
    return self.nodelist.render(context)
  File "/Library/Frameworks/Python.framework/Versions/3.10/lib/python3.10/site-packages/django/template/base.py", line 1005, in render
    return SafeString("".join([node.render_annotated(context) for node in self]))
  File "/Library/Frameworks/Python.framework/Versions/3.10/lib/python3.10/site-packages/django/template/base.py", line 1005, in <listcomp>
    return SafeString("".join([node.render_annotated(context) for node in self]))
  File "/Library/Frameworks/Python.framework/Versions/3.10/lib/python3.10/site-packages/django/template/base.py", line 966, in render_annotated
    return self.render(context)
  File "/Library/Frameworks/Python.framework/Versions/3.10/lib/python3.10/site-packages/django/template/loader_tags.py", line 157, in render
    return compiled_parent._render(context)
  File "/Library/Frameworks/Python.framework/Versions/3.10/lib/python3.10/site-packages/django/template/base.py", line 167, in _render
    return self.nodelist.render(context)
  File "/Library/Frameworks/Python.framework/Versions/3.10/lib/python3.10/site-packages/django/template/base.py", line 1005, in render
    return SafeString("".join([node.render_annotated(context) for node in self]))
  File "/Library/Frameworks/Python.framework/Versions/3.10/lib/python3.10/site-packages/django/template/base.py", line 1005, in <listcomp>
    return SafeString("".join([node.render_annotated(context) for node in self]))
  File "/Library/Frameworks/Python.framework/Versions/3.10/lib/python3.10/site-packages/django/template/base.py", line 966, in render_annotated
    return self.render(context)
  File "/Library/Frameworks/Python.framework/Versions/3.10/lib/python3.10/site-packages/django/template/loader_tags.py", line 157, in render
    return compiled_parent._render(context)
  File "/Library/Frameworks/Python.framework/Versions/3.10/lib/python3.10/site-packages/django/template/base.py", line 167, in _render
    return self.nodelist.render(context)
  File "/Library/Frameworks/Python.framework/Versions/3.10/lib/python3.10/site-packages/django/template/base.py", line 1005, in render
    return SafeString("".join([node.render_annotated(context) for node in self]))
  File "/Library/Frameworks/Python.framework/Versions/3.10/lib/python3.10/site-packages/django/template/base.py", line 1005, in <listcomp>
    return SafeString("".join([node.render_annotated(context) for node in self]))
  File "/Library/Frameworks/Python.framework/Versions/3.10/lib/python3.10/site-packages/django/template/base.py", line 966, in render_annotated
    return self.render(context)
  File "/Library/Frameworks/Python.framework/Versions/3.10/lib/python3.10/site-packages/django/template/loader_tags.py", line 63, in render
    result = block.nodelist.render(context)
  File "/Library/Frameworks/Python.framework/Versions/3.10/lib/python3.10/site-packages/django/template/base.py", line 1005, in render
    return SafeString("".join([node.render_annotated(context) for node in self]))
  File "/Library/Frameworks/Python.framework/Versions/3.10/lib/python3.10/site-packages/django/template/base.py", line 1005, in <listcomp>
    return SafeString("".join([node.render_annotated(context) for node in self]))
  File "/Library/Frameworks/Python.framework/Versions/3.10/lib/python3.10/site-packages/django/template/base.py", line 966, in render_annotated
    return self.render(context)
  File "/Library/Frameworks/Python.framework/Versions/3.10/lib/python3.10/site-packages/django/template/loader_tags.py", line 63, in render
    result = block.nodelist.render(context)
  File "/Library/Frameworks/Python.framework/Versions/3.10/lib/python3.10/site-packages/django/template/base.py", line 1005, in render
    return SafeString("".join([node.render_annotated(context) for node in self]))
  File "/Library/Frameworks/Python.framework/Versions/3.10/lib/python3.10/site-packages/django/template/base.py", line 1005, in <listcomp>
    return SafeString("".join([node.render_annotated(context) for node in self]))
  File "/Library/Frameworks/Python.framework/Versions/3.10/lib/python3.10/site-packages/django/template/base.py", line 966, in render_annotated
    return self.render(context)
  File "/Library/Frameworks/Python.framework/Versions/3.10/lib/python3.10/site-packages/django/template/loader_tags.py", line 63, in render
    result = block.nodelist.render(context)
  File "/Library/Frameworks/Python.framework/Versions/3.10/lib/python3.10/site-packages/django/template/base.py", line 1005, in render
    return SafeString("".join([node.render_annotated(context) for node in self]))
  File "/Library/Frameworks/Python.framework/Versions/3.10/lib/python3.10/site-packages/django/template/base.py", line 1005, in <listcomp>
    return SafeString("".join([node.render_annotated(context) for node in self]))
  File "/Library/Frameworks/Python.framework/Versions/3.10/lib/python3.10/site-packages/django/template/base.py", line 966, in render_annotated
    return self.render(context)
  File "/Library/Frameworks/Python.framework/Versions/3.10/lib/python3.10/site-packages/django/contrib/admin/templatetags/base.py", line 45, in render
    return super().render(context)
  File "/Library/Frameworks/Python.framework/Versions/3.10/lib/python3.10/site-packages/django/template/library.py", line 258, in render
    _dict = self.func(*resolved_args, **resolved_kwargs)
  File "/Library/Frameworks/Python.framework/Versions/3.10/lib/python3.10/site-packages/django/contrib/admin/templatetags/admin_list.py", line 336, in result_list
    "results": list(results(cl)),
  File "/Library/Frameworks/Python.framework/Versions/3.10/lib/python3.10/site-packages/django/contrib/admin/templatetags/admin_list.py", line 312, in results
    yield ResultList(None, items_for_result(cl, res, None))
  File "/Library/Frameworks/Python.framework/Versions/3.10/lib/python3.10/site-packages/django/contrib/admin/templatetags/admin_list.py", line 303, in __init__
    super().__init__(*items)
  File "/Library/Frameworks/Python.framework/Versions/3.10/lib/python3.10/site-packages/django/contrib/admin/templatetags/admin_list.py", line 213, in items_for_result
    f, attr, value = lookup_field(field_name, result, cl.model_admin)
  File "/Library/Frameworks/Python.framework/Versions/3.10/lib/python3.10/site-packages/django/contrib/admin/utils.py", line 284, in lookup_field
    value = attr()
  File "/Users/zharkynaskatkyzy/PycharmProjects/Zmall/server/apps/advert/models.py", line 226, in __str__
    return self.name
AttributeError: 'FeedbackMessage' object has no attribute 'name'
2022-09-14 16:33:57,821 [autoreload | INFO] /Users/zharkynaskatkyzy/PycharmProjects/Zmall/server/apps/advert/models.py changed, reloading.
2022-09-14 16:33:58,413 [autoreload | INFO] Watching for file changes with StatReloader
2022-09-14 16:34:50,779 [autoreload | INFO] /Users/zharkynaskatkyzy/PycharmProjects/Zmall/server/apps/advert/models.py changed, reloading.
2022-09-14 16:34:51,494 [autoreload | INFO] Watching for file changes with StatReloader
2022-09-14 16:35:48,013 [autoreload | INFO] /Users/zharkynaskatkyzy/PycharmProjects/Zmall/server/config/settings/base.py changed, reloading.
2022-09-14 16:35:49,281 [autoreload | INFO] Watching for file changes with StatReloader
2022-09-14 16:36:32,097 [autoreload | INFO] /Users/zharkynaskatkyzy/PycharmProjects/Zmall/server/config/settings/base.py changed, reloading.
2022-09-14 16:36:32,857 [autoreload | INFO] Watching for file changes with StatReloader
