2022-09-14 18:24:16,610 [autoreload | INFO] Watching for file changes with StatReloader
2022-09-14 18:27:05,338 [autoreload | INFO] /Users/zharkynaskatkyzy/PycharmProjects/Zmall/server/apps/advert/serializers/advert_serializers.py changed, reloading.
2022-09-14 18:27:05,932 [autoreload | INFO] Watching for file changes with StatReloader
2022-09-14 18:27:32,111 [autoreload | INFO] /Users/zharkynaskatkyzy/PycharmProjects/Zmall/server/config/settings/base.py changed, reloading.
2022-09-14 18:27:32,578 [autoreload | INFO] Watching for file changes with StatReloader
2022-09-14 18:27:35,193 [log | WARNING] Not Found: /
2022-09-14 18:27:37,723 [log | WARNING] Not Found: /
2022-09-14 18:28:32,613 [autoreload | INFO] /Users/zharkynaskatkyzy/PycharmProjects/Zmall/server/apps/advert/serializers/advert_serializers.py changed, reloading.
2022-09-14 18:28:33,180 [autoreload | INFO] Watching for file changes with StatReloader
2022-09-14 18:30:20,675 [autoreload | INFO] /Users/zharkynaskatkyzy/PycharmProjects/Zmall/server/apps/advert/serializers/advert_serializers.py changed, reloading.
2022-09-14 18:30:21,186 [autoreload | INFO] Watching for file changes with StatReloader
2022-09-14 18:31:40,721 [log | WARNING] Method Not Allowed: /api/v1/user/login/
2022-09-14 18:32:38,966 [log | WARNING] Method Not Allowed: /api/v1/user/login/
2022-09-14 18:33:22,620 [log | WARNING] Bad Request: /api/v1/advert/
2022-09-14 18:33:54,444 [autoreload | INFO] /Users/zharkynaskatkyzy/PycharmProjects/Zmall/server/apps/advert/serializers/advert_serializers.py changed, reloading.
2022-09-14 18:33:55,013 [autoreload | INFO] Watching for file changes with StatReloader
2022-09-14 18:36:27,897 [autoreload | INFO] /Users/zharkynaskatkyzy/PycharmProjects/Zmall/server/apps/advert/views/advert_views.py changed, reloading.
2022-09-14 18:36:28,533 [autoreload | INFO] Watching for file changes with StatReloader
2022-09-14 18:36:52,574 [autoreload | INFO] /Users/zharkynaskatkyzy/PycharmProjects/Zmall/server/apps/advert/views/advert_views.py changed, reloading.
2022-09-14 18:36:53,367 [autoreload | INFO] Watching for file changes with StatReloader
2022-09-14 18:38:27,887 [autoreload | INFO] /Users/zharkynaskatkyzy/PycharmProjects/Zmall/server/apps/advert/views/advert_views.py changed, reloading.
2022-09-14 18:38:28,508 [autoreload | INFO] Watching for file changes with StatReloader
2022-09-14 18:38:35,020 [autoreload | INFO] /Users/zharkynaskatkyzy/PycharmProjects/Zmall/server/apps/advert/views/advert_views.py changed, reloading.
2022-09-14 18:38:35,854 [autoreload | INFO] Watching for file changes with StatReloader
2022-09-14 18:38:41,136 [autoreload | INFO] /Users/zharkynaskatkyzy/PycharmProjects/Zmall/server/apps/advert/views/advert_views.py changed, reloading.
2022-09-14 18:38:41,685 [autoreload | INFO] Watching for file changes with StatReloader
2022-09-14 18:43:06,601 [autoreload | INFO] /Users/zharkynaskatkyzy/PycharmProjects/Zmall/server/apps/advert/views/advert_views.py changed, reloading.
2022-09-14 18:43:07,167 [autoreload | INFO] Watching for file changes with StatReloader
2022-09-14 18:44:09,580 [autoreload | INFO] /Users/zharkynaskatkyzy/PycharmProjects/Zmall/server/apps/advert/urls.py changed, reloading.
2022-09-14 18:44:10,124 [autoreload | INFO] Watching for file changes with StatReloader
2022-09-14 18:44:22,935 [base | WARNING] view's ContactView raised exception during schema generation; use `getattr(self, 'swagger_fake_view', False)` to detect and short-circuit this
Traceback (most recent call last):
  File "/Library/Frameworks/Python.framework/Versions/3.10/lib/python3.10/site-packages/drf_yasg/inspectors/base.py", line 42, in call_view_method
    return view_method()
  File "/Library/Frameworks/Python.framework/Versions/3.10/lib/python3.10/site-packages/rest_framework/generics.py", line 108, in get_serializer
    serializer_class = self.get_serializer_class()
  File "/Library/Frameworks/Python.framework/Versions/3.10/lib/python3.10/site-packages/rest_framework/generics.py", line 122, in get_serializer_class
    assert self.serializer_class is not None, (
AssertionError: 'ContactView' should either include a `serializer_class` attribute, or override the `get_serializer_class()` method.
2022-09-14 18:44:22,936 [base | WARNING] view's ContactView raised exception during schema generation; use `getattr(self, 'swagger_fake_view', False)` to detect and short-circuit this
Traceback (most recent call last):
  File "/Library/Frameworks/Python.framework/Versions/3.10/lib/python3.10/site-packages/drf_yasg/inspectors/base.py", line 42, in call_view_method
    return view_method()
  File "/Library/Frameworks/Python.framework/Versions/3.10/lib/python3.10/site-packages/rest_framework/generics.py", line 108, in get_serializer
    serializer_class = self.get_serializer_class()
  File "/Library/Frameworks/Python.framework/Versions/3.10/lib/python3.10/site-packages/rest_framework/generics.py", line 122, in get_serializer_class
    assert self.serializer_class is not None, (
AssertionError: 'ContactView' should either include a `serializer_class` attribute, or override the `get_serializer_class()` method.
2022-09-14 18:44:22,951 [base | WARNING] view's VerifyEmail raised exception during schema generation; use `getattr(self, 'swagger_fake_view', False)` to detect and short-circuit this
Traceback (most recent call last):
  File "/Library/Frameworks/Python.framework/Versions/3.10/lib/python3.10/site-packages/drf_yasg/inspectors/base.py", line 42, in call_view_method
    return view_method()
  File "/Library/Frameworks/Python.framework/Versions/3.10/lib/python3.10/site-packages/rest_framework/generics.py", line 108, in get_serializer
    serializer_class = self.get_serializer_class()
  File "/Library/Frameworks/Python.framework/Versions/3.10/lib/python3.10/site-packages/rest_framework/generics.py", line 122, in get_serializer_class
    assert self.serializer_class is not None, (
AssertionError: 'VerifyEmail' should either include a `serializer_class` attribute, or override the `get_serializer_class()` method.
2022-09-14 18:45:46,370 [log | WARNING] Method Not Allowed: /api/v1/update/
2022-09-14 18:45:55,866 [log | WARNING] Not Found: /api/v1/update/1
2022-09-14 18:46:35,724 [autoreload | INFO] /Users/zharkynaskatkyzy/PycharmProjects/Zmall/server/apps/advert/views/advert_views.py changed, reloading.
2022-09-14 18:46:36,510 [autoreload | INFO] Watching for file changes with StatReloader
2022-09-14 18:46:47,102 [base | WARNING] view's ContactView raised exception during schema generation; use `getattr(self, 'swagger_fake_view', False)` to detect and short-circuit this
Traceback (most recent call last):
  File "/Library/Frameworks/Python.framework/Versions/3.10/lib/python3.10/site-packages/drf_yasg/inspectors/base.py", line 42, in call_view_method
    return view_method()
  File "/Library/Frameworks/Python.framework/Versions/3.10/lib/python3.10/site-packages/rest_framework/generics.py", line 108, in get_serializer
    serializer_class = self.get_serializer_class()
  File "/Library/Frameworks/Python.framework/Versions/3.10/lib/python3.10/site-packages/rest_framework/generics.py", line 122, in get_serializer_class
    assert self.serializer_class is not None, (
AssertionError: 'ContactView' should either include a `serializer_class` attribute, or override the `get_serializer_class()` method.
2022-09-14 18:46:47,103 [base | WARNING] view's ContactView raised exception during schema generation; use `getattr(self, 'swagger_fake_view', False)` to detect and short-circuit this
Traceback (most recent call last):
  File "/Library/Frameworks/Python.framework/Versions/3.10/lib/python3.10/site-packages/drf_yasg/inspectors/base.py", line 42, in call_view_method
    return view_method()
  File "/Library/Frameworks/Python.framework/Versions/3.10/lib/python3.10/site-packages/rest_framework/generics.py", line 108, in get_serializer
    serializer_class = self.get_serializer_class()
  File "/Library/Frameworks/Python.framework/Versions/3.10/lib/python3.10/site-packages/rest_framework/generics.py", line 122, in get_serializer_class
    assert self.serializer_class is not None, (
AssertionError: 'ContactView' should either include a `serializer_class` attribute, or override the `get_serializer_class()` method.
2022-09-14 18:46:47,115 [base | WARNING] view's VerifyEmail raised exception during schema generation; use `getattr(self, 'swagger_fake_view', False)` to detect and short-circuit this
Traceback (most recent call last):
  File "/Library/Frameworks/Python.framework/Versions/3.10/lib/python3.10/site-packages/drf_yasg/inspectors/base.py", line 42, in call_view_method
    return view_method()
  File "/Library/Frameworks/Python.framework/Versions/3.10/lib/python3.10/site-packages/rest_framework/generics.py", line 108, in get_serializer
    serializer_class = self.get_serializer_class()
  File "/Library/Frameworks/Python.framework/Versions/3.10/lib/python3.10/site-packages/rest_framework/generics.py", line 122, in get_serializer_class
    assert self.serializer_class is not None, (
AssertionError: 'VerifyEmail' should either include a `serializer_class` attribute, or override the `get_serializer_class()` method.
2022-09-14 18:47:21,220 [log | WARNING] Unauthorized: /api/v1/advert/1/
2022-09-14 18:49:13,134 [log | WARNING] Unauthorized: /api/v1/advert/1/
2022-09-14 18:51:25,930 [log | WARNING] Unauthorized: /api/v1/advert/
2022-09-14 18:51:37,271 [log | WARNING] Method Not Allowed: /api/v1/user/login/
2022-09-14 18:51:55,866 [log | WARNING] Method Not Allowed: /api/v1/advert/
2022-09-14 18:52:13,105 [log | WARNING] Not Found: /api/v1/advert/82/
2022-09-14 18:53:23,808 [autoreload | INFO] /Users/zharkynaskatkyzy/PycharmProjects/Zmall/server/apps/advert/views/advert_views.py changed, reloading.
2022-09-14 18:53:24,659 [autoreload | INFO] Watching for file changes with StatReloader
2022-09-14 18:58:02,994 [autoreload | INFO] /Users/zharkynaskatkyzy/PycharmProjects/Zmall/server/apps/advert/views/advert_views.py changed, reloading.
2022-09-14 18:58:03,617 [autoreload | INFO] Watching for file changes with StatReloader
2022-09-14 18:58:57,516 [autoreload | INFO] /Users/zharkynaskatkyzy/PycharmProjects/Zmall/server/apps/advert/urls.py changed, reloading.
2022-09-14 18:58:58,059 [autoreload | INFO] Watching for file changes with StatReloader
2022-09-14 18:59:03,837 [base | WARNING] view's ContactView raised exception during schema generation; use `getattr(self, 'swagger_fake_view', False)` to detect and short-circuit this
Traceback (most recent call last):
  File "/Library/Frameworks/Python.framework/Versions/3.10/lib/python3.10/site-packages/drf_yasg/inspectors/base.py", line 42, in call_view_method
    return view_method()
  File "/Library/Frameworks/Python.framework/Versions/3.10/lib/python3.10/site-packages/rest_framework/generics.py", line 108, in get_serializer
    serializer_class = self.get_serializer_class()
  File "/Library/Frameworks/Python.framework/Versions/3.10/lib/python3.10/site-packages/rest_framework/generics.py", line 122, in get_serializer_class
    assert self.serializer_class is not None, (
AssertionError: 'ContactView' should either include a `serializer_class` attribute, or override the `get_serializer_class()` method.
2022-09-14 18:59:03,837 [base | WARNING] view's ContactView raised exception during schema generation; use `getattr(self, 'swagger_fake_view', False)` to detect and short-circuit this
Traceback (most recent call last):
  File "/Library/Frameworks/Python.framework/Versions/3.10/lib/python3.10/site-packages/drf_yasg/inspectors/base.py", line 42, in call_view_method
    return view_method()
  File "/Library/Frameworks/Python.framework/Versions/3.10/lib/python3.10/site-packages/rest_framework/generics.py", line 108, in get_serializer
    serializer_class = self.get_serializer_class()
  File "/Library/Frameworks/Python.framework/Versions/3.10/lib/python3.10/site-packages/rest_framework/generics.py", line 122, in get_serializer_class
    assert self.serializer_class is not None, (
AssertionError: 'ContactView' should either include a `serializer_class` attribute, or override the `get_serializer_class()` method.
2022-09-14 18:59:03,848 [base | WARNING] view's VerifyEmail raised exception during schema generation; use `getattr(self, 'swagger_fake_view', False)` to detect and short-circuit this
Traceback (most recent call last):
  File "/Library/Frameworks/Python.framework/Versions/3.10/lib/python3.10/site-packages/drf_yasg/inspectors/base.py", line 42, in call_view_method
    return view_method()
  File "/Library/Frameworks/Python.framework/Versions/3.10/lib/python3.10/site-packages/rest_framework/generics.py", line 108, in get_serializer
    serializer_class = self.get_serializer_class()
  File "/Library/Frameworks/Python.framework/Versions/3.10/lib/python3.10/site-packages/rest_framework/generics.py", line 122, in get_serializer_class
    assert self.serializer_class is not None, (
AssertionError: 'VerifyEmail' should either include a `serializer_class` attribute, or override the `get_serializer_class()` method.
2022-09-14 19:00:43,427 [autoreload | INFO] /Users/zharkynaskatkyzy/PycharmProjects/Zmall/server/apps/advert/views/advert_views.py changed, reloading.
2022-09-14 19:00:44,012 [autoreload | INFO] Watching for file changes with StatReloader
2022-09-14 19:00:46,333 [base | WARNING] view's ContactView raised exception during schema generation; use `getattr(self, 'swagger_fake_view', False)` to detect and short-circuit this
Traceback (most recent call last):
  File "/Library/Frameworks/Python.framework/Versions/3.10/lib/python3.10/site-packages/drf_yasg/inspectors/base.py", line 42, in call_view_method
    return view_method()
  File "/Library/Frameworks/Python.framework/Versions/3.10/lib/python3.10/site-packages/rest_framework/generics.py", line 108, in get_serializer
    serializer_class = self.get_serializer_class()
  File "/Library/Frameworks/Python.framework/Versions/3.10/lib/python3.10/site-packages/rest_framework/generics.py", line 122, in get_serializer_class
    assert self.serializer_class is not None, (
AssertionError: 'ContactView' should either include a `serializer_class` attribute, or override the `get_serializer_class()` method.
2022-09-14 19:00:46,336 [base | WARNING] view's ContactView raised exception during schema generation; use `getattr(self, 'swagger_fake_view', False)` to detect and short-circuit this
Traceback (most recent call last):
  File "/Library/Frameworks/Python.framework/Versions/3.10/lib/python3.10/site-packages/drf_yasg/inspectors/base.py", line 42, in call_view_method
    return view_method()
  File "/Library/Frameworks/Python.framework/Versions/3.10/lib/python3.10/site-packages/rest_framework/generics.py", line 108, in get_serializer
    serializer_class = self.get_serializer_class()
  File "/Library/Frameworks/Python.framework/Versions/3.10/lib/python3.10/site-packages/rest_framework/generics.py", line 122, in get_serializer_class
    assert self.serializer_class is not None, (
AssertionError: 'ContactView' should either include a `serializer_class` attribute, or override the `get_serializer_class()` method.
2022-09-14 19:00:46,349 [base | WARNING] view's VerifyEmail raised exception during schema generation; use `getattr(self, 'swagger_fake_view', False)` to detect and short-circuit this
Traceback (most recent call last):
  File "/Library/Frameworks/Python.framework/Versions/3.10/lib/python3.10/site-packages/drf_yasg/inspectors/base.py", line 42, in call_view_method
    return view_method()
  File "/Library/Frameworks/Python.framework/Versions/3.10/lib/python3.10/site-packages/rest_framework/generics.py", line 108, in get_serializer
    serializer_class = self.get_serializer_class()
  File "/Library/Frameworks/Python.framework/Versions/3.10/lib/python3.10/site-packages/rest_framework/generics.py", line 122, in get_serializer_class
    assert self.serializer_class is not None, (
AssertionError: 'VerifyEmail' should either include a `serializer_class` attribute, or override the `get_serializer_class()` method.
2022-09-14 19:01:24,065 [log | WARNING] Unauthorized: /api/v1/advert/82/
2022-09-14 19:02:16,571 [base | WARNING] view's ContactView raised exception during schema generation; use `getattr(self, 'swagger_fake_view', False)` to detect and short-circuit this
Traceback (most recent call last):
  File "/Library/Frameworks/Python.framework/Versions/3.10/lib/python3.10/site-packages/drf_yasg/inspectors/base.py", line 42, in call_view_method
    return view_method()
  File "/Library/Frameworks/Python.framework/Versions/3.10/lib/python3.10/site-packages/rest_framework/generics.py", line 108, in get_serializer
    serializer_class = self.get_serializer_class()
  File "/Library/Frameworks/Python.framework/Versions/3.10/lib/python3.10/site-packages/rest_framework/generics.py", line 122, in get_serializer_class
    assert self.serializer_class is not None, (
AssertionError: 'ContactView' should either include a `serializer_class` attribute, or override the `get_serializer_class()` method.
2022-09-14 19:02:16,572 [base | WARNING] view's ContactView raised exception during schema generation; use `getattr(self, 'swagger_fake_view', False)` to detect and short-circuit this
Traceback (most recent call last):
  File "/Library/Frameworks/Python.framework/Versions/3.10/lib/python3.10/site-packages/drf_yasg/inspectors/base.py", line 42, in call_view_method
    return view_method()
  File "/Library/Frameworks/Python.framework/Versions/3.10/lib/python3.10/site-packages/rest_framework/generics.py", line 108, in get_serializer
    serializer_class = self.get_serializer_class()
  File "/Library/Frameworks/Python.framework/Versions/3.10/lib/python3.10/site-packages/rest_framework/generics.py", line 122, in get_serializer_class
    assert self.serializer_class is not None, (
AssertionError: 'ContactView' should either include a `serializer_class` attribute, or override the `get_serializer_class()` method.
2022-09-14 19:02:16,587 [base | WARNING] view's VerifyEmail raised exception during schema generation; use `getattr(self, 'swagger_fake_view', False)` to detect and short-circuit this
Traceback (most recent call last):
  File "/Library/Frameworks/Python.framework/Versions/3.10/lib/python3.10/site-packages/drf_yasg/inspectors/base.py", line 42, in call_view_method
    return view_method()
  File "/Library/Frameworks/Python.framework/Versions/3.10/lib/python3.10/site-packages/rest_framework/generics.py", line 108, in get_serializer
    serializer_class = self.get_serializer_class()
  File "/Library/Frameworks/Python.framework/Versions/3.10/lib/python3.10/site-packages/rest_framework/generics.py", line 122, in get_serializer_class
    assert self.serializer_class is not None, (
AssertionError: 'VerifyEmail' should either include a `serializer_class` attribute, or override the `get_serializer_class()` method.
2022-09-15 03:01:04,883 [log | ERROR] Internal Server Error: /swagger/
Traceback (most recent call last):
  File "/usr/local/lib/python3.9/site-packages/redis/connection.py", line 611, in connect
    sock = self.retry.call_with_retry(
  File "/usr/local/lib/python3.9/site-packages/redis/retry.py", line 46, in call_with_retry
    return do()
  File "/usr/local/lib/python3.9/site-packages/redis/connection.py", line 612, in <lambda>
    lambda: self._connect(), lambda error: self.disconnect(error)
  File "/usr/local/lib/python3.9/site-packages/redis/connection.py", line 677, in _connect
    raise err
  File "/usr/local/lib/python3.9/site-packages/redis/connection.py", line 665, in _connect
    sock.connect(socket_address)
OSError: [Errno 99] Cannot assign requested address

During handling of the above exception, another exception occurred:

Traceback (most recent call last):
  File "/usr/local/lib/python3.9/site-packages/django/core/handlers/exception.py", line 55, in inner
    response = get_response(request)
  File "/backend/config/middleware.py", line 31, in __call__
    if not redis.exists(client_count) and not redis.exists(client_date):
  File "/usr/local/lib/python3.9/site-packages/redis/commands/core.py", line 1612, in exists
    return self.execute_command("EXISTS", *names)
  File "/usr/local/lib/python3.9/site-packages/redis/client.py", line 1235, in execute_command
    conn = self.connection or pool.get_connection(command_name, **options)
  File "/usr/local/lib/python3.9/site-packages/redis/connection.py", line 1387, in get_connection
    connection.connect()
  File "/usr/local/lib/python3.9/site-packages/redis/connection.py", line 617, in connect
    raise ConnectionError(self._error_message(e))
redis.exceptions.ConnectionError: Error 99 connecting to localhost:6379. Cannot assign requested address.
2022-09-15 03:01:16,144 [log | ERROR] Internal Server Error: /swagger/
Traceback (most recent call last):
  File "/usr/local/lib/python3.9/site-packages/redis/connection.py", line 611, in connect
    sock = self.retry.call_with_retry(
  File "/usr/local/lib/python3.9/site-packages/redis/retry.py", line 46, in call_with_retry
    return do()
  File "/usr/local/lib/python3.9/site-packages/redis/connection.py", line 612, in <lambda>
    lambda: self._connect(), lambda error: self.disconnect(error)
  File "/usr/local/lib/python3.9/site-packages/redis/connection.py", line 677, in _connect
    raise err
  File "/usr/local/lib/python3.9/site-packages/redis/connection.py", line 665, in _connect
    sock.connect(socket_address)
OSError: [Errno 99] Cannot assign requested address

During handling of the above exception, another exception occurred:

Traceback (most recent call last):
  File "/usr/local/lib/python3.9/site-packages/django/core/handlers/exception.py", line 55, in inner
    response = get_response(request)
  File "/backend/config/middleware.py", line 31, in __call__
    if not redis.exists(client_count) and not redis.exists(client_date):
  File "/usr/local/lib/python3.9/site-packages/redis/commands/core.py", line 1612, in exists
    return self.execute_command("EXISTS", *names)
  File "/usr/local/lib/python3.9/site-packages/redis/client.py", line 1235, in execute_command
    conn = self.connection or pool.get_connection(command_name, **options)
  File "/usr/local/lib/python3.9/site-packages/redis/connection.py", line 1387, in get_connection
    connection.connect()
  File "/usr/local/lib/python3.9/site-packages/redis/connection.py", line 617, in connect
    raise ConnectionError(self._error_message(e))
redis.exceptions.ConnectionError: Error 99 connecting to localhost:6379. Cannot assign requested address.
2022-09-15 03:01:20,755 [log | ERROR] Internal Server Error: /swagger/
Traceback (most recent call last):
  File "/usr/local/lib/python3.9/site-packages/redis/connection.py", line 611, in connect
    sock = self.retry.call_with_retry(
  File "/usr/local/lib/python3.9/site-packages/redis/retry.py", line 46, in call_with_retry
    return do()
  File "/usr/local/lib/python3.9/site-packages/redis/connection.py", line 612, in <lambda>
    lambda: self._connect(), lambda error: self.disconnect(error)
  File "/usr/local/lib/python3.9/site-packages/redis/connection.py", line 677, in _connect
    raise err
  File "/usr/local/lib/python3.9/site-packages/redis/connection.py", line 665, in _connect
    sock.connect(socket_address)
OSError: [Errno 99] Cannot assign requested address

During handling of the above exception, another exception occurred:

Traceback (most recent call last):
  File "/usr/local/lib/python3.9/site-packages/django/core/handlers/exception.py", line 55, in inner
    response = get_response(request)
  File "/backend/config/middleware.py", line 31, in __call__
    if not redis.exists(client_count) and not redis.exists(client_date):
  File "/usr/local/lib/python3.9/site-packages/redis/commands/core.py", line 1612, in exists
    return self.execute_command("EXISTS", *names)
  File "/usr/local/lib/python3.9/site-packages/redis/client.py", line 1235, in execute_command
    conn = self.connection or pool.get_connection(command_name, **options)
  File "/usr/local/lib/python3.9/site-packages/redis/connection.py", line 1387, in get_connection
    connection.connect()
  File "/usr/local/lib/python3.9/site-packages/redis/connection.py", line 617, in connect
    raise ConnectionError(self._error_message(e))
redis.exceptions.ConnectionError: Error 99 connecting to localhost:6379. Cannot assign requested address.
2022-09-15 03:01:30,827 [log | ERROR] Internal Server Error: /api/v1/city/
Traceback (most recent call last):
  File "/usr/local/lib/python3.9/site-packages/redis/connection.py", line 611, in connect
    sock = self.retry.call_with_retry(
  File "/usr/local/lib/python3.9/site-packages/redis/retry.py", line 46, in call_with_retry
    return do()
  File "/usr/local/lib/python3.9/site-packages/redis/connection.py", line 612, in <lambda>
    lambda: self._connect(), lambda error: self.disconnect(error)
  File "/usr/local/lib/python3.9/site-packages/redis/connection.py", line 677, in _connect
    raise err
  File "/usr/local/lib/python3.9/site-packages/redis/connection.py", line 665, in _connect
    sock.connect(socket_address)
OSError: [Errno 99] Cannot assign requested address

During handling of the above exception, another exception occurred:

Traceback (most recent call last):
  File "/usr/local/lib/python3.9/site-packages/django/core/handlers/exception.py", line 55, in inner
    response = get_response(request)
  File "/backend/config/middleware.py", line 31, in __call__
    if not redis.exists(client_count) and not redis.exists(client_date):
  File "/usr/local/lib/python3.9/site-packages/redis/commands/core.py", line 1612, in exists
    return self.execute_command("EXISTS", *names)
  File "/usr/local/lib/python3.9/site-packages/redis/client.py", line 1235, in execute_command
    conn = self.connection or pool.get_connection(command_name, **options)
  File "/usr/local/lib/python3.9/site-packages/redis/connection.py", line 1387, in get_connection
    connection.connect()
  File "/usr/local/lib/python3.9/site-packages/redis/connection.py", line 617, in connect
    raise ConnectionError(self._error_message(e))
redis.exceptions.ConnectionError: Error 99 connecting to localhost:6379. Cannot assign requested address.
2022-09-15 03:01:32,557 [log | ERROR] Internal Server Error: /api/v1/city/
Traceback (most recent call last):
  File "/usr/local/lib/python3.9/site-packages/redis/connection.py", line 611, in connect
    sock = self.retry.call_with_retry(
  File "/usr/local/lib/python3.9/site-packages/redis/retry.py", line 46, in call_with_retry
    return do()
  File "/usr/local/lib/python3.9/site-packages/redis/connection.py", line 612, in <lambda>
    lambda: self._connect(), lambda error: self.disconnect(error)
  File "/usr/local/lib/python3.9/site-packages/redis/connection.py", line 677, in _connect
    raise err
  File "/usr/local/lib/python3.9/site-packages/redis/connection.py", line 665, in _connect
    sock.connect(socket_address)
OSError: [Errno 99] Cannot assign requested address

During handling of the above exception, another exception occurred:

Traceback (most recent call last):
  File "/usr/local/lib/python3.9/site-packages/django/core/handlers/exception.py", line 55, in inner
    response = get_response(request)
  File "/backend/config/middleware.py", line 31, in __call__
    if not redis.exists(client_count) and not redis.exists(client_date):
  File "/usr/local/lib/python3.9/site-packages/redis/commands/core.py", line 1612, in exists
    return self.execute_command("EXISTS", *names)
  File "/usr/local/lib/python3.9/site-packages/redis/client.py", line 1235, in execute_command
    conn = self.connection or pool.get_connection(command_name, **options)
  File "/usr/local/lib/python3.9/site-packages/redis/connection.py", line 1387, in get_connection
    connection.connect()
  File "/usr/local/lib/python3.9/site-packages/redis/connection.py", line 617, in connect
    raise ConnectionError(self._error_message(e))
redis.exceptions.ConnectionError: Error 99 connecting to localhost:6379. Cannot assign requested address.
2022-09-15 03:01:33,423 [log | ERROR] Internal Server Error: /api/v1/city/
Traceback (most recent call last):
  File "/usr/local/lib/python3.9/site-packages/redis/connection.py", line 611, in connect
    sock = self.retry.call_with_retry(
  File "/usr/local/lib/python3.9/site-packages/redis/retry.py", line 46, in call_with_retry
    return do()
  File "/usr/local/lib/python3.9/site-packages/redis/connection.py", line 612, in <lambda>
    lambda: self._connect(), lambda error: self.disconnect(error)
  File "/usr/local/lib/python3.9/site-packages/redis/connection.py", line 677, in _connect
    raise err
  File "/usr/local/lib/python3.9/site-packages/redis/connection.py", line 665, in _connect
    sock.connect(socket_address)
OSError: [Errno 99] Cannot assign requested address

During handling of the above exception, another exception occurred:

Traceback (most recent call last):
  File "/usr/local/lib/python3.9/site-packages/django/core/handlers/exception.py", line 55, in inner
    response = get_response(request)
  File "/backend/config/middleware.py", line 31, in __call__
    if not redis.exists(client_count) and not redis.exists(client_date):
  File "/usr/local/lib/python3.9/site-packages/redis/commands/core.py", line 1612, in exists
    return self.execute_command("EXISTS", *names)
  File "/usr/local/lib/python3.9/site-packages/redis/client.py", line 1235, in execute_command
    conn = self.connection or pool.get_connection(command_name, **options)
  File "/usr/local/lib/python3.9/site-packages/redis/connection.py", line 1387, in get_connection
    connection.connect()
  File "/usr/local/lib/python3.9/site-packages/redis/connection.py", line 617, in connect
    raise ConnectionError(self._error_message(e))
redis.exceptions.ConnectionError: Error 99 connecting to localhost:6379. Cannot assign requested address.
2022-09-15 03:01:37,856 [log | ERROR] Internal Server Error: /api/v1/category/
Traceback (most recent call last):
  File "/usr/local/lib/python3.9/site-packages/redis/connection.py", line 611, in connect
    sock = self.retry.call_with_retry(
  File "/usr/local/lib/python3.9/site-packages/redis/retry.py", line 46, in call_with_retry
    return do()
  File "/usr/local/lib/python3.9/site-packages/redis/connection.py", line 612, in <lambda>
    lambda: self._connect(), lambda error: self.disconnect(error)
  File "/usr/local/lib/python3.9/site-packages/redis/connection.py", line 677, in _connect
    raise err
  File "/usr/local/lib/python3.9/site-packages/redis/connection.py", line 665, in _connect
    sock.connect(socket_address)
OSError: [Errno 99] Cannot assign requested address

During handling of the above exception, another exception occurred:

Traceback (most recent call last):
  File "/usr/local/lib/python3.9/site-packages/django/core/handlers/exception.py", line 55, in inner
    response = get_response(request)
  File "/backend/config/middleware.py", line 31, in __call__
    if not redis.exists(client_count) and not redis.exists(client_date):
  File "/usr/local/lib/python3.9/site-packages/redis/commands/core.py", line 1612, in exists
    return self.execute_command("EXISTS", *names)
  File "/usr/local/lib/python3.9/site-packages/redis/client.py", line 1235, in execute_command
    conn = self.connection or pool.get_connection(command_name, **options)
  File "/usr/local/lib/python3.9/site-packages/redis/connection.py", line 1387, in get_connection
    connection.connect()
  File "/usr/local/lib/python3.9/site-packages/redis/connection.py", line 617, in connect
    raise ConnectionError(self._error_message(e))
redis.exceptions.ConnectionError: Error 99 connecting to localhost:6379. Cannot assign requested address.
2022-09-15 03:01:45,550 [log | ERROR] Internal Server Error: /api/v1/category/
Traceback (most recent call last):
  File "/usr/local/lib/python3.9/site-packages/redis/connection.py", line 611, in connect
    sock = self.retry.call_with_retry(
  File "/usr/local/lib/python3.9/site-packages/redis/retry.py", line 46, in call_with_retry
    return do()
  File "/usr/local/lib/python3.9/site-packages/redis/connection.py", line 612, in <lambda>
    lambda: self._connect(), lambda error: self.disconnect(error)
  File "/usr/local/lib/python3.9/site-packages/redis/connection.py", line 677, in _connect
    raise err
  File "/usr/local/lib/python3.9/site-packages/redis/connection.py", line 665, in _connect
    sock.connect(socket_address)
OSError: [Errno 99] Cannot assign requested address

During handling of the above exception, another exception occurred:

Traceback (most recent call last):
  File "/usr/local/lib/python3.9/site-packages/django/core/handlers/exception.py", line 55, in inner
    response = get_response(request)
  File "/backend/config/middleware.py", line 31, in __call__
    if not redis.exists(client_count) and not redis.exists(client_date):
  File "/usr/local/lib/python3.9/site-packages/redis/commands/core.py", line 1612, in exists
    return self.execute_command("EXISTS", *names)
  File "/usr/local/lib/python3.9/site-packages/redis/client.py", line 1235, in execute_command
    conn = self.connection or pool.get_connection(command_name, **options)
  File "/usr/local/lib/python3.9/site-packages/redis/connection.py", line 1387, in get_connection
    connection.connect()
  File "/usr/local/lib/python3.9/site-packages/redis/connection.py", line 617, in connect
    raise ConnectionError(self._error_message(e))
redis.exceptions.ConnectionError: Error 99 connecting to localhost:6379. Cannot assign requested address.
2022-09-15 03:01:50,013 [log | ERROR] Internal Server Error: /
Traceback (most recent call last):
  File "/usr/local/lib/python3.9/site-packages/redis/connection.py", line 611, in connect
    sock = self.retry.call_with_retry(
  File "/usr/local/lib/python3.9/site-packages/redis/retry.py", line 46, in call_with_retry
    return do()
  File "/usr/local/lib/python3.9/site-packages/redis/connection.py", line 612, in <lambda>
    lambda: self._connect(), lambda error: self.disconnect(error)
  File "/usr/local/lib/python3.9/site-packages/redis/connection.py", line 677, in _connect
    raise err
  File "/usr/local/lib/python3.9/site-packages/redis/connection.py", line 665, in _connect
    sock.connect(socket_address)
OSError: [Errno 99] Cannot assign requested address

During handling of the above exception, another exception occurred:

Traceback (most recent call last):
  File "/usr/local/lib/python3.9/site-packages/django/core/handlers/exception.py", line 55, in inner
    response = get_response(request)
  File "/backend/config/middleware.py", line 31, in __call__
    if not redis.exists(client_count) and not redis.exists(client_date):
  File "/usr/local/lib/python3.9/site-packages/redis/commands/core.py", line 1612, in exists
    return self.execute_command("EXISTS", *names)
  File "/usr/local/lib/python3.9/site-packages/redis/client.py", line 1235, in execute_command
    conn = self.connection or pool.get_connection(command_name, **options)
  File "/usr/local/lib/python3.9/site-packages/redis/connection.py", line 1387, in get_connection
    connection.connect()
  File "/usr/local/lib/python3.9/site-packages/redis/connection.py", line 617, in connect
    raise ConnectionError(self._error_message(e))
redis.exceptions.ConnectionError: Error 99 connecting to localhost:6379. Cannot assign requested address.
2022-09-15 03:02:19,402 [log | ERROR] Internal Server Error: /
Traceback (most recent call last):
  File "/usr/local/lib/python3.9/site-packages/redis/connection.py", line 611, in connect
    sock = self.retry.call_with_retry(
  File "/usr/local/lib/python3.9/site-packages/redis/retry.py", line 46, in call_with_retry
    return do()
  File "/usr/local/lib/python3.9/site-packages/redis/connection.py", line 612, in <lambda>
    lambda: self._connect(), lambda error: self.disconnect(error)
  File "/usr/local/lib/python3.9/site-packages/redis/connection.py", line 677, in _connect
    raise err
  File "/usr/local/lib/python3.9/site-packages/redis/connection.py", line 665, in _connect
    sock.connect(socket_address)
OSError: [Errno 99] Cannot assign requested address

During handling of the above exception, another exception occurred:

Traceback (most recent call last):
  File "/usr/local/lib/python3.9/site-packages/django/core/handlers/exception.py", line 55, in inner
    response = get_response(request)
  File "/backend/config/middleware.py", line 31, in __call__
    if not redis.exists(client_count) and not redis.exists(client_date):
  File "/usr/local/lib/python3.9/site-packages/redis/commands/core.py", line 1612, in exists
    return self.execute_command("EXISTS", *names)
  File "/usr/local/lib/python3.9/site-packages/redis/client.py", line 1235, in execute_command
    conn = self.connection or pool.get_connection(command_name, **options)
  File "/usr/local/lib/python3.9/site-packages/redis/connection.py", line 1387, in get_connection
    connection.connect()
  File "/usr/local/lib/python3.9/site-packages/redis/connection.py", line 617, in connect
    raise ConnectionError(self._error_message(e))
redis.exceptions.ConnectionError: Error 99 connecting to localhost:6379. Cannot assign requested address.
2022-09-15 03:02:19,984 [log | ERROR] Internal Server Error: /
Traceback (most recent call last):
  File "/usr/local/lib/python3.9/site-packages/redis/connection.py", line 611, in connect
    sock = self.retry.call_with_retry(
  File "/usr/local/lib/python3.9/site-packages/redis/retry.py", line 46, in call_with_retry
    return do()
  File "/usr/local/lib/python3.9/site-packages/redis/connection.py", line 612, in <lambda>
    lambda: self._connect(), lambda error: self.disconnect(error)
  File "/usr/local/lib/python3.9/site-packages/redis/connection.py", line 677, in _connect
    raise err
  File "/usr/local/lib/python3.9/site-packages/redis/connection.py", line 665, in _connect
    sock.connect(socket_address)
OSError: [Errno 99] Cannot assign requested address

During handling of the above exception, another exception occurred:

Traceback (most recent call last):
  File "/usr/local/lib/python3.9/site-packages/django/core/handlers/exception.py", line 55, in inner
    response = get_response(request)
  File "/backend/config/middleware.py", line 31, in __call__
    if not redis.exists(client_count) and not redis.exists(client_date):
  File "/usr/local/lib/python3.9/site-packages/redis/commands/core.py", line 1612, in exists
    return self.execute_command("EXISTS", *names)
  File "/usr/local/lib/python3.9/site-packages/redis/client.py", line 1235, in execute_command
    conn = self.connection or pool.get_connection(command_name, **options)
  File "/usr/local/lib/python3.9/site-packages/redis/connection.py", line 1387, in get_connection
    connection.connect()
  File "/usr/local/lib/python3.9/site-packages/redis/connection.py", line 617, in connect
    raise ConnectionError(self._error_message(e))
redis.exceptions.ConnectionError: Error 99 connecting to localhost:6379. Cannot assign requested address.
2022-09-15 03:02:20,635 [log | ERROR] Internal Server Error: /
Traceback (most recent call last):
  File "/usr/local/lib/python3.9/site-packages/redis/connection.py", line 611, in connect
    sock = self.retry.call_with_retry(
  File "/usr/local/lib/python3.9/site-packages/redis/retry.py", line 46, in call_with_retry
    return do()
  File "/usr/local/lib/python3.9/site-packages/redis/connection.py", line 612, in <lambda>
    lambda: self._connect(), lambda error: self.disconnect(error)
  File "/usr/local/lib/python3.9/site-packages/redis/connection.py", line 677, in _connect
    raise err
  File "/usr/local/lib/python3.9/site-packages/redis/connection.py", line 665, in _connect
    sock.connect(socket_address)
OSError: [Errno 99] Cannot assign requested address

During handling of the above exception, another exception occurred:

Traceback (most recent call last):
  File "/usr/local/lib/python3.9/site-packages/django/core/handlers/exception.py", line 55, in inner
    response = get_response(request)
  File "/backend/config/middleware.py", line 31, in __call__
    if not redis.exists(client_count) and not redis.exists(client_date):
  File "/usr/local/lib/python3.9/site-packages/redis/commands/core.py", line 1612, in exists
    return self.execute_command("EXISTS", *names)
  File "/usr/local/lib/python3.9/site-packages/redis/client.py", line 1235, in execute_command
    conn = self.connection or pool.get_connection(command_name, **options)
  File "/usr/local/lib/python3.9/site-packages/redis/connection.py", line 1387, in get_connection
    connection.connect()
  File "/usr/local/lib/python3.9/site-packages/redis/connection.py", line 617, in connect
    raise ConnectionError(self._error_message(e))
redis.exceptions.ConnectionError: Error 99 connecting to localhost:6379. Cannot assign requested address.
2022-09-15 03:02:21,547 [log | ERROR] Internal Server Error: /
Traceback (most recent call last):
  File "/usr/local/lib/python3.9/site-packages/redis/connection.py", line 611, in connect
    sock = self.retry.call_with_retry(
  File "/usr/local/lib/python3.9/site-packages/redis/retry.py", line 46, in call_with_retry
    return do()
  File "/usr/local/lib/python3.9/site-packages/redis/connection.py", line 612, in <lambda>
    lambda: self._connect(), lambda error: self.disconnect(error)
  File "/usr/local/lib/python3.9/site-packages/redis/connection.py", line 677, in _connect
    raise err
  File "/usr/local/lib/python3.9/site-packages/redis/connection.py", line 665, in _connect
    sock.connect(socket_address)
OSError: [Errno 99] Cannot assign requested address

During handling of the above exception, another exception occurred:

Traceback (most recent call last):
  File "/usr/local/lib/python3.9/site-packages/django/core/handlers/exception.py", line 55, in inner
    response = get_response(request)
  File "/backend/config/middleware.py", line 31, in __call__
    if not redis.exists(client_count) and not redis.exists(client_date):
  File "/usr/local/lib/python3.9/site-packages/redis/commands/core.py", line 1612, in exists
    return self.execute_command("EXISTS", *names)
  File "/usr/local/lib/python3.9/site-packages/redis/client.py", line 1235, in execute_command
    conn = self.connection or pool.get_connection(command_name, **options)
  File "/usr/local/lib/python3.9/site-packages/redis/connection.py", line 1387, in get_connection
    connection.connect()
  File "/usr/local/lib/python3.9/site-packages/redis/connection.py", line 617, in connect
    raise ConnectionError(self._error_message(e))
redis.exceptions.ConnectionError: Error 99 connecting to localhost:6379. Cannot assign requested address.
2022-09-15 03:02:22,208 [log | ERROR] Internal Server Error: /
Traceback (most recent call last):
  File "/usr/local/lib/python3.9/site-packages/redis/connection.py", line 611, in connect
    sock = self.retry.call_with_retry(
  File "/usr/local/lib/python3.9/site-packages/redis/retry.py", line 46, in call_with_retry
    return do()
  File "/usr/local/lib/python3.9/site-packages/redis/connection.py", line 612, in <lambda>
    lambda: self._connect(), lambda error: self.disconnect(error)
  File "/usr/local/lib/python3.9/site-packages/redis/connection.py", line 677, in _connect
    raise err
  File "/usr/local/lib/python3.9/site-packages/redis/connection.py", line 665, in _connect
    sock.connect(socket_address)
OSError: [Errno 99] Cannot assign requested address

During handling of the above exception, another exception occurred:

Traceback (most recent call last):
  File "/usr/local/lib/python3.9/site-packages/django/core/handlers/exception.py", line 55, in inner
    response = get_response(request)
  File "/backend/config/middleware.py", line 31, in __call__
    if not redis.exists(client_count) and not redis.exists(client_date):
  File "/usr/local/lib/python3.9/site-packages/redis/commands/core.py", line 1612, in exists
    return self.execute_command("EXISTS", *names)
  File "/usr/local/lib/python3.9/site-packages/redis/client.py", line 1235, in execute_command
    conn = self.connection or pool.get_connection(command_name, **options)
  File "/usr/local/lib/python3.9/site-packages/redis/connection.py", line 1387, in get_connection
    connection.connect()
  File "/usr/local/lib/python3.9/site-packages/redis/connection.py", line 617, in connect
    raise ConnectionError(self._error_message(e))
redis.exceptions.ConnectionError: Error 99 connecting to localhost:6379. Cannot assign requested address.
2022-09-15 03:02:31,996 [log | ERROR] Internal Server Error: /
Traceback (most recent call last):
  File "/usr/local/lib/python3.9/site-packages/redis/connection.py", line 611, in connect
    sock = self.retry.call_with_retry(
  File "/usr/local/lib/python3.9/site-packages/redis/retry.py", line 46, in call_with_retry
    return do()
  File "/usr/local/lib/python3.9/site-packages/redis/connection.py", line 612, in <lambda>
    lambda: self._connect(), lambda error: self.disconnect(error)
  File "/usr/local/lib/python3.9/site-packages/redis/connection.py", line 677, in _connect
    raise err
  File "/usr/local/lib/python3.9/site-packages/redis/connection.py", line 665, in _connect
    sock.connect(socket_address)
OSError: [Errno 99] Cannot assign requested address

During handling of the above exception, another exception occurred:

Traceback (most recent call last):
  File "/usr/local/lib/python3.9/site-packages/django/core/handlers/exception.py", line 55, in inner
    response = get_response(request)
  File "/backend/config/middleware.py", line 31, in __call__
    if not redis.exists(client_count) and not redis.exists(client_date):
  File "/usr/local/lib/python3.9/site-packages/redis/commands/core.py", line 1612, in exists
    return self.execute_command("EXISTS", *names)
  File "/usr/local/lib/python3.9/site-packages/redis/client.py", line 1235, in execute_command
    conn = self.connection or pool.get_connection(command_name, **options)
  File "/usr/local/lib/python3.9/site-packages/redis/connection.py", line 1387, in get_connection
    connection.connect()
  File "/usr/local/lib/python3.9/site-packages/redis/connection.py", line 617, in connect
    raise ConnectionError(self._error_message(e))
redis.exceptions.ConnectionError: Error 99 connecting to localhost:6379. Cannot assign requested address.
2022-09-15 03:02:32,620 [log | ERROR] Internal Server Error: /
Traceback (most recent call last):
  File "/usr/local/lib/python3.9/site-packages/redis/connection.py", line 611, in connect
    sock = self.retry.call_with_retry(
  File "/usr/local/lib/python3.9/site-packages/redis/retry.py", line 46, in call_with_retry
    return do()
  File "/usr/local/lib/python3.9/site-packages/redis/connection.py", line 612, in <lambda>
    lambda: self._connect(), lambda error: self.disconnect(error)
  File "/usr/local/lib/python3.9/site-packages/redis/connection.py", line 677, in _connect
    raise err
  File "/usr/local/lib/python3.9/site-packages/redis/connection.py", line 665, in _connect
    sock.connect(socket_address)
OSError: [Errno 99] Cannot assign requested address

During handling of the above exception, another exception occurred:

Traceback (most recent call last):
  File "/usr/local/lib/python3.9/site-packages/django/core/handlers/exception.py", line 55, in inner
    response = get_response(request)
  File "/backend/config/middleware.py", line 31, in __call__
    if not redis.exists(client_count) and not redis.exists(client_date):
  File "/usr/local/lib/python3.9/site-packages/redis/commands/core.py", line 1612, in exists
    return self.execute_command("EXISTS", *names)
  File "/usr/local/lib/python3.9/site-packages/redis/client.py", line 1235, in execute_command
    conn = self.connection or pool.get_connection(command_name, **options)
  File "/usr/local/lib/python3.9/site-packages/redis/connection.py", line 1387, in get_connection
    connection.connect()
  File "/usr/local/lib/python3.9/site-packages/redis/connection.py", line 617, in connect
    raise ConnectionError(self._error_message(e))
redis.exceptions.ConnectionError: Error 99 connecting to localhost:6379. Cannot assign requested address.
2022-09-15 03:08:09,680 [autoreload | INFO] /Users/zharkynaskatkyzy/PycharmProjects/Zmall/server/apps/advert/views/advert_views.py changed, reloading.
2022-09-15 03:08:10,336 [autoreload | INFO] Watching for file changes with StatReloader
2022-09-15 03:10:26,200 [log | WARNING] Not Found: /api/v1/user_advert/89/
2022-09-15 03:10:47,647 [base | WARNING] view's ContactView raised exception during schema generation; use `getattr(self, 'swagger_fake_view', False)` to detect and short-circuit this
Traceback (most recent call last):
  File "/Library/Frameworks/Python.framework/Versions/3.10/lib/python3.10/site-packages/drf_yasg/inspectors/base.py", line 42, in call_view_method
    return view_method()
  File "/Library/Frameworks/Python.framework/Versions/3.10/lib/python3.10/site-packages/rest_framework/generics.py", line 108, in get_serializer
    serializer_class = self.get_serializer_class()
  File "/Library/Frameworks/Python.framework/Versions/3.10/lib/python3.10/site-packages/rest_framework/generics.py", line 122, in get_serializer_class
    assert self.serializer_class is not None, (
AssertionError: 'ContactView' should either include a `serializer_class` attribute, or override the `get_serializer_class()` method.
2022-09-15 03:10:47,648 [base | WARNING] view's ContactView raised exception during schema generation; use `getattr(self, 'swagger_fake_view', False)` to detect and short-circuit this
Traceback (most recent call last):
  File "/Library/Frameworks/Python.framework/Versions/3.10/lib/python3.10/site-packages/drf_yasg/inspectors/base.py", line 42, in call_view_method
    return view_method()
  File "/Library/Frameworks/Python.framework/Versions/3.10/lib/python3.10/site-packages/rest_framework/generics.py", line 108, in get_serializer
    serializer_class = self.get_serializer_class()
  File "/Library/Frameworks/Python.framework/Versions/3.10/lib/python3.10/site-packages/rest_framework/generics.py", line 122, in get_serializer_class
    assert self.serializer_class is not None, (
AssertionError: 'ContactView' should either include a `serializer_class` attribute, or override the `get_serializer_class()` method.
2022-09-15 03:10:47,662 [base | WARNING] view's VerifyEmail raised exception during schema generation; use `getattr(self, 'swagger_fake_view', False)` to detect and short-circuit this
Traceback (most recent call last):
  File "/Library/Frameworks/Python.framework/Versions/3.10/lib/python3.10/site-packages/drf_yasg/inspectors/base.py", line 42, in call_view_method
    return view_method()
  File "/Library/Frameworks/Python.framework/Versions/3.10/lib/python3.10/site-packages/rest_framework/generics.py", line 108, in get_serializer
    serializer_class = self.get_serializer_class()
  File "/Library/Frameworks/Python.framework/Versions/3.10/lib/python3.10/site-packages/rest_framework/generics.py", line 122, in get_serializer_class
    assert self.serializer_class is not None, (
AssertionError: 'VerifyEmail' should either include a `serializer_class` attribute, or override the `get_serializer_class()` method.
2022-09-15 03:11:12,702 [log | WARNING] Not Found: /api/v1/user_advert/89/
2022-09-15 03:11:21,926 [log | WARNING] Not Found: /api/v1/user_advert/89/
2022-09-15 03:11:22,599 [log | WARNING] Not Found: /api/v1/user_advert/89/
2022-09-15 03:11:23,127 [log | WARNING] Not Found: /api/v1/user_advert/89/
2022-09-15 03:11:23,587 [log | WARNING] Not Found: /api/v1/user_advert/89/
2022-09-15 03:11:23,981 [log | WARNING] Not Found: /api/v1/user_advert/89/
2022-09-15 03:12:10,407 [log | WARNING] Not Found: /api/v1/user_advert_update/89/
2022-09-15 03:12:32,674 [log | WARNING] Not Found: /api/v1/user_advert/89/
2022-09-15 03:12:36,249 [log | WARNING] Not Found: /api/v1/user_advert/89/
2022-09-15 03:13:01,163 [log | WARNING] Not Found: /api/v1/user_advert/82/
2022-09-15 03:13:02,221 [log | WARNING] Not Found: /api/v1/user_advert/82/
2022-09-15 03:13:02,904 [log | WARNING] Not Found: /api/v1/user_advert/82/
2022-09-15 03:13:04,171 [log | WARNING] Not Found: /api/v1/user_advert/82/
2022-09-15 03:13:15,008 [log | WARNING] Not Found: /api/v1/user_advert/82/
2022-09-15 03:13:15,673 [log | WARNING] Not Found: /api/v1/user_advert/82/
2022-09-15 03:13:16,180 [log | WARNING] Not Found: /api/v1/user_advert/82/
2022-09-15 03:13:27,726 [log | WARNING] Method Not Allowed: /api/v1/user/login/
2022-09-15 03:14:23,965 [log | WARNING] Not Found: /api/v1/user_advert/82/
2022-09-15 03:14:24,732 [log | WARNING] Not Found: /api/v1/user_advert/82/
2022-09-15 03:15:04,618 [log | WARNING] Unauthorized: /api/v1/user_advert_update/82/
2022-09-15 03:16:53,696 [autoreload | INFO] /Users/zharkynaskatkyzy/PycharmProjects/Zmall/server/apps/advert/models.py changed, reloading.
2022-09-15 03:16:54,878 [autoreload | INFO] Watching for file changes with StatReloader
2022-09-15 03:17:40,815 [autoreload | INFO] /Users/zharkynaskatkyzy/PycharmProjects/Zmall/server/apps/advert/models.py changed, reloading.
2022-09-15 03:17:41,423 [autoreload | INFO] Watching for file changes with StatReloader
2022-09-15 03:20:04,863 [autoreload | INFO] /Users/zharkynaskatkyzy/PycharmProjects/Zmall/server/apps/advert/serializers/advert_serializers.py changed, reloading.
2022-09-15 03:20:05,492 [autoreload | INFO] Watching for file changes with StatReloader
2022-09-15 03:21:40,024 [autoreload | INFO] /Users/zharkynaskatkyzy/PycharmProjects/Zmall/server/apps/advert/urls.py changed, reloading.
2022-09-15 03:21:40,643 [autoreload | INFO] Watching for file changes with StatReloader
2022-09-15 03:21:48,679 [base | WARNING] view's ContactView raised exception during schema generation; use `getattr(self, 'swagger_fake_view', False)` to detect and short-circuit this
Traceback (most recent call last):
  File "/Library/Frameworks/Python.framework/Versions/3.10/lib/python3.10/site-packages/drf_yasg/inspectors/base.py", line 42, in call_view_method
    return view_method()
  File "/Library/Frameworks/Python.framework/Versions/3.10/lib/python3.10/site-packages/rest_framework/generics.py", line 108, in get_serializer
    serializer_class = self.get_serializer_class()
  File "/Library/Frameworks/Python.framework/Versions/3.10/lib/python3.10/site-packages/rest_framework/generics.py", line 122, in get_serializer_class
    assert self.serializer_class is not None, (
AssertionError: 'ContactView' should either include a `serializer_class` attribute, or override the `get_serializer_class()` method.
2022-09-15 03:21:48,680 [base | WARNING] view's ContactView raised exception during schema generation; use `getattr(self, 'swagger_fake_view', False)` to detect and short-circuit this
Traceback (most recent call last):
  File "/Library/Frameworks/Python.framework/Versions/3.10/lib/python3.10/site-packages/drf_yasg/inspectors/base.py", line 42, in call_view_method
    return view_method()
  File "/Library/Frameworks/Python.framework/Versions/3.10/lib/python3.10/site-packages/rest_framework/generics.py", line 108, in get_serializer
    serializer_class = self.get_serializer_class()
  File "/Library/Frameworks/Python.framework/Versions/3.10/lib/python3.10/site-packages/rest_framework/generics.py", line 122, in get_serializer_class
    assert self.serializer_class is not None, (
AssertionError: 'ContactView' should either include a `serializer_class` attribute, or override the `get_serializer_class()` method.
2022-09-15 03:21:48,692 [base | WARNING] view's VerifyEmail raised exception during schema generation; use `getattr(self, 'swagger_fake_view', False)` to detect and short-circuit this
Traceback (most recent call last):
  File "/Library/Frameworks/Python.framework/Versions/3.10/lib/python3.10/site-packages/drf_yasg/inspectors/base.py", line 42, in call_view_method
    return view_method()
  File "/Library/Frameworks/Python.framework/Versions/3.10/lib/python3.10/site-packages/rest_framework/generics.py", line 108, in get_serializer
    serializer_class = self.get_serializer_class()
  File "/Library/Frameworks/Python.framework/Versions/3.10/lib/python3.10/site-packages/rest_framework/generics.py", line 122, in get_serializer_class
    assert self.serializer_class is not None, (
AssertionError: 'VerifyEmail' should either include a `serializer_class` attribute, or override the `get_serializer_class()` method.
2022-09-15 03:22:47,613 [autoreload | INFO] /Users/zharkynaskatkyzy/PycharmProjects/Zmall/server/apps/advert/admin.py changed, reloading.
2022-09-15 03:22:48,237 [autoreload | INFO] Watching for file changes with StatReloader
2022-09-15 03:24:11,467 [autoreload | INFO] /Users/zharkynaskatkyzy/PycharmProjects/Zmall/server/apps/advert/models.py changed, reloading.
2022-09-15 03:24:12,424 [autoreload | INFO] Watching for file changes with StatReloader
2022-09-15 03:26:45,896 [autoreload | INFO] /Users/zharkynaskatkyzy/PycharmProjects/Zmall/server/config/settings/base.py changed, reloading.
2022-09-15 03:26:46,470 [autoreload | INFO] Watching for file changes with StatReloader
