2022-09-07 10:27:29,565 [autoreload | INFO] Watching for file changes with StatReloader
2022-09-07 10:27:30,804 [log | WARNING] Not Found: /
2022-09-07 10:27:31,119 [log | WARNING] Not Found: /favicon.ico
2022-09-07 10:44:39,245 [autoreload | INFO] Watching for file changes with StatReloader
2022-09-07 10:44:42,960 [log | ERROR] Internal Server Error: /
Traceback (most recent call last):
  File "/Users/c0mrade/Documents/Zmall/server/env/lib/python3.10/site-packages/django/core/handlers/exception.py", line 55, in inner
    response = get_response(request)
  File "/Users/c0mrade/Documents/Zmall/server/env/lib/python3.10/site-packages/django/utils/deprecation.py", line 138, in __call__
    response = self.process_response(request, response)
  File "/Users/c0mrade/Documents/Zmall/server/env/lib/python3.10/site-packages/django/middleware/common.py", line 114, in process_response
    response.headers["Content-Length"] = str(len(response.content))
  File "/Users/c0mrade/Documents/Zmall/server/env/lib/python3.10/site-packages/django/template/response.py", line 135, in content
    raise ContentNotRenderedError(
django.template.response.ContentNotRenderedError: The response content must be rendered before it can be accessed.
2022-09-07 10:44:43,311 [log | ERROR] Internal Server Error: /favicon.ico
Traceback (most recent call last):
  File "/Users/c0mrade/Documents/Zmall/server/env/lib/python3.10/site-packages/django/core/handlers/exception.py", line 55, in inner
    response = get_response(request)
  File "/Users/c0mrade/Documents/Zmall/server/env/lib/python3.10/site-packages/django/utils/deprecation.py", line 138, in __call__
    response = self.process_response(request, response)
  File "/Users/c0mrade/Documents/Zmall/server/env/lib/python3.10/site-packages/django/middleware/common.py", line 114, in process_response
    response.headers["Content-Length"] = str(len(response.content))
  File "/Users/c0mrade/Documents/Zmall/server/env/lib/python3.10/site-packages/django/template/response.py", line 135, in content
    raise ContentNotRenderedError(
django.template.response.ContentNotRenderedError: The response content must be rendered before it can be accessed.
2022-09-07 10:45:18,171 [autoreload | INFO] Watching for file changes with StatReloader
2022-09-07 10:45:19,523 [log | ERROR] Internal Server Error: /
Traceback (most recent call last):
  File "/Users/c0mrade/Documents/Zmall/server/env/lib/python3.10/site-packages/django/core/handlers/exception.py", line 55, in inner
    response = get_response(request)
  File "/Users/c0mrade/Documents/Zmall/server/config/middleware.py", line 32, in __call__
    raise ValueError("rate limit")
ValueError: rate limit
2022-09-07 10:45:19,566 [log | ERROR] Internal Server Error: /favicon.ico
Traceback (most recent call last):
  File "/Users/c0mrade/Documents/Zmall/server/env/lib/python3.10/site-packages/django/core/handlers/exception.py", line 55, in inner
    response = get_response(request)
  File "/Users/c0mrade/Documents/Zmall/server/config/middleware.py", line 32, in __call__
    raise ValueError("rate limit")
ValueError: rate limit
2022-09-07 10:45:20,272 [log | ERROR] Internal Server Error: /
Traceback (most recent call last):
  File "/Users/c0mrade/Documents/Zmall/server/env/lib/python3.10/site-packages/django/core/handlers/exception.py", line 55, in inner
    response = get_response(request)
  File "/Users/c0mrade/Documents/Zmall/server/config/middleware.py", line 32, in __call__
    raise ValueError("rate limit")
ValueError: rate limit
2022-09-07 10:45:20,447 [log | ERROR] Internal Server Error: /
Traceback (most recent call last):
  File "/Users/c0mrade/Documents/Zmall/server/env/lib/python3.10/site-packages/django/core/handlers/exception.py", line 55, in inner
    response = get_response(request)
  File "/Users/c0mrade/Documents/Zmall/server/config/middleware.py", line 32, in __call__
    raise ValueError("rate limit")
ValueError: rate limit
2022-09-07 10:45:20,580 [log | ERROR] Internal Server Error: /
Traceback (most recent call last):
  File "/Users/c0mrade/Documents/Zmall/server/env/lib/python3.10/site-packages/django/core/handlers/exception.py", line 55, in inner
    response = get_response(request)
  File "/Users/c0mrade/Documents/Zmall/server/config/middleware.py", line 32, in __call__
    raise ValueError("rate limit")
ValueError: rate limit
2022-09-07 10:45:20,632 [log | ERROR] Internal Server Error: /favicon.ico
Traceback (most recent call last):
  File "/Users/c0mrade/Documents/Zmall/server/env/lib/python3.10/site-packages/django/core/handlers/exception.py", line 55, in inner
    response = get_response(request)
  File "/Users/c0mrade/Documents/Zmall/server/config/middleware.py", line 32, in __call__
    raise ValueError("rate limit")
ValueError: rate limit
2022-09-07 10:50:06,586 [autoreload | INFO] Watching for file changes with StatReloader
2022-09-07 10:50:09,736 [log | ERROR] Internal Server Error: /
Traceback (most recent call last):
  File "/Users/c0mrade/Documents/Zmall/server/env/lib/python3.10/site-packages/django/core/handlers/exception.py", line 55, in inner
    response = get_response(request)
  File "/Users/c0mrade/Documents/Zmall/server/config/middleware.py", line 33, in __call__
    if redis.get(client_ip) > 10:
TypeError: '>' not supported between instances of 'bytes' and 'int'
2022-09-07 10:50:09,823 [log | ERROR] Internal Server Error: /favicon.ico
Traceback (most recent call last):
  File "/Users/c0mrade/Documents/Zmall/server/env/lib/python3.10/site-packages/django/core/handlers/exception.py", line 55, in inner
    response = get_response(request)
  File "/Users/c0mrade/Documents/Zmall/server/config/middleware.py", line 33, in __call__
    if redis.get(client_ip) > 10:
TypeError: '>' not supported between instances of 'bytes' and 'int'
2022-09-07 10:50:38,340 [autoreload | INFO] Watching for file changes with StatReloader
2022-09-07 10:50:40,846 [log | WARNING] Not Found: /
2022-09-07 10:50:52,359 [log | WARNING] Not Found: /
2022-09-07 10:50:52,945 [log | WARNING] Not Found: /
2022-09-07 10:50:53,832 [log | WARNING] Not Found: /
2022-09-07 10:50:54,228 [log | WARNING] Not Found: /
2022-09-07 10:50:54,638 [log | WARNING] Not Found: /
2022-09-07 10:50:55,058 [log | WARNING] Not Found: /
2022-09-07 10:50:55,445 [log | WARNING] Not Found: /
2022-09-07 10:50:55,914 [log | ERROR] Internal Server Error: /
Traceback (most recent call last):
  File "/Users/c0mrade/Documents/Zmall/server/env/lib/python3.10/site-packages/django/core/handlers/exception.py", line 55, in inner
    response = get_response(request)
  File "/Users/c0mrade/Documents/Zmall/server/config/middleware.py", line 34, in __call__
    raise ValueError("rate limit")
ValueError: rate limit
2022-09-07 10:50:56,272 [log | ERROR] Internal Server Error: /
Traceback (most recent call last):
  File "/Users/c0mrade/Documents/Zmall/server/env/lib/python3.10/site-packages/django/core/handlers/exception.py", line 55, in inner
    response = get_response(request)
  File "/Users/c0mrade/Documents/Zmall/server/config/middleware.py", line 34, in __call__
    raise ValueError("rate limit")
ValueError: rate limit
2022-09-07 11:33:53,707 [autoreload | INFO] Watching for file changes with StatReloader
2022-09-07 11:34:12,731 [autoreload | INFO] /Users/c0mrade/Documents/Zmall/server/config/urls.py changed, reloading.
2022-09-07 11:34:13,170 [autoreload | INFO] Watching for file changes with StatReloader
2022-09-07 11:34:16,859 [log | ERROR] Internal Server Error: /
Traceback (most recent call last):
  File "/Users/c0mrade/Documents/Zmall/server/env/lib/python3.10/site-packages/django/core/handlers/exception.py", line 55, in inner
    response = get_response(request)
  File "/Users/c0mrade/Documents/Zmall/server/config/middleware.py", line 34, in __call__
    request_count, request_date = str(redis.get(client_ip)).split(',')
ValueError: not enough values to unpack (expected 2, got 1)
2022-09-07 11:34:17,206 [log | ERROR] Internal Server Error: /favicon.ico
Traceback (most recent call last):
  File "/Users/c0mrade/Documents/Zmall/server/env/lib/python3.10/site-packages/django/core/handlers/exception.py", line 55, in inner
    response = get_response(request)
  File "/Users/c0mrade/Documents/Zmall/server/config/middleware.py", line 34, in __call__
    request_count, request_date = str(redis.get(client_ip)).split(',')
ValueError: not enough values to unpack (expected 2, got 1)
2022-09-07 11:34:36,350 [autoreload | INFO] Watching for file changes with StatReloader
2022-09-07 11:34:37,640 [log | ERROR] Internal Server Error: /
Traceback (most recent call last):
  File "/Users/c0mrade/Documents/Zmall/server/env/lib/python3.10/site-packages/django/core/handlers/exception.py", line 55, in inner
    response = get_response(request)
  File "/Users/c0mrade/Documents/Zmall/server/config/middleware.py", line 35, in __call__
    if int(request_count) > 10 and request_date == today:
ValueError: invalid literal for int() with base 10: "b'15'"
2022-09-07 11:34:37,691 [log | ERROR] Internal Server Error: /favicon.ico
Traceback (most recent call last):
  File "/Users/c0mrade/Documents/Zmall/server/env/lib/python3.10/site-packages/django/core/handlers/exception.py", line 55, in inner
    response = get_response(request)
  File "/Users/c0mrade/Documents/Zmall/server/config/middleware.py", line 35, in __call__
    if int(request_count) > 10 and request_date == today:
ValueError: invalid literal for int() with base 10: "b'16'"
2022-09-07 11:35:59,695 [autoreload | INFO] Watching for file changes with StatReloader
2022-09-07 11:36:01,504 [log | WARNING] Not Found: /
2022-09-07 11:36:01,559 [log | WARNING] Not Found: /favicon.ico
2022-09-07 11:36:30,850 [autoreload | INFO] Watching for file changes with StatReloader
2022-09-07 11:36:31,555 [log | ERROR] Internal Server Error: /
Traceback (most recent call last):
  File "/Users/c0mrade/Documents/Zmall/server/env/lib/python3.10/site-packages/django/core/handlers/exception.py", line 55, in inner
    response = get_response(request)
  File "/Users/c0mrade/Documents/Zmall/server/config/middleware.py", line 35, in __call__
    print(int(request_count, base=10), request_date)
ValueError: invalid literal for int() with base 10: "b'19'"
2022-09-07 11:36:31,642 [log | ERROR] Internal Server Error: /favicon.ico
Traceback (most recent call last):
  File "/Users/c0mrade/Documents/Zmall/server/env/lib/python3.10/site-packages/django/core/handlers/exception.py", line 55, in inner
    response = get_response(request)
  File "/Users/c0mrade/Documents/Zmall/server/config/middleware.py", line 35, in __call__
    print(int(request_count, base=10), request_date)
ValueError: invalid literal for int() with base 10: "b'20'"
2022-09-07 11:37:11,792 [autoreload | INFO] Watching for file changes with StatReloader
2022-09-07 11:37:34,496 [autoreload | INFO] Watching for file changes with StatReloader
2022-09-07 11:37:36,499 [log | ERROR] Internal Server Error: /
Traceback (most recent call last):
  File "/Users/c0mrade/Documents/Zmall/server/env/lib/python3.10/site-packages/django/core/handlers/exception.py", line 55, in inner
    response = get_response(request)
  File "/Users/c0mrade/Documents/Zmall/server/config/middleware.py", line 35, in __call__
    print(int(str(request_count)), request_date)
ValueError: invalid literal for int() with base 10: "b'21'"
2022-09-07 11:37:36,576 [log | ERROR] Internal Server Error: /favicon.ico
Traceback (most recent call last):
  File "/Users/c0mrade/Documents/Zmall/server/env/lib/python3.10/site-packages/django/core/handlers/exception.py", line 55, in inner
    response = get_response(request)
  File "/Users/c0mrade/Documents/Zmall/server/config/middleware.py", line 35, in __call__
    print(int(str(request_count)), request_date)
ValueError: invalid literal for int() with base 10: "b'22'"
2022-09-07 11:37:52,928 [autoreload | INFO] Watching for file changes with StatReloader
2022-09-07 11:38:07,961 [autoreload | INFO] Watching for file changes with StatReloader
2022-09-07 11:38:08,314 [log | WARNING] Not Found: /
2022-09-07 11:38:08,359 [log | WARNING] Not Found: /favicon.ico
2022-09-07 11:38:08,506 [log | WARNING] Not Found: /
2022-09-07 11:38:08,693 [log | WARNING] Not Found: /
2022-09-07 11:38:08,878 [log | WARNING] Not Found: /
2022-09-07 17:28:13,571 [autoreload | INFO] Watching for file changes with StatReloader
2022-09-07 17:28:16,061 [log | WARNING] Not Found: /
2022-09-07 17:28:16,365 [log | WARNING] Not Found: /favicon.ico
2022-09-07 17:29:10,962 [autoreload | INFO] /Users/c0mrade/Documents/Zmall/server/config/middleware.py changed, reloading.
2022-09-07 17:29:11,413 [autoreload | INFO] Watching for file changes with StatReloader
2022-09-07 17:29:12,398 [log | WARNING] Not Found: /
2022-09-07 17:29:12,428 [log | WARNING] Not Found: /favicon.ico
2022-09-07 17:29:20,860 [autoreload | INFO] /Users/c0mrade/Documents/Zmall/server/config/middleware.py changed, reloading.
2022-09-07 17:29:21,266 [autoreload | INFO] Watching for file changes with StatReloader
2022-09-07 17:29:21,514 [log | WARNING] Not Found: /
2022-09-07 17:29:21,540 [log | WARNING] Not Found: /favicon.ico
2022-09-07 17:29:21,821 [log | WARNING] Not Found: /
2022-09-07 17:29:22,017 [log | WARNING] Not Found: /
2022-09-07 17:29:27,636 [autoreload | INFO] /Users/c0mrade/Documents/Zmall/server/config/middleware.py changed, reloading.
2022-09-07 17:29:28,016 [autoreload | INFO] Watching for file changes with StatReloader
2022-09-07 17:29:29,939 [log | ERROR] Internal Server Error: /
Traceback (most recent call last):
  File "/Users/c0mrade/Documents/Zmall/server/env/lib/python3.10/site-packages/django/core/handlers/exception.py", line 55, in inner
    response = get_response(request)
  File "/Users/c0mrade/Documents/Zmall/server/config/middleware.py", line 35, in __call__
    print(int(request_count), request_date)
ValueError: invalid literal for int() with base 10: "b'36'"
2022-09-07 17:29:29,988 [log | ERROR] Internal Server Error: /favicon.ico
Traceback (most recent call last):
  File "/Users/c0mrade/Documents/Zmall/server/env/lib/python3.10/site-packages/django/core/handlers/exception.py", line 55, in inner
    response = get_response(request)
  File "/Users/c0mrade/Documents/Zmall/server/config/middleware.py", line 35, in __call__
    print(int(request_count), request_date)
ValueError: invalid literal for int() with base 10: "b'37'"
2022-09-07 17:30:15,522 [autoreload | INFO] Watching for file changes with StatReloader
2022-09-07 17:30:16,565 [log | ERROR] Internal Server Error: /
Traceback (most recent call last):
  File "/Users/c0mrade/Documents/Zmall/server/env/lib/python3.10/site-packages/django/core/handlers/exception.py", line 55, in inner
    response = get_response(request)
  File "/Users/c0mrade/Documents/Zmall/server/config/middleware.py", line 35, in __call__
    print(int(request_count, 2), request_date)
ValueError: invalid literal for int() with base 2: "b'38'"
2022-09-07 17:30:16,638 [log | ERROR] Internal Server Error: /favicon.ico
Traceback (most recent call last):
  File "/Users/c0mrade/Documents/Zmall/server/env/lib/python3.10/site-packages/django/core/handlers/exception.py", line 55, in inner
    response = get_response(request)
  File "/Users/c0mrade/Documents/Zmall/server/config/middleware.py", line 35, in __call__
    print(int(request_count, 2), request_date)
ValueError: invalid literal for int() with base 2: "b'39'"
2022-09-07 17:30:43,876 [autoreload | INFO] /Users/c0mrade/Documents/Zmall/server/config/middleware.py changed, reloading.
2022-09-07 17:30:44,351 [autoreload | INFO] Watching for file changes with StatReloader
2022-09-07 17:30:46,129 [log | WARNING] Not Found: /
2022-09-07 17:30:46,164 [log | WARNING] Not Found: /favicon.ico
2022-09-07 17:30:59,081 [autoreload | INFO] /Users/c0mrade/Documents/Zmall/server/config/middleware.py changed, reloading.
2022-09-07 17:30:59,448 [autoreload | INFO] Watching for file changes with StatReloader
2022-09-07 17:31:00,299 [log | WARNING] Not Found: /
2022-09-07 17:31:00,338 [log | WARNING] Not Found: /favicon.ico
2022-09-07 17:31:04,801 [autoreload | INFO] /Users/c0mrade/Documents/Zmall/server/config/middleware.py changed, reloading.
2022-09-07 17:31:05,122 [autoreload | INFO] Watching for file changes with StatReloader
2022-09-07 17:31:07,219 [log | WARNING] Not Found: /
2022-09-07 17:31:07,249 [log | WARNING] Not Found: /favicon.ico
2022-09-07 17:31:14,670 [autoreload | INFO] /Users/c0mrade/Documents/Zmall/server/config/middleware.py changed, reloading.
2022-09-07 17:31:14,979 [autoreload | INFO] Watching for file changes with StatReloader
2022-09-07 17:31:17,166 [log | WARNING] Not Found: /
2022-09-07 17:31:36,951 [autoreload | INFO] /Users/c0mrade/Documents/Zmall/server/config/middleware.py changed, reloading.
2022-09-07 17:31:37,283 [autoreload | INFO] Watching for file changes with StatReloader
2022-09-07 17:31:59,113 [autoreload | INFO] /Users/c0mrade/Documents/Zmall/server/config/middleware.py changed, reloading.
2022-09-07 17:31:59,559 [autoreload | INFO] Watching for file changes with StatReloader
2022-09-07 17:32:17,742 [log | ERROR] Internal Server Error: /
Traceback (most recent call last):
  File "/Users/c0mrade/Documents/Zmall/server/env/lib/python3.10/site-packages/django/core/handlers/exception.py", line 55, in inner
    response = get_response(request)
  File "/Users/c0mrade/Documents/Zmall/server/config/middleware.py", line 33, in __call__
    redis.incr(client_ip)
  File "/Users/c0mrade/Documents/Zmall/server/env/lib/python3.10/site-packages/redis/commands/core.py", line 1831, in incrby
    return self.execute_command("INCRBY", name, amount)
  File "/Users/c0mrade/Documents/Zmall/server/env/lib/python3.10/site-packages/redis/client.py", line 1238, in execute_command
    return conn.retry.call_with_retry(
  File "/Users/c0mrade/Documents/Zmall/server/env/lib/python3.10/site-packages/redis/retry.py", line 46, in call_with_retry
    return do()
  File "/Users/c0mrade/Documents/Zmall/server/env/lib/python3.10/site-packages/redis/client.py", line 1239, in <lambda>
    lambda: self._send_command_parse_response(
  File "/Users/c0mrade/Documents/Zmall/server/env/lib/python3.10/site-packages/redis/client.py", line 1215, in _send_command_parse_response
    return self.parse_response(conn, command_name, **options)
  File "/Users/c0mrade/Documents/Zmall/server/env/lib/python3.10/site-packages/redis/client.py", line 1254, in parse_response
    response = connection.read_response()
  File "/Users/c0mrade/Documents/Zmall/server/env/lib/python3.10/site-packages/redis/connection.py", line 839, in read_response
    raise response
redis.exceptions.ResponseError: value is not an integer or out of range
2022-09-07 17:32:17,831 [log | ERROR] Internal Server Error: /favicon.ico
Traceback (most recent call last):
  File "/Users/c0mrade/Documents/Zmall/server/env/lib/python3.10/site-packages/django/core/handlers/exception.py", line 55, in inner
    response = get_response(request)
  File "/Users/c0mrade/Documents/Zmall/server/config/middleware.py", line 33, in __call__
    redis.incr(client_ip)
  File "/Users/c0mrade/Documents/Zmall/server/env/lib/python3.10/site-packages/redis/commands/core.py", line 1831, in incrby
    return self.execute_command("INCRBY", name, amount)
  File "/Users/c0mrade/Documents/Zmall/server/env/lib/python3.10/site-packages/redis/client.py", line 1238, in execute_command
    return conn.retry.call_with_retry(
  File "/Users/c0mrade/Documents/Zmall/server/env/lib/python3.10/site-packages/redis/retry.py", line 46, in call_with_retry
    return do()
  File "/Users/c0mrade/Documents/Zmall/server/env/lib/python3.10/site-packages/redis/client.py", line 1239, in <lambda>
    lambda: self._send_command_parse_response(
  File "/Users/c0mrade/Documents/Zmall/server/env/lib/python3.10/site-packages/redis/client.py", line 1215, in _send_command_parse_response
    return self.parse_response(conn, command_name, **options)
  File "/Users/c0mrade/Documents/Zmall/server/env/lib/python3.10/site-packages/redis/client.py", line 1254, in parse_response
    response = connection.read_response()
  File "/Users/c0mrade/Documents/Zmall/server/env/lib/python3.10/site-packages/redis/connection.py", line 839, in read_response
    raise response
redis.exceptions.ResponseError: value is not an integer or out of range
2022-09-07 17:32:30,161 [autoreload | INFO] /Users/c0mrade/Documents/Zmall/server/config/middleware.py changed, reloading.
2022-09-07 17:32:30,589 [autoreload | INFO] Watching for file changes with StatReloader
2022-09-07 17:32:31,171 [log | ERROR] Internal Server Error: /
Traceback (most recent call last):
  File "/Users/c0mrade/Documents/Zmall/server/env/lib/python3.10/site-packages/django/core/handlers/exception.py", line 55, in inner
    response = get_response(request)
  File "/Users/c0mrade/Documents/Zmall/server/config/middleware.py", line 33, in __call__
    redis.incr(client_ip)
  File "/Users/c0mrade/Documents/Zmall/server/env/lib/python3.10/site-packages/redis/commands/core.py", line 1831, in incrby
    return self.execute_command("INCRBY", name, amount)
  File "/Users/c0mrade/Documents/Zmall/server/env/lib/python3.10/site-packages/redis/client.py", line 1238, in execute_command
    return conn.retry.call_with_retry(
  File "/Users/c0mrade/Documents/Zmall/server/env/lib/python3.10/site-packages/redis/retry.py", line 46, in call_with_retry
    return do()
  File "/Users/c0mrade/Documents/Zmall/server/env/lib/python3.10/site-packages/redis/client.py", line 1239, in <lambda>
    lambda: self._send_command_parse_response(
  File "/Users/c0mrade/Documents/Zmall/server/env/lib/python3.10/site-packages/redis/client.py", line 1215, in _send_command_parse_response
    return self.parse_response(conn, command_name, **options)
  File "/Users/c0mrade/Documents/Zmall/server/env/lib/python3.10/site-packages/redis/client.py", line 1254, in parse_response
    response = connection.read_response()
  File "/Users/c0mrade/Documents/Zmall/server/env/lib/python3.10/site-packages/redis/connection.py", line 839, in read_response
    raise response
redis.exceptions.ResponseError: value is not an integer or out of range
2022-09-07 17:32:31,232 [log | ERROR] Internal Server Error: /favicon.ico
Traceback (most recent call last):
  File "/Users/c0mrade/Documents/Zmall/server/env/lib/python3.10/site-packages/django/core/handlers/exception.py", line 55, in inner
    response = get_response(request)
  File "/Users/c0mrade/Documents/Zmall/server/config/middleware.py", line 33, in __call__
    redis.incr(client_ip)
  File "/Users/c0mrade/Documents/Zmall/server/env/lib/python3.10/site-packages/redis/commands/core.py", line 1831, in incrby
    return self.execute_command("INCRBY", name, amount)
  File "/Users/c0mrade/Documents/Zmall/server/env/lib/python3.10/site-packages/redis/client.py", line 1238, in execute_command
    return conn.retry.call_with_retry(
  File "/Users/c0mrade/Documents/Zmall/server/env/lib/python3.10/site-packages/redis/retry.py", line 46, in call_with_retry
    return do()
  File "/Users/c0mrade/Documents/Zmall/server/env/lib/python3.10/site-packages/redis/client.py", line 1239, in <lambda>
    lambda: self._send_command_parse_response(
  File "/Users/c0mrade/Documents/Zmall/server/env/lib/python3.10/site-packages/redis/client.py", line 1215, in _send_command_parse_response
    return self.parse_response(conn, command_name, **options)
  File "/Users/c0mrade/Documents/Zmall/server/env/lib/python3.10/site-packages/redis/client.py", line 1254, in parse_response
    response = connection.read_response()
  File "/Users/c0mrade/Documents/Zmall/server/env/lib/python3.10/site-packages/redis/connection.py", line 839, in read_response
    raise response
redis.exceptions.ResponseError: value is not an integer or out of range
2022-09-07 17:32:50,102 [autoreload | INFO] Watching for file changes with StatReloader
2022-09-07 17:32:51,557 [log | ERROR] Internal Server Error: /
Traceback (most recent call last):
  File "/Users/c0mrade/Documents/Zmall/server/env/lib/python3.10/site-packages/django/core/handlers/exception.py", line 55, in inner
    response = get_response(request)
  File "/Users/c0mrade/Documents/Zmall/server/config/middleware.py", line 33, in __call__
    redis.incr(client_ip)
  File "/Users/c0mrade/Documents/Zmall/server/env/lib/python3.10/site-packages/redis/commands/core.py", line 1831, in incrby
    return self.execute_command("INCRBY", name, amount)
  File "/Users/c0mrade/Documents/Zmall/server/env/lib/python3.10/site-packages/redis/client.py", line 1238, in execute_command
    return conn.retry.call_with_retry(
  File "/Users/c0mrade/Documents/Zmall/server/env/lib/python3.10/site-packages/redis/retry.py", line 46, in call_with_retry
    return do()
  File "/Users/c0mrade/Documents/Zmall/server/env/lib/python3.10/site-packages/redis/client.py", line 1239, in <lambda>
    lambda: self._send_command_parse_response(
  File "/Users/c0mrade/Documents/Zmall/server/env/lib/python3.10/site-packages/redis/client.py", line 1215, in _send_command_parse_response
    return self.parse_response(conn, command_name, **options)
  File "/Users/c0mrade/Documents/Zmall/server/env/lib/python3.10/site-packages/redis/client.py", line 1254, in parse_response
    response = connection.read_response()
  File "/Users/c0mrade/Documents/Zmall/server/env/lib/python3.10/site-packages/redis/connection.py", line 839, in read_response
    raise response
redis.exceptions.ResponseError: value is not an integer or out of range
2022-09-07 17:32:51,630 [log | ERROR] Internal Server Error: /favicon.ico
Traceback (most recent call last):
  File "/Users/c0mrade/Documents/Zmall/server/env/lib/python3.10/site-packages/django/core/handlers/exception.py", line 55, in inner
    response = get_response(request)
  File "/Users/c0mrade/Documents/Zmall/server/config/middleware.py", line 33, in __call__
    redis.incr(client_ip)
  File "/Users/c0mrade/Documents/Zmall/server/env/lib/python3.10/site-packages/redis/commands/core.py", line 1831, in incrby
    return self.execute_command("INCRBY", name, amount)
  File "/Users/c0mrade/Documents/Zmall/server/env/lib/python3.10/site-packages/redis/client.py", line 1238, in execute_command
    return conn.retry.call_with_retry(
  File "/Users/c0mrade/Documents/Zmall/server/env/lib/python3.10/site-packages/redis/retry.py", line 46, in call_with_retry
    return do()
  File "/Users/c0mrade/Documents/Zmall/server/env/lib/python3.10/site-packages/redis/client.py", line 1239, in <lambda>
    lambda: self._send_command_parse_response(
  File "/Users/c0mrade/Documents/Zmall/server/env/lib/python3.10/site-packages/redis/client.py", line 1215, in _send_command_parse_response
    return self.parse_response(conn, command_name, **options)
  File "/Users/c0mrade/Documents/Zmall/server/env/lib/python3.10/site-packages/redis/client.py", line 1254, in parse_response
    response = connection.read_response()
  File "/Users/c0mrade/Documents/Zmall/server/env/lib/python3.10/site-packages/redis/connection.py", line 839, in read_response
    raise response
redis.exceptions.ResponseError: value is not an integer or out of range
2022-09-07 17:33:03,855 [autoreload | INFO] /Users/c0mrade/Documents/Zmall/server/config/middleware.py changed, reloading.
2022-09-07 17:33:04,273 [autoreload | INFO] Watching for file changes with StatReloader
2022-09-07 17:33:04,948 [log | ERROR] Internal Server Error: /
Traceback (most recent call last):
  File "/Users/c0mrade/Documents/Zmall/server/env/lib/python3.10/site-packages/django/core/handlers/exception.py", line 55, in inner
    response = get_response(request)
  File "/Users/c0mrade/Documents/Zmall/server/config/middleware.py", line 33, in __call__
    redis.incr(client_ip)
  File "/Users/c0mrade/Documents/Zmall/server/env/lib/python3.10/site-packages/redis/commands/core.py", line 1831, in incrby
    return self.execute_command("INCRBY", name, amount)
  File "/Users/c0mrade/Documents/Zmall/server/env/lib/python3.10/site-packages/redis/client.py", line 1238, in execute_command
    return conn.retry.call_with_retry(
  File "/Users/c0mrade/Documents/Zmall/server/env/lib/python3.10/site-packages/redis/retry.py", line 46, in call_with_retry
    return do()
  File "/Users/c0mrade/Documents/Zmall/server/env/lib/python3.10/site-packages/redis/client.py", line 1239, in <lambda>
    lambda: self._send_command_parse_response(
  File "/Users/c0mrade/Documents/Zmall/server/env/lib/python3.10/site-packages/redis/client.py", line 1215, in _send_command_parse_response
    return self.parse_response(conn, command_name, **options)
  File "/Users/c0mrade/Documents/Zmall/server/env/lib/python3.10/site-packages/redis/client.py", line 1254, in parse_response
    response = connection.read_response()
  File "/Users/c0mrade/Documents/Zmall/server/env/lib/python3.10/site-packages/redis/connection.py", line 839, in read_response
    raise response
redis.exceptions.ResponseError: value is not an integer or out of range
2022-09-07 17:33:05,022 [log | ERROR] Internal Server Error: /favicon.ico
Traceback (most recent call last):
  File "/Users/c0mrade/Documents/Zmall/server/env/lib/python3.10/site-packages/django/core/handlers/exception.py", line 55, in inner
    response = get_response(request)
  File "/Users/c0mrade/Documents/Zmall/server/config/middleware.py", line 33, in __call__
    redis.incr(client_ip)
  File "/Users/c0mrade/Documents/Zmall/server/env/lib/python3.10/site-packages/redis/commands/core.py", line 1831, in incrby
    return self.execute_command("INCRBY", name, amount)
  File "/Users/c0mrade/Documents/Zmall/server/env/lib/python3.10/site-packages/redis/client.py", line 1238, in execute_command
    return conn.retry.call_with_retry(
  File "/Users/c0mrade/Documents/Zmall/server/env/lib/python3.10/site-packages/redis/retry.py", line 46, in call_with_retry
    return do()
  File "/Users/c0mrade/Documents/Zmall/server/env/lib/python3.10/site-packages/redis/client.py", line 1239, in <lambda>
    lambda: self._send_command_parse_response(
  File "/Users/c0mrade/Documents/Zmall/server/env/lib/python3.10/site-packages/redis/client.py", line 1215, in _send_command_parse_response
    return self.parse_response(conn, command_name, **options)
  File "/Users/c0mrade/Documents/Zmall/server/env/lib/python3.10/site-packages/redis/client.py", line 1254, in parse_response
    response = connection.read_response()
  File "/Users/c0mrade/Documents/Zmall/server/env/lib/python3.10/site-packages/redis/connection.py", line 839, in read_response
    raise response
redis.exceptions.ResponseError: value is not an integer or out of range
2022-09-07 17:34:59,691 [autoreload | INFO] /Users/c0mrade/Documents/Zmall/server/config/middleware.py changed, reloading.
2022-09-07 17:35:00,174 [autoreload | INFO] Watching for file changes with StatReloader
2022-09-07 17:35:06,599 [autoreload | INFO] /Users/c0mrade/Documents/Zmall/server/config/middleware.py changed, reloading.
2022-09-07 17:35:07,007 [autoreload | INFO] Watching for file changes with StatReloader
2022-09-07 17:35:07,200 [log | ERROR] Internal Server Error: /
Traceback (most recent call last):
  File "/Users/c0mrade/Documents/Zmall/server/env/lib/python3.10/site-packages/django/core/handlers/exception.py", line 55, in inner
    response = get_response(request)
  File "/Users/c0mrade/Documents/Zmall/server/config/middleware.py", line 34, in __call__
    redis.mset({client_ip: f"{int(request_count) + 1},{today}"})
ValueError: invalid literal for int() with base 10: "b'0"
2022-09-07 17:35:07,267 [log | ERROR] Internal Server Error: /favicon.ico
Traceback (most recent call last):
  File "/Users/c0mrade/Documents/Zmall/server/env/lib/python3.10/site-packages/django/core/handlers/exception.py", line 55, in inner
    response = get_response(request)
  File "/Users/c0mrade/Documents/Zmall/server/config/middleware.py", line 34, in __call__
    redis.mset({client_ip: f"{int(request_count) + 1},{today}"})
ValueError: invalid literal for int() with base 10: "b'0"
2022-09-07 17:35:17,541 [autoreload | INFO] /Users/c0mrade/Documents/Zmall/server/config/middleware.py changed, reloading.
2022-09-07 17:35:17,929 [autoreload | INFO] Watching for file changes with StatReloader
2022-09-07 17:35:19,907 [log | ERROR] Internal Server Error: /
Traceback (most recent call last):
  File "/Users/c0mrade/Documents/Zmall/server/env/lib/python3.10/site-packages/django/core/handlers/exception.py", line 55, in inner
    response = get_response(request)
  File "/Users/c0mrade/Documents/Zmall/server/config/middleware.py", line 34, in __call__
    redis.mset({client_ip: f"{int(request_count[2:-1]) + 1},{today}"})
ValueError: invalid literal for int() with base 10: ''
2022-09-07 17:35:19,953 [log | ERROR] Internal Server Error: /favicon.ico
Traceback (most recent call last):
  File "/Users/c0mrade/Documents/Zmall/server/env/lib/python3.10/site-packages/django/core/handlers/exception.py", line 55, in inner
    response = get_response(request)
  File "/Users/c0mrade/Documents/Zmall/server/config/middleware.py", line 34, in __call__
    redis.mset({client_ip: f"{int(request_count[2:-1]) + 1},{today}"})
ValueError: invalid literal for int() with base 10: ''
2022-09-07 17:35:20,240 [autoreload | INFO] /Users/c0mrade/Documents/Zmall/server/config/middleware.py changed, reloading.
2022-09-07 17:35:20,541 [autoreload | INFO] Watching for file changes with StatReloader
2022-09-07 17:35:27,951 [autoreload | INFO] /Users/c0mrade/Documents/Zmall/server/config/middleware.py changed, reloading.
2022-09-07 17:35:28,283 [autoreload | INFO] Watching for file changes with StatReloader
2022-09-07 17:35:28,543 [log | ERROR] Internal Server Error: /
Traceback (most recent call last):
  File "/Users/c0mrade/Documents/Zmall/server/env/lib/python3.10/site-packages/django/core/handlers/exception.py", line 55, in inner
    response = get_response(request)
  File "/Users/c0mrade/Documents/Zmall/server/config/middleware.py", line 34, in __call__
    redis.mset({client_ip: f"{int(request_count[1:-1]) + 1},{today}"})
ValueError: invalid literal for int() with base 10: "'"
2022-09-07 17:35:28,608 [log | ERROR] Internal Server Error: /favicon.ico
Traceback (most recent call last):
  File "/Users/c0mrade/Documents/Zmall/server/env/lib/python3.10/site-packages/django/core/handlers/exception.py", line 55, in inner
    response = get_response(request)
  File "/Users/c0mrade/Documents/Zmall/server/config/middleware.py", line 34, in __call__
    redis.mset({client_ip: f"{int(request_count[1:-1]) + 1},{today}"})
ValueError: invalid literal for int() with base 10: "'"
2022-09-07 17:35:29,106 [log | ERROR] Internal Server Error: /
Traceback (most recent call last):
  File "/Users/c0mrade/Documents/Zmall/server/env/lib/python3.10/site-packages/django/core/handlers/exception.py", line 55, in inner
    response = get_response(request)
  File "/Users/c0mrade/Documents/Zmall/server/config/middleware.py", line 34, in __call__
    redis.mset({client_ip: f"{int(request_count[1:-1]) + 1},{today}"})
ValueError: invalid literal for int() with base 10: "'"
2022-09-07 17:35:29,173 [log | ERROR] Internal Server Error: /favicon.ico
Traceback (most recent call last):
  File "/Users/c0mrade/Documents/Zmall/server/env/lib/python3.10/site-packages/django/core/handlers/exception.py", line 55, in inner
    response = get_response(request)
  File "/Users/c0mrade/Documents/Zmall/server/config/middleware.py", line 34, in __call__
    redis.mset({client_ip: f"{int(request_count[1:-1]) + 1},{today}"})
ValueError: invalid literal for int() with base 10: "'"
2022-09-07 17:35:57,353 [autoreload | INFO] /Users/c0mrade/Documents/Zmall/server/config/middleware.py changed, reloading.
2022-09-07 17:35:57,836 [autoreload | INFO] Watching for file changes with StatReloader
2022-09-07 17:36:04,273 [autoreload | INFO] /Users/c0mrade/Documents/Zmall/server/config/middleware.py changed, reloading.
2022-09-07 17:36:04,589 [autoreload | INFO] Watching for file changes with StatReloader
2022-09-07 17:36:04,808 [log | ERROR] Internal Server Error: /
Traceback (most recent call last):
  File "/Users/c0mrade/Documents/Zmall/server/env/lib/python3.10/site-packages/django/core/handlers/exception.py", line 55, in inner
    response = get_response(request)
  File "/Users/c0mrade/Documents/Zmall/server/config/middleware.py", line 35, in __call__
    redis.mset({client_ip: f"{int(str(request_count[1:-1])) + 1},{today}"})
ValueError: invalid literal for int() with base 10: "'"
2022-09-07 17:36:06,183 [log | ERROR] Internal Server Error: /
Traceback (most recent call last):
  File "/Users/c0mrade/Documents/Zmall/server/env/lib/python3.10/site-packages/django/core/handlers/exception.py", line 55, in inner
    response = get_response(request)
  File "/Users/c0mrade/Documents/Zmall/server/config/middleware.py", line 35, in __call__
    redis.mset({client_ip: f"{int(str(request_count[1:-1])) + 1},{today}"})
ValueError: invalid literal for int() with base 10: "'"
2022-09-07 17:36:06,264 [log | ERROR] Internal Server Error: /favicon.ico
Traceback (most recent call last):
  File "/Users/c0mrade/Documents/Zmall/server/env/lib/python3.10/site-packages/django/core/handlers/exception.py", line 55, in inner
    response = get_response(request)
  File "/Users/c0mrade/Documents/Zmall/server/config/middleware.py", line 35, in __call__
    redis.mset({client_ip: f"{int(str(request_count[1:-1])) + 1},{today}"})
ValueError: invalid literal for int() with base 10: "'"
2022-09-07 17:36:13,932 [log | ERROR] Internal Server Error: /
Traceback (most recent call last):
  File "/Users/c0mrade/Documents/Zmall/server/env/lib/python3.10/site-packages/django/core/handlers/exception.py", line 55, in inner
    response = get_response(request)
  File "/Users/c0mrade/Documents/Zmall/server/config/middleware.py", line 35, in __call__
    # redis.mset({client_ip: f"{int(str(request_count[1:-1])) + 1},{today}"})
ValueError: invalid literal for int() with base 10: "'"
2022-09-07 17:36:14,149 [autoreload | INFO] /Users/c0mrade/Documents/Zmall/server/config/middleware.py changed, reloading.
2022-09-07 17:36:14,613 [autoreload | INFO] Watching for file changes with StatReloader
2022-09-07 17:36:14,864 [log | WARNING] Not Found: /
2022-09-07 17:36:15,023 [log | WARNING] Not Found: /
2022-09-07 17:36:15,069 [log | WARNING] Not Found: /favicon.ico
2022-09-07 17:36:20,003 [autoreload | INFO] /Users/c0mrade/Documents/Zmall/server/config/middleware.py changed, reloading.
2022-09-07 17:36:20,392 [autoreload | INFO] Watching for file changes with StatReloader
2022-09-07 17:36:20,753 [log | WARNING] Not Found: /
2022-09-07 17:36:20,917 [log | WARNING] Not Found: /
2022-09-07 17:36:33,027 [autoreload | INFO] /Users/c0mrade/Documents/Zmall/server/config/middleware.py changed, reloading.
2022-09-07 17:36:33,449 [autoreload | INFO] Watching for file changes with StatReloader
2022-09-07 17:36:34,326 [log | WARNING] Not Found: /
2022-09-07 17:36:34,358 [log | WARNING] Not Found: /favicon.ico
2022-09-07 17:36:37,757 [autoreload | INFO] /Users/c0mrade/Documents/Zmall/server/config/middleware.py changed, reloading.
2022-09-07 17:36:38,104 [autoreload | INFO] Watching for file changes with StatReloader
2022-09-07 17:36:38,318 [log | WARNING] Not Found: /
2022-09-07 17:36:38,347 [log | WARNING] Not Found: /favicon.ico
2022-09-07 17:36:38,636 [log | WARNING] Not Found: /
2022-09-07 17:37:06,203 [autoreload | INFO] /Users/c0mrade/Documents/Zmall/server/config/middleware.py changed, reloading.
2022-09-07 17:37:06,642 [autoreload | INFO] Watching for file changes with StatReloader
2022-09-07 17:37:12,052 [autoreload | INFO] /Users/c0mrade/Documents/Zmall/server/config/middleware.py changed, reloading.
2022-09-07 17:37:12,438 [autoreload | INFO] Watching for file changes with StatReloader
2022-09-07 17:37:22,970 [autoreload | INFO] /Users/c0mrade/Documents/Zmall/server/config/middleware.py changed, reloading.
2022-09-07 17:37:23,342 [autoreload | INFO] Watching for file changes with StatReloader
2022-09-07 17:37:38,948 [autoreload | INFO] Watching for file changes with StatReloader
2022-09-07 17:37:40,206 [log | WARNING] Not Found: /
2022-09-07 17:37:40,232 [log | WARNING] Not Found: /favicon.ico
2022-09-07 17:37:50,590 [autoreload | INFO] /Users/c0mrade/Documents/Zmall/server/config/middleware.py changed, reloading.
2022-09-07 17:37:50,933 [autoreload | INFO] Watching for file changes with StatReloader
2022-09-07 17:37:51,976 [log | WARNING] Not Found: /
2022-09-07 17:37:52,017 [log | WARNING] Not Found: /favicon.ico
2022-09-07 17:38:06,640 [autoreload | INFO] /Users/c0mrade/Documents/Zmall/server/config/middleware.py changed, reloading.
2022-09-07 17:38:06,978 [autoreload | INFO] Watching for file changes with StatReloader
2022-09-07 17:38:09,217 [autoreload | INFO] /Users/c0mrade/Documents/Zmall/server/config/middleware.py changed, reloading.
2022-09-07 17:38:09,527 [autoreload | INFO] Watching for file changes with StatReloader
2022-09-07 17:38:14,847 [autoreload | INFO] /Users/c0mrade/Documents/Zmall/server/config/middleware.py changed, reloading.
2022-09-07 17:38:15,184 [autoreload | INFO] Watching for file changes with StatReloader
2022-09-07 17:38:15,964 [log | WARNING] Not Found: /
2022-09-07 17:38:15,995 [log | WARNING] Not Found: /favicon.ico
2022-09-07 17:39:21,497 [autoreload | INFO] /Users/c0mrade/Documents/Zmall/server/config/middleware.py changed, reloading.
2022-09-07 17:39:21,962 [autoreload | INFO] Watching for file changes with StatReloader
2022-09-07 17:39:22,677 [log | WARNING] Not Found: /
2022-09-07 17:39:22,715 [log | WARNING] Not Found: /favicon.ico
2022-09-07 17:39:29,411 [autoreload | INFO] /Users/c0mrade/Documents/Zmall/server/config/middleware.py changed, reloading.
2022-09-07 17:39:29,837 [autoreload | INFO] Watching for file changes with StatReloader
2022-09-07 17:39:30,941 [log | WARNING] Not Found: /
2022-09-07 17:39:30,988 [log | WARNING] Not Found: /favicon.ico
2022-09-07 17:39:31,362 [log | WARNING] Not Found: /
2022-09-07 17:39:34,233 [autoreload | INFO] /Users/c0mrade/Documents/Zmall/server/config/middleware.py changed, reloading.
2022-09-07 17:39:34,543 [autoreload | INFO] Watching for file changes with StatReloader
2022-09-07 17:40:04,810 [autoreload | INFO] /Users/c0mrade/Documents/Zmall/server/config/middleware.py changed, reloading.
2022-09-07 17:40:05,214 [autoreload | INFO] Watching for file changes with StatReloader
2022-09-07 17:40:26,144 [autoreload | INFO] /Users/c0mrade/Documents/Zmall/server/config/middleware.py changed, reloading.
2022-09-07 17:40:26,492 [autoreload | INFO] Watching for file changes with StatReloader
2022-09-07 17:40:42,204 [autoreload | INFO] /Users/c0mrade/Documents/Zmall/server/config/middleware.py changed, reloading.
2022-09-07 17:40:42,529 [autoreload | INFO] Watching for file changes with StatReloader
2022-09-07 17:41:00,037 [log | ERROR] Internal Server Error: /
Traceback (most recent call last):
  File "/Users/c0mrade/Documents/Zmall/server/env/lib/python3.10/site-packages/django/core/handlers/exception.py", line 55, in inner
    response = get_response(request)
  File "/Users/c0mrade/Documents/Zmall/server/config/middleware.py", line 38, in __call__
    redis.mset({client_ip: f"{int(request_count[2:]) + 1},{request_date}"})
TypeError: 'int' object is not subscriptable
2022-09-07 17:41:32,614 [autoreload | INFO] /Users/c0mrade/Documents/Zmall/server/config/middleware.py changed, reloading.
2022-09-07 17:41:33,092 [autoreload | INFO] Watching for file changes with StatReloader
2022-09-07 17:41:33,812 [log | ERROR] Internal Server Error: /
Traceback (most recent call last):
  File "/Users/c0mrade/Documents/Zmall/server/env/lib/python3.10/site-packages/django/core/handlers/exception.py", line 55, in inner
    response = get_response(request)
  File "/Users/c0mrade/Documents/Zmall/server/config/middleware.py", line 40, in __call__
    raise ValueError("rate limit")
ValueError: rate limit
2022-09-07 17:41:33,845 [log | WARNING] Not Found: /favicon.ico
2022-09-07 17:41:34,051 [log | WARNING] Not Found: /
2022-09-07 17:41:34,268 [log | WARNING] Not Found: /
2022-09-07 17:41:38,701 [log | WARNING] Not Found: /
2022-09-07 17:41:38,746 [log | WARNING] Not Found: /favicon.ico
2022-09-07 17:41:39,068 [log | WARNING] Not Found: /
2022-09-07 17:41:39,282 [log | WARNING] Not Found: /
2022-09-07 17:41:39,443 [log | WARNING] Not Found: /
2022-09-07 17:41:39,611 [log | WARNING] Not Found: /
2022-09-07 17:41:39,806 [log | WARNING] Not Found: /
2022-09-07 17:41:39,847 [log | WARNING] Not Found: /favicon.ico
2022-09-07 17:41:39,973 [log | WARNING] Not Found: /
2022-09-07 17:41:40,164 [log | WARNING] Not Found: /
2022-09-07 17:41:40,341 [log | WARNING] Not Found: /
2022-09-07 17:41:40,504 [log | WARNING] Not Found: /
2022-09-07 17:41:40,672 [log | WARNING] Not Found: /
2022-09-07 17:41:40,853 [log | WARNING] Not Found: /
2022-09-07 17:41:53,025 [autoreload | INFO] /Users/c0mrade/Documents/Zmall/server/config/middleware.py changed, reloading.
2022-09-07 17:41:53,478 [autoreload | INFO] Watching for file changes with StatReloader
2022-09-07 17:41:53,919 [log | WARNING] Not Found: /
2022-09-07 17:42:02,981 [autoreload | INFO] /Users/c0mrade/Documents/Zmall/server/config/middleware.py changed, reloading.
2022-09-07 17:42:03,435 [autoreload | INFO] Watching for file changes with StatReloader
2022-09-07 17:42:03,616 [log | WARNING] Not Found: /
2022-09-07 17:42:03,653 [log | WARNING] Not Found: /favicon.ico
2022-09-07 17:42:03,820 [log | WARNING] Not Found: /
2022-09-07 17:42:04,001 [log | WARNING] Not Found: /
2022-09-07 17:42:04,243 [log | WARNING] Not Found: /
2022-09-07 17:42:04,405 [log | WARNING] Not Found: /favicon.ico
2022-09-07 17:42:04,415 [log | WARNING] Not Found: /
2022-09-07 17:42:04,647 [log | WARNING] Not Found: /
2022-09-07 17:42:04,906 [log | WARNING] Not Found: /
2022-09-07 17:42:17,284 [autoreload | INFO] /Users/c0mrade/Documents/Zmall/server/config/middleware.py changed, reloading.
2022-09-07 17:42:17,709 [autoreload | INFO] Watching for file changes with StatReloader
2022-09-07 17:42:22,059 [autoreload | INFO] /Users/c0mrade/Documents/Zmall/server/config/middleware.py changed, reloading.
2022-09-07 17:42:22,478 [autoreload | INFO] Watching for file changes with StatReloader
2022-09-07 17:42:33,246 [autoreload | INFO] Watching for file changes with StatReloader
2022-09-07 17:43:29,615 [autoreload | INFO] Watching for file changes with StatReloader
2022-09-07 17:44:21,288 [autoreload | INFO] /Users/c0mrade/Documents/Zmall/server/config/middleware.py changed, reloading.
2022-09-07 17:44:21,816 [autoreload | INFO] Watching for file changes with StatReloader
2022-09-07 17:44:22,209 [log | WARNING] Not Found: /
2022-09-07 17:44:22,262 [log | WARNING] Not Found: /favicon.ico
2022-09-07 17:44:28,287 [autoreload | INFO] /Users/c0mrade/Documents/Zmall/server/config/middleware.py changed, reloading.
2022-09-07 17:44:28,615 [autoreload | INFO] Watching for file changes with StatReloader
2022-09-07 17:44:28,780 [log | WARNING] Not Found: /
2022-09-07 17:44:28,812 [log | WARNING] Not Found: /favicon.ico
2022-09-07 17:44:44,341 [autoreload | INFO] /Users/c0mrade/Documents/Zmall/server/config/middleware.py changed, reloading.
2022-09-07 17:44:44,671 [autoreload | INFO] Watching for file changes with StatReloader
2022-09-07 17:44:45,913 [log | WARNING] Not Found: /
2022-09-07 17:44:45,936 [log | WARNING] Not Found: /favicon.ico
2022-09-07 17:45:19,155 [autoreload | INFO] /Users/c0mrade/Documents/Zmall/server/config/middleware.py changed, reloading.
2022-09-07 17:45:19,608 [autoreload | INFO] Watching for file changes with StatReloader
2022-09-07 17:45:22,360 [log | WARNING] Not Found: /
2022-09-07 17:45:22,406 [log | WARNING] Not Found: /favicon.ico
2022-09-07 17:45:28,950 [log | WARNING] Not Found: /
2022-09-07 17:45:40,714 [autoreload | INFO] /Users/c0mrade/Documents/Zmall/server/config/middleware.py changed, reloading.
2022-09-07 17:45:41,167 [autoreload | INFO] Watching for file changes with StatReloader
2022-09-07 17:45:43,012 [log | WARNING] Not Found: /
2022-09-07 17:45:43,051 [log | WARNING] Not Found: /favicon.ico
2022-09-07 17:45:45,349 [log | WARNING] Not Found: /
2022-09-07 17:45:45,552 [log | WARNING] Not Found: /
2022-09-07 17:45:45,761 [log | WARNING] Not Found: /
2022-09-07 17:46:11,507 [autoreload | INFO] /Users/c0mrade/Documents/Zmall/server/config/middleware.py changed, reloading.
2022-09-07 17:46:11,951 [autoreload | INFO] Watching for file changes with StatReloader
2022-09-07 17:46:17,368 [autoreload | INFO] /Users/c0mrade/Documents/Zmall/server/config/middleware.py changed, reloading.
2022-09-07 17:46:17,842 [autoreload | INFO] Watching for file changes with StatReloader
2022-09-07 17:46:19,772 [log | WARNING] Not Found: /
2022-09-07 17:46:19,821 [log | WARNING] Not Found: /favicon.ico
2022-09-07 17:46:30,624 [autoreload | INFO] /Users/c0mrade/Documents/Zmall/server/config/middleware.py changed, reloading.
2022-09-07 17:46:31,066 [autoreload | INFO] Watching for file changes with StatReloader
2022-09-07 17:46:33,247 [log | WARNING] Not Found: /
2022-09-07 17:46:33,290 [log | WARNING] Not Found: /favicon.ico
2022-09-07 17:46:44,800 [autoreload | INFO] /Users/c0mrade/Documents/Zmall/server/config/middleware.py changed, reloading.
2022-09-07 17:46:45,222 [autoreload | INFO] Watching for file changes with StatReloader
2022-09-07 17:46:48,293 [log | WARNING] Not Found: /
2022-09-07 17:46:51,738 [autoreload | INFO] /Users/c0mrade/Documents/Zmall/server/config/middleware.py changed, reloading.
2022-09-07 17:46:52,067 [autoreload | INFO] Watching for file changes with StatReloader
2022-09-07 17:46:53,810 [log | ERROR] Internal Server Error: /
Traceback (most recent call last):
  File "/Users/c0mrade/Documents/Zmall/server/env/lib/python3.10/site-packages/django/core/handlers/exception.py", line 55, in inner
    response = get_response(request)
  File "/Users/c0mrade/Documents/Zmall/server/config/middleware.py", line 39, in __call__
    redis.set({client_ip: f"{int(request_count[2:]) + 1},{request_date}"})
TypeError: BasicKeyCommands.set() missing 1 required positional argument: 'value'
2022-09-07 17:46:53,866 [log | ERROR] Internal Server Error: /favicon.ico
Traceback (most recent call last):
  File "/Users/c0mrade/Documents/Zmall/server/env/lib/python3.10/site-packages/django/core/handlers/exception.py", line 55, in inner
    response = get_response(request)
  File "/Users/c0mrade/Documents/Zmall/server/config/middleware.py", line 39, in __call__
    redis.set({client_ip: f"{int(request_count[2:]) + 1},{request_date}"})
TypeError: BasicKeyCommands.set() missing 1 required positional argument: 'value'
2022-09-07 17:47:08,879 [autoreload | INFO] /Users/c0mrade/Documents/Zmall/server/config/middleware.py changed, reloading.
2022-09-07 17:47:09,208 [autoreload | INFO] Watching for file changes with StatReloader
2022-09-07 17:47:10,534 [log | WARNING] Not Found: /
2022-09-07 17:47:10,568 [log | WARNING] Not Found: /favicon.ico
2022-09-07 17:47:18,761 [autoreload | INFO] /Users/c0mrade/Documents/Zmall/server/config/middleware.py changed, reloading.
2022-09-07 17:47:19,090 [autoreload | INFO] Watching for file changes with StatReloader
2022-09-07 17:47:27,577 [autoreload | INFO] /Users/c0mrade/Documents/Zmall/server/config/middleware.py changed, reloading.
2022-09-07 17:47:27,962 [autoreload | INFO] Watching for file changes with StatReloader
2022-09-07 17:47:29,125 [log | WARNING] Not Found: /
2022-09-07 17:47:29,166 [log | WARNING] Not Found: /favicon.ico
2022-09-07 17:47:29,607 [log | WARNING] Not Found: /
2022-09-07 17:47:32,726 [log | WARNING] Not Found: /
2022-09-07 17:47:32,760 [log | WARNING] Not Found: /favicon.ico
2022-09-07 17:48:01,289 [autoreload | INFO] /Users/c0mrade/Documents/Zmall/server/config/middleware.py changed, reloading.
2022-09-07 17:48:01,711 [autoreload | INFO] Watching for file changes with StatReloader
2022-09-07 17:48:02,991 [log | WARNING] Not Found: /
2022-09-07 17:48:03,159 [log | WARNING] Not Found: /
2022-09-07 17:48:03,341 [log | WARNING] Not Found: /
2022-09-07 17:48:20,583 [autoreload | INFO] /Users/c0mrade/Documents/Zmall/server/config/middleware.py changed, reloading.
2022-09-07 17:48:21,026 [autoreload | INFO] Watching for file changes with StatReloader
2022-09-07 17:48:22,182 [log | WARNING] Not Found: /
2022-09-07 17:48:22,238 [log | WARNING] Not Found: /favicon.ico
2022-09-07 17:53:18,417 [autoreload | INFO] Watching for file changes with StatReloader
2022-09-07 17:53:20,373 [log | ERROR] Internal Server Error: /
Traceback (most recent call last):
  File "/Users/c0mrade/Documents/Zmall/server/env/lib/python3.10/site-packages/django/core/handlers/exception.py", line 55, in inner
    response = get_response(request)
  File "/Users/c0mrade/Documents/Zmall/server/config/middleware.py", line 39, in __call__
    if client_date < today:
TypeError: '<' not supported between instances of 'bytes' and 'str'
2022-09-07 17:53:20,450 [log | ERROR] Internal Server Error: /favicon.ico
Traceback (most recent call last):
  File "/Users/c0mrade/Documents/Zmall/server/env/lib/python3.10/site-packages/django/core/handlers/exception.py", line 55, in inner
    response = get_response(request)
  File "/Users/c0mrade/Documents/Zmall/server/config/middleware.py", line 39, in __call__
    if client_date < today:
TypeError: '<' not supported between instances of 'bytes' and 'str'
2022-09-07 17:53:27,997 [autoreload | INFO] /Users/c0mrade/Documents/Zmall/server/config/middleware.py changed, reloading.
2022-09-07 17:53:28,310 [autoreload | INFO] Watching for file changes with StatReloader
2022-09-07 17:53:36,756 [autoreload | INFO] /Users/c0mrade/Documents/Zmall/server/config/middleware.py changed, reloading.
2022-09-07 17:53:37,080 [autoreload | INFO] Watching for file changes with StatReloader
2022-09-07 17:53:37,717 [log | WARNING] Not Found: /
2022-09-07 17:54:00,074 [autoreload | INFO] /Users/c0mrade/Documents/Zmall/server/config/middleware.py changed, reloading.
2022-09-07 17:54:00,422 [autoreload | INFO] Watching for file changes with StatReloader
2022-09-07 17:54:01,938 [log | ERROR] Internal Server Error: /
Traceback (most recent call last):
  File "/Users/c0mrade/Documents/Zmall/server/env/lib/python3.10/site-packages/django/core/handlers/exception.py", line 55, in inner
    response = get_response(request)
  File "/Users/c0mrade/Documents/Zmall/server/config/middleware.py", line 46, in __call__
    if int(client_count) > 10 and client_date == today:
ValueError: invalid literal for int() with base 10: "4'"
2022-09-07 17:54:05,848 [autoreload | INFO] /Users/c0mrade/Documents/Zmall/server/config/middleware.py changed, reloading.
2022-09-07 17:54:06,190 [autoreload | INFO] Watching for file changes with StatReloader
2022-09-07 17:54:08,385 [log | ERROR] Internal Server Error: /
Traceback (most recent call last):
  File "/Users/c0mrade/Documents/Zmall/server/env/lib/python3.10/site-packages/django/core/handlers/exception.py", line 55, in inner
    response = get_response(request)
  File "/Users/c0mrade/Documents/Zmall/server/config/middleware.py", line 46, in __call__
    if int(client_count) > 10 and client_date == today:
ValueError: invalid literal for int() with base 10: ''
2022-09-07 17:54:15,758 [autoreload | INFO] /Users/c0mrade/Documents/Zmall/server/config/middleware.py changed, reloading.
2022-09-07 17:54:16,094 [autoreload | INFO] Watching for file changes with StatReloader
2022-09-07 17:54:16,948 [log | WARNING] Not Found: /
2022-09-07 17:54:25,567 [autoreload | INFO] /Users/c0mrade/Documents/Zmall/server/config/middleware.py changed, reloading.
2022-09-07 17:54:25,891 [autoreload | INFO] Watching for file changes with StatReloader
2022-09-07 17:54:27,362 [log | WARNING] Not Found: /
2022-09-07 17:54:37,539 [autoreload | INFO] /Users/c0mrade/Documents/Zmall/server/config/middleware.py changed, reloading.
2022-09-07 17:54:37,845 [autoreload | INFO] Watching for file changes with StatReloader
2022-09-07 17:54:39,095 [log | WARNING] Not Found: /
2022-09-07 17:54:46,348 [autoreload | INFO] /Users/c0mrade/Documents/Zmall/server/config/middleware.py changed, reloading.
2022-09-07 17:54:46,683 [autoreload | INFO] Watching for file changes with StatReloader
2022-09-07 17:54:47,634 [log | WARNING] Not Found: /
2022-09-07 17:54:48,046 [log | WARNING] Not Found: /
2022-09-07 17:54:48,444 [log | ERROR] Internal Server Error: /
Traceback (most recent call last):
  File "/Users/c0mrade/Documents/Zmall/server/env/lib/python3.10/site-packages/django/core/handlers/exception.py", line 55, in inner
    response = get_response(request)
  File "/Users/c0mrade/Documents/Zmall/server/config/middleware.py", line 44, in __call__
    raise ValueError("rate limit")
ValueError: rate limit
2022-09-07 17:54:49,316 [log | ERROR] Internal Server Error: /
Traceback (most recent call last):
  File "/Users/c0mrade/Documents/Zmall/server/env/lib/python3.10/site-packages/django/core/handlers/exception.py", line 55, in inner
    response = get_response(request)
  File "/Users/c0mrade/Documents/Zmall/server/config/middleware.py", line 44, in __call__
    raise ValueError("rate limit")
ValueError: rate limit
2022-09-07 17:54:49,474 [log | ERROR] Internal Server Error: /
Traceback (most recent call last):
  File "/Users/c0mrade/Documents/Zmall/server/env/lib/python3.10/site-packages/django/core/handlers/exception.py", line 55, in inner
    response = get_response(request)
  File "/Users/c0mrade/Documents/Zmall/server/config/middleware.py", line 44, in __call__
    raise ValueError("rate limit")
ValueError: rate limit
2022-09-07 17:54:49,634 [log | ERROR] Internal Server Error: /
Traceback (most recent call last):
  File "/Users/c0mrade/Documents/Zmall/server/env/lib/python3.10/site-packages/django/core/handlers/exception.py", line 55, in inner
    response = get_response(request)
  File "/Users/c0mrade/Documents/Zmall/server/config/middleware.py", line 44, in __call__
    raise ValueError("rate limit")
ValueError: rate limit
2022-09-07 18:08:33,281 [autoreload | INFO] Watching for file changes with StatReloader
2022-09-07 18:08:51,132 [autoreload | INFO] /Users/c0mrade/Documents/Zmall/server/config/middleware.py changed, reloading.
2022-09-07 18:08:51,654 [autoreload | INFO] Watching for file changes with StatReloader
2022-09-07 18:08:52,546 [log | WARNING] Not Found: /
2022-09-07 18:08:56,815 [base | WARNING] view's VerifyEmail raised exception during schema generation; use `getattr(self, 'swagger_fake_view', False)` to detect and short-circuit this
Traceback (most recent call last):
  File "/Users/c0mrade/Documents/Zmall/server/env/lib/python3.10/site-packages/drf_yasg/inspectors/base.py", line 42, in call_view_method
    return view_method()
  File "/Users/c0mrade/Documents/Zmall/server/env/lib/python3.10/site-packages/rest_framework/generics.py", line 108, in get_serializer
    serializer_class = self.get_serializer_class()
  File "/Users/c0mrade/Documents/Zmall/server/env/lib/python3.10/site-packages/rest_framework/generics.py", line 122, in get_serializer_class
    assert self.serializer_class is not None, (
AssertionError: 'VerifyEmail' should either include a `serializer_class` attribute, or override the `get_serializer_class()` method.
2022-09-07 18:09:10,618 [autoreload | INFO] /Users/c0mrade/Documents/Zmall/server/config/urls.py changed, reloading.
2022-09-07 18:09:11,145 [autoreload | INFO] Watching for file changes with StatReloader
2022-09-07 18:09:11,556 [log | ERROR] Internal Server Error: /swagger/
Traceback (most recent call last):
  File "/Users/c0mrade/Documents/Zmall/server/env/lib/python3.10/site-packages/django/core/handlers/exception.py", line 55, in inner
    response = get_response(request)
  File "/Users/c0mrade/Documents/Zmall/server/env/lib/python3.10/site-packages/django/core/handlers/base.py", line 197, in _get_response
    response = wrapped_callback(request, *callback_args, **callback_kwargs)
  File "/Users/c0mrade/Documents/Zmall/server/env/lib/python3.10/site-packages/django/views/decorators/csrf.py", line 54, in wrapped_view
    return view_func(*args, **kwargs)
  File "/Users/c0mrade/Documents/Zmall/server/env/lib/python3.10/site-packages/django/views/generic/base.py", line 103, in view
    return self.dispatch(request, *args, **kwargs)
  File "/Users/c0mrade/Documents/Zmall/server/env/lib/python3.10/site-packages/rest_framework/views.py", line 509, in dispatch
    response = self.handle_exception(exc)
  File "/Users/c0mrade/Documents/Zmall/server/env/lib/python3.10/site-packages/rest_framework/views.py", line 469, in handle_exception
    self.raise_uncaught_exception(exc)
  File "/Users/c0mrade/Documents/Zmall/server/env/lib/python3.10/site-packages/rest_framework/views.py", line 480, in raise_uncaught_exception
    raise exc
  File "/Users/c0mrade/Documents/Zmall/server/env/lib/python3.10/site-packages/rest_framework/views.py", line 506, in dispatch
    response = handler(request, *args, **kwargs)
  File "/Users/c0mrade/Documents/Zmall/server/env/lib/python3.10/site-packages/drf_yasg/views.py", line 94, in get
    schema = generator.get_schema(request, self.public)
  File "/Users/c0mrade/Documents/Zmall/server/env/lib/python3.10/site-packages/drf_yasg/generators.py", line 248, in get_schema
    paths, prefix = self.get_paths(endpoints, components, request, public)
  File "/Users/c0mrade/Documents/Zmall/server/env/lib/python3.10/site-packages/drf_yasg/generators.py", line 406, in get_paths
    operation = self.get_operation(view, path, prefix, method, components, request)
  File "/Users/c0mrade/Documents/Zmall/server/env/lib/python3.10/site-packages/drf_yasg/generators.py", line 448, in get_operation
    operation = view_inspector.get_operation(operation_keys)
  File "/Users/c0mrade/Documents/Zmall/server/env/lib/python3.10/site-packages/drf_yasg/inspectors/view.py", line 45, in get_operation
    responses = self.get_responses()
  File "/Users/c0mrade/Documents/Zmall/server/env/lib/python3.10/site-packages/drf_yasg/inspectors/view.py", line 180, in get_responses
    response_serializers = self.get_response_serializers()
  File "/Users/c0mrade/Documents/Zmall/server/env/lib/python3.10/site-packages/drf_yasg/inspectors/view.py", line 235, in get_response_serializers
    responses = self.get_default_responses()
  File "/Users/c0mrade/Documents/Zmall/server/env/lib/python3.10/site-packages/drf_yasg/inspectors/view.py", line 211, in get_default_responses
    default_schema = self.serializer_to_schema(default_schema) or ''
  File "/Users/c0mrade/Documents/Zmall/server/env/lib/python3.10/site-packages/drf_yasg/inspectors/base.py", line 438, in serializer_to_schema
    return self.probe_inspectors(
  File "/Users/c0mrade/Documents/Zmall/server/env/lib/python3.10/site-packages/drf_yasg/inspectors/base.py", line 110, in probe_inspectors
    result = method(obj, **kwargs)
  File "/Users/c0mrade/Documents/Zmall/server/env/lib/python3.10/site-packages/drf_yasg/inspectors/field.py", line 33, in get_schema
    return self.probe_field_inspectors(serializer, openapi.Schema, self.use_definitions)
  File "/Users/c0mrade/Documents/Zmall/server/env/lib/python3.10/site-packages/drf_yasg/inspectors/base.py", line 228, in probe_field_inspectors
    return self.probe_inspectors(
  File "/Users/c0mrade/Documents/Zmall/server/env/lib/python3.10/site-packages/drf_yasg/inspectors/base.py", line 110, in probe_inspectors
    result = method(obj, **kwargs)
  File "/Users/c0mrade/Documents/Zmall/server/env/lib/python3.10/site-packages/drf_yasg/inspectors/field.py", line 132, in field_to_swagger_object
    raise SwaggerGenerationError(
drf_yasg.errors.SwaggerGenerationError: Schema for <class 'advert.serializers.advert_serializers.AdvertImageSerializer'> would override distinct serializer <class 'custom_admin.serializers.AdvertImageSerializer'> because they implicitly share the same ref_name; explicitly set the ref_name attribute on both serializers' Meta classes
2022-09-07 18:09:12,557 [log | ERROR] Internal Server Error: /swagger/
Traceback (most recent call last):
  File "/Users/c0mrade/Documents/Zmall/server/env/lib/python3.10/site-packages/django/core/handlers/exception.py", line 55, in inner
    response = get_response(request)
  File "/Users/c0mrade/Documents/Zmall/server/env/lib/python3.10/site-packages/django/core/handlers/base.py", line 197, in _get_response
    response = wrapped_callback(request, *callback_args, **callback_kwargs)
  File "/Users/c0mrade/Documents/Zmall/server/env/lib/python3.10/site-packages/django/views/decorators/csrf.py", line 54, in wrapped_view
    return view_func(*args, **kwargs)
  File "/Users/c0mrade/Documents/Zmall/server/env/lib/python3.10/site-packages/django/views/generic/base.py", line 103, in view
    return self.dispatch(request, *args, **kwargs)
  File "/Users/c0mrade/Documents/Zmall/server/env/lib/python3.10/site-packages/rest_framework/views.py", line 509, in dispatch
    response = self.handle_exception(exc)
  File "/Users/c0mrade/Documents/Zmall/server/env/lib/python3.10/site-packages/rest_framework/views.py", line 469, in handle_exception
    self.raise_uncaught_exception(exc)
  File "/Users/c0mrade/Documents/Zmall/server/env/lib/python3.10/site-packages/rest_framework/views.py", line 480, in raise_uncaught_exception
    raise exc
  File "/Users/c0mrade/Documents/Zmall/server/env/lib/python3.10/site-packages/rest_framework/views.py", line 506, in dispatch
    response = handler(request, *args, **kwargs)
  File "/Users/c0mrade/Documents/Zmall/server/env/lib/python3.10/site-packages/drf_yasg/views.py", line 94, in get
    schema = generator.get_schema(request, self.public)
  File "/Users/c0mrade/Documents/Zmall/server/env/lib/python3.10/site-packages/drf_yasg/generators.py", line 248, in get_schema
    paths, prefix = self.get_paths(endpoints, components, request, public)
  File "/Users/c0mrade/Documents/Zmall/server/env/lib/python3.10/site-packages/drf_yasg/generators.py", line 406, in get_paths
    operation = self.get_operation(view, path, prefix, method, components, request)
  File "/Users/c0mrade/Documents/Zmall/server/env/lib/python3.10/site-packages/drf_yasg/generators.py", line 448, in get_operation
    operation = view_inspector.get_operation(operation_keys)
  File "/Users/c0mrade/Documents/Zmall/server/env/lib/python3.10/site-packages/drf_yasg/inspectors/view.py", line 45, in get_operation
    responses = self.get_responses()
  File "/Users/c0mrade/Documents/Zmall/server/env/lib/python3.10/site-packages/drf_yasg/inspectors/view.py", line 180, in get_responses
    response_serializers = self.get_response_serializers()
  File "/Users/c0mrade/Documents/Zmall/server/env/lib/python3.10/site-packages/drf_yasg/inspectors/view.py", line 235, in get_response_serializers
    responses = self.get_default_responses()
  File "/Users/c0mrade/Documents/Zmall/server/env/lib/python3.10/site-packages/drf_yasg/inspectors/view.py", line 211, in get_default_responses
    default_schema = self.serializer_to_schema(default_schema) or ''
  File "/Users/c0mrade/Documents/Zmall/server/env/lib/python3.10/site-packages/drf_yasg/inspectors/base.py", line 438, in serializer_to_schema
    return self.probe_inspectors(
  File "/Users/c0mrade/Documents/Zmall/server/env/lib/python3.10/site-packages/drf_yasg/inspectors/base.py", line 110, in probe_inspectors
    result = method(obj, **kwargs)
  File "/Users/c0mrade/Documents/Zmall/server/env/lib/python3.10/site-packages/drf_yasg/inspectors/field.py", line 33, in get_schema
    return self.probe_field_inspectors(serializer, openapi.Schema, self.use_definitions)
  File "/Users/c0mrade/Documents/Zmall/server/env/lib/python3.10/site-packages/drf_yasg/inspectors/base.py", line 228, in probe_field_inspectors
    return self.probe_inspectors(
  File "/Users/c0mrade/Documents/Zmall/server/env/lib/python3.10/site-packages/drf_yasg/inspectors/base.py", line 110, in probe_inspectors
    result = method(obj, **kwargs)
  File "/Users/c0mrade/Documents/Zmall/server/env/lib/python3.10/site-packages/drf_yasg/inspectors/field.py", line 132, in field_to_swagger_object
    raise SwaggerGenerationError(
drf_yasg.errors.SwaggerGenerationError: Schema for <class 'advert.serializers.advert_serializers.AdvertImageSerializer'> would override distinct serializer <class 'custom_admin.serializers.AdvertImageSerializer'> because they implicitly share the same ref_name; explicitly set the ref_name attribute on both serializers' Meta classes
2022-09-07 18:09:49,721 [autoreload | INFO] /Users/c0mrade/Documents/Zmall/server/apps/custom_admin/views.py changed, reloading.
2022-09-07 18:09:50,167 [autoreload | INFO] Watching for file changes with StatReloader
2022-09-07 18:09:51,882 [log | ERROR] Internal Server Error: /swagger/
Traceback (most recent call last):
  File "/Users/c0mrade/Documents/Zmall/server/env/lib/python3.10/site-packages/django/core/handlers/exception.py", line 55, in inner
    response = get_response(request)
  File "/Users/c0mrade/Documents/Zmall/server/env/lib/python3.10/site-packages/django/core/handlers/base.py", line 197, in _get_response
    response = wrapped_callback(request, *callback_args, **callback_kwargs)
  File "/Users/c0mrade/Documents/Zmall/server/env/lib/python3.10/site-packages/django/views/decorators/csrf.py", line 54, in wrapped_view
    return view_func(*args, **kwargs)
  File "/Users/c0mrade/Documents/Zmall/server/env/lib/python3.10/site-packages/django/views/generic/base.py", line 103, in view
    return self.dispatch(request, *args, **kwargs)
  File "/Users/c0mrade/Documents/Zmall/server/env/lib/python3.10/site-packages/rest_framework/views.py", line 509, in dispatch
    response = self.handle_exception(exc)
  File "/Users/c0mrade/Documents/Zmall/server/env/lib/python3.10/site-packages/rest_framework/views.py", line 469, in handle_exception
    self.raise_uncaught_exception(exc)
  File "/Users/c0mrade/Documents/Zmall/server/env/lib/python3.10/site-packages/rest_framework/views.py", line 480, in raise_uncaught_exception
    raise exc
  File "/Users/c0mrade/Documents/Zmall/server/env/lib/python3.10/site-packages/rest_framework/views.py", line 506, in dispatch
    response = handler(request, *args, **kwargs)
  File "/Users/c0mrade/Documents/Zmall/server/env/lib/python3.10/site-packages/drf_yasg/views.py", line 94, in get
    schema = generator.get_schema(request, self.public)
  File "/Users/c0mrade/Documents/Zmall/server/env/lib/python3.10/site-packages/drf_yasg/generators.py", line 248, in get_schema
    paths, prefix = self.get_paths(endpoints, components, request, public)
  File "/Users/c0mrade/Documents/Zmall/server/env/lib/python3.10/site-packages/drf_yasg/generators.py", line 406, in get_paths
    operation = self.get_operation(view, path, prefix, method, components, request)
  File "/Users/c0mrade/Documents/Zmall/server/env/lib/python3.10/site-packages/drf_yasg/generators.py", line 448, in get_operation
    operation = view_inspector.get_operation(operation_keys)
  File "/Users/c0mrade/Documents/Zmall/server/env/lib/python3.10/site-packages/drf_yasg/inspectors/view.py", line 45, in get_operation
    responses = self.get_responses()
  File "/Users/c0mrade/Documents/Zmall/server/env/lib/python3.10/site-packages/drf_yasg/inspectors/view.py", line 180, in get_responses
    response_serializers = self.get_response_serializers()
  File "/Users/c0mrade/Documents/Zmall/server/env/lib/python3.10/site-packages/drf_yasg/inspectors/view.py", line 235, in get_response_serializers
    responses = self.get_default_responses()
  File "/Users/c0mrade/Documents/Zmall/server/env/lib/python3.10/site-packages/drf_yasg/inspectors/view.py", line 211, in get_default_responses
    default_schema = self.serializer_to_schema(default_schema) or ''
  File "/Users/c0mrade/Documents/Zmall/server/env/lib/python3.10/site-packages/drf_yasg/inspectors/base.py", line 438, in serializer_to_schema
    return self.probe_inspectors(
  File "/Users/c0mrade/Documents/Zmall/server/env/lib/python3.10/site-packages/drf_yasg/inspectors/base.py", line 110, in probe_inspectors
    result = method(obj, **kwargs)
  File "/Users/c0mrade/Documents/Zmall/server/env/lib/python3.10/site-packages/drf_yasg/inspectors/field.py", line 33, in get_schema
    return self.probe_field_inspectors(serializer, openapi.Schema, self.use_definitions)
  File "/Users/c0mrade/Documents/Zmall/server/env/lib/python3.10/site-packages/drf_yasg/inspectors/base.py", line 228, in probe_field_inspectors
    return self.probe_inspectors(
  File "/Users/c0mrade/Documents/Zmall/server/env/lib/python3.10/site-packages/drf_yasg/inspectors/base.py", line 110, in probe_inspectors
    result = method(obj, **kwargs)
  File "/Users/c0mrade/Documents/Zmall/server/env/lib/python3.10/site-packages/drf_yasg/inspectors/field.py", line 132, in field_to_swagger_object
    raise SwaggerGenerationError(
drf_yasg.errors.SwaggerGenerationError: Schema for <class 'advert.serializers.category_serializers.CategorySerializer'> would override distinct serializer <class 'custom_admin.serializers.CategorySerializer'> because they implicitly share the same ref_name; explicitly set the ref_name attribute on both serializers' Meta classes
2022-09-07 18:10:21,301 [autoreload | INFO] /Users/c0mrade/Documents/Zmall/server/apps/custom_admin/views.py changed, reloading.
2022-09-07 18:10:21,767 [autoreload | INFO] Watching for file changes with StatReloader
2022-09-07 18:10:22,186 [base | WARNING] view's VerifyEmail raised exception during schema generation; use `getattr(self, 'swagger_fake_view', False)` to detect and short-circuit this
Traceback (most recent call last):
  File "/Users/c0mrade/Documents/Zmall/server/env/lib/python3.10/site-packages/drf_yasg/inspectors/base.py", line 42, in call_view_method
    return view_method()
  File "/Users/c0mrade/Documents/Zmall/server/env/lib/python3.10/site-packages/rest_framework/generics.py", line 108, in get_serializer
    serializer_class = self.get_serializer_class()
  File "/Users/c0mrade/Documents/Zmall/server/env/lib/python3.10/site-packages/rest_framework/generics.py", line 122, in get_serializer_class
    assert self.serializer_class is not None, (
AssertionError: 'VerifyEmail' should either include a `serializer_class` attribute, or override the `get_serializer_class()` method.
2022-09-07 18:10:22,647 [base | WARNING] view's VerifyEmail raised exception during schema generation; use `getattr(self, 'swagger_fake_view', False)` to detect and short-circuit this
Traceback (most recent call last):
  File "/Users/c0mrade/Documents/Zmall/server/env/lib/python3.10/site-packages/drf_yasg/inspectors/base.py", line 42, in call_view_method
    return view_method()
  File "/Users/c0mrade/Documents/Zmall/server/env/lib/python3.10/site-packages/rest_framework/generics.py", line 108, in get_serializer
    serializer_class = self.get_serializer_class()
  File "/Users/c0mrade/Documents/Zmall/server/env/lib/python3.10/site-packages/rest_framework/generics.py", line 122, in get_serializer_class
    assert self.serializer_class is not None, (
AssertionError: 'VerifyEmail' should either include a `serializer_class` attribute, or override the `get_serializer_class()` method.
2022-09-07 18:10:40,729 [autoreload | INFO] /Users/c0mrade/Documents/Zmall/server/apps/custom_admin/urls.py changed, reloading.
2022-09-07 18:10:41,195 [autoreload | INFO] Watching for file changes with StatReloader
2022-09-07 18:10:42,474 [base | WARNING] view's VerifyEmail raised exception during schema generation; use `getattr(self, 'swagger_fake_view', False)` to detect and short-circuit this
Traceback (most recent call last):
  File "/Users/c0mrade/Documents/Zmall/server/env/lib/python3.10/site-packages/drf_yasg/inspectors/base.py", line 42, in call_view_method
    return view_method()
  File "/Users/c0mrade/Documents/Zmall/server/env/lib/python3.10/site-packages/rest_framework/generics.py", line 108, in get_serializer
    serializer_class = self.get_serializer_class()
  File "/Users/c0mrade/Documents/Zmall/server/env/lib/python3.10/site-packages/rest_framework/generics.py", line 122, in get_serializer_class
    assert self.serializer_class is not None, (
AssertionError: 'VerifyEmail' should either include a `serializer_class` attribute, or override the `get_serializer_class()` method.
2022-09-07 18:10:42,505 [autoreload | INFO] /Users/c0mrade/Documents/Zmall/server/apps/custom_admin/urls.py changed, reloading.
2022-09-07 18:10:42,919 [autoreload | INFO] Watching for file changes with StatReloader
2022-09-07 18:10:49,823 [base | WARNING] view's VerifyEmail raised exception during schema generation; use `getattr(self, 'swagger_fake_view', False)` to detect and short-circuit this
Traceback (most recent call last):
  File "/Users/c0mrade/Documents/Zmall/server/env/lib/python3.10/site-packages/drf_yasg/inspectors/base.py", line 42, in call_view_method
    return view_method()
  File "/Users/c0mrade/Documents/Zmall/server/env/lib/python3.10/site-packages/rest_framework/generics.py", line 108, in get_serializer
    serializer_class = self.get_serializer_class()
  File "/Users/c0mrade/Documents/Zmall/server/env/lib/python3.10/site-packages/rest_framework/generics.py", line 122, in get_serializer_class
    assert self.serializer_class is not None, (
AssertionError: 'VerifyEmail' should either include a `serializer_class` attribute, or override the `get_serializer_class()` method.
2022-09-07 18:14:17,487 [autoreload | INFO] Watching for file changes with StatReloader
2022-09-07 18:14:19,697 [base | WARNING] view's VerifyEmail raised exception during schema generation; use `getattr(self, 'swagger_fake_view', False)` to detect and short-circuit this
Traceback (most recent call last):
  File "/Users/c0mrade/Documents/Zmall/server/env/lib/python3.10/site-packages/drf_yasg/inspectors/base.py", line 42, in call_view_method
    return view_method()
  File "/Users/c0mrade/Documents/Zmall/server/env/lib/python3.10/site-packages/rest_framework/generics.py", line 108, in get_serializer
    serializer_class = self.get_serializer_class()
  File "/Users/c0mrade/Documents/Zmall/server/env/lib/python3.10/site-packages/rest_framework/generics.py", line 122, in get_serializer_class
    assert self.serializer_class is not None, (
AssertionError: 'VerifyEmail' should either include a `serializer_class` attribute, or override the `get_serializer_class()` method.
2022-09-07 18:15:07,860 [autoreload | INFO] /Users/c0mrade/Documents/Zmall/server/apps/custom_admin/serializers.py changed, reloading.
2022-09-07 18:15:08,331 [autoreload | INFO] Watching for file changes with StatReloader
2022-09-07 18:15:27,121 [autoreload | INFO] /Users/c0mrade/Documents/Zmall/server/apps/custom_admin/views.py changed, reloading.
2022-09-07 18:15:27,538 [autoreload | INFO] Watching for file changes with StatReloader
2022-09-07 18:15:40,173 [autoreload | INFO] /Users/c0mrade/Documents/Zmall/server/apps/custom_admin/urls.py changed, reloading.
2022-09-07 18:15:40,512 [autoreload | INFO] Watching for file changes with StatReloader
2022-09-07 18:15:42,758 [autoreload | INFO] /Users/c0mrade/Documents/Zmall/server/apps/custom_admin/urls.py changed, reloading.
2022-09-07 18:15:43,072 [autoreload | INFO] Watching for file changes with StatReloader
2022-09-07 18:15:47,368 [autoreload | INFO] /Users/c0mrade/Documents/Zmall/server/apps/custom_admin/urls.py changed, reloading.
2022-09-07 18:15:47,668 [autoreload | INFO] Watching for file changes with StatReloader
2022-09-07 18:15:49,288 [base | WARNING] view's VerifyEmail raised exception during schema generation; use `getattr(self, 'swagger_fake_view', False)` to detect and short-circuit this
Traceback (most recent call last):
  File "/Users/c0mrade/Documents/Zmall/server/env/lib/python3.10/site-packages/drf_yasg/inspectors/base.py", line 42, in call_view_method
    return view_method()
  File "/Users/c0mrade/Documents/Zmall/server/env/lib/python3.10/site-packages/rest_framework/generics.py", line 108, in get_serializer
    serializer_class = self.get_serializer_class()
  File "/Users/c0mrade/Documents/Zmall/server/env/lib/python3.10/site-packages/rest_framework/generics.py", line 122, in get_serializer_class
    assert self.serializer_class is not None, (
AssertionError: 'VerifyEmail' should either include a `serializer_class` attribute, or override the `get_serializer_class()` method.
2022-09-07 18:16:03,540 [autoreload | INFO] /Users/c0mrade/Documents/Zmall/server/apps/custom_admin/urls.py changed, reloading.
2022-09-07 18:16:03,996 [autoreload | INFO] Watching for file changes with StatReloader
