2022-09-14 18:24:16,610 [autoreload | INFO] Watching for file changes with StatReloader
2022-09-14 18:27:05,338 [autoreload | INFO] /Users/zharkynaskatkyzy/PycharmProjects/Zmall/server/apps/advert/serializers/advert_serializers.py changed, reloading.
2022-09-14 18:27:05,932 [autoreload | INFO] Watching for file changes with StatReloader
2022-09-14 18:27:32,111 [autoreload | INFO] /Users/zharkynaskatkyzy/PycharmProjects/Zmall/server/config/settings/base.py changed, reloading.
2022-09-14 18:27:32,578 [autoreload | INFO] Watching for file changes with StatReloader
2022-09-14 18:27:35,193 [log | WARNING] Not Found: /
2022-09-14 18:27:37,723 [log | WARNING] Not Found: /
2022-09-14 18:28:32,613 [autoreload | INFO] /Users/zharkynaskatkyzy/PycharmProjects/Zmall/server/apps/advert/serializers/advert_serializers.py changed, reloading.
2022-09-14 18:28:33,180 [autoreload | INFO] Watching for file changes with StatReloader
2022-09-14 18:30:20,675 [autoreload | INFO] /Users/zharkynaskatkyzy/PycharmProjects/Zmall/server/apps/advert/serializers/advert_serializers.py changed, reloading.
2022-09-14 18:30:21,186 [autoreload | INFO] Watching for file changes with StatReloader
2022-09-14 18:31:40,721 [log | WARNING] Method Not Allowed: /api/v1/user/login/
2022-09-14 18:32:38,966 [log | WARNING] Method Not Allowed: /api/v1/user/login/
2022-09-14 18:33:22,620 [log | WARNING] Bad Request: /api/v1/advert/
2022-09-14 18:33:54,444 [autoreload | INFO] /Users/zharkynaskatkyzy/PycharmProjects/Zmall/server/apps/advert/serializers/advert_serializers.py changed, reloading.
2022-09-14 18:33:55,013 [autoreload | INFO] Watching for file changes with StatReloader
2022-09-14 18:36:27,897 [autoreload | INFO] /Users/zharkynaskatkyzy/PycharmProjects/Zmall/server/apps/advert/views/advert_views.py changed, reloading.
2022-09-14 18:36:28,533 [autoreload | INFO] Watching for file changes with StatReloader
2022-09-14 18:36:52,574 [autoreload | INFO] /Users/zharkynaskatkyzy/PycharmProjects/Zmall/server/apps/advert/views/advert_views.py changed, reloading.
2022-09-14 18:36:53,367 [autoreload | INFO] Watching for file changes with StatReloader
2022-09-14 18:38:27,887 [autoreload | INFO] /Users/zharkynaskatkyzy/PycharmProjects/Zmall/server/apps/advert/views/advert_views.py changed, reloading.
2022-09-14 18:38:28,508 [autoreload | INFO] Watching for file changes with StatReloader
2022-09-14 18:38:35,020 [autoreload | INFO] /Users/zharkynaskatkyzy/PycharmProjects/Zmall/server/apps/advert/views/advert_views.py changed, reloading.
2022-09-14 18:38:35,854 [autoreload | INFO] Watching for file changes with StatReloader
2022-09-14 18:38:41,136 [autoreload | INFO] /Users/zharkynaskatkyzy/PycharmProjects/Zmall/server/apps/advert/views/advert_views.py changed, reloading.
2022-09-14 18:38:41,685 [autoreload | INFO] Watching for file changes with StatReloader
2022-09-14 18:43:06,601 [autoreload | INFO] /Users/zharkynaskatkyzy/PycharmProjects/Zmall/server/apps/advert/views/advert_views.py changed, reloading.
2022-09-14 18:43:07,167 [autoreload | INFO] Watching for file changes with StatReloader
2022-09-14 18:44:09,580 [autoreload | INFO] /Users/zharkynaskatkyzy/PycharmProjects/Zmall/server/apps/advert/urls.py changed, reloading.
2022-09-14 18:44:10,124 [autoreload | INFO] Watching for file changes with StatReloader
2022-09-14 18:44:22,935 [base | WARNING] view's ContactView raised exception during schema generation; use `getattr(self, 'swagger_fake_view', False)` to detect and short-circuit this
Traceback (most recent call last):
  File "/Library/Frameworks/Python.framework/Versions/3.10/lib/python3.10/site-packages/drf_yasg/inspectors/base.py", line 42, in call_view_method
    return view_method()
  File "/Library/Frameworks/Python.framework/Versions/3.10/lib/python3.10/site-packages/rest_framework/generics.py", line 108, in get_serializer
    serializer_class = self.get_serializer_class()
  File "/Library/Frameworks/Python.framework/Versions/3.10/lib/python3.10/site-packages/rest_framework/generics.py", line 122, in get_serializer_class
    assert self.serializer_class is not None, (
AssertionError: 'ContactView' should either include a `serializer_class` attribute, or override the `get_serializer_class()` method.
2022-09-14 18:44:22,936 [base | WARNING] view's ContactView raised exception during schema generation; use `getattr(self, 'swagger_fake_view', False)` to detect and short-circuit this
Traceback (most recent call last):
  File "/Library/Frameworks/Python.framework/Versions/3.10/lib/python3.10/site-packages/drf_yasg/inspectors/base.py", line 42, in call_view_method
    return view_method()
  File "/Library/Frameworks/Python.framework/Versions/3.10/lib/python3.10/site-packages/rest_framework/generics.py", line 108, in get_serializer
    serializer_class = self.get_serializer_class()
  File "/Library/Frameworks/Python.framework/Versions/3.10/lib/python3.10/site-packages/rest_framework/generics.py", line 122, in get_serializer_class
    assert self.serializer_class is not None, (
AssertionError: 'ContactView' should either include a `serializer_class` attribute, or override the `get_serializer_class()` method.
2022-09-14 18:44:22,951 [base | WARNING] view's VerifyEmail raised exception during schema generation; use `getattr(self, 'swagger_fake_view', False)` to detect and short-circuit this
Traceback (most recent call last):
  File "/Library/Frameworks/Python.framework/Versions/3.10/lib/python3.10/site-packages/drf_yasg/inspectors/base.py", line 42, in call_view_method
    return view_method()
  File "/Library/Frameworks/Python.framework/Versions/3.10/lib/python3.10/site-packages/rest_framework/generics.py", line 108, in get_serializer
    serializer_class = self.get_serializer_class()
  File "/Library/Frameworks/Python.framework/Versions/3.10/lib/python3.10/site-packages/rest_framework/generics.py", line 122, in get_serializer_class
    assert self.serializer_class is not None, (
AssertionError: 'VerifyEmail' should either include a `serializer_class` attribute, or override the `get_serializer_class()` method.
2022-09-14 18:45:46,370 [log | WARNING] Method Not Allowed: /api/v1/update/
2022-09-14 18:45:55,866 [log | WARNING] Not Found: /api/v1/update/1
2022-09-14 18:46:35,724 [autoreload | INFO] /Users/zharkynaskatkyzy/PycharmProjects/Zmall/server/apps/advert/views/advert_views.py changed, reloading.
2022-09-14 18:46:36,510 [autoreload | INFO] Watching for file changes with StatReloader
2022-09-14 18:46:47,102 [base | WARNING] view's ContactView raised exception during schema generation; use `getattr(self, 'swagger_fake_view', False)` to detect and short-circuit this
Traceback (most recent call last):
  File "/Library/Frameworks/Python.framework/Versions/3.10/lib/python3.10/site-packages/drf_yasg/inspectors/base.py", line 42, in call_view_method
    return view_method()
  File "/Library/Frameworks/Python.framework/Versions/3.10/lib/python3.10/site-packages/rest_framework/generics.py", line 108, in get_serializer
    serializer_class = self.get_serializer_class()
  File "/Library/Frameworks/Python.framework/Versions/3.10/lib/python3.10/site-packages/rest_framework/generics.py", line 122, in get_serializer_class
    assert self.serializer_class is not None, (
AssertionError: 'ContactView' should either include a `serializer_class` attribute, or override the `get_serializer_class()` method.
2022-09-14 18:46:47,103 [base | WARNING] view's ContactView raised exception during schema generation; use `getattr(self, 'swagger_fake_view', False)` to detect and short-circuit this
Traceback (most recent call last):
  File "/Library/Frameworks/Python.framework/Versions/3.10/lib/python3.10/site-packages/drf_yasg/inspectors/base.py", line 42, in call_view_method
    return view_method()
  File "/Library/Frameworks/Python.framework/Versions/3.10/lib/python3.10/site-packages/rest_framework/generics.py", line 108, in get_serializer
    serializer_class = self.get_serializer_class()
  File "/Library/Frameworks/Python.framework/Versions/3.10/lib/python3.10/site-packages/rest_framework/generics.py", line 122, in get_serializer_class
    assert self.serializer_class is not None, (
AssertionError: 'ContactView' should either include a `serializer_class` attribute, or override the `get_serializer_class()` method.
2022-09-14 18:46:47,115 [base | WARNING] view's VerifyEmail raised exception during schema generation; use `getattr(self, 'swagger_fake_view', False)` to detect and short-circuit this
Traceback (most recent call last):
  File "/Library/Frameworks/Python.framework/Versions/3.10/lib/python3.10/site-packages/drf_yasg/inspectors/base.py", line 42, in call_view_method
    return view_method()
  File "/Library/Frameworks/Python.framework/Versions/3.10/lib/python3.10/site-packages/rest_framework/generics.py", line 108, in get_serializer
    serializer_class = self.get_serializer_class()
  File "/Library/Frameworks/Python.framework/Versions/3.10/lib/python3.10/site-packages/rest_framework/generics.py", line 122, in get_serializer_class
    assert self.serializer_class is not None, (
AssertionError: 'VerifyEmail' should either include a `serializer_class` attribute, or override the `get_serializer_class()` method.
2022-09-14 18:47:21,220 [log | WARNING] Unauthorized: /api/v1/advert/1/
2022-09-14 18:49:13,134 [log | WARNING] Unauthorized: /api/v1/advert/1/
2022-09-14 18:51:25,930 [log | WARNING] Unauthorized: /api/v1/advert/
2022-09-14 18:51:37,271 [log | WARNING] Method Not Allowed: /api/v1/user/login/
2022-09-14 18:51:55,866 [log | WARNING] Method Not Allowed: /api/v1/advert/
2022-09-14 18:52:13,105 [log | WARNING] Not Found: /api/v1/advert/82/
2022-09-14 18:53:23,808 [autoreload | INFO] /Users/zharkynaskatkyzy/PycharmProjects/Zmall/server/apps/advert/views/advert_views.py changed, reloading.
2022-09-14 18:53:24,659 [autoreload | INFO] Watching for file changes with StatReloader
2022-09-14 18:58:02,994 [autoreload | INFO] /Users/zharkynaskatkyzy/PycharmProjects/Zmall/server/apps/advert/views/advert_views.py changed, reloading.
2022-09-14 18:58:03,617 [autoreload | INFO] Watching for file changes with StatReloader
2022-09-14 18:58:57,516 [autoreload | INFO] /Users/zharkynaskatkyzy/PycharmProjects/Zmall/server/apps/advert/urls.py changed, reloading.
2022-09-14 18:58:58,059 [autoreload | INFO] Watching for file changes with StatReloader
2022-09-14 18:59:03,837 [base | WARNING] view's ContactView raised exception during schema generation; use `getattr(self, 'swagger_fake_view', False)` to detect and short-circuit this
Traceback (most recent call last):
  File "/Library/Frameworks/Python.framework/Versions/3.10/lib/python3.10/site-packages/drf_yasg/inspectors/base.py", line 42, in call_view_method
    return view_method()
  File "/Library/Frameworks/Python.framework/Versions/3.10/lib/python3.10/site-packages/rest_framework/generics.py", line 108, in get_serializer
    serializer_class = self.get_serializer_class()
  File "/Library/Frameworks/Python.framework/Versions/3.10/lib/python3.10/site-packages/rest_framework/generics.py", line 122, in get_serializer_class
    assert self.serializer_class is not None, (
AssertionError: 'ContactView' should either include a `serializer_class` attribute, or override the `get_serializer_class()` method.
2022-09-14 18:59:03,837 [base | WARNING] view's ContactView raised exception during schema generation; use `getattr(self, 'swagger_fake_view', False)` to detect and short-circuit this
Traceback (most recent call last):
  File "/Library/Frameworks/Python.framework/Versions/3.10/lib/python3.10/site-packages/drf_yasg/inspectors/base.py", line 42, in call_view_method
    return view_method()
  File "/Library/Frameworks/Python.framework/Versions/3.10/lib/python3.10/site-packages/rest_framework/generics.py", line 108, in get_serializer
    serializer_class = self.get_serializer_class()
  File "/Library/Frameworks/Python.framework/Versions/3.10/lib/python3.10/site-packages/rest_framework/generics.py", line 122, in get_serializer_class
    assert self.serializer_class is not None, (
AssertionError: 'ContactView' should either include a `serializer_class` attribute, or override the `get_serializer_class()` method.
2022-09-14 18:59:03,848 [base | WARNING] view's VerifyEmail raised exception during schema generation; use `getattr(self, 'swagger_fake_view', False)` to detect and short-circuit this
Traceback (most recent call last):
  File "/Library/Frameworks/Python.framework/Versions/3.10/lib/python3.10/site-packages/drf_yasg/inspectors/base.py", line 42, in call_view_method
    return view_method()
  File "/Library/Frameworks/Python.framework/Versions/3.10/lib/python3.10/site-packages/rest_framework/generics.py", line 108, in get_serializer
    serializer_class = self.get_serializer_class()
  File "/Library/Frameworks/Python.framework/Versions/3.10/lib/python3.10/site-packages/rest_framework/generics.py", line 122, in get_serializer_class
    assert self.serializer_class is not None, (
AssertionError: 'VerifyEmail' should either include a `serializer_class` attribute, or override the `get_serializer_class()` method.
2022-09-14 19:00:43,427 [autoreload | INFO] /Users/zharkynaskatkyzy/PycharmProjects/Zmall/server/apps/advert/views/advert_views.py changed, reloading.
2022-09-14 19:00:44,012 [autoreload | INFO] Watching for file changes with StatReloader
2022-09-14 19:00:46,333 [base | WARNING] view's ContactView raised exception during schema generation; use `getattr(self, 'swagger_fake_view', False)` to detect and short-circuit this
Traceback (most recent call last):
  File "/Library/Frameworks/Python.framework/Versions/3.10/lib/python3.10/site-packages/drf_yasg/inspectors/base.py", line 42, in call_view_method
    return view_method()
  File "/Library/Frameworks/Python.framework/Versions/3.10/lib/python3.10/site-packages/rest_framework/generics.py", line 108, in get_serializer
    serializer_class = self.get_serializer_class()
  File "/Library/Frameworks/Python.framework/Versions/3.10/lib/python3.10/site-packages/rest_framework/generics.py", line 122, in get_serializer_class
    assert self.serializer_class is not None, (
AssertionError: 'ContactView' should either include a `serializer_class` attribute, or override the `get_serializer_class()` method.
2022-09-14 19:00:46,336 [base | WARNING] view's ContactView raised exception during schema generation; use `getattr(self, 'swagger_fake_view', False)` to detect and short-circuit this
Traceback (most recent call last):
  File "/Library/Frameworks/Python.framework/Versions/3.10/lib/python3.10/site-packages/drf_yasg/inspectors/base.py", line 42, in call_view_method
    return view_method()
  File "/Library/Frameworks/Python.framework/Versions/3.10/lib/python3.10/site-packages/rest_framework/generics.py", line 108, in get_serializer
    serializer_class = self.get_serializer_class()
  File "/Library/Frameworks/Python.framework/Versions/3.10/lib/python3.10/site-packages/rest_framework/generics.py", line 122, in get_serializer_class
    assert self.serializer_class is not None, (
AssertionError: 'ContactView' should either include a `serializer_class` attribute, or override the `get_serializer_class()` method.
2022-09-14 19:00:46,349 [base | WARNING] view's VerifyEmail raised exception during schema generation; use `getattr(self, 'swagger_fake_view', False)` to detect and short-circuit this
Traceback (most recent call last):
  File "/Library/Frameworks/Python.framework/Versions/3.10/lib/python3.10/site-packages/drf_yasg/inspectors/base.py", line 42, in call_view_method
    return view_method()
  File "/Library/Frameworks/Python.framework/Versions/3.10/lib/python3.10/site-packages/rest_framework/generics.py", line 108, in get_serializer
    serializer_class = self.get_serializer_class()
  File "/Library/Frameworks/Python.framework/Versions/3.10/lib/python3.10/site-packages/rest_framework/generics.py", line 122, in get_serializer_class
    assert self.serializer_class is not None, (
AssertionError: 'VerifyEmail' should either include a `serializer_class` attribute, or override the `get_serializer_class()` method.
2022-09-14 19:01:24,065 [log | WARNING] Unauthorized: /api/v1/advert/82/
2022-09-14 19:02:16,571 [base | WARNING] view's ContactView raised exception during schema generation; use `getattr(self, 'swagger_fake_view', False)` to detect and short-circuit this
Traceback (most recent call last):
  File "/Library/Frameworks/Python.framework/Versions/3.10/lib/python3.10/site-packages/drf_yasg/inspectors/base.py", line 42, in call_view_method
    return view_method()
  File "/Library/Frameworks/Python.framework/Versions/3.10/lib/python3.10/site-packages/rest_framework/generics.py", line 108, in get_serializer
    serializer_class = self.get_serializer_class()
  File "/Library/Frameworks/Python.framework/Versions/3.10/lib/python3.10/site-packages/rest_framework/generics.py", line 122, in get_serializer_class
    assert self.serializer_class is not None, (
AssertionError: 'ContactView' should either include a `serializer_class` attribute, or override the `get_serializer_class()` method.
2022-09-14 19:02:16,572 [base | WARNING] view's ContactView raised exception during schema generation; use `getattr(self, 'swagger_fake_view', False)` to detect and short-circuit this
Traceback (most recent call last):
  File "/Library/Frameworks/Python.framework/Versions/3.10/lib/python3.10/site-packages/drf_yasg/inspectors/base.py", line 42, in call_view_method
    return view_method()
  File "/Library/Frameworks/Python.framework/Versions/3.10/lib/python3.10/site-packages/rest_framework/generics.py", line 108, in get_serializer
    serializer_class = self.get_serializer_class()
  File "/Library/Frameworks/Python.framework/Versions/3.10/lib/python3.10/site-packages/rest_framework/generics.py", line 122, in get_serializer_class
    assert self.serializer_class is not None, (
AssertionError: 'ContactView' should either include a `serializer_class` attribute, or override the `get_serializer_class()` method.
2022-09-14 19:02:16,587 [base | WARNING] view's VerifyEmail raised exception during schema generation; use `getattr(self, 'swagger_fake_view', False)` to detect and short-circuit this
Traceback (most recent call last):
  File "/Library/Frameworks/Python.framework/Versions/3.10/lib/python3.10/site-packages/drf_yasg/inspectors/base.py", line 42, in call_view_method
    return view_method()
  File "/Library/Frameworks/Python.framework/Versions/3.10/lib/python3.10/site-packages/rest_framework/generics.py", line 108, in get_serializer
    serializer_class = self.get_serializer_class()
  File "/Library/Frameworks/Python.framework/Versions/3.10/lib/python3.10/site-packages/rest_framework/generics.py", line 122, in get_serializer_class
    assert self.serializer_class is not None, (
AssertionError: 'VerifyEmail' should either include a `serializer_class` attribute, or override the `get_serializer_class()` method.
2022-09-15 03:01:04,883 [log | ERROR] Internal Server Error: /swagger/
Traceback (most recent call last):
  File "/usr/local/lib/python3.9/site-packages/redis/connection.py", line 611, in connect
    sock = self.retry.call_with_retry(
  File "/usr/local/lib/python3.9/site-packages/redis/retry.py", line 46, in call_with_retry
    return do()
  File "/usr/local/lib/python3.9/site-packages/redis/connection.py", line 612, in <lambda>
    lambda: self._connect(), lambda error: self.disconnect(error)
  File "/usr/local/lib/python3.9/site-packages/redis/connection.py", line 677, in _connect
    raise err
  File "/usr/local/lib/python3.9/site-packages/redis/connection.py", line 665, in _connect
    sock.connect(socket_address)
OSError: [Errno 99] Cannot assign requested address

During handling of the above exception, another exception occurred:

Traceback (most recent call last):
  File "/usr/local/lib/python3.9/site-packages/django/core/handlers/exception.py", line 55, in inner
    response = get_response(request)
  File "/backend/config/middleware.py", line 31, in __call__
    if not redis.exists(client_count) and not redis.exists(client_date):
  File "/usr/local/lib/python3.9/site-packages/redis/commands/core.py", line 1612, in exists
    return self.execute_command("EXISTS", *names)
  File "/usr/local/lib/python3.9/site-packages/redis/client.py", line 1235, in execute_command
    conn = self.connection or pool.get_connection(command_name, **options)
  File "/usr/local/lib/python3.9/site-packages/redis/connection.py", line 1387, in get_connection
    connection.connect()
  File "/usr/local/lib/python3.9/site-packages/redis/connection.py", line 617, in connect
    raise ConnectionError(self._error_message(e))
redis.exceptions.ConnectionError: Error 99 connecting to localhost:6379. Cannot assign requested address.
2022-09-15 03:01:16,144 [log | ERROR] Internal Server Error: /swagger/
Traceback (most recent call last):
  File "/usr/local/lib/python3.9/site-packages/redis/connection.py", line 611, in connect
    sock = self.retry.call_with_retry(
  File "/usr/local/lib/python3.9/site-packages/redis/retry.py", line 46, in call_with_retry
    return do()
  File "/usr/local/lib/python3.9/site-packages/redis/connection.py", line 612, in <lambda>
    lambda: self._connect(), lambda error: self.disconnect(error)
  File "/usr/local/lib/python3.9/site-packages/redis/connection.py", line 677, in _connect
    raise err
  File "/usr/local/lib/python3.9/site-packages/redis/connection.py", line 665, in _connect
    sock.connect(socket_address)
OSError: [Errno 99] Cannot assign requested address

During handling of the above exception, another exception occurred:

Traceback (most recent call last):
  File "/usr/local/lib/python3.9/site-packages/django/core/handlers/exception.py", line 55, in inner
    response = get_response(request)
  File "/backend/config/middleware.py", line 31, in __call__
    if not redis.exists(client_count) and not redis.exists(client_date):
  File "/usr/local/lib/python3.9/site-packages/redis/commands/core.py", line 1612, in exists
    return self.execute_command("EXISTS", *names)
  File "/usr/local/lib/python3.9/site-packages/redis/client.py", line 1235, in execute_command
    conn = self.connection or pool.get_connection(command_name, **options)
  File "/usr/local/lib/python3.9/site-packages/redis/connection.py", line 1387, in get_connection
    connection.connect()
  File "/usr/local/lib/python3.9/site-packages/redis/connection.py", line 617, in connect
    raise ConnectionError(self._error_message(e))
redis.exceptions.ConnectionError: Error 99 connecting to localhost:6379. Cannot assign requested address.
2022-09-15 03:01:20,755 [log | ERROR] Internal Server Error: /swagger/
Traceback (most recent call last):
  File "/usr/local/lib/python3.9/site-packages/redis/connection.py", line 611, in connect
    sock = self.retry.call_with_retry(
  File "/usr/local/lib/python3.9/site-packages/redis/retry.py", line 46, in call_with_retry
    return do()
  File "/usr/local/lib/python3.9/site-packages/redis/connection.py", line 612, in <lambda>
    lambda: self._connect(), lambda error: self.disconnect(error)
  File "/usr/local/lib/python3.9/site-packages/redis/connection.py", line 677, in _connect
    raise err
  File "/usr/local/lib/python3.9/site-packages/redis/connection.py", line 665, in _connect
    sock.connect(socket_address)
OSError: [Errno 99] Cannot assign requested address

During handling of the above exception, another exception occurred:

Traceback (most recent call last):
  File "/usr/local/lib/python3.9/site-packages/django/core/handlers/exception.py", line 55, in inner
    response = get_response(request)
  File "/backend/config/middleware.py", line 31, in __call__
    if not redis.exists(client_count) and not redis.exists(client_date):
  File "/usr/local/lib/python3.9/site-packages/redis/commands/core.py", line 1612, in exists
    return self.execute_command("EXISTS", *names)
  File "/usr/local/lib/python3.9/site-packages/redis/client.py", line 1235, in execute_command
    conn = self.connection or pool.get_connection(command_name, **options)
  File "/usr/local/lib/python3.9/site-packages/redis/connection.py", line 1387, in get_connection
    connection.connect()
  File "/usr/local/lib/python3.9/site-packages/redis/connection.py", line 617, in connect
    raise ConnectionError(self._error_message(e))
redis.exceptions.ConnectionError: Error 99 connecting to localhost:6379. Cannot assign requested address.
2022-09-15 03:01:30,827 [log | ERROR] Internal Server Error: /api/v1/city/
Traceback (most recent call last):
  File "/usr/local/lib/python3.9/site-packages/redis/connection.py", line 611, in connect
    sock = self.retry.call_with_retry(
  File "/usr/local/lib/python3.9/site-packages/redis/retry.py", line 46, in call_with_retry
    return do()
  File "/usr/local/lib/python3.9/site-packages/redis/connection.py", line 612, in <lambda>
    lambda: self._connect(), lambda error: self.disconnect(error)
  File "/usr/local/lib/python3.9/site-packages/redis/connection.py", line 677, in _connect
    raise err
  File "/usr/local/lib/python3.9/site-packages/redis/connection.py", line 665, in _connect
    sock.connect(socket_address)
OSError: [Errno 99] Cannot assign requested address

During handling of the above exception, another exception occurred:

Traceback (most recent call last):
  File "/usr/local/lib/python3.9/site-packages/django/core/handlers/exception.py", line 55, in inner
    response = get_response(request)
  File "/backend/config/middleware.py", line 31, in __call__
    if not redis.exists(client_count) and not redis.exists(client_date):
  File "/usr/local/lib/python3.9/site-packages/redis/commands/core.py", line 1612, in exists
    return self.execute_command("EXISTS", *names)
  File "/usr/local/lib/python3.9/site-packages/redis/client.py", line 1235, in execute_command
    conn = self.connection or pool.get_connection(command_name, **options)
  File "/usr/local/lib/python3.9/site-packages/redis/connection.py", line 1387, in get_connection
    connection.connect()
  File "/usr/local/lib/python3.9/site-packages/redis/connection.py", line 617, in connect
    raise ConnectionError(self._error_message(e))
redis.exceptions.ConnectionError: Error 99 connecting to localhost:6379. Cannot assign requested address.
2022-09-15 03:01:32,557 [log | ERROR] Internal Server Error: /api/v1/city/
Traceback (most recent call last):
  File "/usr/local/lib/python3.9/site-packages/redis/connection.py", line 611, in connect
    sock = self.retry.call_with_retry(
  File "/usr/local/lib/python3.9/site-packages/redis/retry.py", line 46, in call_with_retry
    return do()
  File "/usr/local/lib/python3.9/site-packages/redis/connection.py", line 612, in <lambda>
    lambda: self._connect(), lambda error: self.disconnect(error)
  File "/usr/local/lib/python3.9/site-packages/redis/connection.py", line 677, in _connect
    raise err
  File "/usr/local/lib/python3.9/site-packages/redis/connection.py", line 665, in _connect
    sock.connect(socket_address)
OSError: [Errno 99] Cannot assign requested address

During handling of the above exception, another exception occurred:

Traceback (most recent call last):
  File "/usr/local/lib/python3.9/site-packages/django/core/handlers/exception.py", line 55, in inner
    response = get_response(request)
  File "/backend/config/middleware.py", line 31, in __call__
    if not redis.exists(client_count) and not redis.exists(client_date):
  File "/usr/local/lib/python3.9/site-packages/redis/commands/core.py", line 1612, in exists
    return self.execute_command("EXISTS", *names)
  File "/usr/local/lib/python3.9/site-packages/redis/client.py", line 1235, in execute_command
    conn = self.connection or pool.get_connection(command_name, **options)
  File "/usr/local/lib/python3.9/site-packages/redis/connection.py", line 1387, in get_connection
    connection.connect()
  File "/usr/local/lib/python3.9/site-packages/redis/connection.py", line 617, in connect
    raise ConnectionError(self._error_message(e))
redis.exceptions.ConnectionError: Error 99 connecting to localhost:6379. Cannot assign requested address.
2022-09-15 03:01:33,423 [log | ERROR] Internal Server Error: /api/v1/city/
Traceback (most recent call last):
  File "/usr/local/lib/python3.9/site-packages/redis/connection.py", line 611, in connect
    sock = self.retry.call_with_retry(
  File "/usr/local/lib/python3.9/site-packages/redis/retry.py", line 46, in call_with_retry
    return do()
  File "/usr/local/lib/python3.9/site-packages/redis/connection.py", line 612, in <lambda>
    lambda: self._connect(), lambda error: self.disconnect(error)
  File "/usr/local/lib/python3.9/site-packages/redis/connection.py", line 677, in _connect
    raise err
  File "/usr/local/lib/python3.9/site-packages/redis/connection.py", line 665, in _connect
    sock.connect(socket_address)
OSError: [Errno 99] Cannot assign requested address

During handling of the above exception, another exception occurred:

Traceback (most recent call last):
  File "/usr/local/lib/python3.9/site-packages/django/core/handlers/exception.py", line 55, in inner
    response = get_response(request)
  File "/backend/config/middleware.py", line 31, in __call__
    if not redis.exists(client_count) and not redis.exists(client_date):
  File "/usr/local/lib/python3.9/site-packages/redis/commands/core.py", line 1612, in exists
    return self.execute_command("EXISTS", *names)
  File "/usr/local/lib/python3.9/site-packages/redis/client.py", line 1235, in execute_command
    conn = self.connection or pool.get_connection(command_name, **options)
  File "/usr/local/lib/python3.9/site-packages/redis/connection.py", line 1387, in get_connection
    connection.connect()
  File "/usr/local/lib/python3.9/site-packages/redis/connection.py", line 617, in connect
    raise ConnectionError(self._error_message(e))
redis.exceptions.ConnectionError: Error 99 connecting to localhost:6379. Cannot assign requested address.
2022-09-15 03:01:37,856 [log | ERROR] Internal Server Error: /api/v1/category/
Traceback (most recent call last):
  File "/usr/local/lib/python3.9/site-packages/redis/connection.py", line 611, in connect
    sock = self.retry.call_with_retry(
  File "/usr/local/lib/python3.9/site-packages/redis/retry.py", line 46, in call_with_retry
    return do()
  File "/usr/local/lib/python3.9/site-packages/redis/connection.py", line 612, in <lambda>
    lambda: self._connect(), lambda error: self.disconnect(error)
  File "/usr/local/lib/python3.9/site-packages/redis/connection.py", line 677, in _connect
    raise err
  File "/usr/local/lib/python3.9/site-packages/redis/connection.py", line 665, in _connect
    sock.connect(socket_address)
OSError: [Errno 99] Cannot assign requested address

During handling of the above exception, another exception occurred:

Traceback (most recent call last):
  File "/usr/local/lib/python3.9/site-packages/django/core/handlers/exception.py", line 55, in inner
    response = get_response(request)
  File "/backend/config/middleware.py", line 31, in __call__
    if not redis.exists(client_count) and not redis.exists(client_date):
  File "/usr/local/lib/python3.9/site-packages/redis/commands/core.py", line 1612, in exists
    return self.execute_command("EXISTS", *names)
  File "/usr/local/lib/python3.9/site-packages/redis/client.py", line 1235, in execute_command
    conn = self.connection or pool.get_connection(command_name, **options)
  File "/usr/local/lib/python3.9/site-packages/redis/connection.py", line 1387, in get_connection
    connection.connect()
  File "/usr/local/lib/python3.9/site-packages/redis/connection.py", line 617, in connect
    raise ConnectionError(self._error_message(e))
redis.exceptions.ConnectionError: Error 99 connecting to localhost:6379. Cannot assign requested address.
2022-09-15 03:01:45,550 [log | ERROR] Internal Server Error: /api/v1/category/
Traceback (most recent call last):
  File "/usr/local/lib/python3.9/site-packages/redis/connection.py", line 611, in connect
    sock = self.retry.call_with_retry(
  File "/usr/local/lib/python3.9/site-packages/redis/retry.py", line 46, in call_with_retry
    return do()
  File "/usr/local/lib/python3.9/site-packages/redis/connection.py", line 612, in <lambda>
    lambda: self._connect(), lambda error: self.disconnect(error)
  File "/usr/local/lib/python3.9/site-packages/redis/connection.py", line 677, in _connect
    raise err
  File "/usr/local/lib/python3.9/site-packages/redis/connection.py", line 665, in _connect
    sock.connect(socket_address)
OSError: [Errno 99] Cannot assign requested address

During handling of the above exception, another exception occurred:

Traceback (most recent call last):
  File "/usr/local/lib/python3.9/site-packages/django/core/handlers/exception.py", line 55, in inner
    response = get_response(request)
  File "/backend/config/middleware.py", line 31, in __call__
    if not redis.exists(client_count) and not redis.exists(client_date):
  File "/usr/local/lib/python3.9/site-packages/redis/commands/core.py", line 1612, in exists
    return self.execute_command("EXISTS", *names)
  File "/usr/local/lib/python3.9/site-packages/redis/client.py", line 1235, in execute_command
    conn = self.connection or pool.get_connection(command_name, **options)
  File "/usr/local/lib/python3.9/site-packages/redis/connection.py", line 1387, in get_connection
    connection.connect()
  File "/usr/local/lib/python3.9/site-packages/redis/connection.py", line 617, in connect
    raise ConnectionError(self._error_message(e))
redis.exceptions.ConnectionError: Error 99 connecting to localhost:6379. Cannot assign requested address.
2022-09-15 03:01:50,013 [log | ERROR] Internal Server Error: /
Traceback (most recent call last):
  File "/usr/local/lib/python3.9/site-packages/redis/connection.py", line 611, in connect
    sock = self.retry.call_with_retry(
  File "/usr/local/lib/python3.9/site-packages/redis/retry.py", line 46, in call_with_retry
    return do()
  File "/usr/local/lib/python3.9/site-packages/redis/connection.py", line 612, in <lambda>
    lambda: self._connect(), lambda error: self.disconnect(error)
  File "/usr/local/lib/python3.9/site-packages/redis/connection.py", line 677, in _connect
    raise err
  File "/usr/local/lib/python3.9/site-packages/redis/connection.py", line 665, in _connect
    sock.connect(socket_address)
OSError: [Errno 99] Cannot assign requested address

During handling of the above exception, another exception occurred:

Traceback (most recent call last):
  File "/usr/local/lib/python3.9/site-packages/django/core/handlers/exception.py", line 55, in inner
    response = get_response(request)
  File "/backend/config/middleware.py", line 31, in __call__
    if not redis.exists(client_count) and not redis.exists(client_date):
  File "/usr/local/lib/python3.9/site-packages/redis/commands/core.py", line 1612, in exists
    return self.execute_command("EXISTS", *names)
  File "/usr/local/lib/python3.9/site-packages/redis/client.py", line 1235, in execute_command
    conn = self.connection or pool.get_connection(command_name, **options)
  File "/usr/local/lib/python3.9/site-packages/redis/connection.py", line 1387, in get_connection
    connection.connect()
  File "/usr/local/lib/python3.9/site-packages/redis/connection.py", line 617, in connect
    raise ConnectionError(self._error_message(e))
redis.exceptions.ConnectionError: Error 99 connecting to localhost:6379. Cannot assign requested address.
2022-09-15 03:02:19,402 [log | ERROR] Internal Server Error: /
Traceback (most recent call last):
  File "/usr/local/lib/python3.9/site-packages/redis/connection.py", line 611, in connect
    sock = self.retry.call_with_retry(
  File "/usr/local/lib/python3.9/site-packages/redis/retry.py", line 46, in call_with_retry
    return do()
  File "/usr/local/lib/python3.9/site-packages/redis/connection.py", line 612, in <lambda>
    lambda: self._connect(), lambda error: self.disconnect(error)
  File "/usr/local/lib/python3.9/site-packages/redis/connection.py", line 677, in _connect
    raise err
  File "/usr/local/lib/python3.9/site-packages/redis/connection.py", line 665, in _connect
    sock.connect(socket_address)
OSError: [Errno 99] Cannot assign requested address

During handling of the above exception, another exception occurred:

Traceback (most recent call last):
  File "/usr/local/lib/python3.9/site-packages/django/core/handlers/exception.py", line 55, in inner
    response = get_response(request)
  File "/backend/config/middleware.py", line 31, in __call__
    if not redis.exists(client_count) and not redis.exists(client_date):
  File "/usr/local/lib/python3.9/site-packages/redis/commands/core.py", line 1612, in exists
    return self.execute_command("EXISTS", *names)
  File "/usr/local/lib/python3.9/site-packages/redis/client.py", line 1235, in execute_command
    conn = self.connection or pool.get_connection(command_name, **options)
  File "/usr/local/lib/python3.9/site-packages/redis/connection.py", line 1387, in get_connection
    connection.connect()
  File "/usr/local/lib/python3.9/site-packages/redis/connection.py", line 617, in connect
    raise ConnectionError(self._error_message(e))
redis.exceptions.ConnectionError: Error 99 connecting to localhost:6379. Cannot assign requested address.
2022-09-15 03:02:19,984 [log | ERROR] Internal Server Error: /
Traceback (most recent call last):
  File "/usr/local/lib/python3.9/site-packages/redis/connection.py", line 611, in connect
    sock = self.retry.call_with_retry(
  File "/usr/local/lib/python3.9/site-packages/redis/retry.py", line 46, in call_with_retry
    return do()
  File "/usr/local/lib/python3.9/site-packages/redis/connection.py", line 612, in <lambda>
    lambda: self._connect(), lambda error: self.disconnect(error)
  File "/usr/local/lib/python3.9/site-packages/redis/connection.py", line 677, in _connect
    raise err
  File "/usr/local/lib/python3.9/site-packages/redis/connection.py", line 665, in _connect
    sock.connect(socket_address)
OSError: [Errno 99] Cannot assign requested address

During handling of the above exception, another exception occurred:

Traceback (most recent call last):
  File "/usr/local/lib/python3.9/site-packages/django/core/handlers/exception.py", line 55, in inner
    response = get_response(request)
  File "/backend/config/middleware.py", line 31, in __call__
    if not redis.exists(client_count) and not redis.exists(client_date):
  File "/usr/local/lib/python3.9/site-packages/redis/commands/core.py", line 1612, in exists
    return self.execute_command("EXISTS", *names)
  File "/usr/local/lib/python3.9/site-packages/redis/client.py", line 1235, in execute_command
    conn = self.connection or pool.get_connection(command_name, **options)
  File "/usr/local/lib/python3.9/site-packages/redis/connection.py", line 1387, in get_connection
    connection.connect()
  File "/usr/local/lib/python3.9/site-packages/redis/connection.py", line 617, in connect
    raise ConnectionError(self._error_message(e))
redis.exceptions.ConnectionError: Error 99 connecting to localhost:6379. Cannot assign requested address.
2022-09-15 03:02:20,635 [log | ERROR] Internal Server Error: /
Traceback (most recent call last):
  File "/usr/local/lib/python3.9/site-packages/redis/connection.py", line 611, in connect
    sock = self.retry.call_with_retry(
  File "/usr/local/lib/python3.9/site-packages/redis/retry.py", line 46, in call_with_retry
    return do()
  File "/usr/local/lib/python3.9/site-packages/redis/connection.py", line 612, in <lambda>
    lambda: self._connect(), lambda error: self.disconnect(error)
  File "/usr/local/lib/python3.9/site-packages/redis/connection.py", line 677, in _connect
    raise err
  File "/usr/local/lib/python3.9/site-packages/redis/connection.py", line 665, in _connect
    sock.connect(socket_address)
OSError: [Errno 99] Cannot assign requested address

During handling of the above exception, another exception occurred:

Traceback (most recent call last):
  File "/usr/local/lib/python3.9/site-packages/django/core/handlers/exception.py", line 55, in inner
    response = get_response(request)
  File "/backend/config/middleware.py", line 31, in __call__
    if not redis.exists(client_count) and not redis.exists(client_date):
  File "/usr/local/lib/python3.9/site-packages/redis/commands/core.py", line 1612, in exists
    return self.execute_command("EXISTS", *names)
  File "/usr/local/lib/python3.9/site-packages/redis/client.py", line 1235, in execute_command
    conn = self.connection or pool.get_connection(command_name, **options)
  File "/usr/local/lib/python3.9/site-packages/redis/connection.py", line 1387, in get_connection
    connection.connect()
  File "/usr/local/lib/python3.9/site-packages/redis/connection.py", line 617, in connect
    raise ConnectionError(self._error_message(e))
redis.exceptions.ConnectionError: Error 99 connecting to localhost:6379. Cannot assign requested address.
2022-09-15 03:02:21,547 [log | ERROR] Internal Server Error: /
Traceback (most recent call last):
  File "/usr/local/lib/python3.9/site-packages/redis/connection.py", line 611, in connect
    sock = self.retry.call_with_retry(
  File "/usr/local/lib/python3.9/site-packages/redis/retry.py", line 46, in call_with_retry
    return do()
  File "/usr/local/lib/python3.9/site-packages/redis/connection.py", line 612, in <lambda>
    lambda: self._connect(), lambda error: self.disconnect(error)
  File "/usr/local/lib/python3.9/site-packages/redis/connection.py", line 677, in _connect
    raise err
  File "/usr/local/lib/python3.9/site-packages/redis/connection.py", line 665, in _connect
    sock.connect(socket_address)
OSError: [Errno 99] Cannot assign requested address

During handling of the above exception, another exception occurred:

Traceback (most recent call last):
  File "/usr/local/lib/python3.9/site-packages/django/core/handlers/exception.py", line 55, in inner
    response = get_response(request)
  File "/backend/config/middleware.py", line 31, in __call__
    if not redis.exists(client_count) and not redis.exists(client_date):
  File "/usr/local/lib/python3.9/site-packages/redis/commands/core.py", line 1612, in exists
    return self.execute_command("EXISTS", *names)
  File "/usr/local/lib/python3.9/site-packages/redis/client.py", line 1235, in execute_command
    conn = self.connection or pool.get_connection(command_name, **options)
  File "/usr/local/lib/python3.9/site-packages/redis/connection.py", line 1387, in get_connection
    connection.connect()
  File "/usr/local/lib/python3.9/site-packages/redis/connection.py", line 617, in connect
    raise ConnectionError(self._error_message(e))
redis.exceptions.ConnectionError: Error 99 connecting to localhost:6379. Cannot assign requested address.
2022-09-15 03:02:22,208 [log | ERROR] Internal Server Error: /
Traceback (most recent call last):
  File "/usr/local/lib/python3.9/site-packages/redis/connection.py", line 611, in connect
    sock = self.retry.call_with_retry(
  File "/usr/local/lib/python3.9/site-packages/redis/retry.py", line 46, in call_with_retry
    return do()
  File "/usr/local/lib/python3.9/site-packages/redis/connection.py", line 612, in <lambda>
    lambda: self._connect(), lambda error: self.disconnect(error)
  File "/usr/local/lib/python3.9/site-packages/redis/connection.py", line 677, in _connect
    raise err
  File "/usr/local/lib/python3.9/site-packages/redis/connection.py", line 665, in _connect
    sock.connect(socket_address)
OSError: [Errno 99] Cannot assign requested address

During handling of the above exception, another exception occurred:

Traceback (most recent call last):
  File "/usr/local/lib/python3.9/site-packages/django/core/handlers/exception.py", line 55, in inner
    response = get_response(request)
  File "/backend/config/middleware.py", line 31, in __call__
    if not redis.exists(client_count) and not redis.exists(client_date):
  File "/usr/local/lib/python3.9/site-packages/redis/commands/core.py", line 1612, in exists
    return self.execute_command("EXISTS", *names)
  File "/usr/local/lib/python3.9/site-packages/redis/client.py", line 1235, in execute_command
    conn = self.connection or pool.get_connection(command_name, **options)
  File "/usr/local/lib/python3.9/site-packages/redis/connection.py", line 1387, in get_connection
    connection.connect()
  File "/usr/local/lib/python3.9/site-packages/redis/connection.py", line 617, in connect
    raise ConnectionError(self._error_message(e))
redis.exceptions.ConnectionError: Error 99 connecting to localhost:6379. Cannot assign requested address.
2022-09-15 03:02:31,996 [log | ERROR] Internal Server Error: /
Traceback (most recent call last):
  File "/usr/local/lib/python3.9/site-packages/redis/connection.py", line 611, in connect
    sock = self.retry.call_with_retry(
  File "/usr/local/lib/python3.9/site-packages/redis/retry.py", line 46, in call_with_retry
    return do()
  File "/usr/local/lib/python3.9/site-packages/redis/connection.py", line 612, in <lambda>
    lambda: self._connect(), lambda error: self.disconnect(error)
  File "/usr/local/lib/python3.9/site-packages/redis/connection.py", line 677, in _connect
    raise err
  File "/usr/local/lib/python3.9/site-packages/redis/connection.py", line 665, in _connect
    sock.connect(socket_address)
OSError: [Errno 99] Cannot assign requested address

During handling of the above exception, another exception occurred:

Traceback (most recent call last):
  File "/usr/local/lib/python3.9/site-packages/django/core/handlers/exception.py", line 55, in inner
    response = get_response(request)
  File "/backend/config/middleware.py", line 31, in __call__
    if not redis.exists(client_count) and not redis.exists(client_date):
  File "/usr/local/lib/python3.9/site-packages/redis/commands/core.py", line 1612, in exists
    return self.execute_command("EXISTS", *names)
  File "/usr/local/lib/python3.9/site-packages/redis/client.py", line 1235, in execute_command
    conn = self.connection or pool.get_connection(command_name, **options)
  File "/usr/local/lib/python3.9/site-packages/redis/connection.py", line 1387, in get_connection
    connection.connect()
  File "/usr/local/lib/python3.9/site-packages/redis/connection.py", line 617, in connect
    raise ConnectionError(self._error_message(e))
redis.exceptions.ConnectionError: Error 99 connecting to localhost:6379. Cannot assign requested address.
2022-09-15 03:02:32,620 [log | ERROR] Internal Server Error: /
Traceback (most recent call last):
  File "/usr/local/lib/python3.9/site-packages/redis/connection.py", line 611, in connect
    sock = self.retry.call_with_retry(
  File "/usr/local/lib/python3.9/site-packages/redis/retry.py", line 46, in call_with_retry
    return do()
  File "/usr/local/lib/python3.9/site-packages/redis/connection.py", line 612, in <lambda>
    lambda: self._connect(), lambda error: self.disconnect(error)
  File "/usr/local/lib/python3.9/site-packages/redis/connection.py", line 677, in _connect
    raise err
  File "/usr/local/lib/python3.9/site-packages/redis/connection.py", line 665, in _connect
    sock.connect(socket_address)
OSError: [Errno 99] Cannot assign requested address

During handling of the above exception, another exception occurred:

Traceback (most recent call last):
  File "/usr/local/lib/python3.9/site-packages/django/core/handlers/exception.py", line 55, in inner
    response = get_response(request)
  File "/backend/config/middleware.py", line 31, in __call__
    if not redis.exists(client_count) and not redis.exists(client_date):
  File "/usr/local/lib/python3.9/site-packages/redis/commands/core.py", line 1612, in exists
    return self.execute_command("EXISTS", *names)
  File "/usr/local/lib/python3.9/site-packages/redis/client.py", line 1235, in execute_command
    conn = self.connection or pool.get_connection(command_name, **options)
  File "/usr/local/lib/python3.9/site-packages/redis/connection.py", line 1387, in get_connection
    connection.connect()
  File "/usr/local/lib/python3.9/site-packages/redis/connection.py", line 617, in connect
    raise ConnectionError(self._error_message(e))
redis.exceptions.ConnectionError: Error 99 connecting to localhost:6379. Cannot assign requested address.
2022-09-15 03:08:09,680 [autoreload | INFO] /Users/zharkynaskatkyzy/PycharmProjects/Zmall/server/apps/advert/views/advert_views.py changed, reloading.
2022-09-15 03:08:10,336 [autoreload | INFO] Watching for file changes with StatReloader
2022-09-15 03:10:26,200 [log | WARNING] Not Found: /api/v1/user_advert/89/
2022-09-15 03:10:47,647 [base | WARNING] view's ContactView raised exception during schema generation; use `getattr(self, 'swagger_fake_view', False)` to detect and short-circuit this
Traceback (most recent call last):
  File "/Library/Frameworks/Python.framework/Versions/3.10/lib/python3.10/site-packages/drf_yasg/inspectors/base.py", line 42, in call_view_method
    return view_method()
  File "/Library/Frameworks/Python.framework/Versions/3.10/lib/python3.10/site-packages/rest_framework/generics.py", line 108, in get_serializer
    serializer_class = self.get_serializer_class()
  File "/Library/Frameworks/Python.framework/Versions/3.10/lib/python3.10/site-packages/rest_framework/generics.py", line 122, in get_serializer_class
    assert self.serializer_class is not None, (
AssertionError: 'ContactView' should either include a `serializer_class` attribute, or override the `get_serializer_class()` method.
2022-09-15 03:10:47,648 [base | WARNING] view's ContactView raised exception during schema generation; use `getattr(self, 'swagger_fake_view', False)` to detect and short-circuit this
Traceback (most recent call last):
  File "/Library/Frameworks/Python.framework/Versions/3.10/lib/python3.10/site-packages/drf_yasg/inspectors/base.py", line 42, in call_view_method
    return view_method()
  File "/Library/Frameworks/Python.framework/Versions/3.10/lib/python3.10/site-packages/rest_framework/generics.py", line 108, in get_serializer
    serializer_class = self.get_serializer_class()
  File "/Library/Frameworks/Python.framework/Versions/3.10/lib/python3.10/site-packages/rest_framework/generics.py", line 122, in get_serializer_class
    assert self.serializer_class is not None, (
AssertionError: 'ContactView' should either include a `serializer_class` attribute, or override the `get_serializer_class()` method.
2022-09-15 03:10:47,662 [base | WARNING] view's VerifyEmail raised exception during schema generation; use `getattr(self, 'swagger_fake_view', False)` to detect and short-circuit this
Traceback (most recent call last):
  File "/Library/Frameworks/Python.framework/Versions/3.10/lib/python3.10/site-packages/drf_yasg/inspectors/base.py", line 42, in call_view_method
    return view_method()
  File "/Library/Frameworks/Python.framework/Versions/3.10/lib/python3.10/site-packages/rest_framework/generics.py", line 108, in get_serializer
    serializer_class = self.get_serializer_class()
  File "/Library/Frameworks/Python.framework/Versions/3.10/lib/python3.10/site-packages/rest_framework/generics.py", line 122, in get_serializer_class
    assert self.serializer_class is not None, (
AssertionError: 'VerifyEmail' should either include a `serializer_class` attribute, or override the `get_serializer_class()` method.
2022-09-15 03:11:12,702 [log | WARNING] Not Found: /api/v1/user_advert/89/
2022-09-15 03:11:21,926 [log | WARNING] Not Found: /api/v1/user_advert/89/
2022-09-15 03:11:22,599 [log | WARNING] Not Found: /api/v1/user_advert/89/
2022-09-15 03:11:23,127 [log | WARNING] Not Found: /api/v1/user_advert/89/
2022-09-15 03:11:23,587 [log | WARNING] Not Found: /api/v1/user_advert/89/
2022-09-15 03:11:23,981 [log | WARNING] Not Found: /api/v1/user_advert/89/
2022-09-15 03:12:10,407 [log | WARNING] Not Found: /api/v1/user_advert_update/89/
2022-09-15 03:12:32,674 [log | WARNING] Not Found: /api/v1/user_advert/89/
2022-09-15 03:12:36,249 [log | WARNING] Not Found: /api/v1/user_advert/89/
2022-09-15 03:13:01,163 [log | WARNING] Not Found: /api/v1/user_advert/82/
2022-09-15 03:13:02,221 [log | WARNING] Not Found: /api/v1/user_advert/82/
2022-09-15 03:13:02,904 [log | WARNING] Not Found: /api/v1/user_advert/82/
2022-09-15 03:13:04,171 [log | WARNING] Not Found: /api/v1/user_advert/82/
2022-09-15 03:13:15,008 [log | WARNING] Not Found: /api/v1/user_advert/82/
2022-09-15 03:13:15,673 [log | WARNING] Not Found: /api/v1/user_advert/82/
2022-09-15 03:13:16,180 [log | WARNING] Not Found: /api/v1/user_advert/82/
2022-09-15 03:13:27,726 [log | WARNING] Method Not Allowed: /api/v1/user/login/
2022-09-15 03:14:23,965 [log | WARNING] Not Found: /api/v1/user_advert/82/
2022-09-15 03:14:24,732 [log | WARNING] Not Found: /api/v1/user_advert/82/
2022-09-15 03:15:04,618 [log | WARNING] Unauthorized: /api/v1/user_advert_update/82/
2022-09-15 03:16:53,696 [autoreload | INFO] /Users/zharkynaskatkyzy/PycharmProjects/Zmall/server/apps/advert/models.py changed, reloading.
2022-09-15 03:16:54,878 [autoreload | INFO] Watching for file changes with StatReloader
2022-09-15 03:17:40,815 [autoreload | INFO] /Users/zharkynaskatkyzy/PycharmProjects/Zmall/server/apps/advert/models.py changed, reloading.
2022-09-15 03:17:41,423 [autoreload | INFO] Watching for file changes with StatReloader
2022-09-15 03:20:04,863 [autoreload | INFO] /Users/zharkynaskatkyzy/PycharmProjects/Zmall/server/apps/advert/serializers/advert_serializers.py changed, reloading.
2022-09-15 03:20:05,492 [autoreload | INFO] Watching for file changes with StatReloader
2022-09-15 03:21:40,024 [autoreload | INFO] /Users/zharkynaskatkyzy/PycharmProjects/Zmall/server/apps/advert/urls.py changed, reloading.
2022-09-15 03:21:40,643 [autoreload | INFO] Watching for file changes with StatReloader
2022-09-15 03:21:48,679 [base | WARNING] view's ContactView raised exception during schema generation; use `getattr(self, 'swagger_fake_view', False)` to detect and short-circuit this
Traceback (most recent call last):
  File "/Library/Frameworks/Python.framework/Versions/3.10/lib/python3.10/site-packages/drf_yasg/inspectors/base.py", line 42, in call_view_method
    return view_method()
  File "/Library/Frameworks/Python.framework/Versions/3.10/lib/python3.10/site-packages/rest_framework/generics.py", line 108, in get_serializer
    serializer_class = self.get_serializer_class()
  File "/Library/Frameworks/Python.framework/Versions/3.10/lib/python3.10/site-packages/rest_framework/generics.py", line 122, in get_serializer_class
    assert self.serializer_class is not None, (
AssertionError: 'ContactView' should either include a `serializer_class` attribute, or override the `get_serializer_class()` method.
2022-09-15 03:21:48,680 [base | WARNING] view's ContactView raised exception during schema generation; use `getattr(self, 'swagger_fake_view', False)` to detect and short-circuit this
Traceback (most recent call last):
  File "/Library/Frameworks/Python.framework/Versions/3.10/lib/python3.10/site-packages/drf_yasg/inspectors/base.py", line 42, in call_view_method
    return view_method()
  File "/Library/Frameworks/Python.framework/Versions/3.10/lib/python3.10/site-packages/rest_framework/generics.py", line 108, in get_serializer
    serializer_class = self.get_serializer_class()
  File "/Library/Frameworks/Python.framework/Versions/3.10/lib/python3.10/site-packages/rest_framework/generics.py", line 122, in get_serializer_class
    assert self.serializer_class is not None, (
AssertionError: 'ContactView' should either include a `serializer_class` attribute, or override the `get_serializer_class()` method.
2022-09-15 03:21:48,692 [base | WARNING] view's VerifyEmail raised exception during schema generation; use `getattr(self, 'swagger_fake_view', False)` to detect and short-circuit this
Traceback (most recent call last):
  File "/Library/Frameworks/Python.framework/Versions/3.10/lib/python3.10/site-packages/drf_yasg/inspectors/base.py", line 42, in call_view_method
    return view_method()
  File "/Library/Frameworks/Python.framework/Versions/3.10/lib/python3.10/site-packages/rest_framework/generics.py", line 108, in get_serializer
    serializer_class = self.get_serializer_class()
  File "/Library/Frameworks/Python.framework/Versions/3.10/lib/python3.10/site-packages/rest_framework/generics.py", line 122, in get_serializer_class
    assert self.serializer_class is not None, (
AssertionError: 'VerifyEmail' should either include a `serializer_class` attribute, or override the `get_serializer_class()` method.
2022-09-15 03:22:47,613 [autoreload | INFO] /Users/zharkynaskatkyzy/PycharmProjects/Zmall/server/apps/advert/admin.py changed, reloading.
2022-09-15 03:22:48,237 [autoreload | INFO] Watching for file changes with StatReloader
2022-09-15 03:24:11,467 [autoreload | INFO] /Users/zharkynaskatkyzy/PycharmProjects/Zmall/server/apps/advert/models.py changed, reloading.
2022-09-15 03:24:12,424 [autoreload | INFO] Watching for file changes with StatReloader
2022-09-15 03:26:45,896 [autoreload | INFO] /Users/zharkynaskatkyzy/PycharmProjects/Zmall/server/config/settings/base.py changed, reloading.
2022-09-15 03:26:46,470 [autoreload | INFO] Watching for file changes with StatReloader
2022-09-15 03:39:01,678 [autoreload | INFO] Watching for file changes with StatReloader
2022-09-15 03:40:31,886 [autoreload | INFO] /Users/zharkynaskatkyzy/PycharmProjects/Zmall/server/config/settings/base.py changed, reloading.
2022-09-15 03:40:32,869 [autoreload | INFO] Watching for file changes with StatReloader
2022-09-15 03:51:05,101 [autoreload | INFO] /Users/zharkynaskatkyzy/PycharmProjects/Zmall/server/config/settings/base.py changed, reloading.
2022-09-15 03:51:06,080 [autoreload | INFO] Watching for file changes with StatReloader
2022-09-15 03:52:28,997 [log | WARNING] Not Found: /
2022-09-15 04:17:59,583 [log | WARNING] Bad Request: /api/v1/advert/
2022-09-15 04:23:04,934 [autoreload | INFO] /Users/zharkynaskatkyzy/PycharmProjects/Zmall/server/config/settings/base.py changed, reloading.
2022-09-15 04:23:08,966 [autoreload | INFO] Watching for file changes with StatReloader
2022-09-15 04:23:54,964 [log | WARNING] Bad Request: /api/v1/advert/
2022-09-15 04:25:11,483 [log | WARNING] Bad Request: /api/v1/advert/
2022-09-15 04:30:10,447 [log | WARNING] Bad Request: /api/v1/advert/
2022-09-15 04:30:28,322 [log | WARNING] Bad Request: /api/v1/advert/
2022-09-15 04:33:28,421 [log | WARNING] Bad Request: /api/v1/advert/
2022-09-15 04:33:42,798 [log | WARNING] Bad Request: /api/v1/advert/
2022-09-15 04:33:48,998 [autoreload | INFO] Watching for file changes with StatReloader
2022-09-15 05:16:38,317 [log | WARNING] Bad Request: /api/v1/advert/
2022-09-15 05:16:53,177 [log | WARNING] Bad Request: /api/v1/advert/
2022-09-15 05:17:39,430 [log | WARNING] Bad Request: /api/v1/advert/
2022-09-15 05:17:52,178 [log | WARNING] Bad Request: /api/v1/advert/
2022-09-15 05:18:07,511 [log | WARNING] Bad Request: /api/v1/advert/
2022-09-15 05:28:45,006 [log | WARNING] Bad Request: /api/v1/advert/
2022-09-15 05:35:18,386 [log | WARNING] Bad Request: /api/v1/advert/
2022-09-15 05:40:04,032 [log | WARNING] Bad Request: /api/v1/advert/
2022-09-15 05:43:19,763 [log | WARNING] Bad Request: /api/v1/advert/
2022-09-15 05:49:39,433 [log | WARNING] Bad Request: /api/v1/advert/
2022-09-15 05:52:22,388 [log | WARNING] Bad Request: /api/v1/advert/
2022-09-15 05:53:33,286 [log | WARNING] Bad Request: /api/v1/advert/
2022-09-15 05:56:13,776 [log | WARNING] Bad Request: /api/v1/advert/
2022-09-15 05:56:36,262 [log | WARNING] Bad Request: /api/v1/advert/
2022-09-15 05:56:52,623 [log | WARNING] Bad Request: /api/v1/advert/
2022-09-15 06:00:41,840 [log | WARNING] Bad Request: /api/v1/advert/
2022-09-15 06:02:12,546 [autoreload | INFO] Watching for file changes with StatReloader
2022-09-15 06:02:18,588 [autoreload | INFO] Watching for file changes with StatReloader
2022-09-15 06:03:21,040 [autoreload | INFO] /Users/zharkynaskatkyzy/PycharmProjects/Zmall/server/config/settings/local.py changed, reloading.
2022-09-15 06:03:22,202 [autoreload | INFO] Watching for file changes with StatReloader
2022-09-15 06:03:24,362 [log | WARNING] Bad Request: /api/v1/advert/
2022-09-15 06:06:19,964 [log | WARNING] Bad Request: /api/v1/advert/
2022-09-15 07:29:16,703 [log | WARNING] Unauthorized: /api/v1/advert/
2022-09-15 07:29:50,503 [log | WARNING] Method Not Allowed: /api/v1/advert/
2022-09-15 07:33:42,252 [log | WARNING] Method Not Allowed: /api/v1/user/login/
2022-09-15 07:34:09,444 [base | WARNING] view's ContactView raised exception during schema generation; use `getattr(self, 'swagger_fake_view', False)` to detect and short-circuit this
Traceback (most recent call last):
  File "/Library/Frameworks/Python.framework/Versions/3.10/lib/python3.10/site-packages/drf_yasg/inspectors/base.py", line 42, in call_view_method
    return view_method()
  File "/Library/Frameworks/Python.framework/Versions/3.10/lib/python3.10/site-packages/rest_framework/generics.py", line 108, in get_serializer
    serializer_class = self.get_serializer_class()
  File "/Library/Frameworks/Python.framework/Versions/3.10/lib/python3.10/site-packages/rest_framework/generics.py", line 122, in get_serializer_class
    assert self.serializer_class is not None, (
AssertionError: 'ContactView' should either include a `serializer_class` attribute, or override the `get_serializer_class()` method.
2022-09-15 07:34:09,447 [base | WARNING] view's ContactView raised exception during schema generation; use `getattr(self, 'swagger_fake_view', False)` to detect and short-circuit this
Traceback (most recent call last):
  File "/Library/Frameworks/Python.framework/Versions/3.10/lib/python3.10/site-packages/drf_yasg/inspectors/base.py", line 42, in call_view_method
    return view_method()
  File "/Library/Frameworks/Python.framework/Versions/3.10/lib/python3.10/site-packages/rest_framework/generics.py", line 108, in get_serializer
    serializer_class = self.get_serializer_class()
  File "/Library/Frameworks/Python.framework/Versions/3.10/lib/python3.10/site-packages/rest_framework/generics.py", line 122, in get_serializer_class
    assert self.serializer_class is not None, (
AssertionError: 'ContactView' should either include a `serializer_class` attribute, or override the `get_serializer_class()` method.
2022-09-15 07:34:09,466 [base | WARNING] view's VerifyEmail raised exception during schema generation; use `getattr(self, 'swagger_fake_view', False)` to detect and short-circuit this
Traceback (most recent call last):
  File "/Library/Frameworks/Python.framework/Versions/3.10/lib/python3.10/site-packages/drf_yasg/inspectors/base.py", line 42, in call_view_method
    return view_method()
  File "/Library/Frameworks/Python.framework/Versions/3.10/lib/python3.10/site-packages/rest_framework/generics.py", line 108, in get_serializer
    serializer_class = self.get_serializer_class()
  File "/Library/Frameworks/Python.framework/Versions/3.10/lib/python3.10/site-packages/rest_framework/generics.py", line 122, in get_serializer_class
    assert self.serializer_class is not None, (
AssertionError: 'VerifyEmail' should either include a `serializer_class` attribute, or override the `get_serializer_class()` method.
2022-09-15 07:34:40,043 [log | WARNING] Unauthorized: /api/v1/admin/advert/
2022-09-15 07:43:16,902 [autoreload | INFO] /Users/zharkynaskatkyzy/PycharmProjects/Zmall/server/apps/advert/models.py changed, reloading.
2022-09-15 07:43:18,148 [autoreload | INFO] Watching for file changes with StatReloader
2022-09-15 07:43:19,937 [log | WARNING] Unsupported Media Type: /api/v1/advert/
2022-09-15 07:44:25,543 [log | WARNING] Unsupported Media Type: /api/v1/advert/
2022-09-15 07:45:14,791 [log | WARNING] Unsupported Media Type: /api/v1/advert/
2022-09-15 07:45:43,925 [log | WARNING] Unsupported Media Type: /api/v1/advert/
2022-09-15 07:47:16,844 [log | WARNING] Unsupported Media Type: /api/v1/advert/
2022-09-15 07:48:48,365 [log | WARNING] Unsupported Media Type: /api/v1/advert/
2022-09-15 07:49:21,876 [log | WARNING] Unsupported Media Type: /api/v1/advert/
2022-09-15 07:52:54,992 [log | WARNING] Bad Request: /api/v1/advert/
2022-09-15 07:56:54,646 [log | WARNING] Bad Request: /api/v1/advert/
2022-09-15 08:04:24,181 [autoreload | INFO] /Users/zharkynaskatkyzy/PycharmProjects/Zmall/server/apps/advert/serializers/advert_serializers.py changed, reloading.
2022-09-15 08:04:25,058 [autoreload | INFO] Watching for file changes with StatReloader
2022-09-15 08:05:25,374 [autoreload | INFO] /Users/zharkynaskatkyzy/PycharmProjects/Zmall/server/apps/advert/serializers/advert_serializers.py changed, reloading.
2022-09-15 08:05:25,902 [autoreload | INFO] Watching for file changes with StatReloader
2022-09-15 08:05:43,509 [log | WARNING] Not Found: /
2022-09-15 08:05:45,958 [log | WARNING] Not Found: /
2022-09-15 08:05:57,157 [log | ERROR] Internal Server Error: /api/v1/advert/1/
Traceback (most recent call last):
  File "/Library/Frameworks/Python.framework/Versions/3.10/lib/python3.10/site-packages/django/core/handlers/exception.py", line 55, in inner
    response = get_response(request)
  File "/Library/Frameworks/Python.framework/Versions/3.10/lib/python3.10/site-packages/django/core/handlers/base.py", line 197, in _get_response
    response = wrapped_callback(request, *callback_args, **callback_kwargs)
  File "/Library/Frameworks/Python.framework/Versions/3.10/lib/python3.10/site-packages/django/views/decorators/csrf.py", line 54, in wrapped_view
    return view_func(*args, **kwargs)
  File "/Library/Frameworks/Python.framework/Versions/3.10/lib/python3.10/site-packages/rest_framework/viewsets.py", line 125, in view
    return self.dispatch(request, *args, **kwargs)
  File "/Library/Frameworks/Python.framework/Versions/3.10/lib/python3.10/site-packages/rest_framework/views.py", line 509, in dispatch
    response = self.handle_exception(exc)
  File "/Library/Frameworks/Python.framework/Versions/3.10/lib/python3.10/site-packages/rest_framework/views.py", line 469, in handle_exception
    self.raise_uncaught_exception(exc)
  File "/Library/Frameworks/Python.framework/Versions/3.10/lib/python3.10/site-packages/rest_framework/views.py", line 480, in raise_uncaught_exception
    raise exc
  File "/Library/Frameworks/Python.framework/Versions/3.10/lib/python3.10/site-packages/rest_framework/views.py", line 506, in dispatch
    response = handler(request, *args, **kwargs)
  File "/Library/Frameworks/Python.framework/Versions/3.10/lib/python3.10/site-packages/rest_framework/mixins.py", line 56, in retrieve
    return Response(serializer.data)
  File "/Library/Frameworks/Python.framework/Versions/3.10/lib/python3.10/site-packages/rest_framework/serializers.py", line 555, in data
    ret = super().data
  File "/Library/Frameworks/Python.framework/Versions/3.10/lib/python3.10/site-packages/rest_framework/serializers.py", line 253, in data
    self._data = self.to_representation(self.instance)
  File "/Library/Frameworks/Python.framework/Versions/3.10/lib/python3.10/site-packages/rest_framework/serializers.py", line 522, in to_representation
    ret[field.field_name] = field.to_representation(attribute)
  File "/Library/Frameworks/Python.framework/Versions/3.10/lib/python3.10/site-packages/rest_framework/fields.py", line 1886, in to_representation
    return method(value)
  File "/Users/zharkynaskatkyzy/PycharmProjects/Zmall/server/apps/advert/serializers/advert_serializers.py", line 107, in get_views
    ad_views = redis_views['views_counter']
TypeError: byte indices must be integers or slices, not str
2022-09-15 08:05:57,557 [log | ERROR] Internal Server Error: /api/v1/advert/1/
Traceback (most recent call last):
  File "/Library/Frameworks/Python.framework/Versions/3.10/lib/python3.10/site-packages/django/core/handlers/exception.py", line 55, in inner
    response = get_response(request)
  File "/Library/Frameworks/Python.framework/Versions/3.10/lib/python3.10/site-packages/django/core/handlers/base.py", line 197, in _get_response
    response = wrapped_callback(request, *callback_args, **callback_kwargs)
  File "/Library/Frameworks/Python.framework/Versions/3.10/lib/python3.10/site-packages/django/views/decorators/csrf.py", line 54, in wrapped_view
    return view_func(*args, **kwargs)
  File "/Library/Frameworks/Python.framework/Versions/3.10/lib/python3.10/site-packages/rest_framework/viewsets.py", line 125, in view
    return self.dispatch(request, *args, **kwargs)
  File "/Library/Frameworks/Python.framework/Versions/3.10/lib/python3.10/site-packages/rest_framework/views.py", line 509, in dispatch
    response = self.handle_exception(exc)
  File "/Library/Frameworks/Python.framework/Versions/3.10/lib/python3.10/site-packages/rest_framework/views.py", line 469, in handle_exception
    self.raise_uncaught_exception(exc)
  File "/Library/Frameworks/Python.framework/Versions/3.10/lib/python3.10/site-packages/rest_framework/views.py", line 480, in raise_uncaught_exception
    raise exc
  File "/Library/Frameworks/Python.framework/Versions/3.10/lib/python3.10/site-packages/rest_framework/views.py", line 506, in dispatch
    response = handler(request, *args, **kwargs)
  File "/Library/Frameworks/Python.framework/Versions/3.10/lib/python3.10/site-packages/rest_framework/mixins.py", line 56, in retrieve
    return Response(serializer.data)
  File "/Library/Frameworks/Python.framework/Versions/3.10/lib/python3.10/site-packages/rest_framework/serializers.py", line 555, in data
    ret = super().data
  File "/Library/Frameworks/Python.framework/Versions/3.10/lib/python3.10/site-packages/rest_framework/serializers.py", line 253, in data
    self._data = self.to_representation(self.instance)
  File "/Library/Frameworks/Python.framework/Versions/3.10/lib/python3.10/site-packages/rest_framework/serializers.py", line 522, in to_representation
    ret[field.field_name] = field.to_representation(attribute)
  File "/Library/Frameworks/Python.framework/Versions/3.10/lib/python3.10/site-packages/rest_framework/fields.py", line 1886, in to_representation
    return method(value)
  File "/Users/zharkynaskatkyzy/PycharmProjects/Zmall/server/apps/advert/serializers/advert_serializers.py", line 107, in get_views
    ad_views = redis_views['views_counter']
TypeError: byte indices must be integers or slices, not str
2022-09-15 08:07:09,303 [autoreload | INFO] /Users/zharkynaskatkyzy/PycharmProjects/Zmall/server/apps/advert/serializers/advert_serializers.py changed, reloading.
2022-09-15 08:07:09,900 [autoreload | INFO] Watching for file changes with StatReloader
2022-09-15 08:12:57,401 [autoreload | INFO] /Users/zharkynaskatkyzy/PycharmProjects/Zmall/server/apps/advert/views/advert_views.py changed, reloading.
2022-09-15 08:12:59,357 [autoreload | INFO] Watching for file changes with StatReloader
2022-09-15 08:13:25,534 [autoreload | INFO] /Users/zharkynaskatkyzy/PycharmProjects/Zmall/server/apps/advert/serializers/advert_serializers.py changed, reloading.
2022-09-15 08:13:27,056 [autoreload | INFO] Watching for file changes with StatReloader
2022-09-15 08:19:53,119 [autoreload | INFO] /Users/zharkynaskatkyzy/PycharmProjects/Zmall/server/apps/advert/serializers/advert_serializers.py changed, reloading.
2022-09-15 08:19:55,201 [autoreload | INFO] Watching for file changes with StatReloader
2022-09-15 08:24:10,249 [autoreload | INFO] /Users/zharkynaskatkyzy/PycharmProjects/Zmall/server/apps/advert/views/statistics_views.py changed, reloading.
2022-09-15 08:24:11,907 [autoreload | INFO] Watching for file changes with StatReloader
2022-09-15 08:25:44,323 [autoreload | INFO] /Users/zharkynaskatkyzy/PycharmProjects/Zmall/server/apps/advert/views/statistics_views.py changed, reloading.
2022-09-15 08:25:44,962 [autoreload | INFO] Watching for file changes with StatReloader
2022-09-15 08:26:02,697 [autoreload | INFO] /Users/zharkynaskatkyzy/PycharmProjects/Zmall/server/apps/advert/views/statistics_views.py changed, reloading.
2022-09-15 08:26:03,188 [autoreload | INFO] Watching for file changes with StatReloader
2022-09-15 08:26:28,294 [autoreload | INFO] Watching for file changes with StatReloader
2022-09-15 08:26:30,999 [log | WARNING] Not Found: /
2022-09-15 08:26:33,490 [log | WARNING] Not Found: /
2022-09-15 08:28:52,449 [autoreload | INFO] /Users/zharkynaskatkyzy/PycharmProjects/Zmall/server/apps/advert/views/statistics_views.py changed, reloading.
2022-09-15 08:28:53,195 [autoreload | INFO] Watching for file changes with StatReloader
2022-09-15 08:30:19,604 [autoreload | INFO] /Users/zharkynaskatkyzy/PycharmProjects/Zmall/server/apps/advert/views/statistics_views.py changed, reloading.
2022-09-15 08:30:20,227 [autoreload | INFO] Watching for file changes with StatReloader
2022-09-15 08:30:51,997 [autoreload | INFO] Watching for file changes with StatReloader
2022-09-15 08:31:18,447 [autoreload | INFO] /Users/zharkynaskatkyzy/PycharmProjects/Zmall/server/apps/advert/views/statistics_views.py changed, reloading.
2022-09-15 08:31:18,981 [autoreload | INFO] Watching for file changes with StatReloader
2022-09-15 08:31:36,061 [autoreload | INFO] /Users/zharkynaskatkyzy/PycharmProjects/Zmall/server/apps/advert/views/statistics_views.py changed, reloading.
2022-09-15 08:31:36,551 [autoreload | INFO] Watching for file changes with StatReloader
2022-09-15 08:31:50,391 [autoreload | INFO] /Users/zharkynaskatkyzy/PycharmProjects/Zmall/server/apps/advert/views/advert_views.py changed, reloading.
2022-09-15 08:31:50,963 [autoreload | INFO] Watching for file changes with StatReloader
2022-09-15 08:32:18,409 [autoreload | INFO] /Users/zharkynaskatkyzy/PycharmProjects/Zmall/server/apps/advert/views/advert_views.py changed, reloading.
2022-09-15 08:32:18,957 [autoreload | INFO] Watching for file changes with StatReloader
2022-09-15 08:32:56,989 [autoreload | INFO] /Users/zharkynaskatkyzy/PycharmProjects/Zmall/server/apps/advert/views/statistics_views.py changed, reloading.
2022-09-15 08:32:57,568 [autoreload | INFO] Watching for file changes with StatReloader
2022-09-15 08:34:46,240 [autoreload | INFO] /Users/zharkynaskatkyzy/PycharmProjects/Zmall/server/apps/advert/views/statistics_views.py changed, reloading.
2022-09-15 08:34:47,751 [autoreload | INFO] Watching for file changes with StatReloader
2022-09-15 08:35:24,882 [autoreload | INFO] /Users/zharkynaskatkyzy/PycharmProjects/Zmall/server/apps/advert/views/statistics_views.py changed, reloading.
2022-09-15 08:35:25,843 [autoreload | INFO] Watching for file changes with StatReloader
2022-09-15 08:35:37,845 [base | WARNING] view's ContactView raised exception during schema generation; use `getattr(self, 'swagger_fake_view', False)` to detect and short-circuit this
Traceback (most recent call last):
  File "/Library/Frameworks/Python.framework/Versions/3.10/lib/python3.10/site-packages/drf_yasg/inspectors/base.py", line 42, in call_view_method
    return view_method()
  File "/Library/Frameworks/Python.framework/Versions/3.10/lib/python3.10/site-packages/rest_framework/generics.py", line 108, in get_serializer
    serializer_class = self.get_serializer_class()
  File "/Library/Frameworks/Python.framework/Versions/3.10/lib/python3.10/site-packages/rest_framework/generics.py", line 122, in get_serializer_class
    assert self.serializer_class is not None, (
AssertionError: 'ContactView' should either include a `serializer_class` attribute, or override the `get_serializer_class()` method.
2022-09-15 08:35:37,846 [base | WARNING] view's ContactView raised exception during schema generation; use `getattr(self, 'swagger_fake_view', False)` to detect and short-circuit this
Traceback (most recent call last):
  File "/Library/Frameworks/Python.framework/Versions/3.10/lib/python3.10/site-packages/drf_yasg/inspectors/base.py", line 42, in call_view_method
    return view_method()
  File "/Library/Frameworks/Python.framework/Versions/3.10/lib/python3.10/site-packages/rest_framework/generics.py", line 108, in get_serializer
    serializer_class = self.get_serializer_class()
  File "/Library/Frameworks/Python.framework/Versions/3.10/lib/python3.10/site-packages/rest_framework/generics.py", line 122, in get_serializer_class
    assert self.serializer_class is not None, (
AssertionError: 'ContactView' should either include a `serializer_class` attribute, or override the `get_serializer_class()` method.
2022-09-15 08:35:37,858 [base | WARNING] view's VerifyEmail raised exception during schema generation; use `getattr(self, 'swagger_fake_view', False)` to detect and short-circuit this
Traceback (most recent call last):
  File "/Library/Frameworks/Python.framework/Versions/3.10/lib/python3.10/site-packages/drf_yasg/inspectors/base.py", line 42, in call_view_method
    return view_method()
  File "/Library/Frameworks/Python.framework/Versions/3.10/lib/python3.10/site-packages/rest_framework/generics.py", line 108, in get_serializer
    serializer_class = self.get_serializer_class()
  File "/Library/Frameworks/Python.framework/Versions/3.10/lib/python3.10/site-packages/rest_framework/generics.py", line 122, in get_serializer_class
    assert self.serializer_class is not None, (
AssertionError: 'VerifyEmail' should either include a `serializer_class` attribute, or override the `get_serializer_class()` method.
2022-09-15 08:35:46,996 [base | WARNING] view's ContactView raised exception during schema generation; use `getattr(self, 'swagger_fake_view', False)` to detect and short-circuit this
Traceback (most recent call last):
  File "/Library/Frameworks/Python.framework/Versions/3.10/lib/python3.10/site-packages/drf_yasg/inspectors/base.py", line 42, in call_view_method
    return view_method()
  File "/Library/Frameworks/Python.framework/Versions/3.10/lib/python3.10/site-packages/rest_framework/generics.py", line 108, in get_serializer
    serializer_class = self.get_serializer_class()
  File "/Library/Frameworks/Python.framework/Versions/3.10/lib/python3.10/site-packages/rest_framework/generics.py", line 122, in get_serializer_class
    assert self.serializer_class is not None, (
AssertionError: 'ContactView' should either include a `serializer_class` attribute, or override the `get_serializer_class()` method.
2022-09-15 08:35:46,996 [base | WARNING] view's ContactView raised exception during schema generation; use `getattr(self, 'swagger_fake_view', False)` to detect and short-circuit this
Traceback (most recent call last):
  File "/Library/Frameworks/Python.framework/Versions/3.10/lib/python3.10/site-packages/drf_yasg/inspectors/base.py", line 42, in call_view_method
    return view_method()
  File "/Library/Frameworks/Python.framework/Versions/3.10/lib/python3.10/site-packages/rest_framework/generics.py", line 108, in get_serializer
    serializer_class = self.get_serializer_class()
  File "/Library/Frameworks/Python.framework/Versions/3.10/lib/python3.10/site-packages/rest_framework/generics.py", line 122, in get_serializer_class
    assert self.serializer_class is not None, (
AssertionError: 'ContactView' should either include a `serializer_class` attribute, or override the `get_serializer_class()` method.
2022-09-15 08:35:47,009 [base | WARNING] view's VerifyEmail raised exception during schema generation; use `getattr(self, 'swagger_fake_view', False)` to detect and short-circuit this
Traceback (most recent call last):
  File "/Library/Frameworks/Python.framework/Versions/3.10/lib/python3.10/site-packages/drf_yasg/inspectors/base.py", line 42, in call_view_method
    return view_method()
  File "/Library/Frameworks/Python.framework/Versions/3.10/lib/python3.10/site-packages/rest_framework/generics.py", line 108, in get_serializer
    serializer_class = self.get_serializer_class()
  File "/Library/Frameworks/Python.framework/Versions/3.10/lib/python3.10/site-packages/rest_framework/generics.py", line 122, in get_serializer_class
    assert self.serializer_class is not None, (
AssertionError: 'VerifyEmail' should either include a `serializer_class` attribute, or override the `get_serializer_class()` method.
2022-09-15 08:36:00,276 [base | WARNING] view's ContactView raised exception during schema generation; use `getattr(self, 'swagger_fake_view', False)` to detect and short-circuit this
Traceback (most recent call last):
  File "/Library/Frameworks/Python.framework/Versions/3.10/lib/python3.10/site-packages/drf_yasg/inspectors/base.py", line 42, in call_view_method
    return view_method()
  File "/Library/Frameworks/Python.framework/Versions/3.10/lib/python3.10/site-packages/rest_framework/generics.py", line 108, in get_serializer
    serializer_class = self.get_serializer_class()
  File "/Library/Frameworks/Python.framework/Versions/3.10/lib/python3.10/site-packages/rest_framework/generics.py", line 122, in get_serializer_class
    assert self.serializer_class is not None, (
AssertionError: 'ContactView' should either include a `serializer_class` attribute, or override the `get_serializer_class()` method.
2022-09-15 08:36:00,276 [base | WARNING] view's ContactView raised exception during schema generation; use `getattr(self, 'swagger_fake_view', False)` to detect and short-circuit this
Traceback (most recent call last):
  File "/Library/Frameworks/Python.framework/Versions/3.10/lib/python3.10/site-packages/drf_yasg/inspectors/base.py", line 42, in call_view_method
    return view_method()
  File "/Library/Frameworks/Python.framework/Versions/3.10/lib/python3.10/site-packages/rest_framework/generics.py", line 108, in get_serializer
    serializer_class = self.get_serializer_class()
  File "/Library/Frameworks/Python.framework/Versions/3.10/lib/python3.10/site-packages/rest_framework/generics.py", line 122, in get_serializer_class
    assert self.serializer_class is not None, (
AssertionError: 'ContactView' should either include a `serializer_class` attribute, or override the `get_serializer_class()` method.
2022-09-15 08:36:00,293 [base | WARNING] view's VerifyEmail raised exception during schema generation; use `getattr(self, 'swagger_fake_view', False)` to detect and short-circuit this
Traceback (most recent call last):
  File "/Library/Frameworks/Python.framework/Versions/3.10/lib/python3.10/site-packages/drf_yasg/inspectors/base.py", line 42, in call_view_method
    return view_method()
  File "/Library/Frameworks/Python.framework/Versions/3.10/lib/python3.10/site-packages/rest_framework/generics.py", line 108, in get_serializer
    serializer_class = self.get_serializer_class()
  File "/Library/Frameworks/Python.framework/Versions/3.10/lib/python3.10/site-packages/rest_framework/generics.py", line 122, in get_serializer_class
    assert self.serializer_class is not None, (
AssertionError: 'VerifyEmail' should either include a `serializer_class` attribute, or override the `get_serializer_class()` method.
2022-09-15 08:37:44,602 [log | WARNING] Bad Request: /api/v1/statistics/
2022-09-15 08:41:29,493 [autoreload | INFO] /Users/zharkynaskatkyzy/PycharmProjects/Zmall/server/apps/advert/serializers/advert_serializers.py changed, reloading.
2022-09-15 08:41:30,354 [autoreload | INFO] Watching for file changes with StatReloader
2022-09-15 08:42:49,255 [base | WARNING] view's ContactView raised exception during schema generation; use `getattr(self, 'swagger_fake_view', False)` to detect and short-circuit this
Traceback (most recent call last):
  File "/Library/Frameworks/Python.framework/Versions/3.10/lib/python3.10/site-packages/drf_yasg/inspectors/base.py", line 42, in call_view_method
    return view_method()
  File "/Library/Frameworks/Python.framework/Versions/3.10/lib/python3.10/site-packages/rest_framework/generics.py", line 108, in get_serializer
    serializer_class = self.get_serializer_class()
  File "/Library/Frameworks/Python.framework/Versions/3.10/lib/python3.10/site-packages/rest_framework/generics.py", line 122, in get_serializer_class
    assert self.serializer_class is not None, (
AssertionError: 'ContactView' should either include a `serializer_class` attribute, or override the `get_serializer_class()` method.
2022-09-15 08:42:49,256 [base | WARNING] view's ContactView raised exception during schema generation; use `getattr(self, 'swagger_fake_view', False)` to detect and short-circuit this
Traceback (most recent call last):
  File "/Library/Frameworks/Python.framework/Versions/3.10/lib/python3.10/site-packages/drf_yasg/inspectors/base.py", line 42, in call_view_method
    return view_method()
  File "/Library/Frameworks/Python.framework/Versions/3.10/lib/python3.10/site-packages/rest_framework/generics.py", line 108, in get_serializer
    serializer_class = self.get_serializer_class()
  File "/Library/Frameworks/Python.framework/Versions/3.10/lib/python3.10/site-packages/rest_framework/generics.py", line 122, in get_serializer_class
    assert self.serializer_class is not None, (
AssertionError: 'ContactView' should either include a `serializer_class` attribute, or override the `get_serializer_class()` method.
2022-09-15 08:42:49,269 [base | WARNING] view's VerifyEmail raised exception during schema generation; use `getattr(self, 'swagger_fake_view', False)` to detect and short-circuit this
Traceback (most recent call last):
  File "/Library/Frameworks/Python.framework/Versions/3.10/lib/python3.10/site-packages/drf_yasg/inspectors/base.py", line 42, in call_view_method
    return view_method()
  File "/Library/Frameworks/Python.framework/Versions/3.10/lib/python3.10/site-packages/rest_framework/generics.py", line 108, in get_serializer
    serializer_class = self.get_serializer_class()
  File "/Library/Frameworks/Python.framework/Versions/3.10/lib/python3.10/site-packages/rest_framework/generics.py", line 122, in get_serializer_class
    assert self.serializer_class is not None, (
AssertionError: 'VerifyEmail' should either include a `serializer_class` attribute, or override the `get_serializer_class()` method.
2022-09-15 08:42:56,253 [log | WARNING] Method Not Allowed: /api/v1/user/login/
2022-09-15 08:44:13,680 [log | ERROR] Internal Server Error: /api/v1/user_advert_update/10
Traceback (most recent call last):
  File "/Library/Frameworks/Python.framework/Versions/3.10/lib/python3.10/site-packages/django/core/handlers/exception.py", line 55, in inner
    response = get_response(request)
  File "/Library/Frameworks/Python.framework/Versions/3.10/lib/python3.10/site-packages/django/utils/deprecation.py", line 135, in __call__
    response = self.process_request(request)
  File "/Library/Frameworks/Python.framework/Versions/3.10/lib/python3.10/site-packages/django/middleware/common.py", line 54, in process_request
    path = self.get_full_path_with_slash(request)
  File "/Library/Frameworks/Python.framework/Versions/3.10/lib/python3.10/site-packages/django/middleware/common.py", line 88, in get_full_path_with_slash
    raise RuntimeError(
RuntimeError: You called this URL via POST, but the URL doesn't end in a slash and you have APPEND_SLASH set. Django can't redirect to the slash URL while maintaining POST data. Change your form to point to 127.0.0.1:8000/api/v1/user_advert_update/10/ (note the trailing slash), or set APPEND_SLASH=False in your Django settings.
2022-09-15 08:44:26,859 [base | WARNING] view's ContactView raised exception during schema generation; use `getattr(self, 'swagger_fake_view', False)` to detect and short-circuit this
Traceback (most recent call last):
  File "/Library/Frameworks/Python.framework/Versions/3.10/lib/python3.10/site-packages/drf_yasg/inspectors/base.py", line 42, in call_view_method
    return view_method()
  File "/Library/Frameworks/Python.framework/Versions/3.10/lib/python3.10/site-packages/rest_framework/generics.py", line 108, in get_serializer
    serializer_class = self.get_serializer_class()
  File "/Library/Frameworks/Python.framework/Versions/3.10/lib/python3.10/site-packages/rest_framework/generics.py", line 122, in get_serializer_class
    assert self.serializer_class is not None, (
AssertionError: 'ContactView' should either include a `serializer_class` attribute, or override the `get_serializer_class()` method.
2022-09-15 08:44:26,863 [base | WARNING] view's ContactView raised exception during schema generation; use `getattr(self, 'swagger_fake_view', False)` to detect and short-circuit this
Traceback (most recent call last):
  File "/Library/Frameworks/Python.framework/Versions/3.10/lib/python3.10/site-packages/drf_yasg/inspectors/base.py", line 42, in call_view_method
    return view_method()
  File "/Library/Frameworks/Python.framework/Versions/3.10/lib/python3.10/site-packages/rest_framework/generics.py", line 108, in get_serializer
    serializer_class = self.get_serializer_class()
  File "/Library/Frameworks/Python.framework/Versions/3.10/lib/python3.10/site-packages/rest_framework/generics.py", line 122, in get_serializer_class
    assert self.serializer_class is not None, (
AssertionError: 'ContactView' should either include a `serializer_class` attribute, or override the `get_serializer_class()` method.
2022-09-15 08:44:26,885 [base | WARNING] view's VerifyEmail raised exception during schema generation; use `getattr(self, 'swagger_fake_view', False)` to detect and short-circuit this
Traceback (most recent call last):
  File "/Library/Frameworks/Python.framework/Versions/3.10/lib/python3.10/site-packages/drf_yasg/inspectors/base.py", line 42, in call_view_method
    return view_method()
  File "/Library/Frameworks/Python.framework/Versions/3.10/lib/python3.10/site-packages/rest_framework/generics.py", line 108, in get_serializer
    serializer_class = self.get_serializer_class()
  File "/Library/Frameworks/Python.framework/Versions/3.10/lib/python3.10/site-packages/rest_framework/generics.py", line 122, in get_serializer_class
    assert self.serializer_class is not None, (
AssertionError: 'VerifyEmail' should either include a `serializer_class` attribute, or override the `get_serializer_class()` method.
2022-09-15 08:44:41,881 [log | WARNING] Method Not Allowed: /api/v1/user_advert_update/83/
2022-09-15 08:46:38,369 [autoreload | INFO] /Users/zharkynaskatkyzy/PycharmProjects/Zmall/server/config/settings/base.py changed, reloading.
